====== Execution Results for Generated Solvers ======

--- Running: 2D_Unsteady_Heat_Equation.py ---
Exit Code: 0
Output:

Errors:

--------------------------------------------------

--- Running: Fully_Developed_Turbulent_Channel_Flow.py ---
Exit Code: 0
Output:

Errors:
Error: failed to send plot to http://127.0.0.1:63342
Traceback (most recent call last):
  File "/home/weichao/Downloads/pycharm-2023.2.1/plugins/python/helpers/pycharm_display/datalore/display/display_.py", line 86, in _send_display_message
    urllib_request.urlopen(url, buffer)
  File "/opt/Dino_parallel/lib/python3.8/urllib/request.py", line 222, in urlopen
    return opener.open(url, data, timeout)
  File "/opt/Dino_parallel/lib/python3.8/urllib/request.py", line 531, in open
    response = meth(req, response)
  File "/opt/Dino_parallel/lib/python3.8/urllib/request.py", line 640, in http_response
    response = self.parent.error(
  File "/opt/Dino_parallel/lib/python3.8/urllib/request.py", line 569, in error
    return self._call_chain(*args)
  File "/opt/Dino_parallel/lib/python3.8/urllib/request.py", line 502, in _call_chain
    result = func(*args)
  File "/opt/Dino_parallel/lib/python3.8/urllib/request.py", line 649, in http_error_default
    raise HTTPError(req.full_url, code, msg, hdrs, fp)
urllib.error.HTTPError: HTTP Error 429: Too Many Requests

During handling of the above exception, another exception occurred:

Traceback (most recent call last):
  File "/home/weichao/Downloads/pycharm-2023.2.1/plugins/python/helpers/pycharm_display/datalore/display/display_.py", line 61, in try_empty_proxy
    urllib_request.urlopen(url, buffer)
  File "/opt/Dino_parallel/lib/python3.8/urllib/request.py", line 222, in urlopen
    return opener.open(url, data, timeout)
  File "/opt/Dino_parallel/lib/python3.8/urllib/request.py", line 531, in open
    response = meth(req, response)
  File "/opt/Dino_parallel/lib/python3.8/urllib/request.py", line 640, in http_response
    response = self.parent.error(
  File "/opt/Dino_parallel/lib/python3.8/urllib/request.py", line 569, in error
    return self._call_chain(*args)
  File "/opt/Dino_parallel/lib/python3.8/urllib/request.py", line 502, in _call_chain
    result = func(*args)
  File "/opt/Dino_parallel/lib/python3.8/urllib/request.py", line 649, in http_error_default
    raise HTTPError(req.full_url, code, msg, hdrs, fp)
urllib.error.HTTPError: HTTP Error 429: Too Many Requests

--------------------------------------------------

--- Running: 2D_Unsteady_Heat_Equation_2.py ---
Exit Code: 0
Output:

Errors:
Error: failed to send plot to http://127.0.0.1:63342
Traceback (most recent call last):
  File "/home/weichao/Downloads/pycharm-2023.2.1/plugins/python/helpers/pycharm_display/datalore/display/display_.py", line 86, in _send_display_message
    urllib_request.urlopen(url, buffer)
  File "/opt/Dino_parallel/lib/python3.8/urllib/request.py", line 222, in urlopen
    return opener.open(url, data, timeout)
  File "/opt/Dino_parallel/lib/python3.8/urllib/request.py", line 531, in open
    response = meth(req, response)
  File "/opt/Dino_parallel/lib/python3.8/urllib/request.py", line 640, in http_response
    response = self.parent.error(
  File "/opt/Dino_parallel/lib/python3.8/urllib/request.py", line 569, in error
    return self._call_chain(*args)
  File "/opt/Dino_parallel/lib/python3.8/urllib/request.py", line 502, in _call_chain
    result = func(*args)
  File "/opt/Dino_parallel/lib/python3.8/urllib/request.py", line 649, in http_error_default
    raise HTTPError(req.full_url, code, msg, hdrs, fp)
urllib.error.HTTPError: HTTP Error 429: Too Many Requests

During handling of the above exception, another exception occurred:

Traceback (most recent call last):
  File "/home/weichao/Downloads/pycharm-2023.2.1/plugins/python/helpers/pycharm_display/datalore/display/display_.py", line 61, in try_empty_proxy
    urllib_request.urlopen(url, buffer)
  File "/opt/Dino_parallel/lib/python3.8/urllib/request.py", line 222, in urlopen
    return opener.open(url, data, timeout)
  File "/opt/Dino_parallel/lib/python3.8/urllib/request.py", line 531, in open
    response = meth(req, response)
  File "/opt/Dino_parallel/lib/python3.8/urllib/request.py", line 640, in http_response
    response = self.parent.error(
  File "/opt/Dino_parallel/lib/python3.8/urllib/request.py", line 569, in error
    return self._call_chain(*args)
  File "/opt/Dino_parallel/lib/python3.8/urllib/request.py", line 502, in _call_chain
    result = func(*args)
  File "/opt/Dino_parallel/lib/python3.8/urllib/request.py", line 649, in http_error_default
    raise HTTPError(req.full_url, code, msg, hdrs, fp)
urllib.error.HTTPError: HTTP Error 429: Too Many Requests

--------------------------------------------------

--- Running: 2D_Diffusion.py ---
Exit Code: 0
Output:

Errors:
Error: failed to send plot to http://127.0.0.1:63342
Traceback (most recent call last):
  File "/home/weichao/Downloads/pycharm-2023.2.1/plugins/python/helpers/pycharm_display/datalore/display/display_.py", line 86, in _send_display_message
    urllib_request.urlopen(url, buffer)
  File "/opt/Dino_parallel/lib/python3.8/urllib/request.py", line 222, in urlopen
    return opener.open(url, data, timeout)
  File "/opt/Dino_parallel/lib/python3.8/urllib/request.py", line 531, in open
    response = meth(req, response)
  File "/opt/Dino_parallel/lib/python3.8/urllib/request.py", line 640, in http_response
    response = self.parent.error(
  File "/opt/Dino_parallel/lib/python3.8/urllib/request.py", line 569, in error
    return self._call_chain(*args)
  File "/opt/Dino_parallel/lib/python3.8/urllib/request.py", line 502, in _call_chain
    result = func(*args)
  File "/opt/Dino_parallel/lib/python3.8/urllib/request.py", line 649, in http_error_default
    raise HTTPError(req.full_url, code, msg, hdrs, fp)
urllib.error.HTTPError: HTTP Error 429: Too Many Requests

During handling of the above exception, another exception occurred:

Traceback (most recent call last):
  File "/home/weichao/Downloads/pycharm-2023.2.1/plugins/python/helpers/pycharm_display/datalore/display/display_.py", line 61, in try_empty_proxy
    urllib_request.urlopen(url, buffer)
  File "/opt/Dino_parallel/lib/python3.8/urllib/request.py", line 222, in urlopen
    return opener.open(url, data, timeout)
  File "/opt/Dino_parallel/lib/python3.8/urllib/request.py", line 531, in open
    response = meth(req, response)
  File "/opt/Dino_parallel/lib/python3.8/urllib/request.py", line 640, in http_response
    response = self.parent.error(
  File "/opt/Dino_parallel/lib/python3.8/urllib/request.py", line 569, in error
    return self._call_chain(*args)
  File "/opt/Dino_parallel/lib/python3.8/urllib/request.py", line 502, in _call_chain
    result = func(*args)
  File "/opt/Dino_parallel/lib/python3.8/urllib/request.py", line 649, in http_error_default
    raise HTTPError(req.full_url, code, msg, hdrs, fp)
urllib.error.HTTPError: HTTP Error 429: Too Many Requests

--------------------------------------------------

--- Running: 2D_Navier_Stokes_Cavity.py ---
Exit Code: 0
Output:

Errors:

--------------------------------------------------

--- Running: 1D_Linear_Convection.py ---
Exit Code: 0
Output:

Errors:

--------------------------------------------------

--- Running: 2D_Inviscid_Burgers.py ---
Exit Code: 0
Output:

Errors:

--------------------------------------------------

--- Running: 2D_Steady_Heat_Equation.py ---
Exit Code: 0
Output:
Warning: Didn't converge after 500 iterations.

Errors:

--------------------------------------------------

--- Running: 2D_Unsteady_Heat_Equation_1.py ---
Exit Code: 0
Output:

Errors:

--------------------------------------------------

--- Running: 2D_Diffusion_FVM.py ---
Exit Code: 0
Output:

Errors:
/home/weichao/.local/lib/python3.8/site-packages/scipy/sparse/linalg/_dsolve/linsolve.py:214: SparseEfficiencyWarning: spsolve requires A be CSC or CSR matrix format
  warn('spsolve requires A be CSC or CSR matrix format',

--------------------------------------------------

--- Running: 2D_Convection.py ---
Exit Code: 0
Output:

Errors:
/opt/CFD-Benchmark/PDE_Benchmark_5/solver_4/2D_Convection.py:29: RuntimeWarning: overflow encountered in multiply
  u[1:, 1:] = un[1:, 1:] - un[1:, 1:] * dt / dx * (un[1:, 1:] - un[1:, :-1]) - vn[1:, 1:] * dt / dy * (un[1:, 1:] - un[:-1, 1:])
/opt/CFD-Benchmark/PDE_Benchmark_5/solver_4/2D_Convection.py:29: RuntimeWarning: invalid value encountered in subtract
  u[1:, 1:] = un[1:, 1:] - un[1:, 1:] * dt / dx * (un[1:, 1:] - un[1:, :-1]) - vn[1:, 1:] * dt / dy * (un[1:, 1:] - un[:-1, 1:])
/opt/CFD-Benchmark/PDE_Benchmark_5/solver_4/2D_Convection.py:30: RuntimeWarning: overflow encountered in multiply
  v[1:, 1:] = vn[1:, 1:] - un[1:, 1:] * dt / dx * (vn[1:, 1:] - vn[1:, :-1]) - vn[1:, 1:] * dt / dy * (vn[1:, 1:] - vn[:-1, 1:])
/opt/CFD-Benchmark/PDE_Benchmark_5/solver_4/2D_Convection.py:30: RuntimeWarning: invalid value encountered in subtract
  v[1:, 1:] = vn[1:, 1:] - un[1:, 1:] * dt / dx * (vn[1:, 1:] - vn[1:, :-1]) - vn[1:, 1:] * dt / dy * (vn[1:, 1:] - vn[:-1, 1:])
/home/weichao/.local/lib/python3.8/site-packages/numpy/ma/core.py:6957: RuntimeWarning: overflow encountered in power
  result = np.where(m, fa, umath.power(fa, fb)).view(basetype)

--------------------------------------------------

--- Running: 1D_Nonlinear_Convection.py ---
Exit Code: 0
Output:

Errors:

--------------------------------------------------

--- Running: 1D_Euler_Shock_Tube.py ---
Exit Code: 0
Output:

Errors:
/opt/CFD-Benchmark/PDE_Benchmark_5/solver_4/1D_Euler_Shock_Tube.py:45: RuntimeWarning: overflow encountered in multiply
  F_pred[2] = (u_pred[2] + (Î³ - 1) * (u_pred[2] - 0.5 * u_pred[1] ** 2 / u_pred[0])) * u_pred[1] / u_pred[0]
/opt/CFD-Benchmark/PDE_Benchmark_5/solver_4/1D_Euler_Shock_Tube.py:47: RuntimeWarning: invalid value encountered in subtract
  u_corr[:, 1:] = 0.5 * (u_con[:, 1:] + u_pred[:, 1:] - dt / dx * (F_pred[:, 1:] - F_pred[:, :-1]))
/opt/CFD-Benchmark/PDE_Benchmark_5/solver_4/1D_Euler_Shock_Tube.py:36: RuntimeWarning: overflow encountered in square
  F[1] = u_con[1] ** 2 / u_con[0] + (Î³ - 1) * (u_con[2] - 0.5 * u_con[1] ** 2 / u_con[0])
/opt/CFD-Benchmark/PDE_Benchmark_5/solver_4/1D_Euler_Shock_Tube.py:36: RuntimeWarning: invalid value encountered in add
  F[1] = u_con[1] ** 2 / u_con[0] + (Î³ - 1) * (u_con[2] - 0.5 * u_con[1] ** 2 / u_con[0])
/opt/CFD-Benchmark/PDE_Benchmark_5/solver_4/1D_Euler_Shock_Tube.py:37: RuntimeWarning: overflow encountered in square
  F[2] = (u_con[2] + (Î³ - 1) * (u_con[2] - 0.5 * u_con[1] ** 2 / u_con[0])) * u_con[1] / u_con[0]
/opt/CFD-Benchmark/PDE_Benchmark_5/solver_4/1D_Euler_Shock_Tube.py:37: RuntimeWarning: overflow encountered in multiply
  F[2] = (u_con[2] + (Î³ - 1) * (u_con[2] - 0.5 * u_con[1] ** 2 / u_con[0])) * u_con[1] / u_con[0]
/opt/CFD-Benchmark/PDE_Benchmark_5/solver_4/1D_Euler_Shock_Tube.py:39: RuntimeWarning: invalid value encountered in subtract
  u_pred[:, :-1] = u_con[:, :-1] - dt / dx * (F[:, 1:] - F[:, :-1])
/opt/CFD-Benchmark/PDE_Benchmark_5/solver_4/1D_Euler_Shock_Tube.py:44: RuntimeWarning: overflow encountered in square
  F_pred[1] = u_pred[1] ** 2 / u_pred[0] + (Î³ - 1) * (u_pred[2] - 0.5 * u_pred[1] ** 2 / u_pred[0])
/opt/CFD-Benchmark/PDE_Benchmark_5/solver_4/1D_Euler_Shock_Tube.py:44: RuntimeWarning: invalid value encountered in add
  F_pred[1] = u_pred[1] ** 2 / u_pred[0] + (Î³ - 1) * (u_pred[2] - 0.5 * u_pred[1] ** 2 / u_pred[0])
/opt/CFD-Benchmark/PDE_Benchmark_5/solver_4/1D_Euler_Shock_Tube.py:45: RuntimeWarning: overflow encountered in square
  F_pred[2] = (u_pred[2] + (Î³ - 1) * (u_pred[2] - 0.5 * u_pred[1] ** 2 / u_pred[0])) * u_pred[1] / u_pred[0]

--------------------------------------------------

--- Running: 2D_Linear_Convection.py ---
Exit Code: 0
Output:

Errors:

--------------------------------------------------

--- Running: 2D_Laplace_Equation.py ---
Exit Code: 0
Output:

Errors:

--------------------------------------------------

--- Running: 1D_Burgers_Equation.py ---
Exit Code: 0
Output:

Errors:

--------------------------------------------------

