====== Execution Results for Generated Solvers ======

--- Running: 2D_Unsteady_Heat_Equation.py ---
Exit Code: 0
Output:

Errors:

--------------------------------------------------

--- Running: Fully_Developed_Turbulent_Channel_Flow.py ---
Exit Code: 0
Output:

Errors:

--------------------------------------------------

--- Running: 2D_Unsteady_Heat_Equation_2.py ---
Exit Code: 0
Output:

Errors:

--------------------------------------------------

--- Running: 2D_Diffusion.py ---
Exit Code: 0
Output:

Errors:

--------------------------------------------------

--- Running: 2D_Navier_Stokes_Cavity.py ---
Exit Code: 0
Output:

Errors:
/home/weichao/.local/lib/python3.8/site-packages/matplotlib/quiver.py:646: RuntimeWarning: divide by zero encountered in scalar divide
  length = a * (widthu_per_lenu / (self.scale * self.width))
/home/weichao/.local/lib/python3.8/site-packages/matplotlib/quiver.py:646: RuntimeWarning: invalid value encountered in multiply
  length = a * (widthu_per_lenu / (self.scale * self.width))

--------------------------------------------------

--- Running: 1D_Linear_Convection.py ---
Exit Code: 0
Output:

Errors:

--------------------------------------------------

--- Running: 2D_Inviscid_Burgers.py ---
Exit Code: 0
Output:

Errors:
/opt/CFD-Benchmark/PDE_Benchmark_5/solver_1/2D_Inviscid_Burgers.py:25: RuntimeWarning: overflow encountered in multiply
  un[1:-1, 1:-1] * dt/dx * (un[1:-1, 1:-1] - un[1:-1, 0:-2]) -
/opt/CFD-Benchmark/PDE_Benchmark_5/solver_1/2D_Inviscid_Burgers.py:26: RuntimeWarning: overflow encountered in multiply
  vn[1:-1, 1:-1] * dt/dy * (un[1:-1, 1:-1] - un[0:-2, 1:-1]))
/opt/CFD-Benchmark/PDE_Benchmark_5/solver_1/2D_Inviscid_Burgers.py:28: RuntimeWarning: overflow encountered in multiply
  un[1:-1, 1:-1] * dt/dx * (vn[1:-1, 1:-1] - vn[1:-1, 0:-2]) -
/opt/CFD-Benchmark/PDE_Benchmark_5/solver_1/2D_Inviscid_Burgers.py:29: RuntimeWarning: overflow encountered in multiply
  vn[1:-1, 1:-1] * dt/dy * (vn[1:-1, 1:-1] - vn[0:-2, 1:-1]))
/opt/CFD-Benchmark/PDE_Benchmark_5/solver_1/2D_Inviscid_Burgers.py:25: RuntimeWarning: invalid value encountered in multiply
  un[1:-1, 1:-1] * dt/dx * (un[1:-1, 1:-1] - un[1:-1, 0:-2]) -
/opt/CFD-Benchmark/PDE_Benchmark_5/solver_1/2D_Inviscid_Burgers.py:26: RuntimeWarning: invalid value encountered in multiply
  vn[1:-1, 1:-1] * dt/dy * (un[1:-1, 1:-1] - un[0:-2, 1:-1]))
/opt/CFD-Benchmark/PDE_Benchmark_5/solver_1/2D_Inviscid_Burgers.py:28: RuntimeWarning: invalid value encountered in multiply
  un[1:-1, 1:-1] * dt/dx * (vn[1:-1, 1:-1] - vn[1:-1, 0:-2]) -
/opt/CFD-Benchmark/PDE_Benchmark_5/solver_1/2D_Inviscid_Burgers.py:29: RuntimeWarning: invalid value encountered in multiply
  vn[1:-1, 1:-1] * dt/dy * (vn[1:-1, 1:-1] - vn[0:-2, 1:-1]))
/home/weichao/.local/lib/python3.8/site-packages/matplotlib/quiver.py:646: RuntimeWarning: divide by zero encountered in scalar divide
  length = a * (widthu_per_lenu / (self.scale * self.width))
/home/weichao/.local/lib/python3.8/site-packages/matplotlib/quiver.py:646: RuntimeWarning: invalid value encountered in multiply
  length = a * (widthu_per_lenu / (self.scale * self.width))

--------------------------------------------------

--- Running: 2D_Steady_Heat_Equation.py ---
Exit Code: 0
Output:

Errors:

--------------------------------------------------

--- Running: 2D_Unsteady_Heat_Equation_1.py ---
Exit Code: 1
Output:

Errors:
Traceback (most recent call last):
  File "/opt/CFD-Benchmark/PDE_Benchmark_5/solver_1/2D_Unsteady_Heat_Equation_1.py", line 48, in <module>
    plt.show()
  File "/home/weichao/.local/lib/python3.8/site-packages/matplotlib/pyplot.py", line 446, in show
    return _get_backend_mod().show(*args, **kwargs)
  File "/home/weichao/Downloads/pycharm-2023.2.1/plugins/python/helpers/pycharm_matplotlib_backend/backend_interagg.py", line 29, in __call__
    manager.show(**kwargs)
  File "/home/weichao/Downloads/pycharm-2023.2.1/plugins/python/helpers/pycharm_matplotlib_backend/backend_interagg.py", line 112, in show
    self.canvas.show()
  File "/home/weichao/Downloads/pycharm-2023.2.1/plugins/python/helpers/pycharm_matplotlib_backend/backend_interagg.py", line 68, in show
    FigureCanvasAgg.draw(self)
  File "/home/weichao/.local/lib/python3.8/site-packages/matplotlib/backends/backend_agg.py", line 400, in draw
    self.figure.draw(self.renderer)
  File "/home/weichao/.local/lib/python3.8/site-packages/matplotlib/artist.py", line 95, in draw_wrapper
    result = draw(artist, renderer, *args, **kwargs)
  File "/home/weichao/.local/lib/python3.8/site-packages/matplotlib/artist.py", line 72, in draw_wrapper
    return draw(artist, renderer)
  File "/home/weichao/.local/lib/python3.8/site-packages/matplotlib/figure.py", line 3185, in draw
    DrawEvent("draw_event", self.canvas, renderer)._process()
  File "/home/weichao/.local/lib/python3.8/site-packages/matplotlib/backend_bases.py", line 1263, in _process
    self.canvas.callbacks.process(self.name, self)
  File "/home/weichao/.local/lib/python3.8/site-packages/matplotlib/cbook/__init__.py", line 319, in process
    self.exception_handler(exc)
  File "/home/weichao/.local/lib/python3.8/site-packages/matplotlib/cbook/__init__.py", line 103, in _exception_printer
    raise exc
  File "/home/weichao/.local/lib/python3.8/site-packages/matplotlib/cbook/__init__.py", line 314, in process
    func(*args, **kwargs)
  File "/home/weichao/.local/lib/python3.8/site-packages/matplotlib/animation.py", line 904, in _start
    self._init_draw()
  File "/home/weichao/.local/lib/python3.8/site-packages/matplotlib/animation.py", line 1748, in _init_draw
    self._draw_frame(frame_data)
  File "/home/weichao/.local/lib/python3.8/site-packages/matplotlib/animation.py", line 1767, in _draw_frame
    self._drawn_artists = self._func(framedata, *self._args)
  File "/opt/CFD-Benchmark/PDE_Benchmark_5/solver_1/2D_Unsteady_Heat_Equation_1.py", line 42, in update
    ax.collections = []  # Clear previous plot
AttributeError: can't set attribute

--------------------------------------------------

--- Running: 2D_Diffusion_FVM.py ---
Exit Code: 0
Output:

Errors:

--------------------------------------------------

--- Running: 2D_Convection.py ---
Exit Code: 0
Output:

Errors:
/opt/CFD-Benchmark/PDE_Benchmark_5/solver_1/2D_Convection.py:42: RuntimeWarning: overflow encountered in multiply
  u[1:,1:] = un[1:,1:] - dt/dx*un[1:,1:]*(un[1:,1:]-un[:-1,1:]) - dt/dy*vn[1:,1:]*(un[1:,1:]-un[1:,:-1])
/opt/CFD-Benchmark/PDE_Benchmark_5/solver_1/2D_Convection.py:42: RuntimeWarning: invalid value encountered in subtract
  u[1:,1:] = un[1:,1:] - dt/dx*un[1:,1:]*(un[1:,1:]-un[:-1,1:]) - dt/dy*vn[1:,1:]*(un[1:,1:]-un[1:,:-1])
/opt/CFD-Benchmark/PDE_Benchmark_5/solver_1/2D_Convection.py:43: RuntimeWarning: overflow encountered in multiply
  v[1:,1:] = vn[1:,1:] - dt/dx*un[1:,1:]*(vn[1:,1:]-vn[:-1,1:]) - dt/dy*vn[1:,1:]*(vn[1:,1:]-vn[1:,:-1])
/opt/CFD-Benchmark/PDE_Benchmark_5/solver_1/2D_Convection.py:43: RuntimeWarning: invalid value encountered in subtract
  v[1:,1:] = vn[1:,1:] - dt/dx*un[1:,1:]*(vn[1:,1:]-vn[:-1,1:]) - dt/dy*vn[1:,1:]*(vn[1:,1:]-vn[1:,:-1])

--------------------------------------------------

--- Running: 1D_Nonlinear_Convection.py ---
Exit Code: 0
Output:

Errors:

--------------------------------------------------

--- Running: 1D_Euler_Shock_Tube.py ---
Exit Code: 0
Output:

Errors:
/opt/CFD-Benchmark/PDE_Benchmark_5/solver_1/1D_Euler_Shock_Tube.py:41: RuntimeWarning: overflow encountered in square
  F_star[1, :] = ((U_star[1, :] ** 2) / U_star[0, :]) + (gamma - 1) * (U_star[2, :] - 0.5 * (U_star[1, :] ** 2) / U_star[0, :])
/opt/CFD-Benchmark/PDE_Benchmark_5/solver_1/1D_Euler_Shock_Tube.py:41: RuntimeWarning: invalid value encountered in add
  F_star[1, :] = ((U_star[1, :] ** 2) / U_star[0, :]) + (gamma - 1) * (U_star[2, :] - 0.5 * (U_star[1, :] ** 2) / U_star[0, :])
/opt/CFD-Benchmark/PDE_Benchmark_5/solver_1/1D_Euler_Shock_Tube.py:42: RuntimeWarning: overflow encountered in square
  F_star[2, :] = (U_star[2, :] + (gamma - 1) * (U_star[2, :] - 0.5 * (U_star[1, :] ** 2) / U_star[0, :])) * (U_star[1, :] / U_star[0, :])
/opt/CFD-Benchmark/PDE_Benchmark_5/solver_1/1D_Euler_Shock_Tube.py:44: RuntimeWarning: invalid value encountered in subtract
  U_new[:, 1:] = 0.5 * (U[:, 1:] + U_star[:, 1:] - dt / dx * (F_star[:, 1:] - F_star[:, :-1]))
/opt/CFD-Benchmark/PDE_Benchmark_5/solver_1/1D_Euler_Shock_Tube.py:33: RuntimeWarning: overflow encountered in square
  F[1, :] = ((U[1, :] ** 2) / U[0, :]) + (gamma - 1) * (U[2, :] - 0.5 * (U[1, :] ** 2) / U[0, :])
/opt/CFD-Benchmark/PDE_Benchmark_5/solver_1/1D_Euler_Shock_Tube.py:33: RuntimeWarning: invalid value encountered in add
  F[1, :] = ((U[1, :] ** 2) / U[0, :]) + (gamma - 1) * (U[2, :] - 0.5 * (U[1, :] ** 2) / U[0, :])
/opt/CFD-Benchmark/PDE_Benchmark_5/solver_1/1D_Euler_Shock_Tube.py:34: RuntimeWarning: overflow encountered in square
  F[2, :] = (U[2, :] + (gamma - 1) * (U[2, :] - 0.5 * (U[1, :] ** 2) / U[0, :])) * (U[1, :] / U[0, :])
/opt/CFD-Benchmark/PDE_Benchmark_5/solver_1/1D_Euler_Shock_Tube.py:36: RuntimeWarning: invalid value encountered in subtract
  U_star[:, :-1] = U[:, :-1] - dt / dx * (F[:, 1:] - F[:, :-1])

--------------------------------------------------

--- Running: 2D_Linear_Convection.py ---
Exit Code: 0
Output:

Errors:
Error: failed to send plot to http://127.0.0.1:63342
Traceback (most recent call last):
  File "/home/weichao/Downloads/pycharm-2023.2.1/plugins/python/helpers/pycharm_display/datalore/display/display_.py", line 86, in _send_display_message
    urllib_request.urlopen(url, buffer)
  File "/opt/Dino_parallel/lib/python3.8/urllib/request.py", line 222, in urlopen
    return opener.open(url, data, timeout)
  File "/opt/Dino_parallel/lib/python3.8/urllib/request.py", line 531, in open
    response = meth(req, response)
  File "/opt/Dino_parallel/lib/python3.8/urllib/request.py", line 640, in http_response
    response = self.parent.error(
  File "/opt/Dino_parallel/lib/python3.8/urllib/request.py", line 569, in error
    return self._call_chain(*args)
  File "/opt/Dino_parallel/lib/python3.8/urllib/request.py", line 502, in _call_chain
    result = func(*args)
  File "/opt/Dino_parallel/lib/python3.8/urllib/request.py", line 649, in http_error_default
    raise HTTPError(req.full_url, code, msg, hdrs, fp)
urllib.error.HTTPError: HTTP Error 429: Too Many Requests

During handling of the above exception, another exception occurred:

Traceback (most recent call last):
  File "/home/weichao/Downloads/pycharm-2023.2.1/plugins/python/helpers/pycharm_display/datalore/display/display_.py", line 61, in try_empty_proxy
    urllib_request.urlopen(url, buffer)
  File "/opt/Dino_parallel/lib/python3.8/urllib/request.py", line 222, in urlopen
    return opener.open(url, data, timeout)
  File "/opt/Dino_parallel/lib/python3.8/urllib/request.py", line 531, in open
    response = meth(req, response)
  File "/opt/Dino_parallel/lib/python3.8/urllib/request.py", line 640, in http_response
    response = self.parent.error(
  File "/opt/Dino_parallel/lib/python3.8/urllib/request.py", line 569, in error
    return self._call_chain(*args)
  File "/opt/Dino_parallel/lib/python3.8/urllib/request.py", line 502, in _call_chain
    result = func(*args)
  File "/opt/Dino_parallel/lib/python3.8/urllib/request.py", line 649, in http_error_default
    raise HTTPError(req.full_url, code, msg, hdrs, fp)
urllib.error.HTTPError: HTTP Error 429: Too Many Requests

--------------------------------------------------

--- Running: 2D_Laplace_Equation.py ---
Exit Code: 0
Output:

Errors:
Error: failed to send plot to http://127.0.0.1:63342
Traceback (most recent call last):
  File "/home/weichao/Downloads/pycharm-2023.2.1/plugins/python/helpers/pycharm_display/datalore/display/display_.py", line 86, in _send_display_message
    urllib_request.urlopen(url, buffer)
  File "/opt/Dino_parallel/lib/python3.8/urllib/request.py", line 222, in urlopen
    return opener.open(url, data, timeout)
  File "/opt/Dino_parallel/lib/python3.8/urllib/request.py", line 531, in open
    response = meth(req, response)
  File "/opt/Dino_parallel/lib/python3.8/urllib/request.py", line 640, in http_response
    response = self.parent.error(
  File "/opt/Dino_parallel/lib/python3.8/urllib/request.py", line 569, in error
    return self._call_chain(*args)
  File "/opt/Dino_parallel/lib/python3.8/urllib/request.py", line 502, in _call_chain
    result = func(*args)
  File "/opt/Dino_parallel/lib/python3.8/urllib/request.py", line 649, in http_error_default
    raise HTTPError(req.full_url, code, msg, hdrs, fp)
urllib.error.HTTPError: HTTP Error 429: Too Many Requests

During handling of the above exception, another exception occurred:

Traceback (most recent call last):
  File "/home/weichao/Downloads/pycharm-2023.2.1/plugins/python/helpers/pycharm_display/datalore/display/display_.py", line 61, in try_empty_proxy
    urllib_request.urlopen(url, buffer)
  File "/opt/Dino_parallel/lib/python3.8/urllib/request.py", line 222, in urlopen
    return opener.open(url, data, timeout)
  File "/opt/Dino_parallel/lib/python3.8/urllib/request.py", line 531, in open
    response = meth(req, response)
  File "/opt/Dino_parallel/lib/python3.8/urllib/request.py", line 640, in http_response
    response = self.parent.error(
  File "/opt/Dino_parallel/lib/python3.8/urllib/request.py", line 569, in error
    return self._call_chain(*args)
  File "/opt/Dino_parallel/lib/python3.8/urllib/request.py", line 502, in _call_chain
    result = func(*args)
  File "/opt/Dino_parallel/lib/python3.8/urllib/request.py", line 649, in http_error_default
    raise HTTPError(req.full_url, code, msg, hdrs, fp)
urllib.error.HTTPError: HTTP Error 429: Too Many Requests

--------------------------------------------------

--- Running: 1D_Burgers_Equation.py ---
Exit Code: 0
Output:

Errors:
Error: failed to send plot to http://127.0.0.1:63342
Traceback (most recent call last):
  File "/home/weichao/Downloads/pycharm-2023.2.1/plugins/python/helpers/pycharm_display/datalore/display/display_.py", line 86, in _send_display_message
    urllib_request.urlopen(url, buffer)
  File "/opt/Dino_parallel/lib/python3.8/urllib/request.py", line 222, in urlopen
    return opener.open(url, data, timeout)
  File "/opt/Dino_parallel/lib/python3.8/urllib/request.py", line 531, in open
    response = meth(req, response)
  File "/opt/Dino_parallel/lib/python3.8/urllib/request.py", line 640, in http_response
    response = self.parent.error(
  File "/opt/Dino_parallel/lib/python3.8/urllib/request.py", line 569, in error
    return self._call_chain(*args)
  File "/opt/Dino_parallel/lib/python3.8/urllib/request.py", line 502, in _call_chain
    result = func(*args)
  File "/opt/Dino_parallel/lib/python3.8/urllib/request.py", line 649, in http_error_default
    raise HTTPError(req.full_url, code, msg, hdrs, fp)
urllib.error.HTTPError: HTTP Error 429: Too Many Requests

During handling of the above exception, another exception occurred:

Traceback (most recent call last):
  File "/home/weichao/Downloads/pycharm-2023.2.1/plugins/python/helpers/pycharm_display/datalore/display/display_.py", line 61, in try_empty_proxy
    urllib_request.urlopen(url, buffer)
  File "/opt/Dino_parallel/lib/python3.8/urllib/request.py", line 222, in urlopen
    return opener.open(url, data, timeout)
  File "/opt/Dino_parallel/lib/python3.8/urllib/request.py", line 531, in open
    response = meth(req, response)
  File "/opt/Dino_parallel/lib/python3.8/urllib/request.py", line 640, in http_response
    response = self.parent.error(
  File "/opt/Dino_parallel/lib/python3.8/urllib/request.py", line 569, in error
    return self._call_chain(*args)
  File "/opt/Dino_parallel/lib/python3.8/urllib/request.py", line 502, in _call_chain
    result = func(*args)
  File "/opt/Dino_parallel/lib/python3.8/urllib/request.py", line 649, in http_error_default
    raise HTTPError(req.full_url, code, msg, hdrs, fp)
urllib.error.HTTPError: HTTP Error 429: Too Many Requests

--------------------------------------------------

