====== Execution Results for Generated Solvers ======

--- Running: 2D_Unsteady_Heat_Equation.py ---
Exit Code: 0
Output:

Errors:

--------------------------------------------------

--- Running: Fully_Developed_Turbulent_Channel_Flow.py ---
Exit Code: 0
Output:

Errors:
Error: failed to send plot to http://127.0.0.1:63342
Traceback (most recent call last):
  File "/home/weichao/Downloads/pycharm-2023.2.1/plugins/python/helpers/pycharm_display/datalore/display/display_.py", line 86, in _send_display_message
    urllib_request.urlopen(url, buffer)
  File "/opt/Dino_parallel/lib/python3.8/urllib/request.py", line 222, in urlopen
    return opener.open(url, data, timeout)
  File "/opt/Dino_parallel/lib/python3.8/urllib/request.py", line 531, in open
    response = meth(req, response)
  File "/opt/Dino_parallel/lib/python3.8/urllib/request.py", line 640, in http_response
    response = self.parent.error(
  File "/opt/Dino_parallel/lib/python3.8/urllib/request.py", line 569, in error
    return self._call_chain(*args)
  File "/opt/Dino_parallel/lib/python3.8/urllib/request.py", line 502, in _call_chain
    result = func(*args)
  File "/opt/Dino_parallel/lib/python3.8/urllib/request.py", line 649, in http_error_default
    raise HTTPError(req.full_url, code, msg, hdrs, fp)
urllib.error.HTTPError: HTTP Error 429: Too Many Requests

During handling of the above exception, another exception occurred:

Traceback (most recent call last):
  File "/home/weichao/Downloads/pycharm-2023.2.1/plugins/python/helpers/pycharm_display/datalore/display/display_.py", line 61, in try_empty_proxy
    urllib_request.urlopen(url, buffer)
  File "/opt/Dino_parallel/lib/python3.8/urllib/request.py", line 222, in urlopen
    return opener.open(url, data, timeout)
  File "/opt/Dino_parallel/lib/python3.8/urllib/request.py", line 531, in open
    response = meth(req, response)
  File "/opt/Dino_parallel/lib/python3.8/urllib/request.py", line 640, in http_response
    response = self.parent.error(
  File "/opt/Dino_parallel/lib/python3.8/urllib/request.py", line 569, in error
    return self._call_chain(*args)
  File "/opt/Dino_parallel/lib/python3.8/urllib/request.py", line 502, in _call_chain
    result = func(*args)
  File "/opt/Dino_parallel/lib/python3.8/urllib/request.py", line 649, in http_error_default
    raise HTTPError(req.full_url, code, msg, hdrs, fp)
urllib.error.HTTPError: HTTP Error 429: Too Many Requests

--------------------------------------------------

--- Running: 2D_Unsteady_Heat_Equation_2.py ---
Exit Code: 0
Output:

Errors:
Error: failed to send plot to http://127.0.0.1:63342
Traceback (most recent call last):
  File "/home/weichao/Downloads/pycharm-2023.2.1/plugins/python/helpers/pycharm_display/datalore/display/display_.py", line 86, in _send_display_message
    urllib_request.urlopen(url, buffer)
  File "/opt/Dino_parallel/lib/python3.8/urllib/request.py", line 222, in urlopen
    return opener.open(url, data, timeout)
  File "/opt/Dino_parallel/lib/python3.8/urllib/request.py", line 531, in open
    response = meth(req, response)
  File "/opt/Dino_parallel/lib/python3.8/urllib/request.py", line 640, in http_response
    response = self.parent.error(
  File "/opt/Dino_parallel/lib/python3.8/urllib/request.py", line 569, in error
    return self._call_chain(*args)
  File "/opt/Dino_parallel/lib/python3.8/urllib/request.py", line 502, in _call_chain
    result = func(*args)
  File "/opt/Dino_parallel/lib/python3.8/urllib/request.py", line 649, in http_error_default
    raise HTTPError(req.full_url, code, msg, hdrs, fp)
urllib.error.HTTPError: HTTP Error 429: Too Many Requests

During handling of the above exception, another exception occurred:

Traceback (most recent call last):
  File "/home/weichao/Downloads/pycharm-2023.2.1/plugins/python/helpers/pycharm_display/datalore/display/display_.py", line 61, in try_empty_proxy
    urllib_request.urlopen(url, buffer)
  File "/opt/Dino_parallel/lib/python3.8/urllib/request.py", line 222, in urlopen
    return opener.open(url, data, timeout)
  File "/opt/Dino_parallel/lib/python3.8/urllib/request.py", line 531, in open
    response = meth(req, response)
  File "/opt/Dino_parallel/lib/python3.8/urllib/request.py", line 640, in http_response
    response = self.parent.error(
  File "/opt/Dino_parallel/lib/python3.8/urllib/request.py", line 569, in error
    return self._call_chain(*args)
  File "/opt/Dino_parallel/lib/python3.8/urllib/request.py", line 502, in _call_chain
    result = func(*args)
  File "/opt/Dino_parallel/lib/python3.8/urllib/request.py", line 649, in http_error_default
    raise HTTPError(req.full_url, code, msg, hdrs, fp)
urllib.error.HTTPError: HTTP Error 429: Too Many Requests

--------------------------------------------------

--- Running: 2D_Diffusion.py ---
Exit Code: 0
Output:

Errors:

--------------------------------------------------

--- Running: 2D_Navier_Stokes_Cavity.py ---
Exit Code: 0
Output:

Errors:

--------------------------------------------------

--- Running: 1D_Linear_Convection.py ---
Exit Code: 0
Output:

Errors:
Error: failed to send plot to http://127.0.0.1:63342
Traceback (most recent call last):
  File "/home/weichao/Downloads/pycharm-2023.2.1/plugins/python/helpers/pycharm_display/datalore/display/display_.py", line 86, in _send_display_message
    urllib_request.urlopen(url, buffer)
  File "/opt/Dino_parallel/lib/python3.8/urllib/request.py", line 222, in urlopen
    return opener.open(url, data, timeout)
  File "/opt/Dino_parallel/lib/python3.8/urllib/request.py", line 531, in open
    response = meth(req, response)
  File "/opt/Dino_parallel/lib/python3.8/urllib/request.py", line 640, in http_response
    response = self.parent.error(
  File "/opt/Dino_parallel/lib/python3.8/urllib/request.py", line 569, in error
    return self._call_chain(*args)
  File "/opt/Dino_parallel/lib/python3.8/urllib/request.py", line 502, in _call_chain
    result = func(*args)
  File "/opt/Dino_parallel/lib/python3.8/urllib/request.py", line 649, in http_error_default
    raise HTTPError(req.full_url, code, msg, hdrs, fp)
urllib.error.HTTPError: HTTP Error 429: Too Many Requests

During handling of the above exception, another exception occurred:

Traceback (most recent call last):
  File "/home/weichao/Downloads/pycharm-2023.2.1/plugins/python/helpers/pycharm_display/datalore/display/display_.py", line 61, in try_empty_proxy
    urllib_request.urlopen(url, buffer)
  File "/opt/Dino_parallel/lib/python3.8/urllib/request.py", line 222, in urlopen
    return opener.open(url, data, timeout)
  File "/opt/Dino_parallel/lib/python3.8/urllib/request.py", line 531, in open
    response = meth(req, response)
  File "/opt/Dino_parallel/lib/python3.8/urllib/request.py", line 640, in http_response
    response = self.parent.error(
  File "/opt/Dino_parallel/lib/python3.8/urllib/request.py", line 569, in error
    return self._call_chain(*args)
  File "/opt/Dino_parallel/lib/python3.8/urllib/request.py", line 502, in _call_chain
    result = func(*args)
  File "/opt/Dino_parallel/lib/python3.8/urllib/request.py", line 649, in http_error_default
    raise HTTPError(req.full_url, code, msg, hdrs, fp)
urllib.error.HTTPError: HTTP Error 429: Too Many Requests

--------------------------------------------------

--- Running: 2D_Inviscid_Burgers.py ---
Exit Code: 0
Output:

Errors:
/opt/CFD-Benchmark/PDE_Benchmark_5/solver_2/2D_Inviscid_Burgers.py:28: RuntimeWarning: overflow encountered in multiply
  (un[1:-1, 1:-1] * dt / dx * (un[1:-1, 1:-1] - un[1:-1, 0:-2])) -
/opt/CFD-Benchmark/PDE_Benchmark_5/solver_2/2D_Inviscid_Burgers.py:29: RuntimeWarning: overflow encountered in multiply
  vn[1:-1, 1:-1] * dt / dy * (un[1:-1, 1:-1] - un[0:-2, 1:-1]))
/opt/CFD-Benchmark/PDE_Benchmark_5/solver_2/2D_Inviscid_Burgers.py:27: RuntimeWarning: invalid value encountered in subtract
  u[1:-1, 1:-1] = (un[1:-1, 1:-1] -
/opt/CFD-Benchmark/PDE_Benchmark_5/solver_2/2D_Inviscid_Burgers.py:31: RuntimeWarning: overflow encountered in multiply
  (un[1:-1, 1:-1] * dt / dx * (vn[1:-1, 1:-1] - vn[1:-1, 0:-2])) -
/opt/CFD-Benchmark/PDE_Benchmark_5/solver_2/2D_Inviscid_Burgers.py:32: RuntimeWarning: overflow encountered in multiply
  vn[1:-1, 1:-1] * dt / dy * (vn[1:-1, 1:-1] - vn[0:-2, 1:-1]))
/opt/CFD-Benchmark/PDE_Benchmark_5/solver_2/2D_Inviscid_Burgers.py:30: RuntimeWarning: invalid value encountered in subtract
  v[1:-1, 1:-1] = (vn[1:-1, 1:-1] -
/opt/CFD-Benchmark/PDE_Benchmark_5/solver_2/2D_Inviscid_Burgers.py:28: RuntimeWarning: invalid value encountered in subtract
  (un[1:-1, 1:-1] * dt / dx * (un[1:-1, 1:-1] - un[1:-1, 0:-2])) -
/opt/CFD-Benchmark/PDE_Benchmark_5/solver_2/2D_Inviscid_Burgers.py:29: RuntimeWarning: invalid value encountered in subtract
  vn[1:-1, 1:-1] * dt / dy * (un[1:-1, 1:-1] - un[0:-2, 1:-1]))
/opt/CFD-Benchmark/PDE_Benchmark_5/solver_2/2D_Inviscid_Burgers.py:31: RuntimeWarning: invalid value encountered in subtract
  (un[1:-1, 1:-1] * dt / dx * (vn[1:-1, 1:-1] - vn[1:-1, 0:-2])) -
/opt/CFD-Benchmark/PDE_Benchmark_5/solver_2/2D_Inviscid_Burgers.py:32: RuntimeWarning: invalid value encountered in subtract
  vn[1:-1, 1:-1] * dt / dy * (vn[1:-1, 1:-1] - vn[0:-2, 1:-1]))
/home/weichao/.local/lib/python3.8/site-packages/matplotlib/quiver.py:646: RuntimeWarning: divide by zero encountered in scalar divide
  length = a * (widthu_per_lenu / (self.scale * self.width))
/home/weichao/.local/lib/python3.8/site-packages/matplotlib/quiver.py:646: RuntimeWarning: invalid value encountered in multiply
  length = a * (widthu_per_lenu / (self.scale * self.width))
Error: failed to send plot to http://127.0.0.1:63342
Traceback (most recent call last):
  File "/home/weichao/Downloads/pycharm-2023.2.1/plugins/python/helpers/pycharm_display/datalore/display/display_.py", line 86, in _send_display_message
    urllib_request.urlopen(url, buffer)
  File "/opt/Dino_parallel/lib/python3.8/urllib/request.py", line 222, in urlopen
    return opener.open(url, data, timeout)
  File "/opt/Dino_parallel/lib/python3.8/urllib/request.py", line 531, in open
    response = meth(req, response)
  File "/opt/Dino_parallel/lib/python3.8/urllib/request.py", line 640, in http_response
    response = self.parent.error(
  File "/opt/Dino_parallel/lib/python3.8/urllib/request.py", line 569, in error
    return self._call_chain(*args)
  File "/opt/Dino_parallel/lib/python3.8/urllib/request.py", line 502, in _call_chain
    result = func(*args)
  File "/opt/Dino_parallel/lib/python3.8/urllib/request.py", line 649, in http_error_default
    raise HTTPError(req.full_url, code, msg, hdrs, fp)
urllib.error.HTTPError: HTTP Error 429: Too Many Requests

During handling of the above exception, another exception occurred:

Traceback (most recent call last):
  File "/home/weichao/Downloads/pycharm-2023.2.1/plugins/python/helpers/pycharm_display/datalore/display/display_.py", line 61, in try_empty_proxy
    urllib_request.urlopen(url, buffer)
  File "/opt/Dino_parallel/lib/python3.8/urllib/request.py", line 222, in urlopen
    return opener.open(url, data, timeout)
  File "/opt/Dino_parallel/lib/python3.8/urllib/request.py", line 531, in open
    response = meth(req, response)
  File "/opt/Dino_parallel/lib/python3.8/urllib/request.py", line 640, in http_response
    response = self.parent.error(
  File "/opt/Dino_parallel/lib/python3.8/urllib/request.py", line 569, in error
    return self._call_chain(*args)
  File "/opt/Dino_parallel/lib/python3.8/urllib/request.py", line 502, in _call_chain
    result = func(*args)
  File "/opt/Dino_parallel/lib/python3.8/urllib/request.py", line 649, in http_error_default
    raise HTTPError(req.full_url, code, msg, hdrs, fp)
urllib.error.HTTPError: HTTP Error 429: Too Many Requests

--------------------------------------------------

--- Running: 2D_Steady_Heat_Equation.py ---
Exit Code: 0
Output:

Errors:

--------------------------------------------------

--- Running: 2D_Unsteady_Heat_Equation_1.py ---
Exit Code: 0
Output:

Errors:
Error: failed to send plot to http://127.0.0.1:63342
Traceback (most recent call last):
  File "/home/weichao/Downloads/pycharm-2023.2.1/plugins/python/helpers/pycharm_display/datalore/display/display_.py", line 86, in _send_display_message
    urllib_request.urlopen(url, buffer)
  File "/opt/Dino_parallel/lib/python3.8/urllib/request.py", line 222, in urlopen
    return opener.open(url, data, timeout)
  File "/opt/Dino_parallel/lib/python3.8/urllib/request.py", line 531, in open
    response = meth(req, response)
  File "/opt/Dino_parallel/lib/python3.8/urllib/request.py", line 640, in http_response
    response = self.parent.error(
  File "/opt/Dino_parallel/lib/python3.8/urllib/request.py", line 569, in error
    return self._call_chain(*args)
  File "/opt/Dino_parallel/lib/python3.8/urllib/request.py", line 502, in _call_chain
    result = func(*args)
  File "/opt/Dino_parallel/lib/python3.8/urllib/request.py", line 649, in http_error_default
    raise HTTPError(req.full_url, code, msg, hdrs, fp)
urllib.error.HTTPError: HTTP Error 429: Too Many Requests

During handling of the above exception, another exception occurred:

Traceback (most recent call last):
  File "/home/weichao/Downloads/pycharm-2023.2.1/plugins/python/helpers/pycharm_display/datalore/display/display_.py", line 61, in try_empty_proxy
    urllib_request.urlopen(url, buffer)
  File "/opt/Dino_parallel/lib/python3.8/urllib/request.py", line 222, in urlopen
    return opener.open(url, data, timeout)
  File "/opt/Dino_parallel/lib/python3.8/urllib/request.py", line 531, in open
    response = meth(req, response)
  File "/opt/Dino_parallel/lib/python3.8/urllib/request.py", line 640, in http_response
    response = self.parent.error(
  File "/opt/Dino_parallel/lib/python3.8/urllib/request.py", line 569, in error
    return self._call_chain(*args)
  File "/opt/Dino_parallel/lib/python3.8/urllib/request.py", line 502, in _call_chain
    result = func(*args)
  File "/opt/Dino_parallel/lib/python3.8/urllib/request.py", line 649, in http_error_default
    raise HTTPError(req.full_url, code, msg, hdrs, fp)
urllib.error.HTTPError: HTTP Error 429: Too Many Requests

--------------------------------------------------

--- Running: 2D_Diffusion_FVM.py ---
Exit Code: 0
Output:

Errors:
/home/weichao/.local/lib/python3.8/site-packages/scipy/sparse/_index.py:103: SparseEfficiencyWarning: Changing the sparsity structure of a csr_matrix is expensive. lil_matrix is more efficient.
  self._set_intXint(row, col, x.flat[0])
Error: failed to send plot to http://127.0.0.1:63342
Traceback (most recent call last):
  File "/home/weichao/Downloads/pycharm-2023.2.1/plugins/python/helpers/pycharm_display/datalore/display/display_.py", line 86, in _send_display_message
    urllib_request.urlopen(url, buffer)
  File "/opt/Dino_parallel/lib/python3.8/urllib/request.py", line 222, in urlopen
    return opener.open(url, data, timeout)
  File "/opt/Dino_parallel/lib/python3.8/urllib/request.py", line 531, in open
    response = meth(req, response)
  File "/opt/Dino_parallel/lib/python3.8/urllib/request.py", line 640, in http_response
    response = self.parent.error(
  File "/opt/Dino_parallel/lib/python3.8/urllib/request.py", line 569, in error
    return self._call_chain(*args)
  File "/opt/Dino_parallel/lib/python3.8/urllib/request.py", line 502, in _call_chain
    result = func(*args)
  File "/opt/Dino_parallel/lib/python3.8/urllib/request.py", line 649, in http_error_default
    raise HTTPError(req.full_url, code, msg, hdrs, fp)
urllib.error.HTTPError: HTTP Error 429: Too Many Requests

During handling of the above exception, another exception occurred:

Traceback (most recent call last):
  File "/home/weichao/Downloads/pycharm-2023.2.1/plugins/python/helpers/pycharm_display/datalore/display/display_.py", line 61, in try_empty_proxy
    urllib_request.urlopen(url, buffer)
  File "/opt/Dino_parallel/lib/python3.8/urllib/request.py", line 222, in urlopen
    return opener.open(url, data, timeout)
  File "/opt/Dino_parallel/lib/python3.8/urllib/request.py", line 531, in open
    response = meth(req, response)
  File "/opt/Dino_parallel/lib/python3.8/urllib/request.py", line 640, in http_response
    response = self.parent.error(
  File "/opt/Dino_parallel/lib/python3.8/urllib/request.py", line 569, in error
    return self._call_chain(*args)
  File "/opt/Dino_parallel/lib/python3.8/urllib/request.py", line 502, in _call_chain
    result = func(*args)
  File "/opt/Dino_parallel/lib/python3.8/urllib/request.py", line 649, in http_error_default
    raise HTTPError(req.full_url, code, msg, hdrs, fp)
urllib.error.HTTPError: HTTP Error 429: Too Many Requests

--------------------------------------------------

--- Running: 2D_Convection.py ---
Exit Code: 0
Output:

Errors:
Error: failed to send plot to http://127.0.0.1:63342
Traceback (most recent call last):
  File "/home/weichao/Downloads/pycharm-2023.2.1/plugins/python/helpers/pycharm_display/datalore/display/display_.py", line 86, in _send_display_message
    urllib_request.urlopen(url, buffer)
  File "/opt/Dino_parallel/lib/python3.8/urllib/request.py", line 222, in urlopen
    return opener.open(url, data, timeout)
  File "/opt/Dino_parallel/lib/python3.8/urllib/request.py", line 531, in open
    response = meth(req, response)
  File "/opt/Dino_parallel/lib/python3.8/urllib/request.py", line 640, in http_response
    response = self.parent.error(
  File "/opt/Dino_parallel/lib/python3.8/urllib/request.py", line 569, in error
    return self._call_chain(*args)
  File "/opt/Dino_parallel/lib/python3.8/urllib/request.py", line 502, in _call_chain
    result = func(*args)
  File "/opt/Dino_parallel/lib/python3.8/urllib/request.py", line 649, in http_error_default
    raise HTTPError(req.full_url, code, msg, hdrs, fp)
urllib.error.HTTPError: HTTP Error 429: Too Many Requests

During handling of the above exception, another exception occurred:

Traceback (most recent call last):
  File "/home/weichao/Downloads/pycharm-2023.2.1/plugins/python/helpers/pycharm_display/datalore/display/display_.py", line 61, in try_empty_proxy
    urllib_request.urlopen(url, buffer)
  File "/opt/Dino_parallel/lib/python3.8/urllib/request.py", line 222, in urlopen
    return opener.open(url, data, timeout)
  File "/opt/Dino_parallel/lib/python3.8/urllib/request.py", line 531, in open
    response = meth(req, response)
  File "/opt/Dino_parallel/lib/python3.8/urllib/request.py", line 640, in http_response
    response = self.parent.error(
  File "/opt/Dino_parallel/lib/python3.8/urllib/request.py", line 569, in error
    return self._call_chain(*args)
  File "/opt/Dino_parallel/lib/python3.8/urllib/request.py", line 502, in _call_chain
    result = func(*args)
  File "/opt/Dino_parallel/lib/python3.8/urllib/request.py", line 649, in http_error_default
    raise HTTPError(req.full_url, code, msg, hdrs, fp)
urllib.error.HTTPError: HTTP Error 429: Too Many Requests
Error: failed to send plot to http://127.0.0.1:63342
Traceback (most recent call last):
  File "/home/weichao/Downloads/pycharm-2023.2.1/plugins/python/helpers/pycharm_display/datalore/display/display_.py", line 86, in _send_display_message
    urllib_request.urlopen(url, buffer)
  File "/opt/Dino_parallel/lib/python3.8/urllib/request.py", line 222, in urlopen
    return opener.open(url, data, timeout)
  File "/opt/Dino_parallel/lib/python3.8/urllib/request.py", line 531, in open
    response = meth(req, response)
  File "/opt/Dino_parallel/lib/python3.8/urllib/request.py", line 640, in http_response
    response = self.parent.error(
  File "/opt/Dino_parallel/lib/python3.8/urllib/request.py", line 569, in error
    return self._call_chain(*args)
  File "/opt/Dino_parallel/lib/python3.8/urllib/request.py", line 502, in _call_chain
    result = func(*args)
  File "/opt/Dino_parallel/lib/python3.8/urllib/request.py", line 649, in http_error_default
    raise HTTPError(req.full_url, code, msg, hdrs, fp)
urllib.error.HTTPError: HTTP Error 429: Too Many Requests

During handling of the above exception, another exception occurred:

Traceback (most recent call last):
  File "/home/weichao/Downloads/pycharm-2023.2.1/plugins/python/helpers/pycharm_display/datalore/display/display_.py", line 61, in try_empty_proxy
    urllib_request.urlopen(url, buffer)
  File "/opt/Dino_parallel/lib/python3.8/urllib/request.py", line 222, in urlopen
    return opener.open(url, data, timeout)
  File "/opt/Dino_parallel/lib/python3.8/urllib/request.py", line 531, in open
    response = meth(req, response)
  File "/opt/Dino_parallel/lib/python3.8/urllib/request.py", line 640, in http_response
    response = self.parent.error(
  File "/opt/Dino_parallel/lib/python3.8/urllib/request.py", line 569, in error
    return self._call_chain(*args)
  File "/opt/Dino_parallel/lib/python3.8/urllib/request.py", line 502, in _call_chain
    result = func(*args)
  File "/opt/Dino_parallel/lib/python3.8/urllib/request.py", line 649, in http_error_default
    raise HTTPError(req.full_url, code, msg, hdrs, fp)
urllib.error.HTTPError: HTTP Error 429: Too Many Requests

--------------------------------------------------

--- Running: 1D_Nonlinear_Convection.py ---
Exit Code: 0
Output:

Errors:
Error: failed to send plot to http://127.0.0.1:63342
Traceback (most recent call last):
  File "/home/weichao/Downloads/pycharm-2023.2.1/plugins/python/helpers/pycharm_display/datalore/display/display_.py", line 86, in _send_display_message
    urllib_request.urlopen(url, buffer)
  File "/opt/Dino_parallel/lib/python3.8/urllib/request.py", line 222, in urlopen
    return opener.open(url, data, timeout)
  File "/opt/Dino_parallel/lib/python3.8/urllib/request.py", line 531, in open
    response = meth(req, response)
  File "/opt/Dino_parallel/lib/python3.8/urllib/request.py", line 640, in http_response
    response = self.parent.error(
  File "/opt/Dino_parallel/lib/python3.8/urllib/request.py", line 569, in error
    return self._call_chain(*args)
  File "/opt/Dino_parallel/lib/python3.8/urllib/request.py", line 502, in _call_chain
    result = func(*args)
  File "/opt/Dino_parallel/lib/python3.8/urllib/request.py", line 649, in http_error_default
    raise HTTPError(req.full_url, code, msg, hdrs, fp)
urllib.error.HTTPError: HTTP Error 429: Too Many Requests

During handling of the above exception, another exception occurred:

Traceback (most recent call last):
  File "/home/weichao/Downloads/pycharm-2023.2.1/plugins/python/helpers/pycharm_display/datalore/display/display_.py", line 61, in try_empty_proxy
    urllib_request.urlopen(url, buffer)
  File "/opt/Dino_parallel/lib/python3.8/urllib/request.py", line 222, in urlopen
    return opener.open(url, data, timeout)
  File "/opt/Dino_parallel/lib/python3.8/urllib/request.py", line 531, in open
    response = meth(req, response)
  File "/opt/Dino_parallel/lib/python3.8/urllib/request.py", line 640, in http_response
    response = self.parent.error(
  File "/opt/Dino_parallel/lib/python3.8/urllib/request.py", line 569, in error
    return self._call_chain(*args)
  File "/opt/Dino_parallel/lib/python3.8/urllib/request.py", line 502, in _call_chain
    result = func(*args)
  File "/opt/Dino_parallel/lib/python3.8/urllib/request.py", line 649, in http_error_default
    raise HTTPError(req.full_url, code, msg, hdrs, fp)
urllib.error.HTTPError: HTTP Error 429: Too Many Requests

--------------------------------------------------

--- Running: 1D_Euler_Shock_Tube.py ---
Exit Code: 0
Output:

Errors:
/opt/CFD-Benchmark/PDE_Benchmark_5/solver_2/1D_Euler_Shock_Tube.py:23: RuntimeWarning: overflow encountered in multiply
  F = np.array([U[1, :], (U[1, :]**2 / U[0, :] + (gamma - 1) * (U[2, :] - 0.5 * U[1, :]**2 / U[0, :])), U[1, :] * ((U[2, :] / U[0, :]) + (gamma - 1) * (U[2, :] - 0.5 * U[1, :]**2 / U[0, :]))])
/opt/CFD-Benchmark/PDE_Benchmark_5/solver_2/1D_Euler_Shock_Tube.py:24: RuntimeWarning: invalid value encountered in subtract
  U_star = U[:, :-1] - dt / dx * (F[:, 1:] - F[:, :-1])
/opt/CFD-Benchmark/PDE_Benchmark_5/solver_2/1D_Euler_Shock_Tube.py:25: RuntimeWarning: overflow encountered in square
  F_star = np.array([U_star[1, :], (U_star[1, :]**2 / U_star[0, :] + (gamma - 1) * (U_star[2, :] - 0.5 * U_star[1, :]**2 / U_star[0, :])), U_star[1, :] * ((U_star[2, :] / U_star[0, :]) + (gamma - 1) * (U_star[2, :] - 0.5 * U_star[1, :]**2 / U_star[0, :]))])
/opt/CFD-Benchmark/PDE_Benchmark_5/solver_2/1D_Euler_Shock_Tube.py:25: RuntimeWarning: invalid value encountered in subtract
  F_star = np.array([U_star[1, :], (U_star[1, :]**2 / U_star[0, :] + (gamma - 1) * (U_star[2, :] - 0.5 * U_star[1, :]**2 / U_star[0, :])), U_star[1, :] * ((U_star[2, :] / U_star[0, :]) + (gamma - 1) * (U_star[2, :] - 0.5 * U_star[1, :]**2 / U_star[0, :]))])
/opt/CFD-Benchmark/PDE_Benchmark_5/solver_2/1D_Euler_Shock_Tube.py:25: RuntimeWarning: invalid value encountered in add
  F_star = np.array([U_star[1, :], (U_star[1, :]**2 / U_star[0, :] + (gamma - 1) * (U_star[2, :] - 0.5 * U_star[1, :]**2 / U_star[0, :])), U_star[1, :] * ((U_star[2, :] / U_star[0, :]) + (gamma - 1) * (U_star[2, :] - 0.5 * U_star[1, :]**2 / U_star[0, :]))])
Error: failed to send plot to http://127.0.0.1:63342
Traceback (most recent call last):
  File "/home/weichao/Downloads/pycharm-2023.2.1/plugins/python/helpers/pycharm_display/datalore/display/display_.py", line 86, in _send_display_message
    urllib_request.urlopen(url, buffer)
  File "/opt/Dino_parallel/lib/python3.8/urllib/request.py", line 222, in urlopen
    return opener.open(url, data, timeout)
  File "/opt/Dino_parallel/lib/python3.8/urllib/request.py", line 531, in open
    response = meth(req, response)
  File "/opt/Dino_parallel/lib/python3.8/urllib/request.py", line 640, in http_response
    response = self.parent.error(
  File "/opt/Dino_parallel/lib/python3.8/urllib/request.py", line 569, in error
    return self._call_chain(*args)
  File "/opt/Dino_parallel/lib/python3.8/urllib/request.py", line 502, in _call_chain
    result = func(*args)
  File "/opt/Dino_parallel/lib/python3.8/urllib/request.py", line 649, in http_error_default
    raise HTTPError(req.full_url, code, msg, hdrs, fp)
urllib.error.HTTPError: HTTP Error 429: Too Many Requests

During handling of the above exception, another exception occurred:

Traceback (most recent call last):
  File "/home/weichao/Downloads/pycharm-2023.2.1/plugins/python/helpers/pycharm_display/datalore/display/display_.py", line 61, in try_empty_proxy
    urllib_request.urlopen(url, buffer)
  File "/opt/Dino_parallel/lib/python3.8/urllib/request.py", line 222, in urlopen
    return opener.open(url, data, timeout)
  File "/opt/Dino_parallel/lib/python3.8/urllib/request.py", line 531, in open
    response = meth(req, response)
  File "/opt/Dino_parallel/lib/python3.8/urllib/request.py", line 640, in http_response
    response = self.parent.error(
  File "/opt/Dino_parallel/lib/python3.8/urllib/request.py", line 569, in error
    return self._call_chain(*args)
  File "/opt/Dino_parallel/lib/python3.8/urllib/request.py", line 502, in _call_chain
    result = func(*args)
  File "/opt/Dino_parallel/lib/python3.8/urllib/request.py", line 649, in http_error_default
    raise HTTPError(req.full_url, code, msg, hdrs, fp)
urllib.error.HTTPError: HTTP Error 429: Too Many Requests

--------------------------------------------------

--- Running: 2D_Linear_Convection.py ---
Exit Code: 0
Output:

Errors:
Error: failed to send plot to http://127.0.0.1:63342
Traceback (most recent call last):
  File "/home/weichao/Downloads/pycharm-2023.2.1/plugins/python/helpers/pycharm_display/datalore/display/display_.py", line 86, in _send_display_message
    urllib_request.urlopen(url, buffer)
  File "/opt/Dino_parallel/lib/python3.8/urllib/request.py", line 222, in urlopen
    return opener.open(url, data, timeout)
  File "/opt/Dino_parallel/lib/python3.8/urllib/request.py", line 531, in open
    response = meth(req, response)
  File "/opt/Dino_parallel/lib/python3.8/urllib/request.py", line 640, in http_response
    response = self.parent.error(
  File "/opt/Dino_parallel/lib/python3.8/urllib/request.py", line 569, in error
    return self._call_chain(*args)
  File "/opt/Dino_parallel/lib/python3.8/urllib/request.py", line 502, in _call_chain
    result = func(*args)
  File "/opt/Dino_parallel/lib/python3.8/urllib/request.py", line 649, in http_error_default
    raise HTTPError(req.full_url, code, msg, hdrs, fp)
urllib.error.HTTPError: HTTP Error 429: Too Many Requests

During handling of the above exception, another exception occurred:

Traceback (most recent call last):
  File "/home/weichao/Downloads/pycharm-2023.2.1/plugins/python/helpers/pycharm_display/datalore/display/display_.py", line 61, in try_empty_proxy
    urllib_request.urlopen(url, buffer)
  File "/opt/Dino_parallel/lib/python3.8/urllib/request.py", line 222, in urlopen
    return opener.open(url, data, timeout)
  File "/opt/Dino_parallel/lib/python3.8/urllib/request.py", line 531, in open
    response = meth(req, response)
  File "/opt/Dino_parallel/lib/python3.8/urllib/request.py", line 640, in http_response
    response = self.parent.error(
  File "/opt/Dino_parallel/lib/python3.8/urllib/request.py", line 569, in error
    return self._call_chain(*args)
  File "/opt/Dino_parallel/lib/python3.8/urllib/request.py", line 502, in _call_chain
    result = func(*args)
  File "/opt/Dino_parallel/lib/python3.8/urllib/request.py", line 649, in http_error_default
    raise HTTPError(req.full_url, code, msg, hdrs, fp)
urllib.error.HTTPError: HTTP Error 429: Too Many Requests

--------------------------------------------------

--- Running: 2D_Laplace_Equation.py ---
Exit Code: 0
Output:

Errors:
Error: failed to send plot to http://127.0.0.1:63342
Traceback (most recent call last):
  File "/home/weichao/Downloads/pycharm-2023.2.1/plugins/python/helpers/pycharm_display/datalore/display/display_.py", line 86, in _send_display_message
    urllib_request.urlopen(url, buffer)
  File "/opt/Dino_parallel/lib/python3.8/urllib/request.py", line 222, in urlopen
    return opener.open(url, data, timeout)
  File "/opt/Dino_parallel/lib/python3.8/urllib/request.py", line 531, in open
    response = meth(req, response)
  File "/opt/Dino_parallel/lib/python3.8/urllib/request.py", line 640, in http_response
    response = self.parent.error(
  File "/opt/Dino_parallel/lib/python3.8/urllib/request.py", line 569, in error
    return self._call_chain(*args)
  File "/opt/Dino_parallel/lib/python3.8/urllib/request.py", line 502, in _call_chain
    result = func(*args)
  File "/opt/Dino_parallel/lib/python3.8/urllib/request.py", line 649, in http_error_default
    raise HTTPError(req.full_url, code, msg, hdrs, fp)
urllib.error.HTTPError: HTTP Error 429: Too Many Requests

During handling of the above exception, another exception occurred:

Traceback (most recent call last):
  File "/home/weichao/Downloads/pycharm-2023.2.1/plugins/python/helpers/pycharm_display/datalore/display/display_.py", line 61, in try_empty_proxy
    urllib_request.urlopen(url, buffer)
  File "/opt/Dino_parallel/lib/python3.8/urllib/request.py", line 222, in urlopen
    return opener.open(url, data, timeout)
  File "/opt/Dino_parallel/lib/python3.8/urllib/request.py", line 531, in open
    response = meth(req, response)
  File "/opt/Dino_parallel/lib/python3.8/urllib/request.py", line 640, in http_response
    response = self.parent.error(
  File "/opt/Dino_parallel/lib/python3.8/urllib/request.py", line 569, in error
    return self._call_chain(*args)
  File "/opt/Dino_parallel/lib/python3.8/urllib/request.py", line 502, in _call_chain
    result = func(*args)
  File "/opt/Dino_parallel/lib/python3.8/urllib/request.py", line 649, in http_error_default
    raise HTTPError(req.full_url, code, msg, hdrs, fp)
urllib.error.HTTPError: HTTP Error 429: Too Many Requests

--------------------------------------------------

--- Running: 1D_Burgers_Equation.py ---
Exit Code: 0
Output:

Errors:
Error: failed to send plot to http://127.0.0.1:63342
Traceback (most recent call last):
  File "/home/weichao/Downloads/pycharm-2023.2.1/plugins/python/helpers/pycharm_display/datalore/display/display_.py", line 86, in _send_display_message
    urllib_request.urlopen(url, buffer)
  File "/opt/Dino_parallel/lib/python3.8/urllib/request.py", line 222, in urlopen
    return opener.open(url, data, timeout)
  File "/opt/Dino_parallel/lib/python3.8/urllib/request.py", line 531, in open
    response = meth(req, response)
  File "/opt/Dino_parallel/lib/python3.8/urllib/request.py", line 640, in http_response
    response = self.parent.error(
  File "/opt/Dino_parallel/lib/python3.8/urllib/request.py", line 569, in error
    return self._call_chain(*args)
  File "/opt/Dino_parallel/lib/python3.8/urllib/request.py", line 502, in _call_chain
    result = func(*args)
  File "/opt/Dino_parallel/lib/python3.8/urllib/request.py", line 649, in http_error_default
    raise HTTPError(req.full_url, code, msg, hdrs, fp)
urllib.error.HTTPError: HTTP Error 429: Too Many Requests

During handling of the above exception, another exception occurred:

Traceback (most recent call last):
  File "/home/weichao/Downloads/pycharm-2023.2.1/plugins/python/helpers/pycharm_display/datalore/display/display_.py", line 61, in try_empty_proxy
    urllib_request.urlopen(url, buffer)
  File "/opt/Dino_parallel/lib/python3.8/urllib/request.py", line 222, in urlopen
    return opener.open(url, data, timeout)
  File "/opt/Dino_parallel/lib/python3.8/urllib/request.py", line 531, in open
    response = meth(req, response)
  File "/opt/Dino_parallel/lib/python3.8/urllib/request.py", line 640, in http_response
    response = self.parent.error(
  File "/opt/Dino_parallel/lib/python3.8/urllib/request.py", line 569, in error
    return self._call_chain(*args)
  File "/opt/Dino_parallel/lib/python3.8/urllib/request.py", line 502, in _call_chain
    result = func(*args)
  File "/opt/Dino_parallel/lib/python3.8/urllib/request.py", line 649, in http_error_default
    raise HTTPError(req.full_url, code, msg, hdrs, fp)
urllib.error.HTTPError: HTTP Error 429: Too Many Requests

--------------------------------------------------

