====== Execution Results for Generated Solvers ======

--- Running: 1D_Diffusion.py ---
Exit Code: 0
Output:

Errors:

--------------------------------------------------



====== Execution Summary ======
Total Scripts Passed: 1
Total Scripts Failed: 0
--- Running: Fully_Developed_Turbulent_Channel_Flow.py ---
Exit Code: 1
Output:

Errors:
Traceback (most recent call last):
  File "/opt/CFD-Benchmark/PDE_Benchmark_8/solver/gpt-4o/prompts/Fully_Developed_Turbulent_Channel_Flow.py", line 59, in <module>
    np.save('/opt/CFD-Benchmark/PDE_Benchmark_8/results/prediction/gpt-4o/prompts/ubar_Fully_Developed_Turbulent_Channel_Flow.npy', ubar)
  File "<__array_function__ internals>", line 200, in save
  File "/home/weichao/.local/lib/python3.8/site-packages/numpy/lib/npyio.py", line 518, in save
    file_ctx = open(file, "wb")
FileNotFoundError: [Errno 2] No such file or directory: '/opt/CFD-Benchmark/PDE_Benchmark_8/results/prediction/gpt-4o/prompts/ubar_Fully_Developed_Turbulent_Channel_Flow.npy'

--------------------------------------------------



====== Execution Summary ======
Total Scripts Passed: 1
Total Scripts Failed: 1
--- Running: 2D_Diffusion.py ---
Exit Code: 1
Output:

Errors:
Traceback (most recent call last):
  File "/opt/CFD-Benchmark/PDE_Benchmark_8/solver/gpt-4o/prompts/2D_Diffusion.py", line 38, in <module>
    np.save('/opt/CFD-Benchmark/PDE_Benchmark_8/results/prediction/gpt-4o/prompts/u_2D_Diffusion.npy', u)
  File "<__array_function__ internals>", line 200, in save
  File "/home/weichao/.local/lib/python3.8/site-packages/numpy/lib/npyio.py", line 518, in save
    file_ctx = open(file, "wb")
FileNotFoundError: [Errno 2] No such file or directory: '/opt/CFD-Benchmark/PDE_Benchmark_8/results/prediction/gpt-4o/prompts/u_2D_Diffusion.npy'

--------------------------------------------------



====== Execution Summary ======
Total Scripts Passed: 1
Total Scripts Failed: 2
--- Running: 2D_Navier_Stokes_Cavity.py ---
Exit Code: 1
Output:

Errors:
Traceback (most recent call last):
  File "/opt/CFD-Benchmark/PDE_Benchmark_8/solver/gpt-4o/prompts/2D_Navier_Stokes_Cavity.py", line 98, in <module>
    np.save('/opt/CFD-Benchmark/PDE_Benchmark_8/results/prediction/gpt-4o/prompts/u_2D_Navier_Stokes_Cavity.npy', u)
  File "<__array_function__ internals>", line 200, in save
  File "/home/weichao/.local/lib/python3.8/site-packages/numpy/lib/npyio.py", line 518, in save
    file_ctx = open(file, "wb")
FileNotFoundError: [Errno 2] No such file or directory: '/opt/CFD-Benchmark/PDE_Benchmark_8/results/prediction/gpt-4o/prompts/u_2D_Navier_Stokes_Cavity.npy'

--------------------------------------------------



====== Execution Summary ======
Total Scripts Passed: 1
Total Scripts Failed: 3
--- Running: 1D_Linear_Convection.py ---
Exit Code: 0
Output:

Errors:

--------------------------------------------------



====== Execution Summary ======
Total Scripts Passed: 2
Total Scripts Failed: 3
--- Running: 2D_Inviscid_Burgers.py ---
Exit Code: 1
Output:

Errors:
Traceback (most recent call last):
  File "/opt/CFD-Benchmark/PDE_Benchmark_8/solver/gpt-4o/prompts/2D_Inviscid_Burgers.py", line 44, in <module>
    np.save('/opt/CFD-Benchmark/PDE_Benchmark_8/results/prediction/gpt-4o/prompts/u_2D_Inviscid_Burgers.npy', u)
  File "<__array_function__ internals>", line 200, in save
  File "/home/weichao/.local/lib/python3.8/site-packages/numpy/lib/npyio.py", line 518, in save
    file_ctx = open(file, "wb")
FileNotFoundError: [Errno 2] No such file or directory: '/opt/CFD-Benchmark/PDE_Benchmark_8/results/prediction/gpt-4o/prompts/u_2D_Inviscid_Burgers.npy'

--------------------------------------------------



====== Execution Summary ======
Total Scripts Passed: 2
Total Scripts Failed: 4
--- Running: 2D_Steady_Heat_Equation.py ---
Exit Code: 1
Output:
Converged after 2563 iterations.

Errors:
Traceback (most recent call last):
  File "/opt/CFD-Benchmark/PDE_Benchmark_8/solver/gpt-4o/prompts/2D_Steady_Heat_Equation.py", line 37, in <module>
    np.save('/opt/CFD-Benchmark/PDE_Benchmark_8/results/prediction/gpt-4o/prompts/T_2D_Steady_Heat_Equation.npy', T)
  File "<__array_function__ internals>", line 200, in save
  File "/home/weichao/.local/lib/python3.8/site-packages/numpy/lib/npyio.py", line 518, in save
    file_ctx = open(file, "wb")
FileNotFoundError: [Errno 2] No such file or directory: '/opt/CFD-Benchmark/PDE_Benchmark_8/results/prediction/gpt-4o/prompts/T_2D_Steady_Heat_Equation.npy'

--------------------------------------------------



====== Execution Summary ======
Total Scripts Passed: 2
Total Scripts Failed: 5
--- Running: 2D_Navier_Stokes_Channel.py ---
Exit Code: 1
Output:

Errors:
Traceback (most recent call last):
  File "/opt/CFD-Benchmark/PDE_Benchmark_8/solver/gpt-4o/prompts/2D_Navier_Stokes_Channel.py", line 94, in <module>
    np.save('/opt/CFD-Benchmark/PDE_Benchmark_8/results/prediction/gpt-4o/prompts/u_2D_Navier_Stokes_Channel.npy', u)
  File "<__array_function__ internals>", line 200, in save
  File "/home/weichao/.local/lib/python3.8/site-packages/numpy/lib/npyio.py", line 518, in save
    file_ctx = open(file, "wb")
FileNotFoundError: [Errno 2] No such file or directory: '/opt/CFD-Benchmark/PDE_Benchmark_8/results/prediction/gpt-4o/prompts/u_2D_Navier_Stokes_Channel.npy'

--------------------------------------------------



====== Execution Summary ======
Total Scripts Passed: 2
Total Scripts Failed: 6
--- Running: 2D_Poisson_Equation.py ---
Exit Code: 1
Output:
Converged after 1253 iterations

Errors:
Traceback (most recent call last):
  File "/opt/CFD-Benchmark/PDE_Benchmark_8/solver/gpt-4o/prompts/2D_Poisson_Equation.py", line 46, in <module>
    np.save('/opt/CFD-Benchmark/PDE_Benchmark_8/results/prediction/gpt-4o/prompts/p_2D_Poisson_Equation.npy', p)
  File "<__array_function__ internals>", line 200, in save
  File "/home/weichao/.local/lib/python3.8/site-packages/numpy/lib/npyio.py", line 518, in save
    file_ctx = open(file, "wb")
FileNotFoundError: [Errno 2] No such file or directory: '/opt/CFD-Benchmark/PDE_Benchmark_8/results/prediction/gpt-4o/prompts/p_2D_Poisson_Equation.npy'

--------------------------------------------------



====== Execution Summary ======
Total Scripts Passed: 2
Total Scripts Failed: 7
--- Running: 2D_Convection.py ---
Exit Code: 1
Output:

Errors:
Traceback (most recent call last):
  File "/opt/CFD-Benchmark/PDE_Benchmark_8/solver/gpt-4o/prompts/2D_Convection.py", line 48, in <module>
    np.save('/opt/CFD-Benchmark/PDE_Benchmark_8/results/prediction/gpt-4o/prompts/u_2D_Convection.npy', u)
  File "<__array_function__ internals>", line 200, in save
  File "/home/weichao/.local/lib/python3.8/site-packages/numpy/lib/npyio.py", line 518, in save
    file_ctx = open(file, "wb")
FileNotFoundError: [Errno 2] No such file or directory: '/opt/CFD-Benchmark/PDE_Benchmark_8/results/prediction/gpt-4o/prompts/u_2D_Convection.npy'

--------------------------------------------------



====== Execution Summary ======
Total Scripts Passed: 2
Total Scripts Failed: 8
--- Running: 1D_Nonlinear_Convection.py ---
Exit Code: 0
Output:

Errors:

--------------------------------------------------



====== Execution Summary ======
Total Scripts Passed: 3
Total Scripts Failed: 8
--- Running: 1D_Euler_Shock_Tube.py ---
Exit Code: 1
Output:

Errors:
Traceback (most recent call last):
  File "/opt/CFD-Benchmark/PDE_Benchmark_8/solver/gpt-4o/prompts/1D_Euler_Shock_Tube.py", line 64, in <module>
    np.save('/opt/CFD-Benchmark/PDE_Benchmark_8/results/prediction/gpt-4o/prompts/rho_final_1D_Euler_Shock_Tube.npy', rho_final)
  File "<__array_function__ internals>", line 200, in save
  File "/home/weichao/.local/lib/python3.8/site-packages/numpy/lib/npyio.py", line 518, in save
    file_ctx = open(file, "wb")
FileNotFoundError: [Errno 2] No such file or directory: '/opt/CFD-Benchmark/PDE_Benchmark_8/results/prediction/gpt-4o/prompts/rho_final_1D_Euler_Shock_Tube.npy'

--------------------------------------------------



====== Execution Summary ======
Total Scripts Passed: 3
Total Scripts Failed: 9
--- Running: 2D_Linear_Convection.py ---
Exit Code: 1
Output:

Errors:
Traceback (most recent call last):
  File "/opt/CFD-Benchmark/PDE_Benchmark_8/solver/gpt-4o/prompts/2D_Linear_Convection.py", line 35, in <module>
    np.save('/opt/CFD-Benchmark/PDE_Benchmark_8/results/prediction/gpt-4o/prompts/u_2D_Linear_Convection.npy', u)
  File "<__array_function__ internals>", line 200, in save
  File "/home/weichao/.local/lib/python3.8/site-packages/numpy/lib/npyio.py", line 518, in save
    file_ctx = open(file, "wb")
FileNotFoundError: [Errno 2] No such file or directory: '/opt/CFD-Benchmark/PDE_Benchmark_8/results/prediction/gpt-4o/prompts/u_2D_Linear_Convection.npy'

--------------------------------------------------



====== Execution Summary ======
Total Scripts Passed: 3
Total Scripts Failed: 10
