====== Execution Results for Generated Solvers ======

--- Running: 1D_Nonlinear_Convection_MK.py ---
Exit Code: 1
Output:

Errors:
Traceback (most recent call last):
  File "/opt/CFD-Benchmark/PDE_Benchmark_8/solver/gpt-4o/prompts_no_instruction/1D_Nonlinear_Convection_MK.py", line 34, in <module>
    np.save('/opt/CFD-Benchmark/PDE_Benchmark_8/results/prediction/gpt-4o/prompts_no_instruction/u_1D_Nonlinear_Convection_MK.npy', u)
  File "<__array_function__ internals>", line 200, in save
  File "/home/weichao/.local/lib/python3.8/site-packages/numpy/lib/npyio.py", line 518, in save
    file_ctx = open(file, "wb")
FileNotFoundError: [Errno 2] No such file or directory: '/opt/CFD-Benchmark/PDE_Benchmark_8/results/prediction/gpt-4o/prompts_no_instruction/u_1D_Nonlinear_Convection_MK.npy'

--------------------------------------------------



====== Execution Summary ======
Total Scripts Passed: 0
Total Scripts Failed: 1
--- Running: Fully_Developed_Turbulent_Channel_Flow_KE.py ---
Exit Code: 1
Output:

Errors:
Traceback (most recent call last):
  File "/opt/CFD-Benchmark/PDE_Benchmark_8/solver/gpt-4o/prompts_no_instruction/Fully_Developed_Turbulent_Channel_Flow_KE.py", line 68, in <module>
    np.save('/opt/CFD-Benchmark/PDE_Benchmark_8/results/prediction/gpt-4o/prompts_no_instruction/k_Fully_Developed_Turbulent_Channel_Flow_KE.npy', k)
  File "<__array_function__ internals>", line 200, in save
  File "/home/weichao/.local/lib/python3.8/site-packages/numpy/lib/npyio.py", line 518, in save
    file_ctx = open(file, "wb")
FileNotFoundError: [Errno 2] No such file or directory: '/opt/CFD-Benchmark/PDE_Benchmark_8/results/prediction/gpt-4o/prompts_no_instruction/k_Fully_Developed_Turbulent_Channel_Flow_KE.npy'

--------------------------------------------------



====== Execution Summary ======
Total Scripts Passed: 0
Total Scripts Failed: 2
--- Running: 1D_Diffusion.py ---
Exit Code: 1
Output:

Errors:
Traceback (most recent call last):
  File "/opt/CFD-Benchmark/PDE_Benchmark_8/solver/gpt-4o/prompts_no_instruction/1D_Diffusion.py", line 28, in <module>
    np.save('/opt/CFD-Benchmark/PDE_Benchmark_8/results/prediction/gpt-4o/prompts_no_instruction/u_1D_Diffusion.npy', u)
  File "<__array_function__ internals>", line 200, in save
  File "/home/weichao/.local/lib/python3.8/site-packages/numpy/lib/npyio.py", line 518, in save
    file_ctx = open(file, "wb")
FileNotFoundError: [Errno 2] No such file or directory: '/opt/CFD-Benchmark/PDE_Benchmark_8/results/prediction/gpt-4o/prompts_no_instruction/u_1D_Diffusion.npy'

--------------------------------------------------



====== Execution Summary ======
Total Scripts Passed: 0
Total Scripts Failed: 3
--- Running: 1D_Linear_Convection_corr.py ---
Exit Code: 0
Output:

Errors:

--------------------------------------------------



====== Execution Summary ======
Total Scripts Passed: 1
Total Scripts Failed: 3
--- Running: 2D_Diffusion.py ---
Exit Code: 1
Output:

Errors:
Traceback (most recent call last):
  File "/opt/CFD-Benchmark/PDE_Benchmark_8/solver/gpt-4o/prompts_no_instruction/2D_Diffusion.py", line 32, in <module>
    np.save('/opt/CFD-Benchmark/PDE_Benchmark_8/results/prediction/gpt-4o/prompts_no_instruction/u_2D_Diffusion.npy', u)
  File "<__array_function__ internals>", line 200, in save
  File "/home/weichao/.local/lib/python3.8/site-packages/numpy/lib/npyio.py", line 518, in save
    file_ctx = open(file, "wb")
FileNotFoundError: [Errno 2] No such file or directory: '/opt/CFD-Benchmark/PDE_Benchmark_8/results/prediction/gpt-4o/prompts_no_instruction/u_2D_Diffusion.npy'

--------------------------------------------------



====== Execution Summary ======
Total Scripts Passed: 1
Total Scripts Failed: 4
--- Running: 2D_Inviscid_Burgers_MK.py ---
Exit Code: 1
Output:

Errors:
Traceback (most recent call last):
  File "/opt/CFD-Benchmark/PDE_Benchmark_8/solver/gpt-4o/prompts_no_instruction/2D_Inviscid_Burgers_MK.py", line 71, in <module>
    np.save('/opt/CFD-Benchmark/PDE_Benchmark_8/results/prediction/gpt-4o/prompts_no_instruction/u_2D_Inviscid_Burgers_MK.npy', u)
  File "<__array_function__ internals>", line 200, in save
  File "/home/weichao/.local/lib/python3.8/site-packages/numpy/lib/npyio.py", line 518, in save
    file_ctx = open(file, "wb")
FileNotFoundError: [Errno 2] No such file or directory: '/opt/CFD-Benchmark/PDE_Benchmark_8/results/prediction/gpt-4o/prompts_no_instruction/u_2D_Inviscid_Burgers_MK.npy'

--------------------------------------------------



====== Execution Summary ======
Total Scripts Passed: 1
Total Scripts Failed: 5
