====== Execution Results for Generated Solvers ======

--- Running: 1D_Nonlinear_Convection_MK.py ---
Exit Code: 1
Output:

Errors:
Traceback (most recent call last):
  File "/opt/CFD-Benchmark/PDE_Benchmark_8/solver/gpt-4o/prompts_no_instruction/1D_Nonlinear_Convection_MK.py", line 36, in <module>
    np.save('/opt/CFD-Benchmark/PDE_Benchmark_8/results/prediction/gpt-4o/prompts_no_instruction/u_1D_Nonlinear_Convection_MK.npy', u)
  File "<__array_function__ internals>", line 200, in save
  File "/home/weichao/.local/lib/python3.8/site-packages/numpy/lib/npyio.py", line 518, in save
    file_ctx = open(file, "wb")
FileNotFoundError: [Errno 2] No such file or directory: '/opt/CFD-Benchmark/PDE_Benchmark_8/results/prediction/gpt-4o/prompts_no_instruction/u_1D_Nonlinear_Convection_MK.npy'

--------------------------------------------------



====== Execution Summary ======
Total Scripts Passed: 0
Total Scripts Failed: 1
--- Running: Fully_Developed_Turbulent_Channel_Flow_KE.py ---
Exit Code: 1
Output:

Errors:
Traceback (most recent call last):
  File "/opt/CFD-Benchmark/PDE_Benchmark_8/solver/gpt-4o/prompts_no_instruction/Fully_Developed_Turbulent_Channel_Flow_KE.py", line 92, in <module>
    np.save('/opt/CFD-Benchmark/PDE_Benchmark_8/results/prediction/gpt-4o/prompts_no_instruction/k_Fully_Developed_Turbulent_Channel_Flow_KE.npy', k)
  File "<__array_function__ internals>", line 200, in save
  File "/home/weichao/.local/lib/python3.8/site-packages/numpy/lib/npyio.py", line 518, in save
    file_ctx = open(file, "wb")
FileNotFoundError: [Errno 2] No such file or directory: '/opt/CFD-Benchmark/PDE_Benchmark_8/results/prediction/gpt-4o/prompts_no_instruction/k_Fully_Developed_Turbulent_Channel_Flow_KE.npy'

--------------------------------------------------



====== Execution Summary ======
Total Scripts Passed: 0
Total Scripts Failed: 2
--- Running: 1D_Diffusion.py ---
Exit Code: 1
Output:

Errors:
Traceback (most recent call last):
  File "/opt/CFD-Benchmark/PDE_Benchmark_8/solver/gpt-4o/prompts_no_instruction/1D_Diffusion.py", line 34, in <module>
    np.save('/opt/CFD-Benchmark/PDE_Benchmark_8/results/prediction/gpt-4o/prompts_no_instruction/u_1D_Diffusion.npy', u)
  File "<__array_function__ internals>", line 200, in save
  File "/home/weichao/.local/lib/python3.8/site-packages/numpy/lib/npyio.py", line 518, in save
    file_ctx = open(file, "wb")
FileNotFoundError: [Errno 2] No such file or directory: '/opt/CFD-Benchmark/PDE_Benchmark_8/results/prediction/gpt-4o/prompts_no_instruction/u_1D_Diffusion.npy'

--------------------------------------------------



====== Execution Summary ======
Total Scripts Passed: 0
Total Scripts Failed: 3
--- Running: 1D_Linear_Convection_corr.py ---
Exit Code: 0
Output:

Errors:

--------------------------------------------------



====== Execution Summary ======
Total Scripts Passed: 1
Total Scripts Failed: 3
--- Running: 2D_Diffusion.py ---
Exit Code: 1
Output:

Errors:
Traceback (most recent call last):
  File "/opt/CFD-Benchmark/PDE_Benchmark_8/solver/gpt-4o/prompts_no_instruction/2D_Diffusion.py", line 37, in <module>
    np.save('/opt/CFD-Benchmark/PDE_Benchmark_8/results/prediction/gpt-4o/prompts_no_instruction/u_2D_Diffusion.npy', u)
  File "<__array_function__ internals>", line 200, in save
  File "/home/weichao/.local/lib/python3.8/site-packages/numpy/lib/npyio.py", line 518, in save
    file_ctx = open(file, "wb")
FileNotFoundError: [Errno 2] No such file or directory: '/opt/CFD-Benchmark/PDE_Benchmark_8/results/prediction/gpt-4o/prompts_no_instruction/u_2D_Diffusion.npy'

--------------------------------------------------



====== Execution Summary ======
Total Scripts Passed: 1
Total Scripts Failed: 4
--- Running: 2D_Inviscid_Burgers_MK.py ---
Exit Code: 1
Output:

Errors:
Traceback (most recent call last):
  File "/opt/CFD-Benchmark/PDE_Benchmark_8/solver/gpt-4o/prompts_no_instruction/2D_Inviscid_Burgers_MK.py", line 56, in <module>
    np.save('/opt/CFD-Benchmark/PDE_Benchmark_8/results/prediction/gpt-4o/prompts_no_instruction/u_2D_Inviscid_Burgers_MK.npy', u)
  File "<__array_function__ internals>", line 200, in save
  File "/home/weichao/.local/lib/python3.8/site-packages/numpy/lib/npyio.py", line 518, in save
    file_ctx = open(file, "wb")
FileNotFoundError: [Errno 2] No such file or directory: '/opt/CFD-Benchmark/PDE_Benchmark_8/results/prediction/gpt-4o/prompts_no_instruction/u_2D_Inviscid_Burgers_MK.npy'

--------------------------------------------------



====== Execution Summary ======
Total Scripts Passed: 1
Total Scripts Failed: 5
--- Running: 2D_Steady_Heat_Equation_Jac.py ---
Exit Code: 1
Output:

Errors:
Traceback (most recent call last):
  File "/opt/CFD-Benchmark/PDE_Benchmark_8/solver/gpt-4o/prompts_no_instruction/2D_Steady_Heat_Equation_Jac.py", line 43, in <module>
    np.save('/opt/CFD-Benchmark/PDE_Benchmark_8/results/prediction/gpt-4o/prompts_no_instruction/T_2D_Steady_Heat_Equation_Jac.npy', T)
  File "<__array_function__ internals>", line 200, in save
  File "/home/weichao/.local/lib/python3.8/site-packages/numpy/lib/npyio.py", line 518, in save
    file_ctx = open(file, "wb")
FileNotFoundError: [Errno 2] No such file or directory: '/opt/CFD-Benchmark/PDE_Benchmark_8/results/prediction/gpt-4o/prompts_no_instruction/T_2D_Steady_Heat_Equation_Jac.npy'

--------------------------------------------------



====== Execution Summary ======
Total Scripts Passed: 1
Total Scripts Failed: 6
--- Running: 2D_Navier_Stokes_Cavity.py ---
Exit Code: 1
Output:

Errors:
Traceback (most recent call last):
  File "/opt/CFD-Benchmark/PDE_Benchmark_8/solver/gpt-4o/prompts_no_instruction/2D_Navier_Stokes_Cavity.py", line 93, in <module>
    np.save('/opt/CFD-Benchmark/PDE_Benchmark_8/results/prediction/gpt-4o/prompts_no_instruction/u_2D_Navier_Stokes_Cavity.npy', u)
  File "<__array_function__ internals>", line 200, in save
  File "/home/weichao/.local/lib/python3.8/site-packages/numpy/lib/npyio.py", line 518, in save
    file_ctx = open(file, "wb")
FileNotFoundError: [Errno 2] No such file or directory: '/opt/CFD-Benchmark/PDE_Benchmark_8/results/prediction/gpt-4o/prompts_no_instruction/u_2D_Navier_Stokes_Cavity.npy'

--------------------------------------------------



====== Execution Summary ======
Total Scripts Passed: 1
Total Scripts Failed: 7
--- Running: Fully_Developed_Turbulent_Channel_Flow_V2F.py ---
Exit Code: 1
Output:

Errors:
Traceback (most recent call last):
  File "/opt/CFD-Benchmark/PDE_Benchmark_8/solver/gpt-4o/prompts_no_instruction/Fully_Developed_Turbulent_Channel_Flow_V2F.py", line 64, in <module>
    np.save('/opt/CFD-Benchmark/PDE_Benchmark_8/results/prediction/gpt-4o/prompts_no_instruction/k_final_Fully_Developed_Turbulent_Channel_Flow_V2F.npy', k_final)
  File "<__array_function__ internals>", line 200, in save
  File "/home/weichao/.local/lib/python3.8/site-packages/numpy/lib/npyio.py", line 518, in save
    file_ctx = open(file, "wb")
FileNotFoundError: [Errno 2] No such file or directory: '/opt/CFD-Benchmark/PDE_Benchmark_8/results/prediction/gpt-4o/prompts_no_instruction/k_final_Fully_Developed_Turbulent_Channel_Flow_V2F.npy'

--------------------------------------------------



====== Execution Summary ======
Total Scripts Passed: 1
Total Scripts Failed: 8
--- Running: 2D_Unsteady_Heat_Equation_DF.py ---
Exit Code: 1
Output:

Errors:
Traceback (most recent call last):
  File "/opt/CFD-Benchmark/PDE_Benchmark_8/solver/gpt-4o/prompts_no_instruction/2D_Unsteady_Heat_Equation_DF.py", line 50, in <module>
    np.save('/opt/CFD-Benchmark/PDE_Benchmark_8/results/prediction/gpt-4o/prompts_no_instruction/T_2D_Unsteady_Heat_Equation_DF.npy', T)
  File "<__array_function__ internals>", line 200, in save
  File "/home/weichao/.local/lib/python3.8/site-packages/numpy/lib/npyio.py", line 518, in save
    file_ctx = open(file, "wb")
FileNotFoundError: [Errno 2] No such file or directory: '/opt/CFD-Benchmark/PDE_Benchmark_8/results/prediction/gpt-4o/prompts_no_instruction/T_2D_Unsteady_Heat_Equation_DF.npy'

--------------------------------------------------



====== Execution Summary ======
Total Scripts Passed: 1
Total Scripts Failed: 9
--- Running: 2D_Unsteady_Heat_Equation_SE.py ---
Exit Code: 1
Output:

Errors:
Traceback (most recent call last):
  File "/opt/CFD-Benchmark/PDE_Benchmark_8/solver/gpt-4o/prompts_no_instruction/2D_Unsteady_Heat_Equation_SE.py", line 50, in <module>
    np.save('/opt/CFD-Benchmark/PDE_Benchmark_8/results/prediction/gpt-4o/prompts_no_instruction/T_2D_Unsteady_Heat_Equation_SE.npy', T)
  File "<__array_function__ internals>", line 200, in save
  File "/home/weichao/.local/lib/python3.8/site-packages/numpy/lib/npyio.py", line 518, in save
    file_ctx = open(file, "wb")
FileNotFoundError: [Errno 2] No such file or directory: '/opt/CFD-Benchmark/PDE_Benchmark_8/results/prediction/gpt-4o/prompts_no_instruction/T_2D_Unsteady_Heat_Equation_SE.npy'

--------------------------------------------------



====== Execution Summary ======
Total Scripts Passed: 1
Total Scripts Failed: 10
--- Running: 1D_Linear_Convection_adams.py ---
Exit Code: 1
Output:

Errors:
Traceback (most recent call last):
  File "/opt/CFD-Benchmark/PDE_Benchmark_8/solver/gpt-4o/prompts_no_instruction/1D_Linear_Convection_adams.py", line 60, in <module>
    np.save('/opt/CFD-Benchmark/PDE_Benchmark_8/results/prediction/gpt-4o/prompts_no_instruction/u_new_1D_Linear_Convection_adams.npy', u_new)
  File "<__array_function__ internals>", line 200, in save
  File "/home/weichao/.local/lib/python3.8/site-packages/numpy/lib/npyio.py", line 518, in save
    file_ctx = open(file, "wb")
FileNotFoundError: [Errno 2] No such file or directory: '/opt/CFD-Benchmark/PDE_Benchmark_8/results/prediction/gpt-4o/prompts_no_instruction/u_new_1D_Linear_Convection_adams.npy'

--------------------------------------------------



====== Execution Summary ======
Total Scripts Passed: 1
Total Scripts Failed: 11
--- Running: 2D_Unsteady_Heat_Equation_ADI.py ---
Exit Code: 1
Output:

Errors:
Traceback (most recent call last):
  File "/opt/CFD-Benchmark/PDE_Benchmark_8/solver/gpt-4o/prompts_no_instruction/2D_Unsteady_Heat_Equation_ADI.py", line 60, in <module>
    np.save('/opt/CFD-Benchmark/PDE_Benchmark_8/results/prediction/gpt-4o/prompts_no_instruction/T_2D_Unsteady_Heat_Equation_ADI.npy', T)
  File "<__array_function__ internals>", line 200, in save
  File "/home/weichao/.local/lib/python3.8/site-packages/numpy/lib/npyio.py", line 518, in save
    file_ctx = open(file, "wb")
FileNotFoundError: [Errno 2] No such file or directory: '/opt/CFD-Benchmark/PDE_Benchmark_8/results/prediction/gpt-4o/prompts_no_instruction/T_2D_Unsteady_Heat_Equation_ADI.npy'

--------------------------------------------------



====== Execution Summary ======
Total Scripts Passed: 1
Total Scripts Failed: 12
