2025-03-17 16:01:06,787 - INFO - üîπ Generating code for: 2D_Diffusion_FVM (Attempt 1/10)
2025-03-17 16:01:07,529 - INFO - HTTP Request: POST https://api.openai.com/v1/chat/completions "HTTP/1.1 400 Bad Request"
2025-03-17 16:01:07,531 - INFO - ‚ùå API Call Error for 2D_Diffusion_FVM: Error code: 400 - {'error': {'message': "This model's maximum context length is 8192 tokens. However, you requested 8807 tokens (807 in the messages, 8000 in the completion). Please reduce the length of the messages or completion.", 'type': 'invalid_request_error', 'param': 'messages', 'code': 'context_length_exceeded'}}
2025-03-17 16:01:07,531 - INFO - üîπ Generating code for: 1D_Linear_Convection_corr (Attempt 1/10)
2025-03-17 16:01:07,732 - INFO - HTTP Request: POST https://api.openai.com/v1/chat/completions "HTTP/1.1 400 Bad Request"
2025-03-17 16:01:07,733 - INFO - ‚ùå API Call Error for 1D_Linear_Convection_corr: Error code: 400 - {'error': {'message': "This model's maximum context length is 8192 tokens. However, you requested 8795 tokens (795 in the messages, 8000 in the completion). Please reduce the length of the messages or completion.", 'type': 'invalid_request_error', 'param': 'messages', 'code': 'context_length_exceeded'}}
2025-03-17 16:01:07,734 - INFO - üîπ Generating code for: 1D_Burgers_Equation (Attempt 1/10)
2025-03-17 16:01:07,936 - INFO - HTTP Request: POST https://api.openai.com/v1/chat/completions "HTTP/1.1 400 Bad Request"
2025-03-17 16:01:07,938 - INFO - ‚ùå API Call Error for 1D_Burgers_Equation: Error code: 400 - {'error': {'message': "This model's maximum context length is 8192 tokens. However, you requested 8548 tokens (548 in the messages, 8000 in the completion). Please reduce the length of the messages or completion.", 'type': 'invalid_request_error', 'param': 'messages', 'code': 'context_length_exceeded'}}
2025-03-17 16:01:07,938 - INFO - üîπ Generating code for: 1D_Nonlinear_Convection_MK (Attempt 1/10)
2025-03-17 16:01:08,141 - INFO - HTTP Request: POST https://api.openai.com/v1/chat/completions "HTTP/1.1 400 Bad Request"
2025-03-17 16:01:08,143 - INFO - ‚ùå API Call Error for 1D_Nonlinear_Convection_MK: Error code: 400 - {'error': {'message': "This model's maximum context length is 8192 tokens. However, you requested 8480 tokens (480 in the messages, 8000 in the completion). Please reduce the length of the messages or completion.", 'type': 'invalid_request_error', 'param': 'messages', 'code': 'context_length_exceeded'}}
2025-03-17 16:01:08,143 - INFO - üîπ Generating code for: 2D_Laplace_Equation (Attempt 1/10)
2025-03-17 16:01:08,256 - INFO - HTTP Request: POST https://api.openai.com/v1/chat/completions "HTTP/1.1 400 Bad Request"
2025-03-17 16:01:08,258 - INFO - ‚ùå API Call Error for 2D_Laplace_Equation: Error code: 400 - {'error': {'message': "This model's maximum context length is 8192 tokens. However, you requested 8857 tokens (857 in the messages, 8000 in the completion). Please reduce the length of the messages or completion.", 'type': 'invalid_request_error', 'param': 'messages', 'code': 'context_length_exceeded'}}
2025-03-17 16:01:08,258 - INFO - üîπ Generating code for: 2D_Linear_Convection (Attempt 1/10)
2025-03-17 16:01:08,381 - INFO - HTTP Request: POST https://api.openai.com/v1/chat/completions "HTTP/1.1 400 Bad Request"
2025-03-17 16:01:08,383 - INFO - ‚ùå API Call Error for 2D_Linear_Convection: Error code: 400 - {'error': {'message': "This model's maximum context length is 8192 tokens. However, you requested 8917 tokens (917 in the messages, 8000 in the completion). Please reduce the length of the messages or completion.", 'type': 'invalid_request_error', 'param': 'messages', 'code': 'context_length_exceeded'}}
2025-03-17 16:01:08,383 - INFO - üîπ Generating code for: 1D_Linear_Convection_Dufort_Frankel (Attempt 1/10)
2025-03-17 16:01:08,526 - INFO - HTTP Request: POST https://api.openai.com/v1/chat/completions "HTTP/1.1 400 Bad Request"
2025-03-17 16:01:08,527 - INFO - ‚ùå API Call Error for 1D_Linear_Convection_Dufort_Frankel: Error code: 400 - {'error': {'message': "This model's maximum context length is 8192 tokens. However, you requested 8485 tokens (485 in the messages, 8000 in the completion). Please reduce the length of the messages or completion.", 'type': 'invalid_request_error', 'param': 'messages', 'code': 'context_length_exceeded'}}
2025-03-17 16:01:08,527 - INFO - üîπ Generating code for: 1D_Nonlinear_Convection_LW (Attempt 1/10)
2025-03-17 16:01:08,645 - INFO - HTTP Request: POST https://api.openai.com/v1/chat/completions "HTTP/1.1 400 Bad Request"
2025-03-17 16:01:08,646 - INFO - ‚ùå API Call Error for 1D_Nonlinear_Convection_LW: Error code: 400 - {'error': {'message': "This model's maximum context length is 8192 tokens. However, you requested 8476 tokens (476 in the messages, 8000 in the completion). Please reduce the length of the messages or completion.", 'type': 'invalid_request_error', 'param': 'messages', 'code': 'context_length_exceeded'}}
2025-03-17 16:01:08,646 - INFO - üîπ Generating code for: 1D_Linear_Convection_adams (Attempt 1/10)
2025-03-17 16:01:08,860 - INFO - HTTP Request: POST https://api.openai.com/v1/chat/completions "HTTP/1.1 400 Bad Request"
2025-03-17 16:01:08,862 - INFO - ‚ùå API Call Error for 1D_Linear_Convection_adams: Error code: 400 - {'error': {'message': "This model's maximum context length is 8192 tokens. However, you requested 8806 tokens (806 in the messages, 8000 in the completion). Please reduce the length of the messages or completion.", 'type': 'invalid_request_error', 'param': 'messages', 'code': 'context_length_exceeded'}}
2025-03-17 16:01:08,862 - INFO - üîπ Generating code for: 2D_Steady_Heat_Equation (Attempt 1/10)
2025-03-17 16:01:09,270 - INFO - HTTP Request: POST https://api.openai.com/v1/chat/completions "HTTP/1.1 400 Bad Request"
2025-03-17 16:01:09,271 - INFO - ‚ùå API Call Error for 2D_Steady_Heat_Equation: Error code: 400 - {'error': {'message': "This model's maximum context length is 8192 tokens. However, you requested 8862 tokens (862 in the messages, 8000 in the completion). Please reduce the length of the messages or completion.", 'type': 'invalid_request_error', 'param': 'messages', 'code': 'context_length_exceeded'}}
2025-03-17 16:01:09,271 - INFO - üîπ Generating code for: 2D_Channel_Flow_Navier_Stokes (Attempt 1/10)
2025-03-17 16:01:09,474 - INFO - HTTP Request: POST https://api.openai.com/v1/chat/completions "HTTP/1.1 400 Bad Request"
2025-03-17 16:01:09,476 - INFO - ‚ùå API Call Error for 2D_Channel_Flow_Navier_Stokes: Error code: 400 - {'error': {'message': "This model's maximum context length is 8192 tokens. However, you requested 9024 tokens (1024 in the messages, 8000 in the completion). Please reduce the length of the messages or completion.", 'type': 'invalid_request_error', 'param': 'messages', 'code': 'context_length_exceeded'}}
2025-03-17 16:01:09,476 - INFO - üîπ Generating code for: 2D_Diffusion (Attempt 1/10)
2025-03-17 16:01:09,680 - INFO - HTTP Request: POST https://api.openai.com/v1/chat/completions "HTTP/1.1 400 Bad Request"
2025-03-17 16:01:09,682 - INFO - ‚ùå API Call Error for 2D_Diffusion: Error code: 400 - {'error': {'message': "This model's maximum context length is 8192 tokens. However, you requested 8770 tokens (770 in the messages, 8000 in the completion). Please reduce the length of the messages or completion.", 'type': 'invalid_request_error', 'param': 'messages', 'code': 'context_length_exceeded'}}
2025-03-17 16:01:09,682 - INFO - üîπ Generating code for: 1D_Euler_Shock_Tube (Attempt 1/10)
2025-03-17 16:01:09,885 - INFO - HTTP Request: POST https://api.openai.com/v1/chat/completions "HTTP/1.1 400 Bad Request"
2025-03-17 16:01:09,886 - INFO - ‚ùå API Call Error for 1D_Euler_Shock_Tube: Error code: 400 - {'error': {'message': "This model's maximum context length is 8192 tokens. However, you requested 9100 tokens (1100 in the messages, 8000 in the completion). Please reduce the length of the messages or completion.", 'type': 'invalid_request_error', 'param': 'messages', 'code': 'context_length_exceeded'}}
2025-03-17 16:01:09,886 - INFO - üîπ Generating code for: 1D_Linear_Convection_Explicit (Attempt 1/10)
2025-03-17 16:01:10,089 - INFO - HTTP Request: POST https://api.openai.com/v1/chat/completions "HTTP/1.1 400 Bad Request"
2025-03-17 16:01:10,091 - INFO - ‚ùå API Call Error for 1D_Linear_Convection_Explicit: Error code: 400 - {'error': {'message': "This model's maximum context length is 8192 tokens. However, you requested 8481 tokens (481 in the messages, 8000 in the completion). Please reduce the length of the messages or completion.", 'type': 'invalid_request_error', 'param': 'messages', 'code': 'context_length_exceeded'}}
2025-03-17 16:01:10,091 - INFO - üîπ Generating code for: 2D_Inviscid_Burgers_FOU (Attempt 1/10)
2025-03-17 16:01:10,223 - INFO - HTTP Request: POST https://api.openai.com/v1/chat/completions "HTTP/1.1 400 Bad Request"
2025-03-17 16:01:10,224 - INFO - ‚ùå API Call Error for 2D_Inviscid_Burgers_FOU: Error code: 400 - {'error': {'message': "This model's maximum context length is 8192 tokens. However, you requested 9179 tokens (1179 in the messages, 8000 in the completion). Please reduce the length of the messages or completion.", 'type': 'invalid_request_error', 'param': 'messages', 'code': 'context_length_exceeded'}}
2025-03-17 16:01:10,225 - INFO - üîπ Generating code for: Fully_Developed_Turbulent_Channel_Flow_SA (Attempt 1/10)
2025-03-17 16:01:10,600 - INFO - HTTP Request: POST https://api.openai.com/v1/chat/completions "HTTP/1.1 400 Bad Request"
2025-03-17 16:01:10,602 - INFO - ‚ùå API Call Error for Fully_Developed_Turbulent_Channel_Flow_SA: Error code: 400 - {'error': {'message': "This model's maximum context length is 8192 tokens. However, you requested 9025 tokens (1025 in the messages, 8000 in the completion). Please reduce the length of the messages or completion.", 'type': 'invalid_request_error', 'param': 'messages', 'code': 'context_length_exceeded'}}
2025-03-17 16:01:10,602 - INFO - üîπ Generating code for: 2D_Burgers_Equation (Attempt 1/10)
2025-03-17 16:01:10,812 - INFO - HTTP Request: POST https://api.openai.com/v1/chat/completions "HTTP/1.1 400 Bad Request"
2025-03-17 16:01:10,813 - INFO - ‚ùå API Call Error for 2D_Burgers_Equation: Error code: 400 - {'error': {'message': "This model's maximum context length is 8192 tokens. However, you requested 9194 tokens (1194 in the messages, 8000 in the completion). Please reduce the length of the messages or completion.", 'type': 'invalid_request_error', 'param': 'messages', 'code': 'context_length_exceeded'}}
2025-03-17 16:01:10,813 - INFO - üîπ Generating code for: Fully_Developed_Turbulent_Channel_Flow_k (Attempt 1/10)
2025-03-17 16:01:11,112 - INFO - HTTP Request: POST https://api.openai.com/v1/chat/completions "HTTP/1.1 400 Bad Request"
2025-03-17 16:01:11,113 - INFO - ‚ùå API Call Error for Fully_Developed_Turbulent_Channel_Flow_k: Error code: 400 - {'error': {'message': "This model's maximum context length is 8192 tokens. However, you requested 8822 tokens (822 in the messages, 8000 in the completion). Please reduce the length of the messages or completion.", 'type': 'invalid_request_error', 'param': 'messages', 'code': 'context_length_exceeded'}}
2025-03-17 16:01:11,113 - INFO - üîπ Generating code for: 1D_Linear_Convection_explicit_euler (Attempt 1/10)
2025-03-17 16:01:11,421 - INFO - HTTP Request: POST https://api.openai.com/v1/chat/completions "HTTP/1.1 400 Bad Request"
2025-03-17 16:01:11,421 - INFO - ‚ùå API Call Error for 1D_Linear_Convection_explicit_euler: Error code: 400 - {'error': {'message': "This model's maximum context length is 8192 tokens. However, you requested 8728 tokens (728 in the messages, 8000 in the completion). Please reduce the length of the messages or completion.", 'type': 'invalid_request_error', 'param': 'messages', 'code': 'context_length_exceeded'}}
2025-03-17 16:01:11,422 - INFO - üîπ Generating code for: 2D_Cavity_Flow_Navier_Stokes (Attempt 1/10)
2025-03-17 16:01:11,517 - INFO - HTTP Request: POST https://api.openai.com/v1/chat/completions "HTTP/1.1 400 Bad Request"
2025-03-17 16:01:11,517 - INFO - ‚ùå API Call Error for 2D_Cavity_Flow_Navier_Stokes: Error code: 400 - {'error': {'message': "This model's maximum context length is 8192 tokens. However, you requested 8999 tokens (999 in the messages, 8000 in the completion). Please reduce the length of the messages or completion.", 'type': 'invalid_request_error', 'param': 'messages', 'code': 'context_length_exceeded'}}
2025-03-17 16:01:11,517 - INFO - üîπ Generating code for: 2D_Inviscid_Burgers_MK (Attempt 1/10)
2025-03-17 16:01:11,683 - INFO - HTTP Request: POST https://api.openai.com/v1/chat/completions "HTTP/1.1 400 Bad Request"
2025-03-17 16:01:11,684 - INFO - ‚ùå API Call Error for 2D_Inviscid_Burgers_MK: Error code: 400 - {'error': {'message': "This model's maximum context length is 8192 tokens. However, you requested 9191 tokens (1191 in the messages, 8000 in the completion). Please reduce the length of the messages or completion.", 'type': 'invalid_request_error', 'param': 'messages', 'code': 'context_length_exceeded'}}
2025-03-17 16:01:11,684 - INFO - üîπ Generating code for: 1D_Diffusion (Attempt 1/10)
2025-03-17 16:01:11,827 - INFO - HTTP Request: POST https://api.openai.com/v1/chat/completions "HTTP/1.1 400 Bad Request"
2025-03-17 16:01:11,827 - INFO - ‚ùå API Call Error for 1D_Diffusion: Error code: 400 - {'error': {'message': "This model's maximum context length is 8192 tokens. However, you requested 8431 tokens (431 in the messages, 8000 in the completion). Please reduce the length of the messages or completion.", 'type': 'invalid_request_error', 'param': 'messages', 'code': 'context_length_exceeded'}}
2025-03-17 16:01:11,827 - INFO - üîπ Generating code for: 1D_Linear_Convection_ADI (Attempt 1/10)
2025-03-17 16:01:12,034 - INFO - HTTP Request: POST https://api.openai.com/v1/chat/completions "HTTP/1.1 400 Bad Request"
2025-03-17 16:01:12,035 - INFO - ‚ùå API Call Error for 1D_Linear_Convection_ADI: Error code: 400 - {'error': {'message': "This model's maximum context length is 8192 tokens. However, you requested 8456 tokens (456 in the messages, 8000 in the completion). Please reduce the length of the messages or completion.", 'type': 'invalid_request_error', 'param': 'messages', 'code': 'context_length_exceeded'}}
2025-03-17 16:01:12,036 - INFO - üîπ Generating code for: 1D_Linear_Convection_rk (Attempt 1/10)
2025-03-17 16:01:12,238 - INFO - HTTP Request: POST https://api.openai.com/v1/chat/completions "HTTP/1.1 400 Bad Request"
2025-03-17 16:01:12,240 - INFO - ‚ùå API Call Error for 1D_Linear_Convection_rk: Error code: 400 - {'error': {'message': "This model's maximum context length is 8192 tokens. However, you requested 8879 tokens (879 in the messages, 8000 in the completion). Please reduce the length of the messages or completion.", 'type': 'invalid_request_error', 'param': 'messages', 'code': 'context_length_exceeded'}}
2025-03-17 16:01:12,240 - INFO - üîπ Generating code for: 1D_Nonlinear_Convection_Lax (Attempt 1/10)
2025-03-17 16:01:12,443 - INFO - HTTP Request: POST https://api.openai.com/v1/chat/completions "HTTP/1.1 400 Bad Request"
2025-03-17 16:01:12,445 - INFO - ‚ùå API Call Error for 1D_Nonlinear_Convection_Lax: Error code: 400 - {'error': {'message': "This model's maximum context length is 8192 tokens. However, you requested 8422 tokens (422 in the messages, 8000 in the completion). Please reduce the length of the messages or completion.", 'type': 'invalid_request_error', 'param': 'messages', 'code': 'context_length_exceeded'}}
2025-03-17 16:01:12,445 - INFO - üîπ Generating code for: 2D_Convection (Attempt 1/10)
2025-03-17 16:01:12,554 - INFO - HTTP Request: POST https://api.openai.com/v1/chat/completions "HTTP/1.1 400 Bad Request"
2025-03-17 16:01:12,554 - INFO - ‚ùå API Call Error for 2D_Convection: Error code: 400 - {'error': {'message': "This model's maximum context length is 8192 tokens. However, you requested 8934 tokens (934 in the messages, 8000 in the completion). Please reduce the length of the messages or completion.", 'type': 'invalid_request_error', 'param': 'messages', 'code': 'context_length_exceeded'}}
2025-03-17 16:01:12,555 - INFO - üîπ Generating code for: Fully_Developed_Turbulent_Channel_Flow_Cess (Attempt 1/10)
2025-03-17 16:01:12,641 - INFO - HTTP Request: POST https://api.openai.com/v1/chat/completions "HTTP/1.1 400 Bad Request"
2025-03-17 16:01:12,643 - INFO - ‚ùå API Call Error for Fully_Developed_Turbulent_Channel_Flow_Cess: Error code: 400 - {'error': {'message': "This model's maximum context length is 8192 tokens. However, you requested 8913 tokens (913 in the messages, 8000 in the completion). Please reduce the length of the messages or completion.", 'type': 'invalid_request_error', 'param': 'messages', 'code': 'context_length_exceeded'}}
2025-03-17 16:01:12,643 - INFO - üîπ Generating code for: 2D_Poisson_Equation (Attempt 1/10)
2025-03-17 16:01:12,852 - INFO - HTTP Request: POST https://api.openai.com/v1/chat/completions "HTTP/1.1 400 Bad Request"
2025-03-17 16:01:12,853 - INFO - ‚ùå API Call Error for 2D_Poisson_Equation: Error code: 400 - {'error': {'message': "This model's maximum context length is 8192 tokens. However, you requested 8862 tokens (862 in the messages, 8000 in the completion). Please reduce the length of the messages or completion.", 'type': 'invalid_request_error', 'param': 'messages', 'code': 'context_length_exceeded'}}
2025-03-17 16:01:12,853 - INFO - üîπ Generating code for: Fully_Developed_Turbulent_Channel_Flow_SST (Attempt 1/10)
2025-03-17 16:01:13,059 - INFO - HTTP Request: POST https://api.openai.com/v1/chat/completions "HTTP/1.1 400 Bad Request"
2025-03-17 16:01:13,061 - INFO - ‚ùå API Call Error for Fully_Developed_Turbulent_Channel_Flow_SST: Error code: 400 - {'error': {'message': "This model's maximum context length is 8192 tokens. However, you requested 8842 tokens (842 in the messages, 8000 in the completion). Please reduce the length of the messages or completion.", 'type': 'invalid_request_error', 'param': 'messages', 'code': 'context_length_exceeded'}}
2025-03-17 16:01:13,061 - INFO - üîπ Generating code for: Fully_Developed_Turbulent_Channel_Flow_V2F (Attempt 1/10)
2025-03-17 16:01:13,182 - INFO - HTTP Request: POST https://api.openai.com/v1/chat/completions "HTTP/1.1 400 Bad Request"
2025-03-17 16:01:13,184 - INFO - ‚ùå API Call Error for Fully_Developed_Turbulent_Channel_Flow_V2F: Error code: 400 - {'error': {'message': "This model's maximum context length is 8192 tokens. However, you requested 8982 tokens (982 in the messages, 8000 in the completion). Please reduce the length of the messages or completion.", 'type': 'invalid_request_error', 'param': 'messages', 'code': 'context_length_exceeded'}}
2025-03-17 16:01:13,184 - INFO - 
üéØ Execution completed. Check the solver directory for generated files.
2025-03-17 16:01:53,930 - INFO - üîπ Generating code for: 2D_Diffusion_FVM (Attempt 1/10)
2025-03-17 16:02:26,726 - INFO - HTTP Request: POST https://api.openai.com/v1/chat/completions "HTTP/1.1 200 OK"
2025-03-17 16:02:27,691 - INFO - Execution successful, no errors detected.
2025-03-17 16:02:27,691 - INFO - üéØ 2D_Diffusion_FVM executed successfully without syntax errors.
2025-03-17 16:02:27,691 - INFO - üîπ Generating code for: 1D_Linear_Convection_corr (Attempt 1/10)
2025-03-17 16:02:54,742 - INFO - HTTP Request: POST https://api.openai.com/v1/chat/completions "HTTP/1.1 200 OK"
2025-03-17 16:02:55,443 - INFO - Execution successful, no errors detected.
2025-03-17 16:02:55,443 - INFO - üéØ 1D_Linear_Convection_corr executed successfully without syntax errors.
2025-03-17 16:02:55,443 - INFO - üîπ Generating code for: 1D_Burgers_Equation (Attempt 1/10)
2025-03-17 16:03:25,359 - INFO - HTTP Request: POST https://api.openai.com/v1/chat/completions "HTTP/1.1 200 OK"
2025-03-17 16:03:25,762 - INFO - ‚ùå Error detected in 1D_Burgers_Equation, refining prompt...
2025-03-17 16:03:25,762 - INFO - 

[Feedback]: The previous generated code had the following error:
Traceback (most recent call last):
  File "/opt/CFD-Benchmark/PDE_Benchmark_6/solver/1D_Burgers_Equation.py", line 21, in <module>
    u_init = sp.lambdify((u_sym, nu), -2 * nu * (phiprime / phi) + 4)
  File "/home/weichao/.local/lib/python3.8/site-packages/sympy/utilities/lambdify.py", line 903, in lambdify
    c = compile(funcstr, filename, 'exec')
  File "<lambdifygenerated-1>", line 1
    def _lambdifygenerated(u, 0.07):
                              ^
SyntaxError: invalid syntax
Please correct it.
2025-03-17 16:03:25,762 - INFO - üîπ Generating code for: 1D_Burgers_Equation (Attempt 2/10)
2025-03-17 16:04:18,485 - INFO - HTTP Request: POST https://api.openai.com/v1/chat/completions "HTTP/1.1 200 OK"
2025-03-17 16:04:19,073 - INFO - ‚ùå Error detected in 1D_Burgers_Equation, refining prompt...
2025-03-17 16:04:19,074 - INFO - 

[Feedback]: The previous generated code had the following error:
/home/weichao/.local/lib/python3.8/site-packages/sympy/functions/elementary/exponential.py:85: SymPyDeprecationWarning: 

Using non-Expr arguments in Mul is deprecated (in this case, one of
the arguments has type 'ImmutableDenseNDimArray').

If you really did intend to use a multiplication or addition operation with
this object, use the * or + operator instead.

See https://docs.sympy.org/latest/explanation/active-deprecations.html#non-expr-args-deprecated
for details.

This has been deprecated since SymPy version 1.7. It
will be removed in a future version of SymPy.

  return self.func(1), Mul(*self.args)
Traceback (most recent call last):
  File "/opt/CFD-Benchmark/PDE_Benchmark_6/solver/1D_Burgers_Equation.py", line 15, in <module>
    u = -2 * nu * (phiprime / phi) + 4
  File "/home/weichao/.local/lib/python3.8/site-packages/sympy/core/decorators.py", line 236, in _func
    return func(self, other)
  File "/home/weichao/.local/lib/python3.8/site-packages/sympy/core/decorators.py", line 106, in binary_op_wrapper
    return func(self, other)
  File "/home/weichao/.local/lib/python3.8/site-packages/sympy/core/expr.py", line 259, in __truediv__
    return Mul(self, denom)
  File "/home/weichao/.local/lib/python3.8/site-packages/sympy/core/cache.py", line 72, in wrapper
    retval = cfunc(*args, **kwargs)
  File "/home/weichao/.local/lib/python3.8/site-packages/sympy/core/operations.py", line 98, in __new__
    c_part, nc_part, order_symbols = cls.flatten(args)
  File "/home/weichao/.local/lib/python3.8/site-packages/sympy/core/mul.py", line 436, in flatten
    new_exp = e1 + e2
TypeError: unsupported operand type(s) for +: 'ImmutableDenseNDimArray' and 'NegativeOne'
Please correct it.
2025-03-17 16:04:19,074 - INFO - üîπ Generating code for: 1D_Burgers_Equation (Attempt 3/10)
2025-03-17 16:04:19,195 - INFO - HTTP Request: POST https://api.openai.com/v1/chat/completions "HTTP/1.1 400 Bad Request"
2025-03-17 16:04:19,197 - INFO - ‚ùå API Call Error for 1D_Burgers_Equation: Error code: 400 - {'error': {'message': "This model's maximum context length is 8192 tokens. However, you requested 8244 tokens (1244 in the messages, 7000 in the completion). Please reduce the length of the messages or completion.", 'type': 'invalid_request_error', 'param': 'messages', 'code': 'context_length_exceeded'}}
2025-03-17 16:04:19,197 - INFO - üîπ Generating code for: 1D_Nonlinear_Convection_MK (Attempt 1/10)
2025-03-17 16:04:46,154 - INFO - HTTP Request: POST https://api.openai.com/v1/chat/completions "HTTP/1.1 200 OK"
2025-03-17 16:04:46,744 - INFO - Execution successful, no errors detected.
2025-03-17 16:04:46,744 - INFO - üéØ 1D_Nonlinear_Convection_MK executed successfully without syntax errors.
2025-03-17 16:04:46,744 - INFO - üîπ Generating code for: 2D_Laplace_Equation (Attempt 1/10)
2025-03-17 16:05:17,340 - INFO - HTTP Request: POST https://api.openai.com/v1/chat/completions "HTTP/1.1 200 OK"
2025-03-17 16:05:17,968 - INFO - Execution successful, no errors detected.
2025-03-17 16:05:17,968 - INFO - üéØ 2D_Laplace_Equation executed successfully without syntax errors.
2025-03-17 16:05:17,968 - INFO - üîπ Generating code for: 2D_Linear_Convection (Attempt 1/10)
2025-03-17 16:05:46,194 - INFO - HTTP Request: POST https://api.openai.com/v1/chat/completions "HTTP/1.1 200 OK"
2025-03-17 16:05:46,796 - INFO - Execution successful, no errors detected.
2025-03-17 16:05:46,796 - INFO - üéØ 2D_Linear_Convection executed successfully without syntax errors.
2025-03-17 16:05:46,797 - INFO - üîπ Generating code for: 1D_Linear_Convection_Dufort_Frankel (Attempt 1/10)
2025-03-17 16:06:22,871 - INFO - HTTP Request: POST https://api.openai.com/v1/chat/completions "HTTP/1.1 200 OK"
2025-03-17 16:06:23,035 - INFO - ‚ùå Error detected in 1D_Linear_Convection_Dufort_Frankel, refining prompt...
2025-03-17 16:06:23,035 - INFO - 

[Feedback]: The previous generated code had the following error:
File "/opt/CFD-Benchmark/PDE_Benchmark_6/solver/1D_Linear_Convection_Dufort_Frankel.py", line 24
    u[1] = initial_u - dt * c * (np.roll(initial_u, -1) - np.roll(initial_u, 1)) / (2 * dx) + 
                                                                                             ^
SyntaxError: invalid syntax
Please correct it.
2025-03-17 16:06:23,035 - INFO - üîπ Generating code for: 1D_Linear_Convection_Dufort_Frankel (Attempt 2/10)
2025-03-17 16:06:53,112 - INFO - HTTP Request: POST https://api.openai.com/v1/chat/completions "HTTP/1.1 200 OK"
2025-03-17 16:06:54,235 - INFO - Execution successful, no errors detected.
2025-03-17 16:06:54,235 - INFO - üéØ 1D_Linear_Convection_Dufort_Frankel executed successfully without syntax errors.
2025-03-17 16:06:54,235 - INFO - üîπ Generating code for: 1D_Nonlinear_Convection_LW (Attempt 1/10)
2025-03-17 16:07:25,491 - INFO - HTTP Request: POST https://api.openai.com/v1/chat/completions "HTTP/1.1 200 OK"
2025-03-17 16:07:26,047 - INFO - Execution successful, no errors detected.
2025-03-17 16:07:26,047 - INFO - üéØ 1D_Nonlinear_Convection_LW executed successfully without syntax errors.
2025-03-17 16:07:26,047 - INFO - üîπ Generating code for: 1D_Linear_Convection_adams (Attempt 1/10)
2025-03-17 16:08:07,272 - INFO - HTTP Request: POST https://api.openai.com/v1/chat/completions "HTTP/1.1 200 OK"
2025-03-17 16:08:07,591 - INFO - ‚ùå Error detected in 1D_Linear_Convection_adams, refining prompt...
2025-03-17 16:08:07,592 - INFO - 

[Feedback]: The previous generated code had the following error:
Traceback (most recent call last):
  File "/opt/CFD-Benchmark/PDE_Benchmark_6/solver/1D_Linear_Convection_adams.py", line 46, in <module>
    u[n+1,1:-1] = u[n,1:-1] + delta_t / 2 * (3 * f_n - f_n_minus_1)
ValueError: operands could not be broadcast together with shapes (99,) (97,)
Please correct it.
2025-03-17 16:08:07,592 - INFO - üîπ Generating code for: 1D_Linear_Convection_adams (Attempt 2/10)
2025-03-17 16:08:44,103 - INFO - HTTP Request: POST https://api.openai.com/v1/chat/completions "HTTP/1.1 200 OK"
2025-03-17 16:08:44,883 - INFO - Execution successful, no errors detected.
2025-03-17 16:08:44,884 - INFO - üéØ 1D_Linear_Convection_adams executed successfully without syntax errors.
2025-03-17 16:08:44,884 - INFO - üîπ Generating code for: 2D_Steady_Heat_Equation (Attempt 1/10)
2025-03-17 16:09:11,002 - INFO - HTTP Request: POST https://api.openai.com/v1/chat/completions "HTTP/1.1 200 OK"
2025-03-17 16:09:12,481 - INFO - Execution successful, no errors detected.
2025-03-17 16:09:12,481 - INFO - üéØ 2D_Steady_Heat_Equation executed successfully without syntax errors.
2025-03-17 16:09:12,481 - INFO - üîπ Generating code for: 2D_Channel_Flow_Navier_Stokes (Attempt 1/10)
2025-03-17 16:11:10,197 - INFO - HTTP Request: POST https://api.openai.com/v1/chat/completions "HTTP/1.1 200 OK"
2025-03-17 16:11:10,522 - INFO - ‚ùå Error detected in 2D_Channel_Flow_Navier_Stokes, refining prompt...
2025-03-17 16:11:10,522 - INFO - 

[Feedback]: The previous generated code had the following error:
Traceback (most recent call last):
  File "/opt/CFD-Benchmark/PDE_Benchmark_6/solver/2D_Channel_Flow_Navier_Stokes.py", line 150, in <module>
    u, v, p = channel_flow(nt, u, v, dt, dx, dy, p, rho, nu, F)
  File "/opt/CFD-Benchmark/PDE_Benchmark_6/solver/2D_Channel_Flow_Navier_Stokes.py", line 59, in channel_flow
    p = pressure_poisson_periodic(p, dx, dy, b)
  File "/opt/CFD-Benchmark/PDE_Benchmark_6/solver/2D_Channel_Flow_Navier_Stokes.py", line 40, in pressure_poisson_periodic
    p[-1, :-1] = (((pn[-1, 1:] + pn[-1, :-2]) * dy**2 +
ValueError: operands could not be broadcast together with shapes (40,) (39,)
Please correct it.
2025-03-17 16:11:10,522 - INFO - üîπ Generating code for: 2D_Channel_Flow_Navier_Stokes (Attempt 2/10)
2025-03-17 16:11:10,709 - INFO - HTTP Request: POST https://api.openai.com/v1/chat/completions "HTTP/1.1 400 Bad Request"
2025-03-17 16:11:10,710 - INFO - ‚ùå API Call Error for 2D_Channel_Flow_Navier_Stokes: Error code: 400 - {'error': {'message': "This model's maximum context length is 8192 tokens. However, you requested 8256 tokens (1256 in the messages, 7000 in the completion). Please reduce the length of the messages or completion.", 'type': 'invalid_request_error', 'param': 'messages', 'code': 'context_length_exceeded'}}
2025-03-17 16:11:10,710 - INFO - üîπ Generating code for: 2D_Diffusion (Attempt 1/10)
2025-03-17 16:11:39,349 - INFO - HTTP Request: POST https://api.openai.com/v1/chat/completions "HTTP/1.1 200 OK"
2025-03-17 16:11:39,802 - INFO - ‚ùå Error detected in 2D_Diffusion, refining prompt...
2025-03-17 16:11:39,802 - INFO - 

[Feedback]: The previous generated code had the following error:
Traceback (most recent call last):
  File "/opt/CFD-Benchmark/PDE_Benchmark_6/solver/2D_Diffusion.py", line 51, in <module>
    u = Explicit_Euler(u, nt, dt, dx, dy, nu)
  File "/opt/CFD-Benchmark/PDE_Benchmark_6/solver/2D_Diffusion.py", line 31, in Explicit_Euler
    plot_2D_solution(X,Y,u,n*dt)
  File "/opt/CFD-Benchmark/PDE_Benchmark_6/solver/2D_Diffusion.py", line 12, in plot_2D_solution
    ax = fig.gca(projection='3d')
TypeError: gca() got an unexpected keyword argument 'projection'
Please correct it.
2025-03-17 16:11:39,802 - INFO - üîπ Generating code for: 2D_Diffusion (Attempt 2/10)
2025-03-17 16:12:05,663 - INFO - HTTP Request: POST https://api.openai.com/v1/chat/completions "HTTP/1.1 200 OK"
2025-03-17 16:12:10,464 - INFO - Execution successful, no errors detected.
2025-03-17 16:12:10,464 - INFO - üéØ 2D_Diffusion executed successfully without syntax errors.
2025-03-17 16:12:10,465 - INFO - üîπ Generating code for: 1D_Euler_Shock_Tube (Attempt 1/10)
2025-03-17 16:13:01,675 - INFO - HTTP Request: POST https://api.openai.com/v1/chat/completions "HTTP/1.1 200 OK"
2025-03-17 16:13:02,363 - INFO - Execution successful, no errors detected.
2025-03-17 16:13:02,363 - INFO - üéØ 1D_Euler_Shock_Tube executed successfully without syntax errors.
2025-03-17 16:13:02,363 - INFO - üîπ Generating code for: 1D_Linear_Convection_Explicit (Attempt 1/10)
2025-03-17 16:13:29,427 - INFO - HTTP Request: POST https://api.openai.com/v1/chat/completions "HTTP/1.1 200 OK"
2025-03-17 16:13:29,749 - INFO - ‚ùå Error detected in 1D_Linear_Convection_Explicit, refining prompt...
2025-03-17 16:13:29,750 - INFO - 

[Feedback]: The previous generated code had the following error:
Traceback (most recent call last):
  File "/opt/CFD-Benchmark/PDE_Benchmark_6/solver/1D_Linear_Convection_Explicit.py", line 55, in <module>
    plt.plot(x,np.roll(u[i], Nx//2))
NameError: name 'x' is not defined
Please correct it.
2025-03-17 16:13:29,750 - INFO - üîπ Generating code for: 1D_Linear_Convection_Explicit (Attempt 2/10)
2025-03-17 16:13:58,506 - INFO - HTTP Request: POST https://api.openai.com/v1/chat/completions "HTTP/1.1 200 OK"
2025-03-17 16:13:59,095 - INFO - Execution successful, no errors detected.
2025-03-17 16:13:59,095 - INFO - üéØ 1D_Linear_Convection_Explicit executed successfully without syntax errors.
2025-03-17 16:13:59,095 - INFO - üîπ Generating code for: 2D_Inviscid_Burgers_FOU (Attempt 1/10)
2025-03-17 16:14:29,362 - INFO - HTTP Request: POST https://api.openai.com/v1/chat/completions "HTTP/1.1 200 OK"
2025-03-17 16:14:29,514 - INFO - Execution successful, no errors detected.
2025-03-17 16:14:29,514 - INFO - üéØ 2D_Inviscid_Burgers_FOU executed successfully without syntax errors.
2025-03-17 16:14:29,514 - INFO - üîπ Generating code for: Fully_Developed_Turbulent_Channel_Flow_SA (Attempt 1/10)
2025-03-17 16:15:00,910 - INFO - HTTP Request: POST https://api.openai.com/v1/chat/completions "HTTP/1.1 200 OK"
2025-03-17 16:15:01,301 - INFO - ‚ùå Error detected in Fully_Developed_Turbulent_Channel_Flow_SA, refining prompt...
2025-03-17 16:15:01,301 - INFO - 

[Feedback]: The previous generated code had the following error:
Traceback (most recent call last):
  File "/home/weichao/.local/lib/python3.8/site-packages/numpy/core/fromnumeric.py", line 3185, in ndim
    return a.ndim
AttributeError: 'list' object has no attribute 'ndim'

During handling of the above exception, another exception occurred:

Traceback (most recent call last):
  File "/opt/CFD-Benchmark/PDE_Benchmark_6/solver/Fully_Developed_Turbulent_Channel_Flow_SA.py", line 39, in <module>
    A = dia_matrix(([d, -d[:-1], -d[1:]], [0, -1, 1]), shape=(N, N))
  File "/home/weichao/.local/lib/python3.8/site-packages/scipy/sparse/_dia.py", line 107, in __init__
    if isshape(arg1):
  File "/home/weichao/.local/lib/python3.8/site-packages/scipy/sparse/_sputils.py", line 249, in isshape
    if isintlike(M) and isintlike(N):
  File "/home/weichao/.local/lib/python3.8/site-packages/scipy/sparse/_sputils.py", line 222, in isintlike
    if np.ndim(x) != 0:
  File "<__array_function__ internals>", line 200, in ndim
  File "/home/weichao/.local/lib/python3.8/site-packages/numpy/core/fromnumeric.py", line 3187, in ndim
    return asarray(a).ndim
ValueError: setting an array element with a sequence. The requested array has an inhomogeneous shape after 1 dimensions. The detected shape was (3,) + inhomogeneous part.
Please correct it.
2025-03-17 16:15:01,301 - INFO - üîπ Generating code for: Fully_Developed_Turbulent_Channel_Flow_SA (Attempt 2/10)
2025-03-17 16:15:01,484 - INFO - HTTP Request: POST https://api.openai.com/v1/chat/completions "HTTP/1.1 400 Bad Request"
2025-03-17 16:15:01,486 - INFO - ‚ùå API Call Error for Fully_Developed_Turbulent_Channel_Flow_SA: Error code: 400 - {'error': {'message': "This model's maximum context length is 8192 tokens. However, you requested 8419 tokens (1419 in the messages, 7000 in the completion). Please reduce the length of the messages or completion.", 'type': 'invalid_request_error', 'param': 'messages', 'code': 'context_length_exceeded'}}
2025-03-17 16:15:01,486 - INFO - üîπ Generating code for: 2D_Burgers_Equation (Attempt 1/10)
2025-03-17 16:15:01,688 - INFO - HTTP Request: POST https://api.openai.com/v1/chat/completions "HTTP/1.1 400 Bad Request"
2025-03-17 16:15:01,688 - INFO - ‚ùå API Call Error for 2D_Burgers_Equation: Error code: 400 - {'error': {'message': "This model's maximum context length is 8192 tokens. However, you requested 8194 tokens (1194 in the messages, 7000 in the completion). Please reduce the length of the messages or completion.", 'type': 'invalid_request_error', 'param': 'messages', 'code': 'context_length_exceeded'}}
2025-03-17 16:15:01,688 - INFO - üîπ Generating code for: Fully_Developed_Turbulent_Channel_Flow_k (Attempt 1/10)
2025-03-17 16:15:40,808 - INFO - HTTP Request: POST https://api.openai.com/v1/chat/completions "HTTP/1.1 200 OK"
2025-03-17 16:15:41,188 - INFO - ‚ùå Error detected in Fully_Developed_Turbulent_Channel_Flow_k, refining prompt...
2025-03-17 16:15:41,189 - INFO - 

[Feedback]: The previous generated code had the following error:
Traceback (most recent call last):
  File "/opt/CFD-Benchmark/PDE_Benchmark_6/solver/Fully_Developed_Turbulent_Channel_Flow_k.py", line 38, in <module>
    U[1:] = spsolve(diags(a), f)
  File "/home/weichao/.local/lib/python3.8/site-packages/scipy/sparse/_construct.py", line 151, in diags
    raise ValueError("Different number of diagonals and offsets.")
ValueError: Different number of diagonals and offsets.
Please correct it.
2025-03-17 16:15:41,189 - INFO - üîπ Generating code for: Fully_Developed_Turbulent_Channel_Flow_k (Attempt 2/10)
2025-03-17 16:16:05,553 - INFO - HTTP Request: POST https://api.openai.com/v1/chat/completions "HTTP/1.1 200 OK"
2025-03-17 16:16:05,957 - INFO - ‚ùå Error detected in Fully_Developed_Turbulent_Channel_Flow_k, refining prompt...
2025-03-17 16:16:05,957 - INFO - 

[Feedback]: The previous generated code had the following error:
Traceback (most recent call last):
  File "/opt/CFD-Benchmark/PDE_Benchmark_6/solver/Fully_Developed_Turbulent_Channel_Flow_k.py", line 27, in <module>
    mu_t = C_mu * rho * k**2 / epsilon
NameError: name 'rho' is not defined
Please correct it.
2025-03-17 16:16:05,957 - INFO - üîπ Generating code for: Fully_Developed_Turbulent_Channel_Flow_k (Attempt 3/10)
2025-03-17 16:16:30,687 - INFO - HTTP Request: POST https://api.openai.com/v1/chat/completions "HTTP/1.1 200 OK"
2025-03-17 16:16:31,057 - INFO - ‚ùå Error detected in Fully_Developed_Turbulent_Channel_Flow_k, refining prompt...
2025-03-17 16:16:31,057 - INFO - 

[Feedback]: The previous generated code had the following error:
/home/weichao/.local/lib/python3.8/site-packages/scipy/sparse/linalg/_dsolve/linsolve.py:214: SparseEfficiencyWarning: spsolve requires A be CSC or CSR matrix format
  warn('spsolve requires A be CSC or CSR matrix format',
Traceback (most recent call last):
  File "/opt/CFD-Benchmark/PDE_Benchmark_6/solver/Fully_Developed_Turbulent_Channel_Flow_k.py", line 31, in <module>
    u[1:-1] = spsolve(diags(a, offsets=[-1, 0, 1], shape=(N-1, N-1)), f)
  File "/home/weichao/.local/lib/python3.8/site-packages/scipy/sparse/linalg/_dsolve/linsolve.py", line 238, in spsolve
    raise ValueError("matrix - rhs dimension mismatch (%s - %s)"
ValueError: matrix - rhs dimension mismatch ((99, 99) - 100)
Please correct it.
2025-03-17 16:16:31,057 - INFO - üîπ Generating code for: Fully_Developed_Turbulent_Channel_Flow_k (Attempt 4/10)
2025-03-17 16:16:31,292 - INFO - HTTP Request: POST https://api.openai.com/v1/chat/completions "HTTP/1.1 400 Bad Request"
2025-03-17 16:16:31,293 - INFO - ‚ùå API Call Error for Fully_Developed_Turbulent_Channel_Flow_k: Error code: 400 - {'error': {'message': "This model's maximum context length is 8192 tokens. However, you requested 8274 tokens (1274 in the messages, 7000 in the completion). Please reduce the length of the messages or completion.", 'type': 'invalid_request_error', 'param': 'messages', 'code': 'context_length_exceeded'}}
2025-03-17 16:16:31,293 - INFO - üîπ Generating code for: 1D_Linear_Convection_explicit_euler (Attempt 1/10)
2025-03-17 16:17:00,847 - INFO - HTTP Request: POST https://api.openai.com/v1/chat/completions "HTTP/1.1 200 OK"
2025-03-17 16:17:01,517 - INFO - Execution successful, no errors detected.
2025-03-17 16:17:01,517 - INFO - üéØ 1D_Linear_Convection_explicit_euler executed successfully without syntax errors.
2025-03-17 16:17:01,517 - INFO - üîπ Generating code for: 2D_Cavity_Flow_Navier_Stokes (Attempt 1/10)
2025-03-17 16:18:17,606 - INFO - HTTP Request: POST https://api.openai.com/v1/chat/completions "HTTP/1.1 200 OK"
2025-03-17 16:18:18,617 - INFO - Execution successful, no errors detected.
2025-03-17 16:18:18,617 - INFO - üéØ 2D_Cavity_Flow_Navier_Stokes executed successfully without syntax errors.
2025-03-17 16:18:18,617 - INFO - üîπ Generating code for: 2D_Inviscid_Burgers_MK (Attempt 1/10)
2025-03-17 16:18:55,817 - INFO - HTTP Request: POST https://api.openai.com/v1/chat/completions "HTTP/1.1 200 OK"
2025-03-17 16:18:56,542 - INFO - Execution successful, no errors detected.
2025-03-17 16:18:56,542 - INFO - üéØ 2D_Inviscid_Burgers_MK executed successfully without syntax errors.
2025-03-17 16:18:56,542 - INFO - üîπ Generating code for: 1D_Diffusion (Attempt 1/10)
2025-03-17 16:19:19,842 - INFO - HTTP Request: POST https://api.openai.com/v1/chat/completions "HTTP/1.1 200 OK"
2025-03-17 16:19:22,001 - INFO - Execution successful, no errors detected.
2025-03-17 16:19:22,001 - INFO - üéØ 1D_Diffusion executed successfully without syntax errors.
2025-03-17 16:19:22,001 - INFO - üîπ Generating code for: 1D_Linear_Convection_ADI (Attempt 1/10)
2025-03-17 16:19:52,823 - INFO - HTTP Request: POST https://api.openai.com/v1/chat/completions "HTTP/1.1 200 OK"
2025-03-17 16:19:53,290 - INFO - ‚ùå Error detected in 1D_Linear_Convection_ADI, refining prompt...
2025-03-17 16:19:53,290 - INFO - 

[Feedback]: The previous generated code had the following error:
Traceback (most recent call last):
  File "/opt/CFD-Benchmark/PDE_Benchmark_6/solver/1D_Linear_Convection_ADI.py", line 59, in <module>
    u_sol = ADI(u0, epsilon, c, dx, dt, N)
  File "/opt/CFD-Benchmark/PDE_Benchmark_6/solver/1D_Linear_Convection_ADI.py", line 36, in ADI
    A_inv = np.linalg.inv(A)
  File "<__array_function__ internals>", line 200, in inv
  File "/home/weichao/.local/lib/python3.8/site-packages/numpy/linalg/linalg.py", line 538, in inv
    ainv = _umath_linalg.inv(a, signature=signature, extobj=extobj)
  File "/home/weichao/.local/lib/python3.8/site-packages/numpy/linalg/linalg.py", line 89, in _raise_linalgerror_singular
    raise LinAlgError("Singular matrix")
numpy.linalg.LinAlgError: Singular matrix
Please correct it.
2025-03-17 16:19:53,290 - INFO - üîπ Generating code for: 1D_Linear_Convection_ADI (Attempt 2/10)
2025-03-17 16:20:27,427 - INFO - HTTP Request: POST https://api.openai.com/v1/chat/completions "HTTP/1.1 200 OK"
2025-03-17 16:20:27,785 - INFO - ‚ùå Error detected in 1D_Linear_Convection_ADI, refining prompt...
2025-03-17 16:20:27,785 - INFO - 

[Feedback]: The previous generated code had the following error:
Traceback (most recent call last):
  File "/opt/CFD-Benchmark/PDE_Benchmark_6/solver/1D_Linear_Convection_ADI.py", line 26, in <module>
    u_mid = solve_banded((1, 1), A, u[i-1])
  File "/home/weichao/.local/lib/python3.8/site-packages/scipy/linalg/_basic.py", line 439, in solve_banded
    raise ValueError("shapes of ab and b are not compatible.")
ValueError: shapes of ab and b are not compatible.
Please correct it.
2025-03-17 16:20:27,785 - INFO - üîπ Generating code for: 1D_Linear_Convection_ADI (Attempt 3/10)
2025-03-17 16:20:57,910 - INFO - HTTP Request: POST https://api.openai.com/v1/chat/completions "HTTP/1.1 200 OK"
2025-03-17 16:20:58,727 - INFO - Execution successful, no errors detected.
2025-03-17 16:20:58,728 - INFO - üéØ 1D_Linear_Convection_ADI executed successfully without syntax errors.
2025-03-17 16:20:58,728 - INFO - üîπ Generating code for: 1D_Linear_Convection_rk (Attempt 1/10)
2025-03-17 16:21:31,942 - INFO - HTTP Request: POST https://api.openai.com/v1/chat/completions "HTTP/1.1 200 OK"
2025-03-17 16:21:32,602 - INFO - Execution successful, no errors detected.
2025-03-17 16:21:32,602 - INFO - üéØ 1D_Linear_Convection_rk executed successfully without syntax errors.
2025-03-17 16:21:32,602 - INFO - üîπ Generating code for: 1D_Nonlinear_Convection_Lax (Attempt 1/10)
2025-03-17 16:21:56,026 - INFO - HTTP Request: POST https://api.openai.com/v1/chat/completions "HTTP/1.1 200 OK"
2025-03-17 16:21:57,700 - INFO - Execution successful, no errors detected.
2025-03-17 16:21:57,700 - INFO - üéØ 1D_Nonlinear_Convection_Lax executed successfully without syntax errors.
2025-03-17 16:21:57,700 - INFO - üîπ Generating code for: 2D_Convection (Attempt 1/10)
2025-03-17 16:22:29,798 - INFO - HTTP Request: POST https://api.openai.com/v1/chat/completions "HTTP/1.1 200 OK"
2025-03-17 16:22:30,137 - INFO - Execution successful, no errors detected.
2025-03-17 16:22:30,137 - INFO - üéØ 2D_Convection executed successfully without syntax errors.
2025-03-17 16:22:30,137 - INFO - üîπ Generating code for: Fully_Developed_Turbulent_Channel_Flow_Cess (Attempt 1/10)
2025-03-17 16:22:58,266 - INFO - HTTP Request: POST https://api.openai.com/v1/chat/completions "HTTP/1.1 200 OK"
2025-03-17 16:22:58,975 - INFO - Execution successful, no errors detected.
2025-03-17 16:22:58,975 - INFO - üéØ Fully_Developed_Turbulent_Channel_Flow_Cess executed successfully without syntax errors.
2025-03-17 16:22:58,975 - INFO - üîπ Generating code for: 2D_Poisson_Equation (Attempt 1/10)
2025-03-17 16:23:31,239 - INFO - HTTP Request: POST https://api.openai.com/v1/chat/completions "HTTP/1.1 200 OK"
2025-03-17 16:23:31,994 - INFO - Execution successful, no errors detected.
2025-03-17 16:23:31,994 - INFO - üéØ 2D_Poisson_Equation executed successfully without syntax errors.
2025-03-17 16:23:31,994 - INFO - üîπ Generating code for: Fully_Developed_Turbulent_Channel_Flow_SST (Attempt 1/10)
2025-03-17 16:24:08,819 - INFO - HTTP Request: POST https://api.openai.com/v1/chat/completions "HTTP/1.1 200 OK"
2025-03-17 16:24:09,187 - INFO - ‚ùå Error detected in Fully_Developed_Turbulent_Channel_Flow_SST, refining prompt...
2025-03-17 16:24:09,187 - INFO - 

[Feedback]: The previous generated code had the following error:
/home/weichao/.local/lib/python3.8/site-packages/numpy/lib/function_base.py:1236: RuntimeWarning: invalid value encountered in divide
  out[tuple(slice1)] = (f[tuple(slice4)] - f[tuple(slice2)]) / (2. * ax_dx)
/home/weichao/.local/lib/python3.8/site-packages/numpy/lib/function_base.py:1273: RuntimeWarning: divide by zero encountered in scalar divide
  a = -1.5 / ax_dx
/home/weichao/.local/lib/python3.8/site-packages/numpy/lib/function_base.py:1274: RuntimeWarning: divide by zero encountered in scalar divide
  b = 2. / ax_dx
/home/weichao/.local/lib/python3.8/site-packages/numpy/lib/function_base.py:1275: RuntimeWarning: divide by zero encountered in scalar divide
  c = -0.5 / ax_dx
/home/weichao/.local/lib/python3.8/site-packages/numpy/lib/function_base.py:1283: RuntimeWarning: invalid value encountered in scalar multiply
  out[tuple(slice1)] = a * f[tuple(slice2)] + b * f[tuple(slice3)] + c * f[tuple(slice4)]
/home/weichao/.local/lib/python3.8/site-packages/numpy/lib/function_base.py:1290: RuntimeWarning: divide by zero encountered in scalar divide
  a = 0.5 / ax_dx
/home/weichao/.local/lib/python3.8/site-packages/numpy/lib/function_base.py:1291: RuntimeWarning: divide by zero encountered in scalar divide
  b = -2. / ax_dx
/home/weichao/.local/lib/python3.8/site-packages/numpy/lib/function_base.py:1292: RuntimeWarning: divide by zero encountered in scalar divide
  c = 1.5 / ax_dx
/home/weichao/.local/lib/python3.8/site-packages/numpy/lib/function_base.py:1300: RuntimeWarning: invalid value encountered in scalar multiply
  out[tuple(slice1)] = a * f[tuple(slice2)] + b * f[tuple(slice3)] + c * f[tuple(slice4)]
Traceback (most recent call last):
  File "/opt/CFD-Benchmark/PDE_Benchmark_6/solver/Fully_Developed_Turbulent_Channel_Flow_SST.py", line 49, in <module>
    mu_t = calculate_mu_t(u, y, rho, mu, kappa, B)
  File "/opt/CFD-Benchmark/PDE_Benchmark_6/solver/Fully_Developed_Turbulent_Channel_Flow_SST.py", line 39, in calculate_mu_t
    y_plus = u_tau*y_wall/nu
NameError: name 'nu' is not defined
Please correct it.
2025-03-17 16:24:09,187 - INFO - üîπ Generating code for: Fully_Developed_Turbulent_Channel_Flow_SST (Attempt 2/10)
2025-03-17 16:24:09,538 - INFO - HTTP Request: POST https://api.openai.com/v1/chat/completions "HTTP/1.1 400 Bad Request"
2025-03-17 16:24:09,540 - INFO - ‚ùå API Call Error for Fully_Developed_Turbulent_Channel_Flow_SST: Error code: 400 - {'error': {'message': "This model's maximum context length is 8192 tokens. However, you requested 8452 tokens (1452 in the messages, 7000 in the completion). Please reduce the length of the messages or completion.", 'type': 'invalid_request_error', 'param': 'messages', 'code': 'context_length_exceeded'}}
2025-03-17 16:24:09,540 - INFO - üîπ Generating code for: Fully_Developed_Turbulent_Channel_Flow_V2F (Attempt 1/10)
2025-03-17 16:24:32,884 - INFO - HTTP Request: POST https://api.openai.com/v1/chat/completions "HTTP/1.1 200 OK"
2025-03-17 16:24:33,036 - INFO - Execution successful, no errors detected.
2025-03-17 16:24:33,036 - INFO - üéØ Fully_Developed_Turbulent_Channel_Flow_V2F executed successfully without syntax errors.
2025-03-17 16:24:33,036 - INFO - 
üéØ Execution completed. Check the solver directory for generated files.
2025-03-18 12:39:11,377 - INFO - ####################################################################################################
2025-03-18 12:39:11,399 - INFO - üîπ Generating code for: 2D_Diffusion_FVM (Attempt 1/10)
2025-03-18 12:39:31,372 - INFO - HTTP Request: POST https://api.openai.com/v1/chat/completions "HTTP/1.1 200 OK"
2025-03-18 12:40:55,320 - INFO - ####################################################################################################
2025-03-18 12:40:55,341 - INFO - üîπ Generating code for: 2D_Diffusion_FVM (Attempt 1/10)
2025-03-18 12:41:13,365 - INFO - HTTP Request: POST https://api.openai.com/v1/chat/completions "HTTP/1.1 200 OK"
2025-03-18 12:41:23,800 - INFO - Execution successful, no errors detected.
2025-03-18 12:41:23,800 - INFO - üéØ 2D_Diffusion_FVM executed successfully without syntax errors.
2025-03-18 12:41:23,800 - INFO - üîπ Generating code for: 1D_Linear_Convection_corr (Attempt 1/10)
2025-03-18 12:41:47,039 - INFO - HTTP Request: POST https://api.openai.com/v1/chat/completions "HTTP/1.1 200 OK"
2025-03-18 12:41:47,366 - INFO - ‚ùå Error detected in 1D_Linear_Convection_corr, refining prompt...
2025-03-18 12:41:47,366 - INFO - 

[Feedback]: The previous generated code had the following error:
Traceback (most recent call last):
  File "/opt/CFD-Benchmark/PDE_Benchmark_6/solver/1D_Linear_Convection_corr.py", line 23, in <module>
    u_star[:-1] = u[:-1] - dt * c * (u[1:] - u[:-1]) / dx + dt * epsilon * (u[2:] - 2*u[1:-1] + u[:-2]) / dx**2
ValueError: operands could not be broadcast together with shapes (100,) (99,)
Please correct it.
2025-03-18 12:41:47,366 - INFO - üîπ Generating code for: 1D_Linear_Convection_corr (Attempt 2/10)
2025-03-18 12:42:12,639 - INFO - HTTP Request: POST https://api.openai.com/v1/chat/completions "HTTP/1.1 200 OK"
2025-03-18 12:42:13,407 - INFO - Execution successful, no errors detected.
2025-03-18 12:42:13,407 - INFO - üéØ 1D_Linear_Convection_corr executed successfully without syntax errors.
2025-03-18 12:42:13,407 - INFO - üîπ Generating code for: 1D_Burgers_Equation (Attempt 1/10)
2025-03-18 12:42:41,721 - INFO - HTTP Request: POST https://api.openai.com/v1/chat/completions "HTTP/1.1 200 OK"
2025-03-18 12:42:42,185 - INFO - Execution successful, no errors detected.
2025-03-18 12:42:42,186 - INFO - üéØ 1D_Burgers_Equation executed successfully without syntax errors.
2025-03-18 12:42:42,186 - INFO - üîπ Generating code for: 1D_Nonlinear_Convection_MK (Attempt 1/10)
2025-03-18 12:43:04,194 - INFO - HTTP Request: POST https://api.openai.com/v1/chat/completions "HTTP/1.1 200 OK"
2025-03-18 12:43:04,747 - INFO - Execution successful, no errors detected.
2025-03-18 12:43:04,748 - INFO - üéØ 1D_Nonlinear_Convection_MK executed successfully without syntax errors.
2025-03-18 12:43:04,748 - INFO - üîπ Generating code for: 2D_Laplace_Equation (Attempt 1/10)
2025-03-18 12:43:26,483 - INFO - HTTP Request: POST https://api.openai.com/v1/chat/completions "HTTP/1.1 200 OK"
2025-03-18 12:43:27,191 - INFO - Execution successful, no errors detected.
2025-03-18 12:43:27,192 - INFO - üéØ 2D_Laplace_Equation executed successfully without syntax errors.
2025-03-18 12:43:27,192 - INFO - üîπ Generating code for: 2D_Linear_Convection (Attempt 1/10)
2025-03-18 12:43:50,754 - INFO - HTTP Request: POST https://api.openai.com/v1/chat/completions "HTTP/1.1 200 OK"
2025-03-18 12:43:51,368 - INFO - Execution successful, no errors detected.
2025-03-18 12:43:51,368 - INFO - üéØ 2D_Linear_Convection executed successfully without syntax errors.
2025-03-18 12:43:51,368 - INFO - üîπ Generating code for: 1D_Linear_Convection_Dufort_Frankel (Attempt 1/10)
2025-03-18 12:44:12,464 - INFO - HTTP Request: POST https://api.openai.com/v1/chat/completions "HTTP/1.1 200 OK"
2025-03-18 12:44:12,787 - INFO - ‚ùå Error detected in 1D_Linear_Convection_Dufort_Frankel, refining prompt...
2025-03-18 12:44:12,787 - INFO - 

[Feedback]: The previous generated code had the following error:
Traceback (most recent call last):
  File "/opt/CFD-Benchmark/PDE_Benchmark_6/solver/1D_Linear_Convection_Dufort_Frankel.py", line 30, in <module>
    u = dufort_frankel(u0, c, eps, dx, dt, t)
  File "/opt/CFD-Benchmark/PDE_Benchmark_6/solver/1D_Linear_Convection_Dufort_Frankel.py", line 20, in dufort_frankel
    u[1] = u0 - dt*c*np.gradient(u0, dx)  # First step with forward Euler
IndexError: index 1 is out of bounds for axis 0 with size 1
Please correct it.
2025-03-18 12:44:12,787 - INFO - üîπ Generating code for: 1D_Linear_Convection_Dufort_Frankel (Attempt 2/10)
2025-03-18 12:44:38,586 - INFO - HTTP Request: POST https://api.openai.com/v1/chat/completions "HTTP/1.1 200 OK"
2025-03-18 12:44:38,905 - INFO - ‚ùå Error detected in 1D_Linear_Convection_Dufort_Frankel, refining prompt...
2025-03-18 12:44:38,906 - INFO - 

[Feedback]: The previous generated code had the following error:
Traceback (most recent call last):
  File "/opt/CFD-Benchmark/PDE_Benchmark_6/solver/1D_Linear_Convection_Dufort_Frankel.py", line 28, in <module>
    u = dufort_frankel(u0, c, eps, dx, dt, t)
  File "/opt/CFD-Benchmark/PDE_Benchmark_6/solver/1D_Linear_Convection_Dufort_Frankel.py", line 21, in dufort_frankel
    u[1] = u0 - dt * c * np.gradient(u0, dx) + r * np.gradient(np.gradient(u0, dx), dx)
IndexError: index 1 is out of bounds for axis 0 with size 1
Please correct it.
2025-03-18 12:44:38,906 - INFO - üîπ Generating code for: 1D_Linear_Convection_Dufort_Frankel (Attempt 3/10)
2025-03-18 12:45:04,288 - INFO - HTTP Request: POST https://api.openai.com/v1/chat/completions "HTTP/1.1 200 OK"
2025-03-18 12:45:04,841 - INFO - Execution successful, no errors detected.
2025-03-18 12:45:04,841 - INFO - üéØ 1D_Linear_Convection_Dufort_Frankel executed successfully without syntax errors.
2025-03-18 12:45:04,842 - INFO - üîπ Generating code for: 1D_Nonlinear_Convection_LW (Attempt 1/10)
2025-03-18 12:45:30,557 - INFO - HTTP Request: POST https://api.openai.com/v1/chat/completions "HTTP/1.1 200 OK"
2025-03-18 12:45:31,126 - INFO - Execution successful, no errors detected.
2025-03-18 12:45:31,126 - INFO - üéØ 1D_Nonlinear_Convection_LW executed successfully without syntax errors.
2025-03-18 12:45:31,126 - INFO - üîπ Generating code for: 1D_Linear_Convection_adams (Attempt 1/10)
2025-03-18 12:45:59,798 - INFO - HTTP Request: POST https://api.openai.com/v1/chat/completions "HTTP/1.1 200 OK"
2025-03-18 12:46:00,449 - INFO - Execution successful, no errors detected.
2025-03-18 12:46:00,449 - INFO - üéØ 1D_Linear_Convection_adams executed successfully without syntax errors.
2025-03-18 12:46:00,449 - INFO - üîπ Generating code for: 2D_Steady_Heat_Equation (Attempt 1/10)
2025-03-18 12:46:26,404 - INFO - HTTP Request: POST https://api.openai.com/v1/chat/completions "HTTP/1.1 200 OK"
2025-03-18 12:46:58,355 - INFO - Execution successful, no errors detected.
2025-03-18 12:46:58,356 - INFO - üéØ 2D_Steady_Heat_Equation executed successfully without syntax errors.
2025-03-18 12:46:58,356 - INFO - üîπ Generating code for: 2D_Channel_Flow_Navier_Stokes (Attempt 1/10)
2025-03-18 12:48:39,414 - INFO - HTTP Request: POST https://api.openai.com/v1/chat/completions "HTTP/1.1 200 OK"
2025-03-18 12:48:39,957 - INFO - ‚ùå Error detected in 2D_Channel_Flow_Navier_Stokes, refining prompt...
2025-03-18 12:48:39,957 - INFO - 

[Feedback]: The previous generated code had the following error:
Traceback (most recent call last):
  File "/opt/CFD-Benchmark/PDE_Benchmark_6/solver/2D_Channel_Flow_Navier_Stokes.py", line 144, in <module>
    u, v, p = channel_flow(nt, u, v, dt, dx, dy, p, rho, nu)
  File "/opt/CFD-Benchmark/PDE_Benchmark_6/solver/2D_Channel_Flow_Navier_Stokes.py", line 62, in channel_flow
    b = build_up_b(b, rho, dt, u, v, dx, dy)
UnboundLocalError: local variable 'b' referenced before assignment
Please correct it.
2025-03-18 12:48:39,957 - INFO - üîπ Generating code for: 2D_Channel_Flow_Navier_Stokes (Attempt 2/10)
2025-03-18 12:50:35,394 - INFO - HTTP Request: POST https://api.openai.com/v1/chat/completions "HTTP/1.1 200 OK"
2025-03-18 12:50:35,870 - INFO - Execution successful, no errors detected.
2025-03-18 12:50:35,870 - INFO - üéØ 2D_Channel_Flow_Navier_Stokes executed successfully without syntax errors.
2025-03-18 12:50:35,870 - INFO - üîπ Generating code for: 2D_Diffusion (Attempt 1/10)
2025-03-18 12:50:58,120 - INFO - HTTP Request: POST https://api.openai.com/v1/chat/completions "HTTP/1.1 200 OK"
2025-03-18 12:50:58,779 - INFO - Execution successful, no errors detected.
2025-03-18 12:50:58,779 - INFO - üéØ 2D_Diffusion executed successfully without syntax errors.
2025-03-18 12:50:58,779 - INFO - üîπ Generating code for: 1D_Euler_Shock_Tube (Attempt 1/10)
2025-03-18 12:51:31,719 - INFO - HTTP Request: POST https://api.openai.com/v1/chat/completions "HTTP/1.1 200 OK"
2025-03-18 12:51:32,502 - INFO - Execution successful, no errors detected.
2025-03-18 12:51:32,502 - INFO - üéØ 1D_Euler_Shock_Tube executed successfully without syntax errors.
2025-03-18 12:51:32,502 - INFO - üîπ Generating code for: 1D_Linear_Convection_Explicit (Attempt 1/10)
2025-03-18 12:51:51,064 - INFO - HTTP Request: POST https://api.openai.com/v1/chat/completions "HTTP/1.1 200 OK"
2025-03-18 12:51:51,634 - INFO - Execution successful, no errors detected.
2025-03-18 12:51:51,634 - INFO - üéØ 1D_Linear_Convection_Explicit executed successfully without syntax errors.
2025-03-18 12:51:51,634 - INFO - üîπ Generating code for: 2D_Inviscid_Burgers_FOU (Attempt 1/10)
2025-03-18 12:52:24,545 - INFO - HTTP Request: POST https://api.openai.com/v1/chat/completions "HTTP/1.1 200 OK"
2025-03-18 12:52:25,220 - INFO - Execution successful, no errors detected.
2025-03-18 12:52:25,220 - INFO - üéØ 2D_Inviscid_Burgers_FOU executed successfully without syntax errors.
2025-03-18 12:52:25,220 - INFO - üîπ Generating code for: Fully_Developed_Turbulent_Channel_Flow_SA (Attempt 1/10)
2025-03-18 12:52:51,079 - INFO - HTTP Request: POST https://api.openai.com/v1/chat/completions "HTTP/1.1 200 OK"
2025-03-18 12:52:51,450 - INFO - ‚ùå Error detected in Fully_Developed_Turbulent_Channel_Flow_SA, refining prompt...
2025-03-18 12:52:51,450 - INFO - 

[Feedback]: The previous generated code had the following error:
Traceback (most recent call last):
  File "/opt/CFD-Benchmark/PDE_Benchmark_6/solver/Fully_Developed_Turbulent_Channel_Flow_SA.py", line 48, in <module>
    A = diags([mu_eff[:-1] / dy, -mu_eff[:-1] / dy - mu_eff[1:] / dy, mu_eff[1:] / dy], offsets) + mu_eff[0] * D2
  File "/home/weichao/.local/lib/python3.8/site-packages/scipy/sparse/_base.py", line 471, in __add__
    raise ValueError("inconsistent shapes")
ValueError: inconsistent shapes
Please correct it.
2025-03-18 12:52:51,450 - INFO - üîπ Generating code for: Fully_Developed_Turbulent_Channel_Flow_SA (Attempt 2/10)
2025-03-18 12:53:15,530 - INFO - HTTP Request: POST https://api.openai.com/v1/chat/completions "HTTP/1.1 200 OK"
2025-03-18 12:53:15,902 - INFO - ‚ùå Error detected in Fully_Developed_Turbulent_Channel_Flow_SA, refining prompt...
2025-03-18 12:53:15,902 - INFO - 

[Feedback]: The previous generated code had the following error:
Traceback (most recent call last):
  File "/opt/CFD-Benchmark/PDE_Benchmark_6/solver/Fully_Developed_Turbulent_Channel_Flow_SA.py", line 49, in <module>
    mu_t[1:-1] = rho * nu_tilde * (cb1 * S - cw1 * fw + dnu_tilde_dy / cb3 + cb2 * dnu_tilde_dy**2)
ValueError: operands could not be broadcast together with shapes (98,) (96,)
Please correct it.
2025-03-18 12:53:15,902 - INFO - üîπ Generating code for: Fully_Developed_Turbulent_Channel_Flow_SA (Attempt 3/10)
2025-03-18 12:53:41,492 - INFO - HTTP Request: POST https://api.openai.com/v1/chat/completions "HTTP/1.1 200 OK"
2025-03-18 12:53:41,849 - INFO - ‚ùå Error detected in Fully_Developed_Turbulent_Channel_Flow_SA, refining prompt...
2025-03-18 12:53:41,849 - INFO - 

[Feedback]: The previous generated code had the following error:
Traceback (most recent call last):
  File "/home/weichao/.local/lib/python3.8/site-packages/scipy/sparse/_construct.py", line 187, in diags
    data_arr[j, k:k+length] = diagonal[...,:length]
ValueError: could not broadcast input array from shape (99,) into shape (100,)

The above exception was the direct cause of the following exception:

Traceback (most recent call last):
  File "/opt/CFD-Benchmark/PDE_Benchmark_6/solver/Fully_Developed_Turbulent_Channel_Flow_SA.py", line 44, in <module>
    A = diags([-mu_eff[:-1] / dy**2, (mu_eff[:-1] + mu_eff[1:]) / dy**2, -mu_eff[1:] / dy**2], [-1, 0, 1], shape=(n, n)).tocsc()
  File "/home/weichao/.local/lib/python3.8/site-packages/scipy/sparse/_construct.py", line 190, in diags
    raise ValueError(
ValueError: Diagonal length (index 1: 99 at offset 0) does not agree with matrix size (100, 100).
Please correct it.
2025-03-18 12:53:41,849 - INFO - üîπ Generating code for: Fully_Developed_Turbulent_Channel_Flow_SA (Attempt 4/10)
2025-03-18 12:54:13,047 - INFO - HTTP Request: POST https://api.openai.com/v1/chat/completions "HTTP/1.1 200 OK"
2025-03-18 12:54:13,411 - INFO - ‚ùå Error detected in Fully_Developed_Turbulent_Channel_Flow_SA, refining prompt...
2025-03-18 12:54:13,412 - INFO - 

[Feedback]: The previous generated code had the following error:
/home/weichao/.local/lib/python3.8/site-packages/scipy/sparse/linalg/_dsolve/linsolve.py:214: SparseEfficiencyWarning: spsolve requires A be CSC or CSR matrix format
  warn('spsolve requires A be CSC or CSR matrix format',
Traceback (most recent call last):
  File "/opt/CFD-Benchmark/PDE_Benchmark_6/solver/Fully_Developed_Turbulent_Channel_Flow_SA.py", line 51, in <module>
    tilde_nu = cb1 * np.abs(dudy) * tilde_nu - cw1 * (tilde_nu / y[1:-1])**2
ValueError: operands could not be broadcast together with shapes (100,) (98,)
Please correct it.
2025-03-18 12:54:13,412 - INFO - üîπ Generating code for: Fully_Developed_Turbulent_Channel_Flow_SA (Attempt 5/10)
2025-03-18 12:54:44,687 - INFO - HTTP Request: POST https://api.openai.com/v1/chat/completions "HTTP/1.1 200 OK"
2025-03-18 12:54:45,055 - INFO - ‚ùå Error detected in Fully_Developed_Turbulent_Channel_Flow_SA, refining prompt...
2025-03-18 12:54:45,056 - INFO - 

[Feedback]: The previous generated code had the following error:
Traceback (most recent call last):
  File "/opt/CFD-Benchmark/PDE_Benchmark_6/solver/Fully_Developed_Turbulent_Channel_Flow_SA.py", line 33, in <module>
    mu_t_new = rho * fv1 * S_hat
ValueError: operands could not be broadcast together with shapes (100,) (98,)
Please correct it.
2025-03-18 12:54:45,056 - INFO - üîπ Generating code for: Fully_Developed_Turbulent_Channel_Flow_SA (Attempt 6/10)
2025-03-18 12:55:15,713 - INFO - HTTP Request: POST https://api.openai.com/v1/chat/completions "HTTP/1.1 200 OK"
2025-03-18 12:55:16,350 - INFO - Execution successful, no errors detected.
2025-03-18 12:55:16,350 - INFO - üéØ Fully_Developed_Turbulent_Channel_Flow_SA executed successfully without syntax errors.
2025-03-18 12:55:16,350 - INFO - üîπ Generating code for: 2D_Burgers_Equation (Attempt 1/10)
2025-03-18 12:55:16,635 - INFO - HTTP Request: POST https://api.openai.com/v1/chat/completions "HTTP/1.1 400 Bad Request"
2025-03-18 12:55:16,637 - INFO - ‚ùå API Call Error for 2D_Burgers_Equation: Error code: 400 - {'error': {'message': "This model's maximum context length is 8192 tokens. However, you requested 8194 tokens (1194 in the messages, 7000 in the completion). Please reduce the length of the messages or completion.", 'type': 'invalid_request_error', 'param': 'messages', 'code': 'context_length_exceeded'}}
2025-03-18 12:55:16,637 - INFO - üîπ Generating code for: Fully_Developed_Turbulent_Channel_Flow_k (Attempt 1/10)
2025-03-18 12:55:49,507 - INFO - HTTP Request: POST https://api.openai.com/v1/chat/completions "HTTP/1.1 200 OK"
2025-03-18 12:55:49,883 - INFO - ‚ùå Error detected in Fully_Developed_Turbulent_Channel_Flow_k, refining prompt...
2025-03-18 12:55:49,883 - INFO - 

[Feedback]: The previous generated code had the following error:
Traceback (most recent call last):
  File "/home/weichao/.local/lib/python3.8/site-packages/scipy/sparse/_construct.py", line 187, in diags
    data_arr[j, k:k+length] = diagonal[...,:length]
ValueError: could not broadcast input array from shape (199,) into shape (200,)

The above exception was the direct cause of the following exception:

Traceback (most recent call last):
  File "/opt/CFD-Benchmark/PDE_Benchmark_6/solver/Fully_Developed_Turbulent_Channel_Flow_k.py", line 30, in <module>
    A = diags([mu_eff[:-1] / sigma_k / dy**2, -mu_eff[1:] / sigma_k / dy**2 - mu_eff[:-1] / sigma_k / dy**2, mu_eff[1:] / sigma_k / dy**2], [-1, 0, 1])
  File "/home/weichao/.local/lib/python3.8/site-packages/scipy/sparse/_construct.py", line 190, in diags
    raise ValueError(
ValueError: Diagonal length (index 1: 199 at offset 0) does not agree with matrix size (200, 200).
Please correct it.
2025-03-18 12:55:49,883 - INFO - üîπ Generating code for: Fully_Developed_Turbulent_Channel_Flow_k (Attempt 2/10)
2025-03-18 12:56:21,297 - INFO - HTTP Request: POST https://api.openai.com/v1/chat/completions "HTTP/1.1 200 OK"
2025-03-18 12:56:21,964 - INFO - Execution successful, no errors detected.
2025-03-18 12:56:21,964 - INFO - üéØ Fully_Developed_Turbulent_Channel_Flow_k executed successfully without syntax errors.
2025-03-18 12:56:21,964 - INFO - üîπ Generating code for: 1D_Linear_Convection_explicit_euler (Attempt 1/10)
2025-03-18 12:56:43,823 - INFO - HTTP Request: POST https://api.openai.com/v1/chat/completions "HTTP/1.1 200 OK"
2025-03-18 12:56:44,510 - INFO - Execution successful, no errors detected.
2025-03-18 12:56:44,510 - INFO - üéØ 1D_Linear_Convection_explicit_euler executed successfully without syntax errors.
2025-03-18 12:56:44,510 - INFO - üîπ Generating code for: 2D_Cavity_Flow_Navier_Stokes (Attempt 1/10)
2025-03-18 12:58:01,956 - INFO - HTTP Request: POST https://api.openai.com/v1/chat/completions "HTTP/1.1 200 OK"
2025-03-18 12:58:06,898 - INFO - Execution successful, no errors detected.
2025-03-18 12:58:06,898 - INFO - üéØ 2D_Cavity_Flow_Navier_Stokes executed successfully without syntax errors.
2025-03-18 12:58:06,898 - INFO - üîπ Generating code for: 2D_Inviscid_Burgers_MK (Attempt 1/10)
2025-03-18 12:58:39,640 - INFO - HTTP Request: POST https://api.openai.com/v1/chat/completions "HTTP/1.1 200 OK"
2025-03-18 12:58:40,309 - INFO - Execution successful, no errors detected.
2025-03-18 12:58:40,309 - INFO - üéØ 2D_Inviscid_Burgers_MK executed successfully without syntax errors.
2025-03-18 12:58:40,309 - INFO - üîπ Generating code for: 1D_Diffusion (Attempt 1/10)
2025-03-18 12:58:52,457 - INFO - HTTP Request: POST https://api.openai.com/v1/chat/completions "HTTP/1.1 200 OK"
2025-03-18 12:58:53,014 - INFO - Execution successful, no errors detected.
2025-03-18 12:58:53,014 - INFO - üéØ 1D_Diffusion executed successfully without syntax errors.
2025-03-18 12:58:53,015 - INFO - üîπ Generating code for: 1D_Linear_Convection_ADI (Attempt 1/10)
2025-03-18 12:59:21,062 - INFO - HTTP Request: POST https://api.openai.com/v1/chat/completions "HTTP/1.1 200 OK"
2025-03-18 12:59:21,433 - INFO - ‚ùå Error detected in 1D_Linear_Convection_ADI, refining prompt...
2025-03-18 12:59:21,433 - INFO - 

[Feedback]: The previous generated code had the following error:
Traceback (most recent call last):
  File "/opt/CFD-Benchmark/PDE_Benchmark_6/solver/1D_Linear_Convection_ADI.py", line 22, in <module>
    A = np.array([lower_diag * np.ones(nx-1), main_diag * np.ones(nx), upper_diag * np.ones(nx-1)])
ValueError: setting an array element with a sequence. The requested array has an inhomogeneous shape after 1 dimensions. The detected shape was (3,) + inhomogeneous part.
Please correct it.
2025-03-18 12:59:21,433 - INFO - üîπ Generating code for: 1D_Linear_Convection_ADI (Attempt 2/10)
2025-03-18 12:59:52,959 - INFO - HTTP Request: POST https://api.openai.com/v1/chat/completions "HTTP/1.1 200 OK"
2025-03-18 12:59:53,326 - INFO - ‚ùå Error detected in 1D_Linear_Convection_ADI, refining prompt...
2025-03-18 12:59:53,326 - INFO - 

[Feedback]: The previous generated code had the following error:
Traceback (most recent call last):
  File "/opt/CFD-Benchmark/PDE_Benchmark_6/solver/1D_Linear_Convection_ADI.py", line 22, in <module>
    A = np.array([A_upper*np.ones(N-1), A_diag*np.ones(N), A_lower*np.ones(N-1)])
ValueError: setting an array element with a sequence. The requested array has an inhomogeneous shape after 1 dimensions. The detected shape was (3,) + inhomogeneous part.
Please correct it.
2025-03-18 12:59:53,326 - INFO - üîπ Generating code for: 1D_Linear_Convection_ADI (Attempt 3/10)
2025-03-18 13:00:18,048 - INFO - HTTP Request: POST https://api.openai.com/v1/chat/completions "HTTP/1.1 200 OK"
2025-03-18 13:00:18,794 - INFO - Execution successful, no errors detected.
2025-03-18 13:00:18,794 - INFO - üéØ 1D_Linear_Convection_ADI executed successfully without syntax errors.
2025-03-18 13:00:18,794 - INFO - üîπ Generating code for: 1D_Linear_Convection_rk (Attempt 1/10)
2025-03-18 13:00:39,451 - INFO - HTTP Request: POST https://api.openai.com/v1/chat/completions "HTTP/1.1 200 OK"
2025-03-18 13:00:40,347 - INFO - Execution successful, no errors detected.
2025-03-18 13:00:40,347 - INFO - üéØ 1D_Linear_Convection_rk executed successfully without syntax errors.
2025-03-18 13:00:40,347 - INFO - üîπ Generating code for: 1D_Nonlinear_Convection_Lax (Attempt 1/10)
2025-03-18 13:01:03,608 - INFO - HTTP Request: POST https://api.openai.com/v1/chat/completions "HTTP/1.1 200 OK"
2025-03-18 13:01:04,230 - INFO - Execution successful, no errors detected.
2025-03-18 13:01:04,230 - INFO - üéØ 1D_Nonlinear_Convection_Lax executed successfully without syntax errors.
2025-03-18 13:01:04,230 - INFO - üîπ Generating code for: 2D_Convection (Attempt 1/10)
2025-03-18 13:01:33,972 - INFO - HTTP Request: POST https://api.openai.com/v1/chat/completions "HTTP/1.1 200 OK"
2025-03-18 13:01:34,433 - INFO - ‚ùå Error detected in 2D_Convection, refining prompt...
2025-03-18 13:01:34,433 - INFO - 

[Feedback]: The previous generated code had the following error:
Traceback (most recent call last):
  File "/opt/CFD-Benchmark/PDE_Benchmark_6/solver/2D_Convection.py", line 46, in <module>
    ax = fig.gca(projection='3d')
TypeError: gca() got an unexpected keyword argument 'projection'
Please correct it.
2025-03-18 13:01:34,433 - INFO - üîπ Generating code for: 2D_Convection (Attempt 2/10)
2025-03-18 13:02:04,808 - INFO - HTTP Request: POST https://api.openai.com/v1/chat/completions "HTTP/1.1 200 OK"
2025-03-18 13:02:05,262 - INFO - ‚ùå Error detected in 2D_Convection, refining prompt...
2025-03-18 13:02:05,262 - INFO - 

[Feedback]: The previous generated code had the following error:
Traceback (most recent call last):
  File "/opt/CFD-Benchmark/PDE_Benchmark_6/solver/2D_Convection.py", line 46, in <module>
    ax = fig.gca(projection='3d')
TypeError: gca() got an unexpected keyword argument 'projection'
Please correct it.
2025-03-18 13:02:05,262 - INFO - üîπ Generating code for: 2D_Convection (Attempt 3/10)
2025-03-18 13:02:33,675 - INFO - HTTP Request: POST https://api.openai.com/v1/chat/completions "HTTP/1.1 200 OK"
2025-03-18 13:02:34,135 - INFO - ‚ùå Error detected in 2D_Convection, refining prompt...
2025-03-18 13:02:34,135 - INFO - 

[Feedback]: The previous generated code had the following error:
Traceback (most recent call last):
  File "/opt/CFD-Benchmark/PDE_Benchmark_6/solver/2D_Convection.py", line 37, in <module>
    ax = fig.gca(projection='3d')
TypeError: gca() got an unexpected keyword argument 'projection'
Please correct it.
2025-03-18 13:02:34,135 - INFO - üîπ Generating code for: 2D_Convection (Attempt 4/10)
2025-03-18 13:03:07,569 - INFO - HTTP Request: POST https://api.openai.com/v1/chat/completions "HTTP/1.1 200 OK"
2025-03-18 13:03:08,022 - INFO - ‚ùå Error detected in 2D_Convection, refining prompt...
2025-03-18 13:03:08,022 - INFO - 

[Feedback]: The previous generated code had the following error:
Traceback (most recent call last):
  File "/opt/CFD-Benchmark/PDE_Benchmark_6/solver/2D_Convection.py", line 42, in <module>
    ax = fig.gca(projection='3d')
TypeError: gca() got an unexpected keyword argument 'projection'
Please correct it.
2025-03-18 13:03:08,023 - INFO - üîπ Generating code for: 2D_Convection (Attempt 5/10)
2025-03-18 13:03:39,517 - INFO - HTTP Request: POST https://api.openai.com/v1/chat/completions "HTTP/1.1 200 OK"
2025-03-18 13:03:39,966 - INFO - ‚ùå Error detected in 2D_Convection, refining prompt...
2025-03-18 13:03:39,966 - INFO - 

[Feedback]: The previous generated code had the following error:
Traceback (most recent call last):
  File "/opt/CFD-Benchmark/PDE_Benchmark_6/solver/2D_Convection.py", line 39, in <module>
    ax = fig.gca(projection='3d')
TypeError: gca() got an unexpected keyword argument 'projection'
Please correct it.
2025-03-18 13:03:39,966 - INFO - üîπ Generating code for: 2D_Convection (Attempt 6/10)
2025-03-18 13:04:08,908 - INFO - HTTP Request: POST https://api.openai.com/v1/chat/completions "HTTP/1.1 200 OK"
2025-03-18 13:04:09,366 - INFO - ‚ùå Error detected in 2D_Convection, refining prompt...
2025-03-18 13:04:09,366 - INFO - 

[Feedback]: The previous generated code had the following error:
Traceback (most recent call last):
  File "/opt/CFD-Benchmark/PDE_Benchmark_6/solver/2D_Convection.py", line 42, in <module>
    ax = fig.gca(projection='3d')
TypeError: gca() got an unexpected keyword argument 'projection'
Please correct it.
2025-03-18 13:04:09,366 - INFO - üîπ Generating code for: 2D_Convection (Attempt 7/10)
2025-03-18 13:04:41,675 - INFO - HTTP Request: POST https://api.openai.com/v1/chat/completions "HTTP/1.1 200 OK"
2025-03-18 13:04:42,128 - INFO - ‚ùå Error detected in 2D_Convection, refining prompt...
2025-03-18 13:04:42,128 - INFO - 

[Feedback]: The previous generated code had the following error:
Traceback (most recent call last):
  File "/opt/CFD-Benchmark/PDE_Benchmark_6/solver/2D_Convection.py", line 44, in <module>
    ax = fig.gca(projection='3d')
TypeError: gca() got an unexpected keyword argument 'projection'
Please correct it.
2025-03-18 13:04:42,128 - INFO - üîπ Generating code for: 2D_Convection (Attempt 8/10)
2025-03-18 13:05:07,125 - INFO - HTTP Request: POST https://api.openai.com/v1/chat/completions "HTTP/1.1 200 OK"
2025-03-18 13:05:07,592 - INFO - ‚ùå Error detected in 2D_Convection, refining prompt...
2025-03-18 13:05:07,593 - INFO - 

[Feedback]: The previous generated code had the following error:
Traceback (most recent call last):
  File "/opt/CFD-Benchmark/PDE_Benchmark_6/solver/2D_Convection.py", line 42, in <module>
    ax = fig.gca(projection='3d')
TypeError: gca() got an unexpected keyword argument 'projection'
Please correct it.
2025-03-18 13:05:07,593 - INFO - üîπ Generating code for: 2D_Convection (Attempt 9/10)
2025-03-18 13:05:43,498 - INFO - HTTP Request: POST https://api.openai.com/v1/chat/completions "HTTP/1.1 200 OK"
2025-03-18 13:05:43,961 - INFO - ‚ùå Error detected in 2D_Convection, refining prompt...
2025-03-18 13:05:43,961 - INFO - 

[Feedback]: The previous generated code had the following error:
Traceback (most recent call last):
  File "/opt/CFD-Benchmark/PDE_Benchmark_6/solver/2D_Convection.py", line 42, in <module>
    ax = fig.gca(projection='3d')
TypeError: gca() got an unexpected keyword argument 'projection'
Please correct it.
2025-03-18 13:05:43,961 - INFO - üîπ Generating code for: 2D_Convection (Attempt 10/10)
2025-03-18 13:06:15,578 - INFO - HTTP Request: POST https://api.openai.com/v1/chat/completions "HTTP/1.1 200 OK"
2025-03-18 13:06:16,037 - INFO - ‚ùå Error detected in 2D_Convection, refining prompt...
2025-03-18 13:06:16,037 - INFO - 

[Feedback]: The previous generated code had the following error:
Traceback (most recent call last):
  File "/opt/CFD-Benchmark/PDE_Benchmark_6/solver/2D_Convection.py", line 46, in <module>
    ax = fig.gca(projection='3d')
TypeError: gca() got an unexpected keyword argument 'projection'
Please correct it.
2025-03-18 13:06:16,037 - INFO - ‚ö†Ô∏è Max retries reached for 2D_Convection. Check logs for remaining errors.
2025-03-18 13:06:16,037 - INFO - üîπ Generating code for: Fully_Developed_Turbulent_Channel_Flow_Cess (Attempt 1/10)
2025-03-18 13:06:37,390 - INFO - HTTP Request: POST https://api.openai.com/v1/chat/completions "HTTP/1.1 200 OK"
2025-03-18 13:06:37,755 - INFO - ‚ùå Error detected in Fully_Developed_Turbulent_Channel_Flow_Cess, refining prompt...
2025-03-18 13:06:37,755 - INFO - 

[Feedback]: The previous generated code had the following error:
Traceback (most recent call last):
  File "/home/weichao/.local/lib/python3.8/site-packages/scipy/sparse/_construct.py", line 187, in diags
    data_arr[j, k:k+length] = diagonal[...,:length]
ValueError: could not broadcast input array from shape (100,) into shape (101,)

The above exception was the direct cause of the following exception:

Traceback (most recent call last):
  File "/opt/CFD-Benchmark/PDE_Benchmark_6/solver/Fully_Developed_Turbulent_Channel_Flow_Cess.py", line 34, in <module>
    A = diags([a, b, c], [-1, 0, 1], shape=(N+1, N+1)).tocsc()
  File "/home/weichao/.local/lib/python3.8/site-packages/scipy/sparse/_construct.py", line 190, in diags
    raise ValueError(
ValueError: Diagonal length (index 1: 100 at offset 0) does not agree with matrix size (101, 101).
Please correct it.
2025-03-18 13:06:37,755 - INFO - üîπ Generating code for: Fully_Developed_Turbulent_Channel_Flow_Cess (Attempt 2/10)
2025-03-18 13:07:04,727 - INFO - HTTP Request: POST https://api.openai.com/v1/chat/completions "HTTP/1.1 200 OK"
2025-03-18 13:07:05,380 - INFO - Execution successful, no errors detected.
2025-03-18 13:07:05,380 - INFO - üéØ Fully_Developed_Turbulent_Channel_Flow_Cess executed successfully without syntax errors.
2025-03-18 13:07:05,380 - INFO - üîπ Generating code for: 2D_Poisson_Equation (Attempt 1/10)
2025-03-18 13:07:37,244 - INFO - HTTP Request: POST https://api.openai.com/v1/chat/completions "HTTP/1.1 200 OK"
2025-03-18 13:07:37,929 - INFO - Execution successful, no errors detected.
2025-03-18 13:07:37,929 - INFO - üéØ 2D_Poisson_Equation executed successfully without syntax errors.
2025-03-18 13:07:37,929 - INFO - üîπ Generating code for: Fully_Developed_Turbulent_Channel_Flow_SST (Attempt 1/10)
2025-03-18 13:08:03,981 - INFO - HTTP Request: POST https://api.openai.com/v1/chat/completions "HTTP/1.1 200 OK"
2025-03-18 13:08:04,599 - INFO - Execution successful, no errors detected.
2025-03-18 13:08:04,599 - INFO - üéØ Fully_Developed_Turbulent_Channel_Flow_SST executed successfully without syntax errors.
2025-03-18 13:08:04,599 - INFO - üîπ Generating code for: Fully_Developed_Turbulent_Channel_Flow_V2F (Attempt 1/10)
2025-03-18 13:08:31,889 - INFO - HTTP Request: POST https://api.openai.com/v1/chat/completions "HTTP/1.1 200 OK"
2025-03-18 13:08:32,504 - INFO - Execution successful, no errors detected.
2025-03-18 13:08:32,504 - INFO - üéØ Fully_Developed_Turbulent_Channel_Flow_V2F executed successfully without syntax errors.
2025-03-18 13:08:32,504 - INFO - 
üéØ Execution completed. Check the solver directory for generated files.
2025-03-18 15:36:04,828 - INFO - ####################################################################################################
2025-03-18 15:36:04,828 - INFO - Adjust the prompt of 1D nonlinear convection to ensure stable solution
2025-03-18 15:36:18,504 - INFO - ####################################################################################################
2025-03-18 15:36:18,504 - INFO - Adjust the prompt of 1D nonlinear convection to ensure stable solution
2025-03-18 15:36:18,525 - INFO - üîπ Generating code for: 1D_Nonlinear_Convection_MK (Attempt 1/10)
2025-03-18 15:36:35,514 - INFO - HTTP Request: POST https://api.openai.com/v1/chat/completions "HTTP/1.1 200 OK"
2025-03-18 15:36:36,150 - INFO - Execution successful, no errors detected.
2025-03-18 15:36:36,150 - INFO - üéØ 1D_Nonlinear_Convection_MK executed successfully without syntax errors.
2025-03-18 15:36:36,151 - INFO - üîπ Generating code for: 1D_Nonlinear_Convection_LW (Attempt 1/10)
2025-03-18 15:36:55,494 - INFO - HTTP Request: POST https://api.openai.com/v1/chat/completions "HTTP/1.1 200 OK"
2025-03-18 15:36:56,111 - INFO - Execution successful, no errors detected.
2025-03-18 15:36:56,111 - INFO - üéØ 1D_Nonlinear_Convection_LW executed successfully without syntax errors.
2025-03-18 15:36:56,111 - INFO - üîπ Generating code for: 1D_Nonlinear_Convection_Lax (Attempt 1/10)
2025-03-18 15:37:11,658 - INFO - HTTP Request: POST https://api.openai.com/v1/chat/completions "HTTP/1.1 200 OK"
2025-03-18 15:37:12,235 - INFO - Execution successful, no errors detected.
2025-03-18 15:37:12,235 - INFO - üéØ 1D_Nonlinear_Convection_Lax executed successfully without syntax errors.
2025-03-18 15:37:12,235 - INFO - 
üéØ Execution completed. Check the solver directory for generated files.
2025-03-18 15:47:12,059 - INFO - ####################################################################################################
2025-03-18 15:47:12,059 - INFO - Adjust the prompt adding 2D_Burgers_Equation
2025-03-18 15:47:12,080 - INFO - üîπ Generating code for: 2D_Burgers_Equation (Attempt 1/10)
2025-03-18 15:47:12,265 - INFO - HTTP Request: POST https://api.openai.com/v1/chat/completions "HTTP/1.1 400 Bad Request"
2025-03-18 15:47:12,268 - INFO - ‚ùå API Call Error for 2D_Burgers_Equation: Error code: 400 - {'error': {'message': "This model's maximum context length is 8192 tokens. However, you requested 8194 tokens (1194 in the messages, 7000 in the completion). Please reduce the length of the messages or completion.", 'type': 'invalid_request_error', 'param': 'messages', 'code': 'context_length_exceeded'}}
2025-03-18 15:47:12,268 - INFO - 
üéØ Execution completed. Check the solver directory for generated files.
2025-03-18 15:48:10,037 - INFO - ####################################################################################################
2025-03-18 15:48:10,037 - INFO - Adjust the prompt adding 2D_Burgers_Equation
2025-03-18 15:48:10,058 - INFO - üîπ Generating code for: 2D_Burgers_Equation (Attempt 1/10)
2025-03-18 15:48:10,307 - INFO - HTTP Request: POST https://api.openai.com/v1/chat/completions "HTTP/1.1 400 Bad Request"
2025-03-18 15:48:10,310 - INFO - ‚ùå API Call Error for 2D_Burgers_Equation: Error code: 400 - {'error': {'message': "This model's maximum context length is 8192 tokens. However, you requested 8194 tokens (1194 in the messages, 7000 in the completion). Please reduce the length of the messages or completion.", 'type': 'invalid_request_error', 'param': 'messages', 'code': 'context_length_exceeded'}}
2025-03-18 15:48:10,310 - INFO - 
üéØ Execution completed. Check the solver directory for generated files.
2025-03-18 15:50:18,614 - INFO - ####################################################################################################
2025-03-18 15:50:18,614 - INFO - Adjust the prompt adding 2D_Burgers_Equation
2025-03-18 15:50:18,635 - INFO - üîπ Generating code for: 2D_Burgers_Equation (Attempt 1/10)
2025-03-18 15:50:56,607 - INFO - HTTP Request: POST https://api.openai.com/v1/chat/completions "HTTP/1.1 200 OK"
2025-03-18 15:50:57,064 - INFO - ‚ùå Error detected in 2D_Burgers_Equation, refining prompt...
2025-03-18 15:50:57,064 - INFO - 

[Feedback]: The previous generated code had the following error:
Traceback (most recent call last):
  File "/opt/CFD-Benchmark/PDE_Benchmark_6/solver/2D_Burgers_Equation.py", line 42, in <module>
    ax = fig.gca(projection='3d')
TypeError: gca() got an unexpected keyword argument 'projection'
Please correct it.
2025-03-18 15:50:57,064 - INFO - üîπ Generating code for: 2D_Burgers_Equation (Attempt 2/10)
2025-03-18 15:51:33,574 - INFO - HTTP Request: POST https://api.openai.com/v1/chat/completions "HTTP/1.1 200 OK"
2025-03-18 15:51:34,032 - INFO - ‚ùå Error detected in 2D_Burgers_Equation, refining prompt...
2025-03-18 15:51:34,032 - INFO - 

[Feedback]: The previous generated code had the following error:
Traceback (most recent call last):
  File "/opt/CFD-Benchmark/PDE_Benchmark_6/solver/2D_Burgers_Equation.py", line 42, in <module>
    ax = fig.gca(projection='3d')
TypeError: gca() got an unexpected keyword argument 'projection'
Please correct it.
2025-03-18 15:51:34,032 - INFO - üîπ Generating code for: 2D_Burgers_Equation (Attempt 3/10)
2025-03-18 15:52:08,724 - INFO - ####################################################################################################
2025-03-18 15:52:08,724 - INFO - Adjust the prompt adding 2D_Burgers_Equation
2025-03-18 15:52:08,745 - INFO - üîπ Generating code for: 2D_Burgers_Equation (Attempt 1/10)
2025-03-18 15:52:35,505 - INFO - HTTP Request: POST https://api.openai.com/v1/chat/completions "HTTP/1.1 200 OK"
2025-03-18 15:52:36,831 - INFO - ‚ùå Error detected in 2D_Burgers_Equation, refining prompt...
2025-03-18 15:52:36,831 - INFO - 

[Feedback]: The previous generated code had the following error:
Traceback (most recent call last):
  File "/opt/CFD-Benchmark/PDE_Benchmark_6/solver/2D_Burgers_Equation.py", line 58, in <module>
    ax = fig.gca(projection='3d')
TypeError: gca() got an unexpected keyword argument 'projection'
Please correct it.
2025-03-18 15:52:36,831 - INFO - üîπ Generating code for: 2D_Burgers_Equation (Attempt 2/10)
2025-03-18 15:55:16,485 - INFO - ####################################################################################################
2025-03-18 15:55:16,485 - INFO - Adjust the prompt adding 2D_Burgers_Equation
2025-03-18 15:55:25,274 - INFO - ####################################################################################################
2025-03-18 15:55:25,274 - INFO - Adjust the prompt adding 2D_Burgers_Equation
2025-03-18 15:55:25,295 - INFO - üîπ Generating code for: 2D_Burgers_Equation (Attempt 1/10)
2025-03-18 15:56:02,584 - INFO - HTTP Request: POST https://api.openai.com/v1/chat/completions "HTTP/1.1 200 OK"
2025-03-18 15:56:03,480 - INFO - Execution successful, no errors detected.
2025-03-18 15:56:03,480 - INFO - üéØ 2D_Burgers_Equation executed successfully without syntax errors.
2025-03-18 15:56:03,480 - INFO - 
üéØ Execution completed. Check the solver directory for generated files.
2025-03-18 17:22:47,244 - INFO - ####################################################################################################
2025-03-18 17:22:47,244 - INFO - Adjust the code to not accept warning in the generated code
2025-03-18 17:22:47,266 - INFO - 
üéØ Execution completed. Check the solver directory for generated files.
2025-03-18 17:23:38,275 - INFO - ####################################################################################################
2025-03-18 17:23:38,275 - INFO - Adjust the code to not accept warning in the generated code
2025-03-18 17:23:38,296 - INFO - üîπ Generating code for: 2D_Poisson_Equation (Attempt 1/10)
2025-03-18 17:24:03,469 - INFO - HTTP Request: POST https://api.openai.com/v1/chat/completions "HTTP/1.1 200 OK"
2025-03-18 17:24:04,152 - WARNING - Execution completed with warnings:
/opt/CFD-Benchmark/PDE_Benchmark_6/solver/2D_Poisson_Equation.py:35: RuntimeWarning: divide by zero encountered in scalar divide
  l2_norm = np.sqrt(np.sum((p - pn)**2) / np.sum(pn**2))
2025-03-18 17:24:04,152 - INFO - ‚ùå Error detected in 2D_Poisson_Equation, refining prompt...
2025-03-18 17:24:04,152 - INFO - 

[Feedback]: The previous generated code had the following error:
‚ö†Ô∏è Execution completed with warnings:
/opt/CFD-Benchmark/PDE_Benchmark_6/solver/2D_Poisson_Equation.py:35: RuntimeWarning: divide by zero encountered in scalar divide
  l2_norm = np.sqrt(np.sum((p - pn)**2) / np.sum(pn**2))
Please correct it.
2025-03-18 17:24:04,152 - INFO - üîπ Generating code for: 2D_Poisson_Equation (Attempt 2/10)
2025-03-18 17:24:24,869 - INFO - HTTP Request: POST https://api.openai.com/v1/chat/completions "HTTP/1.1 200 OK"
2025-03-18 17:24:25,604 - WARNING - Execution completed with warnings:
/opt/CFD-Benchmark/PDE_Benchmark_6/solver/2D_Poisson_Equation.py:35: RuntimeWarning: divide by zero encountered in scalar divide
  l1norm = (np.sum(np.abs(p[:]) - np.abs(pn[:])) /
2025-03-18 17:24:25,605 - INFO - ‚ùå Error detected in 2D_Poisson_Equation, refining prompt...
2025-03-18 17:24:25,605 - INFO - 

[Feedback]: The previous generated code had the following error:
‚ö†Ô∏è Execution completed with warnings:
/opt/CFD-Benchmark/PDE_Benchmark_6/solver/2D_Poisson_Equation.py:35: RuntimeWarning: divide by zero encountered in scalar divide
  l1norm = (np.sum(np.abs(p[:]) - np.abs(pn[:])) /
Please correct it.
2025-03-18 17:24:25,605 - INFO - üîπ Generating code for: 2D_Poisson_Equation (Attempt 3/10)
2025-03-18 17:24:45,964 - INFO - HTTP Request: POST https://api.openai.com/v1/chat/completions "HTTP/1.1 200 OK"
2025-03-18 17:24:46,675 - WARNING - Execution completed with warnings:
/opt/CFD-Benchmark/PDE_Benchmark_6/solver/2D_Poisson_Equation.py:35: RuntimeWarning: divide by zero encountered in scalar divide
  l2_norm = np.sqrt(np.sum((p - pn)**2) / np.sum(pn**2))
2025-03-18 17:24:46,675 - INFO - ‚ùå Error detected in 2D_Poisson_Equation, refining prompt...
2025-03-18 17:24:46,675 - INFO - 

[Feedback]: The previous generated code had the following error:
‚ö†Ô∏è Execution completed with warnings:
/opt/CFD-Benchmark/PDE_Benchmark_6/solver/2D_Poisson_Equation.py:35: RuntimeWarning: divide by zero encountered in scalar divide
  l2_norm = np.sqrt(np.sum((p - pn)**2) / np.sum(pn**2))
Please correct it.
2025-03-18 17:24:46,675 - INFO - üîπ Generating code for: 2D_Poisson_Equation (Attempt 4/10)
2025-03-19 12:37:14,701 - INFO - ####################################################################################################
2025-03-19 12:37:14,701 - INFO - Adjust the prompt to add unsteady heat equation
2025-03-19 12:37:36,728 - INFO - ####################################################################################################
2025-03-19 12:37:36,728 - INFO - Adjust the prompt to add unsteady heat equation
2025-03-19 12:37:36,750 - INFO - üîπ Generating code for: 2D_Unsteady_Heat_Equation_SE (Attempt 1/10)
2025-03-19 12:38:01,867 - INFO - HTTP Request: POST https://api.openai.com/v1/chat/completions "HTTP/1.1 200 OK"
2025-03-19 12:38:02,437 - INFO - Execution successful, no errors detected.
2025-03-19 12:38:02,437 - INFO - üéØ 2D_Unsteady_Heat_Equation_SE executed successfully without syntax errors.
2025-03-19 12:38:02,437 - INFO - üîπ Generating code for: 2D_Unsteady_Heat_Equation_ADI (Attempt 1/10)
2025-03-19 12:55:46,038 - INFO - ####################################################################################################
2025-03-19 12:55:46,038 - INFO - Adjust the prompt to add unsteady heat equation
2025-03-19 12:55:46,059 - INFO - üîπ Generating code for: 2D_Unsteady_Heat_Equation_SE (Attempt 1/10)
2025-03-19 12:56:09,270 - INFO - HTTP Request: POST https://api.openai.com/v1/chat/completions "HTTP/1.1 200 OK"
2025-03-19 12:56:10,138 - INFO - Execution successful, no errors detected.
2025-03-19 12:56:10,138 - INFO - üéØ 2D_Unsteady_Heat_Equation_SE executed successfully without syntax errors.
2025-03-19 12:56:10,139 - INFO - üîπ Generating code for: 2D_Unsteady_Heat_Equation_ADI (Attempt 1/10)
2025-03-19 12:56:40,198 - INFO - HTTP Request: POST https://api.openai.com/v1/chat/completions "HTTP/1.1 200 OK"
2025-03-19 12:56:40,592 - ERROR - Execution failed with errors:
Traceback (most recent call last):
  File "/opt/CFD-Benchmark/PDE_Benchmark_6/solver/2D_Unsteady_Heat_Equation_ADI.py", line 55, in <module>
    T = ADI(T, q_values, dx, dy, dt, alpha)
  File "/opt/CFD-Benchmark/PDE_Benchmark_6/solver/2D_Unsteady_Heat_Equation_ADI.py", line 23, in ADI
    T[1:-1, j] = solve_banded((1, 1), A, b)
  File "/home/weichao/.local/lib/python3.8/site-packages/scipy/linalg/_basic.py", line 439, in solve_banded
    raise ValueError("shapes of ab and b are not compatible.")
ValueError: shapes of ab and b are not compatible.
2025-03-19 12:56:40,592 - INFO - ‚ùå Error detected in 2D_Unsteady_Heat_Equation_ADI, refining prompt...
2025-03-19 12:56:40,592 - INFO - 

[Feedback]: The previous generated code had the following error:
Traceback (most recent call last):
  File "/opt/CFD-Benchmark/PDE_Benchmark_6/solver/2D_Unsteady_Heat_Equation_ADI.py", line 55, in <module>
    T = ADI(T, q_values, dx, dy, dt, alpha)
  File "/opt/CFD-Benchmark/PDE_Benchmark_6/solver/2D_Unsteady_Heat_Equation_ADI.py", line 23, in ADI
    T[1:-1, j] = solve_banded((1, 1), A, b)
  File "/home/weichao/.local/lib/python3.8/site-packages/scipy/linalg/_basic.py", line 439, in solve_banded
    raise ValueError("shapes of ab and b are not compatible.")
ValueError: shapes of ab and b are not compatible.
Please correct it.
2025-03-19 12:56:40,592 - INFO - üîπ Generating code for: 2D_Unsteady_Heat_Equation_ADI (Attempt 2/10)
2025-03-19 12:57:20,540 - INFO - HTTP Request: POST https://api.openai.com/v1/chat/completions "HTTP/1.1 200 OK"
2025-03-19 12:57:27,187 - INFO - Execution successful, no errors detected.
2025-03-19 12:57:27,187 - INFO - üéØ 2D_Unsteady_Heat_Equation_ADI executed successfully without syntax errors.
2025-03-19 12:57:27,187 - INFO - üîπ Generating code for: 2D_Unsteady_Heat_Equation_DF (Attempt 1/10)
2025-03-19 12:57:52,138 - INFO - HTTP Request: POST https://api.openai.com/v1/chat/completions "HTTP/1.1 200 OK"
2025-03-19 12:57:52,819 - WARNING - Execution completed with warnings:
/opt/CFD-Benchmark/PDE_Benchmark_6/solver/2D_Unsteady_Heat_Equation_DF.py:31: RuntimeWarning: overflow encountered in add
  T_new[1:-1, 1:-1] = ((2*r*(T[2:, 1:-1] + T[:-2, 1:-1]) +
2025-03-19 12:57:52,819 - INFO - ‚ùå Error detected in 2D_Unsteady_Heat_Equation_DF, refining prompt...
2025-03-19 12:57:52,819 - INFO - 

[Feedback]: The previous generated code had the following error:
‚ö†Ô∏è Execution completed with warnings:
/opt/CFD-Benchmark/PDE_Benchmark_6/solver/2D_Unsteady_Heat_Equation_DF.py:31: RuntimeWarning: overflow encountered in add
  T_new[1:-1, 1:-1] = ((2*r*(T[2:, 1:-1] + T[:-2, 1:-1]) +
Please correct it.
2025-03-19 12:57:52,819 - INFO - üîπ Generating code for: 2D_Unsteady_Heat_Equation_DF (Attempt 2/10)
2025-03-19 12:58:21,366 - INFO - HTTP Request: POST https://api.openai.com/v1/chat/completions "HTTP/1.1 200 OK"
2025-03-19 12:58:52,801 - WARNING - Execution completed with warnings:
/opt/CFD-Benchmark/PDE_Benchmark_6/solver/2D_Unsteady_Heat_Equation_DF.py:29: RuntimeWarning: overflow encountered in scalar add
  T_new[i, j] = (2*r*(T[i+1, j, 1] + T[i-1, j, 1]) + 2*(beta**2)*r*(T[i, j+1, 1] + T[i, j-1, 1]) + T[i, j, 0] + 2*dt*q(i*dx-1, j*dy-1)) / (1 + 2*r + 2*(beta**2)*r)
2025-03-19 12:58:52,801 - INFO - ‚ùå Error detected in 2D_Unsteady_Heat_Equation_DF, refining prompt...
2025-03-19 12:58:52,801 - INFO - 

[Feedback]: The previous generated code had the following error:
‚ö†Ô∏è Execution completed with warnings:
/opt/CFD-Benchmark/PDE_Benchmark_6/solver/2D_Unsteady_Heat_Equation_DF.py:29: RuntimeWarning: overflow encountered in scalar add
  T_new[i, j] = (2*r*(T[i+1, j, 1] + T[i-1, j, 1]) + 2*(beta**2)*r*(T[i, j+1, 1] + T[i, j-1, 1]) + T[i, j, 0] + 2*dt*q(i*dx-1, j*dy-1)) / (1 + 2*r + 2*(beta**2)*r)
Please correct it.
2025-03-19 12:58:52,801 - INFO - üîπ Generating code for: 2D_Unsteady_Heat_Equation_DF (Attempt 3/10)
2025-03-19 12:59:20,962 - INFO - HTTP Request: POST https://api.openai.com/v1/chat/completions "HTTP/1.1 200 OK"
2025-03-19 12:59:21,280 - ERROR - Execution failed with errors:
Traceback (most recent call last):
  File "/opt/CFD-Benchmark/PDE_Benchmark_6/solver/2D_Unsteady_Heat_Equation_DF.py", line 36, in <module>
    T_new = dufort_frankel(T, T_prev, alpha, dt, dx, dy, q(x, y))
TypeError: dufort_frankel() missing 1 required positional argument: 'qy'
2025-03-19 12:59:21,280 - INFO - ‚ùå Error detected in 2D_Unsteady_Heat_Equation_DF, refining prompt...
2025-03-19 12:59:21,280 - INFO - 

[Feedback]: The previous generated code had the following error:
Traceback (most recent call last):
  File "/opt/CFD-Benchmark/PDE_Benchmark_6/solver/2D_Unsteady_Heat_Equation_DF.py", line 36, in <module>
    T_new = dufort_frankel(T, T_prev, alpha, dt, dx, dy, q(x, y))
TypeError: dufort_frankel() missing 1 required positional argument: 'qy'
Please correct it.
2025-03-19 12:59:21,280 - INFO - üîπ Generating code for: 2D_Unsteady_Heat_Equation_DF (Attempt 4/10)
2025-03-19 12:59:44,690 - INFO - HTTP Request: POST https://api.openai.com/v1/chat/completions "HTTP/1.1 200 OK"
2025-03-19 12:59:45,399 - WARNING - Execution completed with warnings:
/opt/CFD-Benchmark/PDE_Benchmark_6/solver/2D_Unsteady_Heat_Equation_DF.py:31: RuntimeWarning: overflow encountered in add
  T[1:-1, 1:-1, n%2] = ((2*r*(Tn[2:, 1:-1, (n-1)%2] + Tn[:-2, 1:-1, (n-1)%2]) +
2025-03-19 12:59:45,399 - INFO - ‚ùå Error detected in 2D_Unsteady_Heat_Equation_DF, refining prompt...
2025-03-19 12:59:45,399 - INFO - 

[Feedback]: The previous generated code had the following error:
‚ö†Ô∏è Execution completed with warnings:
/opt/CFD-Benchmark/PDE_Benchmark_6/solver/2D_Unsteady_Heat_Equation_DF.py:31: RuntimeWarning: overflow encountered in add
  T[1:-1, 1:-1, n%2] = ((2*r*(Tn[2:, 1:-1, (n-1)%2] + Tn[:-2, 1:-1, (n-1)%2]) +
Please correct it.
2025-03-19 12:59:45,399 - INFO - üîπ Generating code for: 2D_Unsteady_Heat_Equation_DF (Attempt 5/10)
2025-03-19 13:00:10,526 - INFO - HTTP Request: POST https://api.openai.com/v1/chat/completions "HTTP/1.1 200 OK"
2025-03-19 13:00:11,466 - ERROR - Execution failed with errors:
/opt/CFD-Benchmark/PDE_Benchmark_6/solver/2D_Unsteady_Heat_Equation_DF.py:32: RuntimeWarning: overflow encountered in add
  T[1:-1, 1:-1, n+1] = (2*r*(T[2:, 1:-1, n] + T[:-2, 1:-1, n]) + 2*beta**2*r*(T[1:-1, 2:, n] + T[1:-1, :-2, n]) + T[1:-1, 1:-1, n-1] + 2*dt*q(X[1:-1, 1:-1], Y[1:-1, 1:-1])) / (1 + 2*r + 2*beta**2*r)
Traceback (most recent call last):
  File "/opt/CFD-Benchmark/PDE_Benchmark_6/solver/2D_Unsteady_Heat_Equation_DF.py", line 32, in <module>
    T[1:-1, 1:-1, n+1] = (2*r*(T[2:, 1:-1, n] + T[:-2, 1:-1, n]) + 2*beta**2*r*(T[1:-1, 2:, n] + T[1:-1, :-2, n]) + T[1:-1, 1:-1, n-1] + 2*dt*q(X[1:-1, 1:-1], Y[1:-1, 1:-1])) / (1 + 2*r + 2*beta**2*r)
IndexError: index 9600 is out of bounds for axis 2 with size 9600
2025-03-19 13:00:11,466 - INFO - ‚ùå Error detected in 2D_Unsteady_Heat_Equation_DF, refining prompt...
2025-03-19 13:00:11,466 - INFO - 

[Feedback]: The previous generated code had the following error:
/opt/CFD-Benchmark/PDE_Benchmark_6/solver/2D_Unsteady_Heat_Equation_DF.py:32: RuntimeWarning: overflow encountered in add
  T[1:-1, 1:-1, n+1] = (2*r*(T[2:, 1:-1, n] + T[:-2, 1:-1, n]) + 2*beta**2*r*(T[1:-1, 2:, n] + T[1:-1, :-2, n]) + T[1:-1, 1:-1, n-1] + 2*dt*q(X[1:-1, 1:-1], Y[1:-1, 1:-1])) / (1 + 2*r + 2*beta**2*r)
Traceback (most recent call last):
  File "/opt/CFD-Benchmark/PDE_Benchmark_6/solver/2D_Unsteady_Heat_Equation_DF.py", line 32, in <module>
    T[1:-1, 1:-1, n+1] = (2*r*(T[2:, 1:-1, n] + T[:-2, 1:-1, n]) + 2*beta**2*r*(T[1:-1, 2:, n] + T[1:-1, :-2, n]) + T[1:-1, 1:-1, n-1] + 2*dt*q(X[1:-1, 1:-1], Y[1:-1, 1:-1])) / (1 + 2*r + 2*beta**2*r)
IndexError: index 9600 is out of bounds for axis 2 with size 9600
Please correct it.
2025-03-19 13:00:11,466 - INFO - üîπ Generating code for: 2D_Unsteady_Heat_Equation_DF (Attempt 6/10)
2025-03-19 13:00:47,473 - INFO - HTTP Request: POST https://api.openai.com/v1/chat/completions "HTTP/1.1 200 OK"
2025-03-19 13:00:48,449 - WARNING - Execution completed with warnings:
/opt/CFD-Benchmark/PDE_Benchmark_6/solver/2D_Unsteady_Heat_Equation_DF.py:12: RuntimeWarning: overflow encountered in add
  T_new[1:-1, 1:-1] = ((2*r*(T[2:, 1:-1] + T[:-2, 1:-1]) + 2*(beta**2)*r*(T[1:-1, 2:] + T[1:-1, :-2]) +
2025-03-19 13:00:48,450 - INFO - ‚ùå Error detected in 2D_Unsteady_Heat_Equation_DF, refining prompt...
2025-03-19 13:00:48,450 - INFO - 

[Feedback]: The previous generated code had the following error:
‚ö†Ô∏è Execution completed with warnings:
/opt/CFD-Benchmark/PDE_Benchmark_6/solver/2D_Unsteady_Heat_Equation_DF.py:12: RuntimeWarning: overflow encountered in add
  T_new[1:-1, 1:-1] = ((2*r*(T[2:, 1:-1] + T[:-2, 1:-1]) + 2*(beta**2)*r*(T[1:-1, 2:] + T[1:-1, :-2]) +
Please correct it.
2025-03-19 13:00:48,450 - INFO - üîπ Generating code for: 2D_Unsteady_Heat_Equation_DF (Attempt 7/10)
2025-03-19 13:01:25,279 - INFO - HTTP Request: POST https://api.openai.com/v1/chat/completions "HTTP/1.1 200 OK"
2025-03-19 13:01:44,046 - ERROR - Execution failed with errors:
/opt/CFD-Benchmark/PDE_Benchmark_6/solver/2D_Unsteady_Heat_Equation_DF.py:32: RuntimeWarning: overflow encountered in scalar add
  T_new[i, j] = (2*r*(T[i+1, j, 1] + T[i-1, j, 1]) + 2*(beta**2)*r*(T[i, j+1, 1] + T[i, j-1, 1]) + T[i, j, 0] + 2*dt*q(x[i], y[j])) / (1 + 2*r + 2*(beta**2)*r)
Traceback (most recent call last):
  File "/opt/CFD-Benchmark/PDE_Benchmark_6/solver/2D_Unsteady_Heat_Equation_DF.py", line 51, in <module>
    plt.show()
  File "/home/weichao/.local/lib/python3.8/site-packages/matplotlib/pyplot.py", line 446, in show
    return _get_backend_mod().show(*args, **kwargs)
  File "/home/weichao/Downloads/pycharm-2023.2.1/plugins/python/helpers/pycharm_matplotlib_backend/backend_interagg.py", line 29, in __call__
    manager.show(**kwargs)
  File "/home/weichao/Downloads/pycharm-2023.2.1/plugins/python/helpers/pycharm_matplotlib_backend/backend_interagg.py", line 112, in show
    self.canvas.show()
  File "/home/weichao/Downloads/pycharm-2023.2.1/plugins/python/helpers/pycharm_matplotlib_backend/backend_interagg.py", line 68, in show
    FigureCanvasAgg.draw(self)
  File "/home/weichao/.local/lib/python3.8/site-packages/matplotlib/backends/backend_agg.py", line 400, in draw
    self.figure.draw(self.renderer)
  File "/home/weichao/.local/lib/python3.8/site-packages/matplotlib/artist.py", line 95, in draw_wrapper
    result = draw(artist, renderer, *args, **kwargs)
  File "/home/weichao/.local/lib/python3.8/site-packages/matplotlib/artist.py", line 72, in draw_wrapper
    return draw(artist, renderer)
  File "/home/weichao/.local/lib/python3.8/site-packages/matplotlib/figure.py", line 3185, in draw
    DrawEvent("draw_event", self.canvas, renderer)._process()
  File "/home/weichao/.local/lib/python3.8/site-packages/matplotlib/backend_bases.py", line 1263, in _process
    self.canvas.callbacks.process(self.name, self)
  File "/home/weichao/.local/lib/python3.8/site-packages/matplotlib/cbook/__init__.py", line 319, in process
    self.exception_handler(exc)
  File "/home/weichao/.local/lib/python3.8/site-packages/matplotlib/cbook/__init__.py", line 103, in _exception_printer
    raise exc
  File "/home/weichao/.local/lib/python3.8/site-packages/matplotlib/cbook/__init__.py", line 314, in process
    func(*args, **kwargs)
  File "/home/weichao/.local/lib/python3.8/site-packages/matplotlib/animation.py", line 904, in _start
    self._init_draw()
  File "/home/weichao/.local/lib/python3.8/site-packages/matplotlib/animation.py", line 1748, in _init_draw
    self._draw_frame(frame_data)
  File "/home/weichao/.local/lib/python3.8/site-packages/matplotlib/animation.py", line 1767, in _draw_frame
    self._drawn_artists = self._func(framedata, *self._args)
  File "/opt/CFD-Benchmark/PDE_Benchmark_6/solver/2D_Unsteady_Heat_Equation_DF.py", line 48, in update
    cax.set_array(T[:, :, frame % 2].flatten())
  File "/home/weichao/.local/lib/python3.8/site-packages/matplotlib/image.py", line 743, in set_array
    self.set_data(A)
  File "/home/weichao/.local/lib/python3.8/site-packages/matplotlib/image.py", line 710, in set_data
    raise TypeError("Invalid shape {} for image data"
TypeError: Invalid shape (1681,) for image data
2025-03-19 13:01:44,046 - INFO - ‚ùå Error detected in 2D_Unsteady_Heat_Equation_DF, refining prompt...
2025-03-19 13:01:44,046 - INFO - 

[Feedback]: The previous generated code had the following error:
/opt/CFD-Benchmark/PDE_Benchmark_6/solver/2D_Unsteady_Heat_Equation_DF.py:32: RuntimeWarning: overflow encountered in scalar add
  T_new[i, j] = (2*r*(T[i+1, j, 1] + T[i-1, j, 1]) + 2*(beta**2)*r*(T[i, j+1, 1] + T[i, j-1, 1]) + T[i, j, 0] + 2*dt*q(x[i], y[j])) / (1 + 2*r + 2*(beta**2)*r)
Traceback (most recent call last):
  File "/opt/CFD-Benchmark/PDE_Benchmark_6/solver/2D_Unsteady_Heat_Equation_DF.py", line 51, in <module>
    plt.show()
  File "/home/weichao/.local/lib/python3.8/site-packages/matplotlib/pyplot.py", line 446, in show
    return _get_backend_mod().show(*args, **kwargs)
  File "/home/weichao/Downloads/pycharm-2023.2.1/plugins/python/helpers/pycharm_matplotlib_backend/backend_interagg.py", line 29, in __call__
    manager.show(**kwargs)
  File "/home/weichao/Downloads/pycharm-2023.2.1/plugins/python/helpers/pycharm_matplotlib_backend/backend_interagg.py", line 112, in show
    self.canvas.show()
  File "/home/weichao/Downloads/pycharm-2023.2.1/plugins/python/helpers/pycharm_matplotlib_backend/backend_interagg.py", line 68, in show
    FigureCanvasAgg.draw(self)
  File "/home/weichao/.local/lib/python3.8/site-packages/matplotlib/backends/backend_agg.py", line 400, in draw
    self.figure.draw(self.renderer)
  File "/home/weichao/.local/lib/python3.8/site-packages/matplotlib/artist.py", line 95, in draw_wrapper
    result = draw(artist, renderer, *args, **kwargs)
  File "/home/weichao/.local/lib/python3.8/site-packages/matplotlib/artist.py", line 72, in draw_wrapper
    return draw(artist, renderer)
  File "/home/weichao/.local/lib/python3.8/site-packages/matplotlib/figure.py", line 3185, in draw
    DrawEvent("draw_event", self.canvas, renderer)._process()
  File "/home/weichao/.local/lib/python3.8/site-packages/matplotlib/backend_bases.py", line 1263, in _process
    self.canvas.callbacks.process(self.name, self)
  File "/home/weichao/.local/lib/python3.8/site-packages/matplotlib/cbook/__init__.py", line 319, in process
    self.exception_handler(exc)
  File "/home/weichao/.local/lib/python3.8/site-packages/matplotlib/cbook/__init__.py", line 103, in _exception_printer
    raise exc
  File "/home/weichao/.local/lib/python3.8/site-packages/matplotlib/cbook/__init__.py", line 314, in process
    func(*args, **kwargs)
  File "/home/weichao/.local/lib/python3.8/site-packages/matplotlib/animation.py", line 904, in _start
    self._init_draw()
  File "/home/weichao/.local/lib/python3.8/site-packages/matplotlib/animation.py", line 1748, in _init_draw
    self._draw_frame(frame_data)
  File "/home/weichao/.local/lib/python3.8/site-packages/matplotlib/animation.py", line 1767, in _draw_frame
    self._drawn_artists = self._func(framedata, *self._args)
  File "/opt/CFD-Benchmark/PDE_Benchmark_6/solver/2D_Unsteady_Heat_Equation_DF.py", line 48, in update
    cax.set_array(T[:, :, frame % 2].flatten())
  File "/home/weichao/.local/lib/python3.8/site-packages/matplotlib/image.py", line 743, in set_array
    self.set_data(A)
  File "/home/weichao/.local/lib/python3.8/site-packages/matplotlib/image.py", line 710, in set_data
    raise TypeError("Invalid shape {} for image data"
TypeError: Invalid shape (1681,) for image data
Please correct it.
2025-03-19 13:01:44,046 - INFO - üîπ Generating code for: 2D_Unsteady_Heat_Equation_DF (Attempt 8/10)
2025-03-20 14:54:26,580 - INFO - ####################################################################################################
2025-03-20 14:54:26,580 - INFO - Adjust the prompt to add unsteady heat equation
2025-03-20 14:54:26,602 - INFO - üîπ Generating code for: Fully_Developed_Turbulent_Channel_Flow_KE (Attempt 1/5)
2025-03-20 14:54:26,783 - INFO - HTTP Request: POST https://api.openai.com/v1/chat/completions "HTTP/1.1 401 Unauthorized"
2025-03-20 14:54:26,783 - INFO - ‚ùå API Call Error for Fully_Developed_Turbulent_Channel_Flow_KE: Error code: 401 - {'error': {'message': 'Incorrect API key provided: your-ope*******-key. You can find your API key at https://platform.openai.com/account/api-keys.', 'type': 'invalid_request_error', 'param': None, 'code': 'invalid_api_key'}}
2025-03-20 14:54:26,783 - INFO - üîπ Generating code for: 2D_Diffusion_FVM (Attempt 1/5)
2025-03-20 14:54:27,066 - INFO - HTTP Request: POST https://api.openai.com/v1/chat/completions "HTTP/1.1 401 Unauthorized"
2025-03-20 14:54:27,067 - INFO - ‚ùå API Call Error for 2D_Diffusion_FVM: Error code: 401 - {'error': {'message': 'Incorrect API key provided: your-ope*******-key. You can find your API key at https://platform.openai.com/account/api-keys.', 'type': 'invalid_request_error', 'param': None, 'code': 'invalid_api_key'}}
2025-03-20 14:54:27,068 - INFO - üîπ Generating code for: 1D_Linear_Convection_corr (Attempt 1/5)
2025-03-20 14:54:27,271 - INFO - HTTP Request: POST https://api.openai.com/v1/chat/completions "HTTP/1.1 401 Unauthorized"
2025-03-20 14:54:27,272 - INFO - ‚ùå API Call Error for 1D_Linear_Convection_corr: Error code: 401 - {'error': {'message': 'Incorrect API key provided: your-ope*******-key. You can find your API key at https://platform.openai.com/account/api-keys.', 'type': 'invalid_request_error', 'param': None, 'code': 'invalid_api_key'}}
2025-03-20 14:54:27,272 - INFO - üîπ Generating code for: 1D_Burgers_Equation (Attempt 1/5)
2025-03-20 14:54:27,385 - INFO - HTTP Request: POST https://api.openai.com/v1/chat/completions "HTTP/1.1 401 Unauthorized"
2025-03-20 14:54:27,386 - INFO - ‚ùå API Call Error for 1D_Burgers_Equation: Error code: 401 - {'error': {'message': 'Incorrect API key provided: your-ope*******-key. You can find your API key at https://platform.openai.com/account/api-keys.', 'type': 'invalid_request_error', 'param': None, 'code': 'invalid_api_key'}}
2025-03-20 14:54:27,386 - INFO - üîπ Generating code for: 1D_Nonlinear_Convection_MK (Attempt 1/5)
2025-03-20 14:54:27,509 - INFO - HTTP Request: POST https://api.openai.com/v1/chat/completions "HTTP/1.1 401 Unauthorized"
2025-03-20 14:54:27,510 - INFO - ‚ùå API Call Error for 1D_Nonlinear_Convection_MK: Error code: 401 - {'error': {'message': 'Incorrect API key provided: your-ope*******-key. You can find your API key at https://platform.openai.com/account/api-keys.', 'type': 'invalid_request_error', 'param': None, 'code': 'invalid_api_key'}}
2025-03-20 14:54:27,511 - INFO - üîπ Generating code for: 2D_Laplace_Equation (Attempt 1/5)
2025-03-20 14:54:27,637 - INFO - HTTP Request: POST https://api.openai.com/v1/chat/completions "HTTP/1.1 401 Unauthorized"
2025-03-20 14:54:27,638 - INFO - ‚ùå API Call Error for 2D_Laplace_Equation: Error code: 401 - {'error': {'message': 'Incorrect API key provided: your-ope*******-key. You can find your API key at https://platform.openai.com/account/api-keys.', 'type': 'invalid_request_error', 'param': None, 'code': 'invalid_api_key'}}
2025-03-20 14:54:27,638 - INFO - üîπ Generating code for: 2D_Linear_Convection (Attempt 1/5)
2025-03-20 14:54:27,762 - INFO - HTTP Request: POST https://api.openai.com/v1/chat/completions "HTTP/1.1 401 Unauthorized"
2025-03-20 14:54:27,763 - INFO - ‚ùå API Call Error for 2D_Linear_Convection: Error code: 401 - {'error': {'message': 'Incorrect API key provided: your-ope*******-key. You can find your API key at https://platform.openai.com/account/api-keys.', 'type': 'invalid_request_error', 'param': None, 'code': 'invalid_api_key'}}
2025-03-20 14:54:27,763 - INFO - üîπ Generating code for: Fully_Developed_Turbulent_Channel_Flow_CESS (Attempt 1/5)
2025-03-20 14:54:27,884 - INFO - HTTP Request: POST https://api.openai.com/v1/chat/completions "HTTP/1.1 401 Unauthorized"
2025-03-20 14:54:27,886 - INFO - ‚ùå API Call Error for Fully_Developed_Turbulent_Channel_Flow_CESS: Error code: 401 - {'error': {'message': 'Incorrect API key provided: your-ope*******-key. You can find your API key at https://platform.openai.com/account/api-keys.', 'type': 'invalid_request_error', 'param': None, 'code': 'invalid_api_key'}}
2025-03-20 14:54:27,886 - INFO - üîπ Generating code for: 1D_Nonlinear_Convection_LW (Attempt 1/5)
2025-03-20 14:54:28,010 - INFO - HTTP Request: POST https://api.openai.com/v1/chat/completions "HTTP/1.1 401 Unauthorized"
2025-03-20 14:54:28,010 - INFO - ‚ùå API Call Error for 1D_Nonlinear_Convection_LW: Error code: 401 - {'error': {'message': 'Incorrect API key provided: your-ope*******-key. You can find your API key at https://platform.openai.com/account/api-keys.', 'type': 'invalid_request_error', 'param': None, 'code': 'invalid_api_key'}}
2025-03-20 14:54:28,010 - INFO - üîπ Generating code for: 1D_Linear_Convection_adams (Attempt 1/5)
2025-03-20 14:54:28,120 - INFO - HTTP Request: POST https://api.openai.com/v1/chat/completions "HTTP/1.1 401 Unauthorized"
2025-03-20 14:54:28,122 - INFO - ‚ùå API Call Error for 1D_Linear_Convection_adams: Error code: 401 - {'error': {'message': 'Incorrect API key provided: your-ope*******-key. You can find your API key at https://platform.openai.com/account/api-keys.', 'type': 'invalid_request_error', 'param': None, 'code': 'invalid_api_key'}}
2025-03-20 14:54:28,122 - INFO - üîπ Generating code for: 2D_Steady_Heat_Equation (Attempt 1/5)
2025-03-20 14:54:28,247 - INFO - HTTP Request: POST https://api.openai.com/v1/chat/completions "HTTP/1.1 401 Unauthorized"
2025-03-20 14:54:28,249 - INFO - ‚ùå API Call Error for 2D_Steady_Heat_Equation: Error code: 401 - {'error': {'message': 'Incorrect API key provided: your-ope*******-key. You can find your API key at https://platform.openai.com/account/api-keys.', 'type': 'invalid_request_error', 'param': None, 'code': 'invalid_api_key'}}
2025-03-20 14:54:28,249 - INFO - üîπ Generating code for: 2D_Navier_Stokes_Channel (Attempt 1/5)
2025-03-20 14:54:28,378 - INFO - HTTP Request: POST https://api.openai.com/v1/chat/completions "HTTP/1.1 401 Unauthorized"
2025-03-20 14:54:28,379 - INFO - ‚ùå API Call Error for 2D_Navier_Stokes_Channel: Error code: 401 - {'error': {'message': 'Incorrect API key provided: your-ope*******-key. You can find your API key at https://platform.openai.com/account/api-keys.', 'type': 'invalid_request_error', 'param': None, 'code': 'invalid_api_key'}}
2025-03-20 14:54:28,379 - INFO - üîπ Generating code for: 2D_Diffusion (Attempt 1/5)
2025-03-20 14:54:28,502 - INFO - HTTP Request: POST https://api.openai.com/v1/chat/completions "HTTP/1.1 401 Unauthorized"
2025-03-20 14:54:28,503 - INFO - ‚ùå API Call Error for 2D_Diffusion: Error code: 401 - {'error': {'message': 'Incorrect API key provided: your-ope*******-key. You can find your API key at https://platform.openai.com/account/api-keys.', 'type': 'invalid_request_error', 'param': None, 'code': 'invalid_api_key'}}
2025-03-20 14:54:28,503 - INFO - üîπ Generating code for: 1D_Euler_Shock_Tube (Attempt 1/5)
2025-03-20 14:54:28,616 - INFO - HTTP Request: POST https://api.openai.com/v1/chat/completions "HTTP/1.1 401 Unauthorized"
2025-03-20 14:54:28,616 - INFO - ‚ùå API Call Error for 1D_Euler_Shock_Tube: Error code: 401 - {'error': {'message': 'Incorrect API key provided: your-ope*******-key. You can find your API key at https://platform.openai.com/account/api-keys.', 'type': 'invalid_request_error', 'param': None, 'code': 'invalid_api_key'}}
2025-03-20 14:54:28,616 - INFO - üîπ Generating code for: 2D_Unsteady_Heat_Equation_SE (Attempt 1/5)
2025-03-20 14:54:28,804 - INFO - HTTP Request: POST https://api.openai.com/v1/chat/completions "HTTP/1.1 401 Unauthorized"
2025-03-20 14:54:28,805 - INFO - ‚ùå API Call Error for 2D_Unsteady_Heat_Equation_SE: Error code: 401 - {'error': {'message': 'Incorrect API key provided: your-ope*******-key. You can find your API key at https://platform.openai.com/account/api-keys.', 'type': 'invalid_request_error', 'param': None, 'code': 'invalid_api_key'}}
2025-03-20 14:54:28,805 - INFO - üîπ Generating code for: 2D_Inviscid_Burgers_FOU (Attempt 1/5)
2025-03-20 14:54:28,916 - INFO - HTTP Request: POST https://api.openai.com/v1/chat/completions "HTTP/1.1 401 Unauthorized"
2025-03-20 14:54:28,918 - INFO - ‚ùå API Call Error for 2D_Inviscid_Burgers_FOU: Error code: 401 - {'error': {'message': 'Incorrect API key provided: your-ope*******-key. You can find your API key at https://platform.openai.com/account/api-keys.', 'type': 'invalid_request_error', 'param': None, 'code': 'invalid_api_key'}}
2025-03-20 14:54:28,918 - INFO - üîπ Generating code for: Fully_Developed_Turbulent_Channel_Flow_SA (Attempt 1/5)
2025-03-20 14:54:29,112 - INFO - HTTP Request: POST https://api.openai.com/v1/chat/completions "HTTP/1.1 401 Unauthorized"
2025-03-20 14:54:29,112 - INFO - ‚ùå API Call Error for Fully_Developed_Turbulent_Channel_Flow_SA: Error code: 401 - {'error': {'message': 'Incorrect API key provided: your-ope*******-key. You can find your API key at https://platform.openai.com/account/api-keys.', 'type': 'invalid_request_error', 'param': None, 'code': 'invalid_api_key'}}
2025-03-20 14:54:29,112 - INFO - üîπ Generating code for: 2D_Burgers_Equation (Attempt 1/5)
2025-03-20 14:54:29,320 - INFO - HTTP Request: POST https://api.openai.com/v1/chat/completions "HTTP/1.1 401 Unauthorized"
2025-03-20 14:54:29,321 - INFO - ‚ùå API Call Error for 2D_Burgers_Equation: Error code: 401 - {'error': {'message': 'Incorrect API key provided: your-ope*******-key. You can find your API key at https://platform.openai.com/account/api-keys.', 'type': 'invalid_request_error', 'param': None, 'code': 'invalid_api_key'}}
2025-03-20 14:54:29,322 - INFO - üîπ Generating code for: 1D_Linear_Convection_explicit_euler (Attempt 1/5)
2025-03-20 14:54:29,831 - INFO - HTTP Request: POST https://api.openai.com/v1/chat/completions "HTTP/1.1 401 Unauthorized"
2025-03-20 14:54:29,832 - INFO - ‚ùå API Call Error for 1D_Linear_Convection_explicit_euler: Error code: 401 - {'error': {'message': 'Incorrect API key provided: your-ope*******-key. You can find your API key at https://platform.openai.com/account/api-keys.', 'type': 'invalid_request_error', 'param': None, 'code': 'invalid_api_key'}}
2025-03-20 14:54:29,832 - INFO - üîπ Generating code for: 2D_Navier_Stokes_Cavity (Attempt 1/5)
2025-03-20 14:54:29,967 - INFO - HTTP Request: POST https://api.openai.com/v1/chat/completions "HTTP/1.1 401 Unauthorized"
2025-03-20 14:54:29,969 - INFO - ‚ùå API Call Error for 2D_Navier_Stokes_Cavity: Error code: 401 - {'error': {'message': 'Incorrect API key provided: your-ope*******-key. You can find your API key at https://platform.openai.com/account/api-keys.', 'type': 'invalid_request_error', 'param': None, 'code': 'invalid_api_key'}}
2025-03-20 14:54:29,969 - INFO - üîπ Generating code for: 2D_Inviscid_Burgers_MK (Attempt 1/5)
2025-03-20 14:54:30,114 - INFO - HTTP Request: POST https://api.openai.com/v1/chat/completions "HTTP/1.1 401 Unauthorized"
2025-03-20 14:54:30,115 - INFO - ‚ùå API Call Error for 2D_Inviscid_Burgers_MK: Error code: 401 - {'error': {'message': 'Incorrect API key provided: your-ope*******-key. You can find your API key at https://platform.openai.com/account/api-keys.', 'type': 'invalid_request_error', 'param': None, 'code': 'invalid_api_key'}}
2025-03-20 14:54:30,115 - INFO - üîπ Generating code for: 1D_Diffusion (Attempt 1/5)
2025-03-20 14:54:30,342 - INFO - HTTP Request: POST https://api.openai.com/v1/chat/completions "HTTP/1.1 401 Unauthorized"
2025-03-20 14:54:30,342 - INFO - ‚ùå API Call Error for 1D_Diffusion: Error code: 401 - {'error': {'message': 'Incorrect API key provided: your-ope*******-key. You can find your API key at https://platform.openai.com/account/api-keys.', 'type': 'invalid_request_error', 'param': None, 'code': 'invalid_api_key'}}
2025-03-20 14:54:30,342 - INFO - üîπ Generating code for: 2D_Unsteady_Heat_Equation_ADI (Attempt 1/5)
2025-03-20 14:54:30,460 - INFO - HTTP Request: POST https://api.openai.com/v1/chat/completions "HTTP/1.1 401 Unauthorized"
2025-03-20 14:54:30,462 - INFO - ‚ùå API Call Error for 2D_Unsteady_Heat_Equation_ADI: Error code: 401 - {'error': {'message': 'Incorrect API key provided: your-ope*******-key. You can find your API key at https://platform.openai.com/account/api-keys.', 'type': 'invalid_request_error', 'param': None, 'code': 'invalid_api_key'}}
2025-03-20 14:54:30,462 - INFO - üîπ Generating code for: 1D_Linear_Convection_rk (Attempt 1/5)
2025-03-20 14:54:30,586 - INFO - HTTP Request: POST https://api.openai.com/v1/chat/completions "HTTP/1.1 401 Unauthorized"
2025-03-20 14:54:30,588 - INFO - ‚ùå API Call Error for 1D_Linear_Convection_rk: Error code: 401 - {'error': {'message': 'Incorrect API key provided: your-ope*******-key. You can find your API key at https://platform.openai.com/account/api-keys.', 'type': 'invalid_request_error', 'param': None, 'code': 'invalid_api_key'}}
2025-03-20 14:54:30,588 - INFO - üîπ Generating code for: 1D_Nonlinear_Convection_Lax (Attempt 1/5)
2025-03-20 14:54:30,706 - INFO - HTTP Request: POST https://api.openai.com/v1/chat/completions "HTTP/1.1 401 Unauthorized"
2025-03-20 14:54:30,706 - INFO - ‚ùå API Call Error for 1D_Nonlinear_Convection_Lax: Error code: 401 - {'error': {'message': 'Incorrect API key provided: your-ope*******-key. You can find your API key at https://platform.openai.com/account/api-keys.', 'type': 'invalid_request_error', 'param': None, 'code': 'invalid_api_key'}}
2025-03-20 14:54:30,706 - INFO - üîπ Generating code for: 2D_Unsteady_Heat_Equation_DF (Attempt 1/5)
2025-03-20 14:54:30,815 - INFO - HTTP Request: POST https://api.openai.com/v1/chat/completions "HTTP/1.1 401 Unauthorized"
2025-03-20 14:54:30,816 - INFO - ‚ùå API Call Error for 2D_Unsteady_Heat_Equation_DF: Error code: 401 - {'error': {'message': 'Incorrect API key provided: your-ope*******-key. You can find your API key at https://platform.openai.com/account/api-keys.', 'type': 'invalid_request_error', 'param': None, 'code': 'invalid_api_key'}}
2025-03-20 14:54:30,817 - INFO - üîπ Generating code for: 2D_Convection (Attempt 1/5)
2025-03-20 14:54:30,940 - INFO - HTTP Request: POST https://api.openai.com/v1/chat/completions "HTTP/1.1 401 Unauthorized"
2025-03-20 14:54:30,940 - INFO - ‚ùå API Call Error for 2D_Convection: Error code: 401 - {'error': {'message': 'Incorrect API key provided: your-ope*******-key. You can find your API key at https://platform.openai.com/account/api-keys.', 'type': 'invalid_request_error', 'param': None, 'code': 'invalid_api_key'}}
2025-03-20 14:54:30,941 - INFO - üîπ Generating code for: 2D_Poisson_Equation (Attempt 1/5)
2025-03-20 14:54:31,060 - INFO - HTTP Request: POST https://api.openai.com/v1/chat/completions "HTTP/1.1 401 Unauthorized"
2025-03-20 14:54:31,062 - INFO - ‚ùå API Call Error for 2D_Poisson_Equation: Error code: 401 - {'error': {'message': 'Incorrect API key provided: your-ope*******-key. You can find your API key at https://platform.openai.com/account/api-keys.', 'type': 'invalid_request_error', 'param': None, 'code': 'invalid_api_key'}}
2025-03-20 14:54:31,062 - INFO - üîπ Generating code for: Fully_Developed_Turbulent_Channel_Flow_SST (Attempt 1/5)
2025-03-20 14:54:31,182 - INFO - HTTP Request: POST https://api.openai.com/v1/chat/completions "HTTP/1.1 401 Unauthorized"
2025-03-20 14:54:31,183 - INFO - ‚ùå API Call Error for Fully_Developed_Turbulent_Channel_Flow_SST: Error code: 401 - {'error': {'message': 'Incorrect API key provided: your-ope*******-key. You can find your API key at https://platform.openai.com/account/api-keys.', 'type': 'invalid_request_error', 'param': None, 'code': 'invalid_api_key'}}
2025-03-20 14:54:31,184 - INFO - üîπ Generating code for: Fully_Developed_Turbulent_Channel_Flow_V2F (Attempt 1/5)
2025-03-20 14:54:31,299 - INFO - HTTP Request: POST https://api.openai.com/v1/chat/completions "HTTP/1.1 401 Unauthorized"
2025-03-20 14:54:31,301 - INFO - ‚ùå API Call Error for Fully_Developed_Turbulent_Channel_Flow_V2F: Error code: 401 - {'error': {'message': 'Incorrect API key provided: your-ope*******-key. You can find your API key at https://platform.openai.com/account/api-keys.', 'type': 'invalid_request_error', 'param': None, 'code': 'invalid_api_key'}}
2025-03-20 14:54:31,301 - INFO - 
üéØ Execution completed. Check the solver directory for generated files.
2025-03-20 14:54:31,301 - INFO - Total Input Tokens: 0
2025-03-20 14:54:31,301 - INFO - Total Output Tokens: 0
2025-03-20 14:54:31,301 - INFO - Total Estimated Cost: $0.000000
2025-03-20 15:09:27,866 - INFO - ####################################################################################################
2025-03-20 15:09:27,866 - INFO - Using the GPT-4o
2025-03-20 15:09:27,888 - INFO - üîπ Generating code for: Fully_Developed_Turbulent_Channel_Flow_KE (Attempt 1/5)
2025-03-20 15:09:45,094 - INFO - HTTP Request: POST https://api.openai.com/v1/chat/completions "HTTP/1.1 200 OK"
2025-03-20 15:09:45,098 - INFO - ‚ùå API Call Error for Fully_Developed_Turbulent_Channel_Flow_KE: 'CompletionUsage' object is not subscriptable
2025-03-20 15:09:45,098 - INFO - üîπ Generating code for: 2D_Diffusion_FVM (Attempt 1/5)
2025-03-20 15:09:53,794 - INFO - HTTP Request: POST https://api.openai.com/v1/chat/completions "HTTP/1.1 200 OK"
2025-03-20 15:09:53,797 - INFO - ‚ùå API Call Error for 2D_Diffusion_FVM: 'CompletionUsage' object is not subscriptable
2025-03-20 15:09:53,798 - INFO - üîπ Generating code for: 1D_Linear_Convection_corr (Attempt 1/5)
2025-03-20 15:10:02,296 - INFO - HTTP Request: POST https://api.openai.com/v1/chat/completions "HTTP/1.1 200 OK"
2025-03-20 15:10:02,299 - INFO - ‚ùå API Call Error for 1D_Linear_Convection_corr: 'CompletionUsage' object is not subscriptable
2025-03-20 15:10:02,299 - INFO - üîπ Generating code for: 1D_Burgers_Equation (Attempt 1/5)
2025-03-20 15:10:11,510 - INFO - HTTP Request: POST https://api.openai.com/v1/chat/completions "HTTP/1.1 200 OK"
2025-03-20 15:10:11,513 - INFO - ‚ùå API Call Error for 1D_Burgers_Equation: 'CompletionUsage' object is not subscriptable
2025-03-20 15:10:11,514 - INFO - üîπ Generating code for: 1D_Nonlinear_Convection_MK (Attempt 1/5)
2025-03-20 15:10:18,307 - INFO - HTTP Request: POST https://api.openai.com/v1/chat/completions "HTTP/1.1 200 OK"
2025-03-20 15:10:18,311 - INFO - ‚ùå API Call Error for 1D_Nonlinear_Convection_MK: 'CompletionUsage' object is not subscriptable
2025-03-20 15:10:18,311 - INFO - üîπ Generating code for: 2D_Laplace_Equation (Attempt 1/5)
2025-03-20 15:10:29,890 - INFO - HTTP Request: POST https://api.openai.com/v1/chat/completions "HTTP/1.1 200 OK"
2025-03-20 15:10:29,891 - INFO - ‚ùå API Call Error for 2D_Laplace_Equation: 'CompletionUsage' object is not subscriptable
2025-03-20 15:10:29,891 - INFO - üîπ Generating code for: 2D_Linear_Convection (Attempt 1/5)
2025-03-20 15:10:36,162 - INFO - HTTP Request: POST https://api.openai.com/v1/chat/completions "HTTP/1.1 200 OK"
2025-03-20 15:10:36,165 - INFO - ‚ùå API Call Error for 2D_Linear_Convection: 'CompletionUsage' object is not subscriptable
2025-03-20 15:10:36,166 - INFO - üîπ Generating code for: Fully_Developed_Turbulent_Channel_Flow_CESS (Attempt 1/5)
2025-03-20 15:10:51,013 - INFO - HTTP Request: POST https://api.openai.com/v1/chat/completions "HTTP/1.1 200 OK"
2025-03-20 15:10:51,017 - INFO - ‚ùå API Call Error for Fully_Developed_Turbulent_Channel_Flow_CESS: 'CompletionUsage' object is not subscriptable
2025-03-20 15:10:51,017 - INFO - üîπ Generating code for: 1D_Nonlinear_Convection_LW (Attempt 1/5)
2025-03-20 15:11:03,094 - INFO - HTTP Request: POST https://api.openai.com/v1/chat/completions "HTTP/1.1 200 OK"
2025-03-20 15:11:03,097 - INFO - ‚ùå API Call Error for 1D_Nonlinear_Convection_LW: 'CompletionUsage' object is not subscriptable
2025-03-20 15:11:03,097 - INFO - üîπ Generating code for: 1D_Linear_Convection_adams (Attempt 1/5)
2025-03-20 15:11:15,587 - INFO - HTTP Request: POST https://api.openai.com/v1/chat/completions "HTTP/1.1 200 OK"
2025-03-20 15:11:15,590 - INFO - ‚ùå API Call Error for 1D_Linear_Convection_adams: 'CompletionUsage' object is not subscriptable
2025-03-20 15:11:15,590 - INFO - üîπ Generating code for: 2D_Steady_Heat_Equation (Attempt 1/5)
2025-03-20 15:11:25,929 - INFO - HTTP Request: POST https://api.openai.com/v1/chat/completions "HTTP/1.1 200 OK"
2025-03-20 15:11:25,933 - INFO - ‚ùå API Call Error for 2D_Steady_Heat_Equation: 'CompletionUsage' object is not subscriptable
2025-03-20 15:11:25,933 - INFO - üîπ Generating code for: 2D_Navier_Stokes_Channel (Attempt 1/5)
2025-03-20 15:11:50,299 - INFO - HTTP Request: POST https://api.openai.com/v1/chat/completions "HTTP/1.1 200 OK"
2025-03-20 15:11:50,344 - INFO - ‚ùå API Call Error for 2D_Navier_Stokes_Channel: 'CompletionUsage' object is not subscriptable
2025-03-20 15:11:50,344 - INFO - üîπ Generating code for: 2D_Diffusion (Attempt 1/5)
2025-03-20 15:11:59,210 - INFO - HTTP Request: POST https://api.openai.com/v1/chat/completions "HTTP/1.1 200 OK"
2025-03-20 15:11:59,213 - INFO - ‚ùå API Call Error for 2D_Diffusion: 'CompletionUsage' object is not subscriptable
2025-03-20 15:11:59,213 - INFO - üîπ Generating code for: 1D_Euler_Shock_Tube (Attempt 1/5)
2025-03-20 15:12:14,160 - INFO - HTTP Request: POST https://api.openai.com/v1/chat/completions "HTTP/1.1 200 OK"
2025-03-20 15:12:14,174 - INFO - ‚ùå API Call Error for 1D_Euler_Shock_Tube: 'CompletionUsage' object is not subscriptable
2025-03-20 15:12:14,174 - INFO - üîπ Generating code for: 2D_Unsteady_Heat_Equation_SE (Attempt 1/5)
2025-03-20 15:12:32,081 - INFO - HTTP Request: POST https://api.openai.com/v1/chat/completions "HTTP/1.1 200 OK"
2025-03-20 15:12:32,084 - INFO - ‚ùå API Call Error for 2D_Unsteady_Heat_Equation_SE: 'CompletionUsage' object is not subscriptable
2025-03-20 15:12:32,085 - INFO - üîπ Generating code for: 2D_Inviscid_Burgers_FOU (Attempt 1/5)
2025-03-20 15:12:43,140 - INFO - HTTP Request: POST https://api.openai.com/v1/chat/completions "HTTP/1.1 200 OK"
2025-03-20 15:12:43,143 - INFO - ‚ùå API Call Error for 2D_Inviscid_Burgers_FOU: 'CompletionUsage' object is not subscriptable
2025-03-20 15:12:43,143 - INFO - üîπ Generating code for: Fully_Developed_Turbulent_Channel_Flow_SA (Attempt 1/5)
2025-03-20 15:12:58,489 - INFO - HTTP Request: POST https://api.openai.com/v1/chat/completions "HTTP/1.1 200 OK"
2025-03-20 15:12:58,492 - INFO - ‚ùå API Call Error for Fully_Developed_Turbulent_Channel_Flow_SA: 'CompletionUsage' object is not subscriptable
2025-03-20 15:12:58,493 - INFO - üîπ Generating code for: 2D_Burgers_Equation (Attempt 1/5)
2025-03-20 15:13:09,247 - INFO - HTTP Request: POST https://api.openai.com/v1/chat/completions "HTTP/1.1 200 OK"
2025-03-20 15:13:09,250 - INFO - ‚ùå API Call Error for 2D_Burgers_Equation: 'CompletionUsage' object is not subscriptable
2025-03-20 15:13:09,250 - INFO - üîπ Generating code for: 1D_Linear_Convection_explicit_euler (Attempt 1/5)
2025-03-20 15:13:18,060 - INFO - HTTP Request: POST https://api.openai.com/v1/chat/completions "HTTP/1.1 200 OK"
2025-03-20 15:13:18,063 - INFO - ‚ùå API Call Error for 1D_Linear_Convection_explicit_euler: 'CompletionUsage' object is not subscriptable
2025-03-20 15:13:18,063 - INFO - üîπ Generating code for: 2D_Navier_Stokes_Cavity (Attempt 1/5)
2025-03-20 15:13:40,895 - INFO - HTTP Request: POST https://api.openai.com/v1/chat/completions "HTTP/1.1 200 OK"
2025-03-20 15:13:40,898 - INFO - ‚ùå API Call Error for 2D_Navier_Stokes_Cavity: 'CompletionUsage' object is not subscriptable
2025-03-20 15:13:40,898 - INFO - üîπ Generating code for: 2D_Inviscid_Burgers_MK (Attempt 1/5)
2025-03-20 15:13:51,954 - INFO - HTTP Request: POST https://api.openai.com/v1/chat/completions "HTTP/1.1 200 OK"
2025-03-20 15:13:51,957 - INFO - ‚ùå API Call Error for 2D_Inviscid_Burgers_MK: 'CompletionUsage' object is not subscriptable
2025-03-20 15:13:51,957 - INFO - üîπ Generating code for: 1D_Diffusion (Attempt 1/5)
2025-03-20 15:13:59,021 - INFO - HTTP Request: POST https://api.openai.com/v1/chat/completions "HTTP/1.1 200 OK"
2025-03-20 15:13:59,024 - INFO - ‚ùå API Call Error for 1D_Diffusion: 'CompletionUsage' object is not subscriptable
2025-03-20 15:13:59,024 - INFO - üîπ Generating code for: 2D_Unsteady_Heat_Equation_ADI (Attempt 1/5)
2025-03-20 15:14:09,951 - INFO - HTTP Request: POST https://api.openai.com/v1/chat/completions "HTTP/1.1 200 OK"
2025-03-20 15:14:09,954 - INFO - ‚ùå API Call Error for 2D_Unsteady_Heat_Equation_ADI: 'CompletionUsage' object is not subscriptable
2025-03-20 15:14:09,954 - INFO - üîπ Generating code for: 1D_Linear_Convection_rk (Attempt 1/5)
2025-03-20 15:14:18,911 - INFO - HTTP Request: POST https://api.openai.com/v1/chat/completions "HTTP/1.1 200 OK"
2025-03-20 15:14:18,914 - INFO - ‚ùå API Call Error for 1D_Linear_Convection_rk: 'CompletionUsage' object is not subscriptable
2025-03-20 15:14:18,914 - INFO - üîπ Generating code for: 1D_Nonlinear_Convection_Lax (Attempt 1/5)
2025-03-20 15:14:25,876 - INFO - HTTP Request: POST https://api.openai.com/v1/chat/completions "HTTP/1.1 200 OK"
2025-03-20 15:14:25,879 - INFO - ‚ùå API Call Error for 1D_Nonlinear_Convection_Lax: 'CompletionUsage' object is not subscriptable
2025-03-20 15:14:25,879 - INFO - üîπ Generating code for: 2D_Unsteady_Heat_Equation_DF (Attempt 1/5)
2025-03-20 15:14:34,887 - INFO - HTTP Request: POST https://api.openai.com/v1/chat/completions "HTTP/1.1 200 OK"
2025-03-20 15:14:34,890 - INFO - ‚ùå API Call Error for 2D_Unsteady_Heat_Equation_DF: 'CompletionUsage' object is not subscriptable
2025-03-20 15:14:34,890 - INFO - üîπ Generating code for: 2D_Convection (Attempt 1/5)
2025-03-20 15:14:44,818 - INFO - HTTP Request: POST https://api.openai.com/v1/chat/completions "HTTP/1.1 200 OK"
2025-03-20 15:14:44,822 - INFO - ‚ùå API Call Error for 2D_Convection: 'CompletionUsage' object is not subscriptable
2025-03-20 15:14:44,822 - INFO - üîπ Generating code for: 2D_Poisson_Equation (Attempt 1/5)
2025-03-20 15:14:52,294 - INFO - HTTP Request: POST https://api.openai.com/v1/chat/completions "HTTP/1.1 200 OK"
2025-03-20 15:14:52,297 - INFO - ‚ùå API Call Error for 2D_Poisson_Equation: 'CompletionUsage' object is not subscriptable
2025-03-20 15:14:52,297 - INFO - üîπ Generating code for: Fully_Developed_Turbulent_Channel_Flow_SST (Attempt 1/5)
2025-03-20 15:15:07,553 - INFO - HTTP Request: POST https://api.openai.com/v1/chat/completions "HTTP/1.1 200 OK"
2025-03-20 15:15:07,556 - INFO - ‚ùå API Call Error for Fully_Developed_Turbulent_Channel_Flow_SST: 'CompletionUsage' object is not subscriptable
2025-03-20 15:15:07,556 - INFO - üîπ Generating code for: Fully_Developed_Turbulent_Channel_Flow_V2F (Attempt 1/5)
2025-03-20 15:15:20,660 - INFO - HTTP Request: POST https://api.openai.com/v1/chat/completions "HTTP/1.1 200 OK"
2025-03-20 15:15:20,663 - INFO - ‚ùå API Call Error for Fully_Developed_Turbulent_Channel_Flow_V2F: 'CompletionUsage' object is not subscriptable
2025-03-20 15:15:20,664 - INFO - 
üéØ Execution completed. Check the solver directory for generated files.
2025-03-20 15:15:20,664 - INFO - Total Input Tokens: 0
2025-03-20 15:15:20,664 - INFO - Total Output Tokens: 0
2025-03-20 15:15:20,664 - INFO - Total Estimated Cost: $0.000000
2025-03-20 15:49:54,605 - INFO - ####################################################################################################
2025-03-20 15:49:54,605 - INFO - Using the GPT-4o
2025-03-20 15:49:54,627 - INFO - üîπ Generating code for: Fully_Developed_Turbulent_Channel_Flow_KE (Attempt 1/5)
2025-03-20 15:50:08,108 - INFO - HTTP Request: POST https://api.openai.com/v1/chat/completions "HTTP/1.1 200 OK"
2025-03-20 15:50:08,112 - INFO - ‚ùå API Call Error for Fully_Developed_Turbulent_Channel_Flow_KE: 'ChatCompletion' object is not subscriptable
2025-03-20 15:50:08,112 - INFO - üîπ Generating code for: 2D_Diffusion_FVM (Attempt 1/5)
2025-03-20 15:51:00,674 - INFO - ####################################################################################################
2025-03-20 15:51:00,674 - INFO - Using the GPT-4o
2025-03-20 15:51:00,696 - INFO - üîπ Generating code for: Fully_Developed_Turbulent_Channel_Flow_KE (Attempt 1/5)
2025-03-20 15:51:16,713 - INFO - HTTP Request: POST https://api.openai.com/v1/chat/completions "HTTP/1.1 200 OK"
2025-03-20 15:51:16,749 - INFO - Input Tokens: 465, Output Tokens: 1633
2025-03-20 15:51:16,749 - INFO - Estimated cost for this request: $0.017493
2025-03-20 15:51:17,165 - ERROR - Execution failed with errors:
Traceback (most recent call last):
  File "/opt/CFD-Benchmark/PDE_Benchmark_7/solver/Fully_Developed_Turbulent_Channel_Flow_KE.py", line 86, in <module>
    k, epsilon, mu_t = solve_k_epsilon(mesh, mu, rho)
  File "/opt/CFD-Benchmark/PDE_Benchmark_7/solver/Fully_Developed_Turbulent_Channel_Flow_KE.py", line 66, in solve_k_epsilon
    k = solve(A_k, b_k)
  File "/home/weichao/.local/lib/python3.8/site-packages/scipy/linalg/_basic.py", line 223, in solve
    _solve_check(n, info)
  File "/home/weichao/.local/lib/python3.8/site-packages/scipy/linalg/_basic.py", line 29, in _solve_check
    raise LinAlgError('Matrix is singular.')
numpy.linalg.LinAlgError: Matrix is singular.
2025-03-20 15:51:17,165 - INFO - ‚ùå Error detected in Fully_Developed_Turbulent_Channel_Flow_KE, refining prompt...
2025-03-20 15:51:17,165 - INFO - 

[Feedback]: The previous generated code had the following error:
Traceback (most recent call last):
  File "/opt/CFD-Benchmark/PDE_Benchmark_7/solver/Fully_Developed_Turbulent_Channel_Flow_KE.py", line 86, in <module>
    k, epsilon, mu_t = solve_k_epsilon(mesh, mu, rho)
  File "/opt/CFD-Benchmark/PDE_Benchmark_7/solver/Fully_Developed_Turbulent_Channel_Flow_KE.py", line 66, in solve_k_epsilon
    k = solve(A_k, b_k)
  File "/home/weichao/.local/lib/python3.8/site-packages/scipy/linalg/_basic.py", line 223, in solve
    _solve_check(n, info)
  File "/home/weichao/.local/lib/python3.8/site-packages/scipy/linalg/_basic.py", line 29, in _solve_check
    raise LinAlgError('Matrix is singular.')
numpy.linalg.LinAlgError: Matrix is singular.
Please correct it.
2025-03-20 15:51:17,165 - INFO - üîπ Generating code for: Fully_Developed_Turbulent_Channel_Flow_KE (Attempt 2/5)
2025-03-20 15:51:30,844 - INFO - HTTP Request: POST https://api.openai.com/v1/chat/completions "HTTP/1.1 200 OK"
2025-03-20 15:51:30,845 - INFO - Input Tokens: 465, Output Tokens: 1606
2025-03-20 15:51:30,845 - INFO - Estimated cost for this request: $0.017223
2025-03-20 15:51:31,227 - ERROR - Execution failed with errors:
/opt/CFD-Benchmark/PDE_Benchmark_7/solver/Fully_Developed_Turbulent_Channel_Flow_KE.py:65: RuntimeWarning: divide by zero encountered in divide
  epsilon = solve(mesh.D2 - np.diag(mu_t / sigma_epsilon), (C_e1 * P_k - C_e2 * rho * epsilon) / k)
Traceback (most recent call last):
  File "/opt/CFD-Benchmark/PDE_Benchmark_7/solver/Fully_Developed_Turbulent_Channel_Flow_KE.py", line 94, in <module>
    u = solve_velocity_profile(mesh, mu, rho)
  File "/opt/CFD-Benchmark/PDE_Benchmark_7/solver/Fully_Developed_Turbulent_Channel_Flow_KE.py", line 72, in solve_velocity_profile
    k, epsilon, mu_t = compute_k_epsilon(mesh, mu, rho)
  File "/opt/CFD-Benchmark/PDE_Benchmark_7/solver/Fully_Developed_Turbulent_Channel_Flow_KE.py", line 65, in compute_k_epsilon
    epsilon = solve(mesh.D2 - np.diag(mu_t / sigma_epsilon), (C_e1 * P_k - C_e2 * rho * epsilon) / k)
  File "/home/weichao/.local/lib/python3.8/site-packages/scipy/linalg/_basic.py", line 144, in solve
    b1 = atleast_1d(_asarray_validated(b, check_finite=check_finite))
  File "/home/weichao/.local/lib/python3.8/site-packages/scipy/_lib/_util.py", line 252, in _asarray_validated
    a = toarray(a)
  File "/home/weichao/.local/lib/python3.8/site-packages/numpy/lib/function_base.py", line 628, in asarray_chkfinite
    raise ValueError(
ValueError: array must not contain infs or NaNs
2025-03-20 15:51:31,227 - INFO - ‚ùå Error detected in Fully_Developed_Turbulent_Channel_Flow_KE, refining prompt...
2025-03-20 15:51:31,227 - INFO - 

[Feedback]: The previous generated code had the following error:
/opt/CFD-Benchmark/PDE_Benchmark_7/solver/Fully_Developed_Turbulent_Channel_Flow_KE.py:65: RuntimeWarning: divide by zero encountered in divide
  epsilon = solve(mesh.D2 - np.diag(mu_t / sigma_epsilon), (C_e1 * P_k - C_e2 * rho * epsilon) / k)
Traceback (most recent call last):
  File "/opt/CFD-Benchmark/PDE_Benchmark_7/solver/Fully_Developed_Turbulent_Channel_Flow_KE.py", line 94, in <module>
    u = solve_velocity_profile(mesh, mu, rho)
  File "/opt/CFD-Benchmark/PDE_Benchmark_7/solver/Fully_Developed_Turbulent_Channel_Flow_KE.py", line 72, in solve_velocity_profile
    k, epsilon, mu_t = compute_k_epsilon(mesh, mu, rho)
  File "/opt/CFD-Benchmark/PDE_Benchmark_7/solver/Fully_Developed_Turbulent_Channel_Flow_KE.py", line 65, in compute_k_epsilon
    epsilon = solve(mesh.D2 - np.diag(mu_t / sigma_epsilon), (C_e1 * P_k - C_e2 * rho * epsilon) / k)
  File "/home/weichao/.local/lib/python3.8/site-packages/scipy/linalg/_basic.py", line 144, in solve
    b1 = atleast_1d(_asarray_validated(b, check_finite=check_finite))
  File "/home/weichao/.local/lib/python3.8/site-packages/scipy/_lib/_util.py", line 252, in _asarray_validated
    a = toarray(a)
  File "/home/weichao/.local/lib/python3.8/site-packages/numpy/lib/function_base.py", line 628, in asarray_chkfinite
    raise ValueError(
ValueError: array must not contain infs or NaNs
Please correct it.
2025-03-20 15:51:31,227 - INFO - üîπ Generating code for: Fully_Developed_Turbulent_Channel_Flow_KE (Attempt 3/5)
2025-03-20 15:51:44,559 - INFO - HTTP Request: POST https://api.openai.com/v1/chat/completions "HTTP/1.1 200 OK"
2025-03-20 15:51:44,563 - INFO - Input Tokens: 465, Output Tokens: 1617
2025-03-20 15:51:44,563 - INFO - Estimated cost for this request: $0.017333
2025-03-20 15:51:44,940 - ERROR - Execution failed with errors:
Traceback (most recent call last):
  File "/opt/CFD-Benchmark/PDE_Benchmark_7/solver/Fully_Developed_Turbulent_Channel_Flow_KE.py", line 103, in <module>
    main()
  File "/opt/CFD-Benchmark/PDE_Benchmark_7/solver/Fully_Developed_Turbulent_Channel_Flow_KE.py", line 78, in main
    k = solve_linear_system(A_k, b_k)
  File "/opt/CFD-Benchmark/PDE_Benchmark_7/solver/Fully_Developed_Turbulent_Channel_Flow_KE.py", line 57, in solve_linear_system
    return solve(A, b)
  File "/home/weichao/.local/lib/python3.8/site-packages/scipy/linalg/_basic.py", line 223, in solve
    _solve_check(n, info)
  File "/home/weichao/.local/lib/python3.8/site-packages/scipy/linalg/_basic.py", line 29, in _solve_check
    raise LinAlgError('Matrix is singular.')
numpy.linalg.LinAlgError: Matrix is singular.
2025-03-20 15:51:44,940 - INFO - ‚ùå Error detected in Fully_Developed_Turbulent_Channel_Flow_KE, refining prompt...
2025-03-20 15:51:44,940 - INFO - 

[Feedback]: The previous generated code had the following error:
Traceback (most recent call last):
  File "/opt/CFD-Benchmark/PDE_Benchmark_7/solver/Fully_Developed_Turbulent_Channel_Flow_KE.py", line 103, in <module>
    main()
  File "/opt/CFD-Benchmark/PDE_Benchmark_7/solver/Fully_Developed_Turbulent_Channel_Flow_KE.py", line 78, in main
    k = solve_linear_system(A_k, b_k)
  File "/opt/CFD-Benchmark/PDE_Benchmark_7/solver/Fully_Developed_Turbulent_Channel_Flow_KE.py", line 57, in solve_linear_system
    return solve(A, b)
  File "/home/weichao/.local/lib/python3.8/site-packages/scipy/linalg/_basic.py", line 223, in solve
    _solve_check(n, info)
  File "/home/weichao/.local/lib/python3.8/site-packages/scipy/linalg/_basic.py", line 29, in _solve_check
    raise LinAlgError('Matrix is singular.')
numpy.linalg.LinAlgError: Matrix is singular.
Please correct it.
2025-03-20 15:51:44,940 - INFO - üîπ Generating code for: Fully_Developed_Turbulent_Channel_Flow_KE (Attempt 4/5)
2025-03-20 15:51:57,675 - INFO - HTTP Request: POST https://api.openai.com/v1/chat/completions "HTTP/1.1 200 OK"
2025-03-20 15:51:57,679 - INFO - Input Tokens: 465, Output Tokens: 1596
2025-03-20 15:51:57,679 - INFO - Estimated cost for this request: $0.017123
2025-03-20 15:51:58,315 - INFO - Execution successful, no errors detected.
2025-03-20 15:51:58,315 - INFO - üéØ Fully_Developed_Turbulent_Channel_Flow_KE executed successfully without syntax errors.
2025-03-20 15:51:58,315 - INFO - üîπ Generating code for: 2D_Diffusion_FVM (Attempt 1/5)
2025-03-20 15:52:04,831 - INFO - HTTP Request: POST https://api.openai.com/v1/chat/completions "HTTP/1.1 200 OK"
2025-03-20 15:52:04,838 - INFO - Input Tokens: 443, Output Tokens: 1017
2025-03-20 15:52:04,838 - INFO - Estimated cost for this request: $0.011278
2025-03-20 15:53:41,702 - INFO - ####################################################################################################
2025-03-20 15:53:41,702 - INFO - Using the GPT-4o
2025-03-20 15:53:41,723 - INFO - üîπ Generating code for: Fully_Developed_Turbulent_Channel_Flow_KE (Attempt 1/5)
2025-03-20 15:53:58,406 - INFO - HTTP Request: POST https://api.openai.com/v1/chat/completions "HTTP/1.1 200 OK"
2025-03-20 15:53:58,410 - INFO - Input Tokens: 465, Output Tokens: 1728
2025-03-20 15:53:58,411 - INFO - Estimated cost for this request: $0.018443
2025-03-20 15:53:58,810 - ERROR - Execution failed with errors:
/opt/CFD-Benchmark/PDE_Benchmark_7/solver/gpt-4o/Fully_Developed_Turbulent_Channel_Flow_KE.py:64: LinAlgWarning: Ill-conditioned matrix (rcond=1.12438e-21): result may not be accurate.
  k = solve(mesh.D2, P_k / rho + mu_t / sigma_k * (mesh.D2 @ k))
/opt/CFD-Benchmark/PDE_Benchmark_7/solver/gpt-4o/Fully_Developed_Turbulent_Channel_Flow_KE.py:65: RuntimeWarning: divide by zero encountered in divide
  epsilon = solve(mesh.D2, (C_e1 * P_k - C_e2 * rho * epsilon) / k + mu_t / sigma_epsilon * (mesh.D2 @ epsilon))
Traceback (most recent call last):
  File "/opt/CFD-Benchmark/PDE_Benchmark_7/solver/gpt-4o/Fully_Developed_Turbulent_Channel_Flow_KE.py", line 106, in <module>
    main()
  File "/opt/CFD-Benchmark/PDE_Benchmark_7/solver/gpt-4o/Fully_Developed_Turbulent_Channel_Flow_KE.py", line 90, in main
    k, epsilon, mu_t = compute_k_epsilon(mesh, mu, rho)
  File "/opt/CFD-Benchmark/PDE_Benchmark_7/solver/gpt-4o/Fully_Developed_Turbulent_Channel_Flow_KE.py", line 65, in compute_k_epsilon
    epsilon = solve(mesh.D2, (C_e1 * P_k - C_e2 * rho * epsilon) / k + mu_t / sigma_epsilon * (mesh.D2 @ epsilon))
  File "/home/weichao/.local/lib/python3.8/site-packages/scipy/linalg/_basic.py", line 144, in solve
    b1 = atleast_1d(_asarray_validated(b, check_finite=check_finite))
  File "/home/weichao/.local/lib/python3.8/site-packages/scipy/_lib/_util.py", line 252, in _asarray_validated
    a = toarray(a)
  File "/home/weichao/.local/lib/python3.8/site-packages/numpy/lib/function_base.py", line 628, in asarray_chkfinite
    raise ValueError(
ValueError: array must not contain infs or NaNs
2025-03-20 15:53:58,810 - INFO - ‚ùå Error detected in Fully_Developed_Turbulent_Channel_Flow_KE, refining prompt...
2025-03-20 15:53:58,810 - INFO - 

[Feedback]: The previous generated code had the following error:
/opt/CFD-Benchmark/PDE_Benchmark_7/solver/gpt-4o/Fully_Developed_Turbulent_Channel_Flow_KE.py:64: LinAlgWarning: Ill-conditioned matrix (rcond=1.12438e-21): result may not be accurate.
  k = solve(mesh.D2, P_k / rho + mu_t / sigma_k * (mesh.D2 @ k))
/opt/CFD-Benchmark/PDE_Benchmark_7/solver/gpt-4o/Fully_Developed_Turbulent_Channel_Flow_KE.py:65: RuntimeWarning: divide by zero encountered in divide
  epsilon = solve(mesh.D2, (C_e1 * P_k - C_e2 * rho * epsilon) / k + mu_t / sigma_epsilon * (mesh.D2 @ epsilon))
Traceback (most recent call last):
  File "/opt/CFD-Benchmark/PDE_Benchmark_7/solver/gpt-4o/Fully_Developed_Turbulent_Channel_Flow_KE.py", line 106, in <module>
    main()
  File "/opt/CFD-Benchmark/PDE_Benchmark_7/solver/gpt-4o/Fully_Developed_Turbulent_Channel_Flow_KE.py", line 90, in main
    k, epsilon, mu_t = compute_k_epsilon(mesh, mu, rho)
  File "/opt/CFD-Benchmark/PDE_Benchmark_7/solver/gpt-4o/Fully_Developed_Turbulent_Channel_Flow_KE.py", line 65, in compute_k_epsilon
    epsilon = solve(mesh.D2, (C_e1 * P_k - C_e2 * rho * epsilon) / k + mu_t / sigma_epsilon * (mesh.D2 @ epsilon))
  File "/home/weichao/.local/lib/python3.8/site-packages/scipy/linalg/_basic.py", line 144, in solve
    b1 = atleast_1d(_asarray_validated(b, check_finite=check_finite))
  File "/home/weichao/.local/lib/python3.8/site-packages/scipy/_lib/_util.py", line 252, in _asarray_validated
    a = toarray(a)
  File "/home/weichao/.local/lib/python3.8/site-packages/numpy/lib/function_base.py", line 628, in asarray_chkfinite
    raise ValueError(
ValueError: array must not contain infs or NaNs
Please correct it.
2025-03-20 15:53:58,810 - INFO - üîπ Generating code for: Fully_Developed_Turbulent_Channel_Flow_KE (Attempt 2/5)
2025-03-20 15:54:13,253 - INFO - HTTP Request: POST https://api.openai.com/v1/chat/completions "HTTP/1.1 200 OK"
2025-03-20 15:54:13,257 - INFO - Input Tokens: 465, Output Tokens: 1614
2025-03-20 15:54:13,257 - INFO - Estimated cost for this request: $0.017303
2025-03-20 15:54:13,663 - ERROR - Execution failed with errors:
Traceback (most recent call last):
  File "/opt/CFD-Benchmark/PDE_Benchmark_7/solver/gpt-4o/Fully_Developed_Turbulent_Channel_Flow_KE.py", line 100, in <module>
    main()
  File "/opt/CFD-Benchmark/PDE_Benchmark_7/solver/gpt-4o/Fully_Developed_Turbulent_Channel_Flow_KE.py", line 75, in main
    k = solve_linear_system(A_k, b_k)
  File "/opt/CFD-Benchmark/PDE_Benchmark_7/solver/gpt-4o/Fully_Developed_Turbulent_Channel_Flow_KE.py", line 55, in solve_linear_system
    return solve(A, b)
  File "/home/weichao/.local/lib/python3.8/site-packages/scipy/linalg/_basic.py", line 223, in solve
    _solve_check(n, info)
  File "/home/weichao/.local/lib/python3.8/site-packages/scipy/linalg/_basic.py", line 29, in _solve_check
    raise LinAlgError('Matrix is singular.')
numpy.linalg.LinAlgError: Matrix is singular.
2025-03-20 15:54:13,663 - INFO - ‚ùå Error detected in Fully_Developed_Turbulent_Channel_Flow_KE, refining prompt...
2025-03-20 15:54:13,663 - INFO - 

[Feedback]: The previous generated code had the following error:
Traceback (most recent call last):
  File "/opt/CFD-Benchmark/PDE_Benchmark_7/solver/gpt-4o/Fully_Developed_Turbulent_Channel_Flow_KE.py", line 100, in <module>
    main()
  File "/opt/CFD-Benchmark/PDE_Benchmark_7/solver/gpt-4o/Fully_Developed_Turbulent_Channel_Flow_KE.py", line 75, in main
    k = solve_linear_system(A_k, b_k)
  File "/opt/CFD-Benchmark/PDE_Benchmark_7/solver/gpt-4o/Fully_Developed_Turbulent_Channel_Flow_KE.py", line 55, in solve_linear_system
    return solve(A, b)
  File "/home/weichao/.local/lib/python3.8/site-packages/scipy/linalg/_basic.py", line 223, in solve
    _solve_check(n, info)
  File "/home/weichao/.local/lib/python3.8/site-packages/scipy/linalg/_basic.py", line 29, in _solve_check
    raise LinAlgError('Matrix is singular.')
numpy.linalg.LinAlgError: Matrix is singular.
Please correct it.
2025-03-20 15:54:13,663 - INFO - üîπ Generating code for: Fully_Developed_Turbulent_Channel_Flow_KE (Attempt 3/5)
