====== Execution Results for Generated Solvers ======

--- Running: 2D_Unsteady_Heat_Equation.py ---
Exit Code: 0
Output:

Errors:

--------------------------------------------------

--- Running: Fully_Developed_Turbulent_Channel_Flow.py ---
Exit Code: 0
Output:

Errors:
Error: failed to send plot to http://127.0.0.1:63342
Traceback (most recent call last):
  File "/home/weichao/Downloads/pycharm-2023.2.1/plugins/python/helpers/pycharm_display/datalore/display/display_.py", line 86, in _send_display_message
    urllib_request.urlopen(url, buffer)
  File "/opt/Dino_parallel/lib/python3.8/urllib/request.py", line 222, in urlopen
    return opener.open(url, data, timeout)
  File "/opt/Dino_parallel/lib/python3.8/urllib/request.py", line 531, in open
    response = meth(req, response)
  File "/opt/Dino_parallel/lib/python3.8/urllib/request.py", line 640, in http_response
    response = self.parent.error(
  File "/opt/Dino_parallel/lib/python3.8/urllib/request.py", line 569, in error
    return self._call_chain(*args)
  File "/opt/Dino_parallel/lib/python3.8/urllib/request.py", line 502, in _call_chain
    result = func(*args)
  File "/opt/Dino_parallel/lib/python3.8/urllib/request.py", line 649, in http_error_default
    raise HTTPError(req.full_url, code, msg, hdrs, fp)
urllib.error.HTTPError: HTTP Error 429: Too Many Requests

During handling of the above exception, another exception occurred:

Traceback (most recent call last):
  File "/home/weichao/Downloads/pycharm-2023.2.1/plugins/python/helpers/pycharm_display/datalore/display/display_.py", line 61, in try_empty_proxy
    urllib_request.urlopen(url, buffer)
  File "/opt/Dino_parallel/lib/python3.8/urllib/request.py", line 222, in urlopen
    return opener.open(url, data, timeout)
  File "/opt/Dino_parallel/lib/python3.8/urllib/request.py", line 531, in open
    response = meth(req, response)
  File "/opt/Dino_parallel/lib/python3.8/urllib/request.py", line 640, in http_response
    response = self.parent.error(
  File "/opt/Dino_parallel/lib/python3.8/urllib/request.py", line 569, in error
    return self._call_chain(*args)
  File "/opt/Dino_parallel/lib/python3.8/urllib/request.py", line 502, in _call_chain
    result = func(*args)
  File "/opt/Dino_parallel/lib/python3.8/urllib/request.py", line 649, in http_error_default
    raise HTTPError(req.full_url, code, msg, hdrs, fp)
urllib.error.HTTPError: HTTP Error 429: Too Many Requests

--------------------------------------------------

--- Running: 2D_Unsteady_Heat_Equation_2.py ---
Exit Code: 0
Output:

Errors:

--------------------------------------------------

--- Running: 2D_Diffusion.py ---
Exit Code: 0
Output:

Errors:
Error: failed to send plot to http://127.0.0.1:63342
Traceback (most recent call last):
  File "/home/weichao/Downloads/pycharm-2023.2.1/plugins/python/helpers/pycharm_display/datalore/display/display_.py", line 86, in _send_display_message
    urllib_request.urlopen(url, buffer)
  File "/opt/Dino_parallel/lib/python3.8/urllib/request.py", line 222, in urlopen
    return opener.open(url, data, timeout)
  File "/opt/Dino_parallel/lib/python3.8/urllib/request.py", line 531, in open
    response = meth(req, response)
  File "/opt/Dino_parallel/lib/python3.8/urllib/request.py", line 640, in http_response
    response = self.parent.error(
  File "/opt/Dino_parallel/lib/python3.8/urllib/request.py", line 569, in error
    return self._call_chain(*args)
  File "/opt/Dino_parallel/lib/python3.8/urllib/request.py", line 502, in _call_chain
    result = func(*args)
  File "/opt/Dino_parallel/lib/python3.8/urllib/request.py", line 649, in http_error_default
    raise HTTPError(req.full_url, code, msg, hdrs, fp)
urllib.error.HTTPError: HTTP Error 429: Too Many Requests

During handling of the above exception, another exception occurred:

Traceback (most recent call last):
  File "/home/weichao/Downloads/pycharm-2023.2.1/plugins/python/helpers/pycharm_display/datalore/display/display_.py", line 61, in try_empty_proxy
    urllib_request.urlopen(url, buffer)
  File "/opt/Dino_parallel/lib/python3.8/urllib/request.py", line 222, in urlopen
    return opener.open(url, data, timeout)
  File "/opt/Dino_parallel/lib/python3.8/urllib/request.py", line 531, in open
    response = meth(req, response)
  File "/opt/Dino_parallel/lib/python3.8/urllib/request.py", line 640, in http_response
    response = self.parent.error(
  File "/opt/Dino_parallel/lib/python3.8/urllib/request.py", line 569, in error
    return self._call_chain(*args)
  File "/opt/Dino_parallel/lib/python3.8/urllib/request.py", line 502, in _call_chain
    result = func(*args)
  File "/opt/Dino_parallel/lib/python3.8/urllib/request.py", line 649, in http_error_default
    raise HTTPError(req.full_url, code, msg, hdrs, fp)
urllib.error.HTTPError: HTTP Error 429: Too Many Requests
Error: failed to send plot to http://127.0.0.1:63342
Traceback (most recent call last):
  File "/home/weichao/Downloads/pycharm-2023.2.1/plugins/python/helpers/pycharm_display/datalore/display/display_.py", line 86, in _send_display_message
    urllib_request.urlopen(url, buffer)
  File "/opt/Dino_parallel/lib/python3.8/urllib/request.py", line 222, in urlopen
    return opener.open(url, data, timeout)
  File "/opt/Dino_parallel/lib/python3.8/urllib/request.py", line 531, in open
    response = meth(req, response)
  File "/opt/Dino_parallel/lib/python3.8/urllib/request.py", line 640, in http_response
    response = self.parent.error(
  File "/opt/Dino_parallel/lib/python3.8/urllib/request.py", line 569, in error
    return self._call_chain(*args)
  File "/opt/Dino_parallel/lib/python3.8/urllib/request.py", line 502, in _call_chain
    result = func(*args)
  File "/opt/Dino_parallel/lib/python3.8/urllib/request.py", line 649, in http_error_default
    raise HTTPError(req.full_url, code, msg, hdrs, fp)
urllib.error.HTTPError: HTTP Error 429: Too Many Requests

During handling of the above exception, another exception occurred:

Traceback (most recent call last):
  File "/home/weichao/Downloads/pycharm-2023.2.1/plugins/python/helpers/pycharm_display/datalore/display/display_.py", line 61, in try_empty_proxy
    urllib_request.urlopen(url, buffer)
  File "/opt/Dino_parallel/lib/python3.8/urllib/request.py", line 222, in urlopen
    return opener.open(url, data, timeout)
  File "/opt/Dino_parallel/lib/python3.8/urllib/request.py", line 531, in open
    response = meth(req, response)
  File "/opt/Dino_parallel/lib/python3.8/urllib/request.py", line 640, in http_response
    response = self.parent.error(
  File "/opt/Dino_parallel/lib/python3.8/urllib/request.py", line 569, in error
    return self._call_chain(*args)
  File "/opt/Dino_parallel/lib/python3.8/urllib/request.py", line 502, in _call_chain
    result = func(*args)
  File "/opt/Dino_parallel/lib/python3.8/urllib/request.py", line 649, in http_error_default
    raise HTTPError(req.full_url, code, msg, hdrs, fp)
urllib.error.HTTPError: HTTP Error 429: Too Many Requests
Error: failed to send plot to http://127.0.0.1:63342
Traceback (most recent call last):
  File "/home/weichao/Downloads/pycharm-2023.2.1/plugins/python/helpers/pycharm_display/datalore/display/display_.py", line 86, in _send_display_message
    urllib_request.urlopen(url, buffer)
  File "/opt/Dino_parallel/lib/python3.8/urllib/request.py", line 222, in urlopen
    return opener.open(url, data, timeout)
  File "/opt/Dino_parallel/lib/python3.8/urllib/request.py", line 531, in open
    response = meth(req, response)
  File "/opt/Dino_parallel/lib/python3.8/urllib/request.py", line 640, in http_response
    response = self.parent.error(
  File "/opt/Dino_parallel/lib/python3.8/urllib/request.py", line 569, in error
    return self._call_chain(*args)
  File "/opt/Dino_parallel/lib/python3.8/urllib/request.py", line 502, in _call_chain
    result = func(*args)
  File "/opt/Dino_parallel/lib/python3.8/urllib/request.py", line 649, in http_error_default
    raise HTTPError(req.full_url, code, msg, hdrs, fp)
urllib.error.HTTPError: HTTP Error 429: Too Many Requests

During handling of the above exception, another exception occurred:

Traceback (most recent call last):
  File "/home/weichao/Downloads/pycharm-2023.2.1/plugins/python/helpers/pycharm_display/datalore/display/display_.py", line 61, in try_empty_proxy
    urllib_request.urlopen(url, buffer)
  File "/opt/Dino_parallel/lib/python3.8/urllib/request.py", line 222, in urlopen
    return opener.open(url, data, timeout)
  File "/opt/Dino_parallel/lib/python3.8/urllib/request.py", line 531, in open
    response = meth(req, response)
  File "/opt/Dino_parallel/lib/python3.8/urllib/request.py", line 640, in http_response
    response = self.parent.error(
  File "/opt/Dino_parallel/lib/python3.8/urllib/request.py", line 569, in error
    return self._call_chain(*args)
  File "/opt/Dino_parallel/lib/python3.8/urllib/request.py", line 502, in _call_chain
    result = func(*args)
  File "/opt/Dino_parallel/lib/python3.8/urllib/request.py", line 649, in http_error_default
    raise HTTPError(req.full_url, code, msg, hdrs, fp)
urllib.error.HTTPError: HTTP Error 429: Too Many Requests
Error: failed to send plot to http://127.0.0.1:63342
Traceback (most recent call last):
  File "/home/weichao/Downloads/pycharm-2023.2.1/plugins/python/helpers/pycharm_display/datalore/display/display_.py", line 86, in _send_display_message
    urllib_request.urlopen(url, buffer)
  File "/opt/Dino_parallel/lib/python3.8/urllib/request.py", line 222, in urlopen
    return opener.open(url, data, timeout)
  File "/opt/Dino_parallel/lib/python3.8/urllib/request.py", line 531, in open
    response = meth(req, response)
  File "/opt/Dino_parallel/lib/python3.8/urllib/request.py", line 640, in http_response
    response = self.parent.error(
  File "/opt/Dino_parallel/lib/python3.8/urllib/request.py", line 569, in error
    return self._call_chain(*args)
  File "/opt/Dino_parallel/lib/python3.8/urllib/request.py", line 502, in _call_chain
    result = func(*args)
  File "/opt/Dino_parallel/lib/python3.8/urllib/request.py", line 649, in http_error_default
    raise HTTPError(req.full_url, code, msg, hdrs, fp)
urllib.error.HTTPError: HTTP Error 429: Too Many Requests

During handling of the above exception, another exception occurred:

Traceback (most recent call last):
  File "/home/weichao/Downloads/pycharm-2023.2.1/plugins/python/helpers/pycharm_display/datalore/display/display_.py", line 61, in try_empty_proxy
    urllib_request.urlopen(url, buffer)
  File "/opt/Dino_parallel/lib/python3.8/urllib/request.py", line 222, in urlopen
    return opener.open(url, data, timeout)
  File "/opt/Dino_parallel/lib/python3.8/urllib/request.py", line 531, in open
    response = meth(req, response)
  File "/opt/Dino_parallel/lib/python3.8/urllib/request.py", line 640, in http_response
    response = self.parent.error(
  File "/opt/Dino_parallel/lib/python3.8/urllib/request.py", line 569, in error
    return self._call_chain(*args)
  File "/opt/Dino_parallel/lib/python3.8/urllib/request.py", line 502, in _call_chain
    result = func(*args)
  File "/opt/Dino_parallel/lib/python3.8/urllib/request.py", line 649, in http_error_default
    raise HTTPError(req.full_url, code, msg, hdrs, fp)
urllib.error.HTTPError: HTTP Error 429: Too Many Requests
Error: failed to send plot to http://127.0.0.1:63342
Traceback (most recent call last):
  File "/home/weichao/Downloads/pycharm-2023.2.1/plugins/python/helpers/pycharm_display/datalore/display/display_.py", line 86, in _send_display_message
    urllib_request.urlopen(url, buffer)
  File "/opt/Dino_parallel/lib/python3.8/urllib/request.py", line 222, in urlopen
    return opener.open(url, data, timeout)
  File "/opt/Dino_parallel/lib/python3.8/urllib/request.py", line 531, in open
    response = meth(req, response)
  File "/opt/Dino_parallel/lib/python3.8/urllib/request.py", line 640, in http_response
    response = self.parent.error(
  File "/opt/Dino_parallel/lib/python3.8/urllib/request.py", line 569, in error
    return self._call_chain(*args)
  File "/opt/Dino_parallel/lib/python3.8/urllib/request.py", line 502, in _call_chain
    result = func(*args)
  File "/opt/Dino_parallel/lib/python3.8/urllib/request.py", line 649, in http_error_default
    raise HTTPError(req.full_url, code, msg, hdrs, fp)
urllib.error.HTTPError: HTTP Error 429: Too Many Requests

During handling of the above exception, another exception occurred:

Traceback (most recent call last):
  File "/home/weichao/Downloads/pycharm-2023.2.1/plugins/python/helpers/pycharm_display/datalore/display/display_.py", line 61, in try_empty_proxy
    urllib_request.urlopen(url, buffer)
  File "/opt/Dino_parallel/lib/python3.8/urllib/request.py", line 222, in urlopen
    return opener.open(url, data, timeout)
  File "/opt/Dino_parallel/lib/python3.8/urllib/request.py", line 531, in open
    response = meth(req, response)
  File "/opt/Dino_parallel/lib/python3.8/urllib/request.py", line 640, in http_response
    response = self.parent.error(
  File "/opt/Dino_parallel/lib/python3.8/urllib/request.py", line 569, in error
    return self._call_chain(*args)
  File "/opt/Dino_parallel/lib/python3.8/urllib/request.py", line 502, in _call_chain
    result = func(*args)
  File "/opt/Dino_parallel/lib/python3.8/urllib/request.py", line 649, in http_error_default
    raise HTTPError(req.full_url, code, msg, hdrs, fp)
urllib.error.HTTPError: HTTP Error 429: Too Many Requests
Error: failed to send plot to http://127.0.0.1:63342
Traceback (most recent call last):
  File "/home/weichao/Downloads/pycharm-2023.2.1/plugins/python/helpers/pycharm_display/datalore/display/display_.py", line 86, in _send_display_message
    urllib_request.urlopen(url, buffer)
  File "/opt/Dino_parallel/lib/python3.8/urllib/request.py", line 222, in urlopen
    return opener.open(url, data, timeout)
  File "/opt/Dino_parallel/lib/python3.8/urllib/request.py", line 531, in open
    response = meth(req, response)
  File "/opt/Dino_parallel/lib/python3.8/urllib/request.py", line 640, in http_response
    response = self.parent.error(
  File "/opt/Dino_parallel/lib/python3.8/urllib/request.py", line 569, in error
    return self._call_chain(*args)
  File "/opt/Dino_parallel/lib/python3.8/urllib/request.py", line 502, in _call_chain
    result = func(*args)
  File "/opt/Dino_parallel/lib/python3.8/urllib/request.py", line 649, in http_error_default
    raise HTTPError(req.full_url, code, msg, hdrs, fp)
urllib.error.HTTPError: HTTP Error 429: Too Many Requests

During handling of the above exception, another exception occurred:

Traceback (most recent call last):
  File "/home/weichao/Downloads/pycharm-2023.2.1/plugins/python/helpers/pycharm_display/datalore/display/display_.py", line 61, in try_empty_proxy
    urllib_request.urlopen(url, buffer)
  File "/opt/Dino_parallel/lib/python3.8/urllib/request.py", line 222, in urlopen
    return opener.open(url, data, timeout)
  File "/opt/Dino_parallel/lib/python3.8/urllib/request.py", line 531, in open
    response = meth(req, response)
  File "/opt/Dino_parallel/lib/python3.8/urllib/request.py", line 640, in http_response
    response = self.parent.error(
  File "/opt/Dino_parallel/lib/python3.8/urllib/request.py", line 569, in error
    return self._call_chain(*args)
  File "/opt/Dino_parallel/lib/python3.8/urllib/request.py", line 502, in _call_chain
    result = func(*args)
  File "/opt/Dino_parallel/lib/python3.8/urllib/request.py", line 649, in http_error_default
    raise HTTPError(req.full_url, code, msg, hdrs, fp)
urllib.error.HTTPError: HTTP Error 429: Too Many Requests
Error: failed to send plot to http://127.0.0.1:63342
Traceback (most recent call last):
  File "/home/weichao/Downloads/pycharm-2023.2.1/plugins/python/helpers/pycharm_display/datalore/display/display_.py", line 86, in _send_display_message
    urllib_request.urlopen(url, buffer)
  File "/opt/Dino_parallel/lib/python3.8/urllib/request.py", line 222, in urlopen
    return opener.open(url, data, timeout)
  File "/opt/Dino_parallel/lib/python3.8/urllib/request.py", line 531, in open
    response = meth(req, response)
  File "/opt/Dino_parallel/lib/python3.8/urllib/request.py", line 640, in http_response
    response = self.parent.error(
  File "/opt/Dino_parallel/lib/python3.8/urllib/request.py", line 569, in error
    return self._call_chain(*args)
  File "/opt/Dino_parallel/lib/python3.8/urllib/request.py", line 502, in _call_chain
    result = func(*args)
  File "/opt/Dino_parallel/lib/python3.8/urllib/request.py", line 649, in http_error_default
    raise HTTPError(req.full_url, code, msg, hdrs, fp)
urllib.error.HTTPError: HTTP Error 429: Too Many Requests

During handling of the above exception, another exception occurred:

Traceback (most recent call last):
  File "/home/weichao/Downloads/pycharm-2023.2.1/plugins/python/helpers/pycharm_display/datalore/display/display_.py", line 61, in try_empty_proxy
    urllib_request.urlopen(url, buffer)
  File "/opt/Dino_parallel/lib/python3.8/urllib/request.py", line 222, in urlopen
    return opener.open(url, data, timeout)
  File "/opt/Dino_parallel/lib/python3.8/urllib/request.py", line 531, in open
    response = meth(req, response)
  File "/opt/Dino_parallel/lib/python3.8/urllib/request.py", line 640, in http_response
    response = self.parent.error(
  File "/opt/Dino_parallel/lib/python3.8/urllib/request.py", line 569, in error
    return self._call_chain(*args)
  File "/opt/Dino_parallel/lib/python3.8/urllib/request.py", line 502, in _call_chain
    result = func(*args)
  File "/opt/Dino_parallel/lib/python3.8/urllib/request.py", line 649, in http_error_default
    raise HTTPError(req.full_url, code, msg, hdrs, fp)
urllib.error.HTTPError: HTTP Error 429: Too Many Requests
Error: failed to send plot to http://127.0.0.1:63342
Traceback (most recent call last):
  File "/home/weichao/Downloads/pycharm-2023.2.1/plugins/python/helpers/pycharm_display/datalore/display/display_.py", line 86, in _send_display_message
    urllib_request.urlopen(url, buffer)
  File "/opt/Dino_parallel/lib/python3.8/urllib/request.py", line 222, in urlopen
    return opener.open(url, data, timeout)
  File "/opt/Dino_parallel/lib/python3.8/urllib/request.py", line 531, in open
    response = meth(req, response)
  File "/opt/Dino_parallel/lib/python3.8/urllib/request.py", line 640, in http_response
    response = self.parent.error(
  File "/opt/Dino_parallel/lib/python3.8/urllib/request.py", line 569, in error
    return self._call_chain(*args)
  File "/opt/Dino_parallel/lib/python3.8/urllib/request.py", line 502, in _call_chain
    result = func(*args)
  File "/opt/Dino_parallel/lib/python3.8/urllib/request.py", line 649, in http_error_default
    raise HTTPError(req.full_url, code, msg, hdrs, fp)
urllib.error.HTTPError: HTTP Error 429: Too Many Requests

During handling of the above exception, another exception occurred:

Traceback (most recent call last):
  File "/home/weichao/Downloads/pycharm-2023.2.1/plugins/python/helpers/pycharm_display/datalore/display/display_.py", line 61, in try_empty_proxy
    urllib_request.urlopen(url, buffer)
  File "/opt/Dino_parallel/lib/python3.8/urllib/request.py", line 222, in urlopen
    return opener.open(url, data, timeout)
  File "/opt/Dino_parallel/lib/python3.8/urllib/request.py", line 531, in open
    response = meth(req, response)
  File "/opt/Dino_parallel/lib/python3.8/urllib/request.py", line 640, in http_response
    response = self.parent.error(
  File "/opt/Dino_parallel/lib/python3.8/urllib/request.py", line 569, in error
    return self._call_chain(*args)
  File "/opt/Dino_parallel/lib/python3.8/urllib/request.py", line 502, in _call_chain
    result = func(*args)
  File "/opt/Dino_parallel/lib/python3.8/urllib/request.py", line 649, in http_error_default
    raise HTTPError(req.full_url, code, msg, hdrs, fp)
urllib.error.HTTPError: HTTP Error 429: Too Many Requests
Error: failed to send plot to http://127.0.0.1:63342
Traceback (most recent call last):
  File "/home/weichao/Downloads/pycharm-2023.2.1/plugins/python/helpers/pycharm_display/datalore/display/display_.py", line 86, in _send_display_message
    urllib_request.urlopen(url, buffer)
  File "/opt/Dino_parallel/lib/python3.8/urllib/request.py", line 222, in urlopen
    return opener.open(url, data, timeout)
  File "/opt/Dino_parallel/lib/python3.8/urllib/request.py", line 531, in open
    response = meth(req, response)
  File "/opt/Dino_parallel/lib/python3.8/urllib/request.py", line 640, in http_response
    response = self.parent.error(
  File "/opt/Dino_parallel/lib/python3.8/urllib/request.py", line 569, in error
    return self._call_chain(*args)
  File "/opt/Dino_parallel/lib/python3.8/urllib/request.py", line 502, in _call_chain
    result = func(*args)
  File "/opt/Dino_parallel/lib/python3.8/urllib/request.py", line 649, in http_error_default
    raise HTTPError(req.full_url, code, msg, hdrs, fp)
urllib.error.HTTPError: HTTP Error 429: Too Many Requests

During handling of the above exception, another exception occurred:

Traceback (most recent call last):
  File "/home/weichao/Downloads/pycharm-2023.2.1/plugins/python/helpers/pycharm_display/datalore/display/display_.py", line 61, in try_empty_proxy
    urllib_request.urlopen(url, buffer)
  File "/opt/Dino_parallel/lib/python3.8/urllib/request.py", line 222, in urlopen
    return opener.open(url, data, timeout)
  File "/opt/Dino_parallel/lib/python3.8/urllib/request.py", line 531, in open
    response = meth(req, response)
  File "/opt/Dino_parallel/lib/python3.8/urllib/request.py", line 640, in http_response
    response = self.parent.error(
  File "/opt/Dino_parallel/lib/python3.8/urllib/request.py", line 569, in error
    return self._call_chain(*args)
  File "/opt/Dino_parallel/lib/python3.8/urllib/request.py", line 502, in _call_chain
    result = func(*args)
  File "/opt/Dino_parallel/lib/python3.8/urllib/request.py", line 649, in http_error_default
    raise HTTPError(req.full_url, code, msg, hdrs, fp)
urllib.error.HTTPError: HTTP Error 429: Too Many Requests
Error: failed to send plot to http://127.0.0.1:63342
Traceback (most recent call last):
  File "/home/weichao/Downloads/pycharm-2023.2.1/plugins/python/helpers/pycharm_display/datalore/display/display_.py", line 86, in _send_display_message
    urllib_request.urlopen(url, buffer)
  File "/opt/Dino_parallel/lib/python3.8/urllib/request.py", line 222, in urlopen
    return opener.open(url, data, timeout)
  File "/opt/Dino_parallel/lib/python3.8/urllib/request.py", line 531, in open
    response = meth(req, response)
  File "/opt/Dino_parallel/lib/python3.8/urllib/request.py", line 640, in http_response
    response = self.parent.error(
  File "/opt/Dino_parallel/lib/python3.8/urllib/request.py", line 569, in error
    return self._call_chain(*args)
  File "/opt/Dino_parallel/lib/python3.8/urllib/request.py", line 502, in _call_chain
    result = func(*args)
  File "/opt/Dino_parallel/lib/python3.8/urllib/request.py", line 649, in http_error_default
    raise HTTPError(req.full_url, code, msg, hdrs, fp)
urllib.error.HTTPError: HTTP Error 429: Too Many Requests

During handling of the above exception, another exception occurred:

Traceback (most recent call last):
  File "/home/weichao/Downloads/pycharm-2023.2.1/plugins/python/helpers/pycharm_display/datalore/display/display_.py", line 61, in try_empty_proxy
    urllib_request.urlopen(url, buffer)
  File "/opt/Dino_parallel/lib/python3.8/urllib/request.py", line 222, in urlopen
    return opener.open(url, data, timeout)
  File "/opt/Dino_parallel/lib/python3.8/urllib/request.py", line 531, in open
    response = meth(req, response)
  File "/opt/Dino_parallel/lib/python3.8/urllib/request.py", line 640, in http_response
    response = self.parent.error(
  File "/opt/Dino_parallel/lib/python3.8/urllib/request.py", line 569, in error
    return self._call_chain(*args)
  File "/opt/Dino_parallel/lib/python3.8/urllib/request.py", line 502, in _call_chain
    result = func(*args)
  File "/opt/Dino_parallel/lib/python3.8/urllib/request.py", line 649, in http_error_default
    raise HTTPError(req.full_url, code, msg, hdrs, fp)
urllib.error.HTTPError: HTTP Error 429: Too Many Requests

--------------------------------------------------

--- Running: 2D_Navier_Stokes_Cavity.py ---
Exit Code: 0
Output:

Errors:

--------------------------------------------------

--- Running: 1D_Linear_Convection.py ---
Exit Code: 0
Output:

Errors:

--------------------------------------------------

--- Running: 2D_Inviscid_Burgers.py ---
Exit Code: 0
Output:

Errors:
Error: failed to send plot to http://127.0.0.1:63342
Traceback (most recent call last):
  File "/home/weichao/Downloads/pycharm-2023.2.1/plugins/python/helpers/pycharm_display/datalore/display/display_.py", line 86, in _send_display_message
    urllib_request.urlopen(url, buffer)
  File "/opt/Dino_parallel/lib/python3.8/urllib/request.py", line 222, in urlopen
    return opener.open(url, data, timeout)
  File "/opt/Dino_parallel/lib/python3.8/urllib/request.py", line 531, in open
    response = meth(req, response)
  File "/opt/Dino_parallel/lib/python3.8/urllib/request.py", line 640, in http_response
    response = self.parent.error(
  File "/opt/Dino_parallel/lib/python3.8/urllib/request.py", line 569, in error
    return self._call_chain(*args)
  File "/opt/Dino_parallel/lib/python3.8/urllib/request.py", line 502, in _call_chain
    result = func(*args)
  File "/opt/Dino_parallel/lib/python3.8/urllib/request.py", line 649, in http_error_default
    raise HTTPError(req.full_url, code, msg, hdrs, fp)
urllib.error.HTTPError: HTTP Error 429: Too Many Requests

During handling of the above exception, another exception occurred:

Traceback (most recent call last):
  File "/home/weichao/Downloads/pycharm-2023.2.1/plugins/python/helpers/pycharm_display/datalore/display/display_.py", line 61, in try_empty_proxy
    urllib_request.urlopen(url, buffer)
  File "/opt/Dino_parallel/lib/python3.8/urllib/request.py", line 222, in urlopen
    return opener.open(url, data, timeout)
  File "/opt/Dino_parallel/lib/python3.8/urllib/request.py", line 531, in open
    response = meth(req, response)
  File "/opt/Dino_parallel/lib/python3.8/urllib/request.py", line 640, in http_response
    response = self.parent.error(
  File "/opt/Dino_parallel/lib/python3.8/urllib/request.py", line 569, in error
    return self._call_chain(*args)
  File "/opt/Dino_parallel/lib/python3.8/urllib/request.py", line 502, in _call_chain
    result = func(*args)
  File "/opt/Dino_parallel/lib/python3.8/urllib/request.py", line 649, in http_error_default
    raise HTTPError(req.full_url, code, msg, hdrs, fp)
urllib.error.HTTPError: HTTP Error 429: Too Many Requests

--------------------------------------------------

--- Running: 2D_Steady_Heat_Equation.py ---
Exit Code: 0
Output:
Converged in 214 iterations.

Errors:
Error: failed to send plot to http://127.0.0.1:63342
Traceback (most recent call last):
  File "/home/weichao/Downloads/pycharm-2023.2.1/plugins/python/helpers/pycharm_display/datalore/display/display_.py", line 86, in _send_display_message
    urllib_request.urlopen(url, buffer)
  File "/opt/Dino_parallel/lib/python3.8/urllib/request.py", line 222, in urlopen
    return opener.open(url, data, timeout)
  File "/opt/Dino_parallel/lib/python3.8/urllib/request.py", line 531, in open
    response = meth(req, response)
  File "/opt/Dino_parallel/lib/python3.8/urllib/request.py", line 640, in http_response
    response = self.parent.error(
  File "/opt/Dino_parallel/lib/python3.8/urllib/request.py", line 569, in error
    return self._call_chain(*args)
  File "/opt/Dino_parallel/lib/python3.8/urllib/request.py", line 502, in _call_chain
    result = func(*args)
  File "/opt/Dino_parallel/lib/python3.8/urllib/request.py", line 649, in http_error_default
    raise HTTPError(req.full_url, code, msg, hdrs, fp)
urllib.error.HTTPError: HTTP Error 429: Too Many Requests

During handling of the above exception, another exception occurred:

Traceback (most recent call last):
  File "/home/weichao/Downloads/pycharm-2023.2.1/plugins/python/helpers/pycharm_display/datalore/display/display_.py", line 61, in try_empty_proxy
    urllib_request.urlopen(url, buffer)
  File "/opt/Dino_parallel/lib/python3.8/urllib/request.py", line 222, in urlopen
    return opener.open(url, data, timeout)
  File "/opt/Dino_parallel/lib/python3.8/urllib/request.py", line 531, in open
    response = meth(req, response)
  File "/opt/Dino_parallel/lib/python3.8/urllib/request.py", line 640, in http_response
    response = self.parent.error(
  File "/opt/Dino_parallel/lib/python3.8/urllib/request.py", line 569, in error
    return self._call_chain(*args)
  File "/opt/Dino_parallel/lib/python3.8/urllib/request.py", line 502, in _call_chain
    result = func(*args)
  File "/opt/Dino_parallel/lib/python3.8/urllib/request.py", line 649, in http_error_default
    raise HTTPError(req.full_url, code, msg, hdrs, fp)
urllib.error.HTTPError: HTTP Error 429: Too Many Requests

--------------------------------------------------

--- Running: 2D_Unsteady_Heat_Equation_1.py ---
Exit Code: 0
Output:

Errors:

--------------------------------------------------

--- Running: 2D_Diffusion_FVM.py ---
Exit Code: 0
Output:

Errors:
Error: failed to send plot to http://127.0.0.1:63342
Traceback (most recent call last):
  File "/home/weichao/Downloads/pycharm-2023.2.1/plugins/python/helpers/pycharm_display/datalore/display/display_.py", line 86, in _send_display_message
    urllib_request.urlopen(url, buffer)
  File "/opt/Dino_parallel/lib/python3.8/urllib/request.py", line 222, in urlopen
    return opener.open(url, data, timeout)
  File "/opt/Dino_parallel/lib/python3.8/urllib/request.py", line 531, in open
    response = meth(req, response)
  File "/opt/Dino_parallel/lib/python3.8/urllib/request.py", line 640, in http_response
    response = self.parent.error(
  File "/opt/Dino_parallel/lib/python3.8/urllib/request.py", line 569, in error
    return self._call_chain(*args)
  File "/opt/Dino_parallel/lib/python3.8/urllib/request.py", line 502, in _call_chain
    result = func(*args)
  File "/opt/Dino_parallel/lib/python3.8/urllib/request.py", line 649, in http_error_default
    raise HTTPError(req.full_url, code, msg, hdrs, fp)
urllib.error.HTTPError: HTTP Error 429: Too Many Requests

During handling of the above exception, another exception occurred:

Traceback (most recent call last):
  File "/home/weichao/Downloads/pycharm-2023.2.1/plugins/python/helpers/pycharm_display/datalore/display/display_.py", line 61, in try_empty_proxy
    urllib_request.urlopen(url, buffer)
  File "/opt/Dino_parallel/lib/python3.8/urllib/request.py", line 222, in urlopen
    return opener.open(url, data, timeout)
  File "/opt/Dino_parallel/lib/python3.8/urllib/request.py", line 531, in open
    response = meth(req, response)
  File "/opt/Dino_parallel/lib/python3.8/urllib/request.py", line 640, in http_response
    response = self.parent.error(
  File "/opt/Dino_parallel/lib/python3.8/urllib/request.py", line 569, in error
    return self._call_chain(*args)
  File "/opt/Dino_parallel/lib/python3.8/urllib/request.py", line 502, in _call_chain
    result = func(*args)
  File "/opt/Dino_parallel/lib/python3.8/urllib/request.py", line 649, in http_error_default
    raise HTTPError(req.full_url, code, msg, hdrs, fp)
urllib.error.HTTPError: HTTP Error 429: Too Many Requests

--------------------------------------------------

--- Running: 2D_Convection.py ---
Exit Code: 0
Output:

Errors:
Error: failed to send plot to http://127.0.0.1:63342
Traceback (most recent call last):
  File "/home/weichao/Downloads/pycharm-2023.2.1/plugins/python/helpers/pycharm_display/datalore/display/display_.py", line 86, in _send_display_message
    urllib_request.urlopen(url, buffer)
  File "/opt/Dino_parallel/lib/python3.8/urllib/request.py", line 222, in urlopen
    return opener.open(url, data, timeout)
  File "/opt/Dino_parallel/lib/python3.8/urllib/request.py", line 531, in open
    response = meth(req, response)
  File "/opt/Dino_parallel/lib/python3.8/urllib/request.py", line 640, in http_response
    response = self.parent.error(
  File "/opt/Dino_parallel/lib/python3.8/urllib/request.py", line 569, in error
    return self._call_chain(*args)
  File "/opt/Dino_parallel/lib/python3.8/urllib/request.py", line 502, in _call_chain
    result = func(*args)
  File "/opt/Dino_parallel/lib/python3.8/urllib/request.py", line 649, in http_error_default
    raise HTTPError(req.full_url, code, msg, hdrs, fp)
urllib.error.HTTPError: HTTP Error 429: Too Many Requests

During handling of the above exception, another exception occurred:

Traceback (most recent call last):
  File "/home/weichao/Downloads/pycharm-2023.2.1/plugins/python/helpers/pycharm_display/datalore/display/display_.py", line 61, in try_empty_proxy
    urllib_request.urlopen(url, buffer)
  File "/opt/Dino_parallel/lib/python3.8/urllib/request.py", line 222, in urlopen
    return opener.open(url, data, timeout)
  File "/opt/Dino_parallel/lib/python3.8/urllib/request.py", line 531, in open
    response = meth(req, response)
  File "/opt/Dino_parallel/lib/python3.8/urllib/request.py", line 640, in http_response
    response = self.parent.error(
  File "/opt/Dino_parallel/lib/python3.8/urllib/request.py", line 569, in error
    return self._call_chain(*args)
  File "/opt/Dino_parallel/lib/python3.8/urllib/request.py", line 502, in _call_chain
    result = func(*args)
  File "/opt/Dino_parallel/lib/python3.8/urllib/request.py", line 649, in http_error_default
    raise HTTPError(req.full_url, code, msg, hdrs, fp)
urllib.error.HTTPError: HTTP Error 429: Too Many Requests

--------------------------------------------------

--- Running: 1D_Nonlinear_Convection.py ---
Exit Code: 0
Output:

Errors:
Error: failed to send plot to http://127.0.0.1:63342
Traceback (most recent call last):
  File "/home/weichao/Downloads/pycharm-2023.2.1/plugins/python/helpers/pycharm_display/datalore/display/display_.py", line 86, in _send_display_message
    urllib_request.urlopen(url, buffer)
  File "/opt/Dino_parallel/lib/python3.8/urllib/request.py", line 222, in urlopen
    return opener.open(url, data, timeout)
  File "/opt/Dino_parallel/lib/python3.8/urllib/request.py", line 531, in open
    response = meth(req, response)
  File "/opt/Dino_parallel/lib/python3.8/urllib/request.py", line 640, in http_response
    response = self.parent.error(
  File "/opt/Dino_parallel/lib/python3.8/urllib/request.py", line 569, in error
    return self._call_chain(*args)
  File "/opt/Dino_parallel/lib/python3.8/urllib/request.py", line 502, in _call_chain
    result = func(*args)
  File "/opt/Dino_parallel/lib/python3.8/urllib/request.py", line 649, in http_error_default
    raise HTTPError(req.full_url, code, msg, hdrs, fp)
urllib.error.HTTPError: HTTP Error 429: Too Many Requests

During handling of the above exception, another exception occurred:

Traceback (most recent call last):
  File "/home/weichao/Downloads/pycharm-2023.2.1/plugins/python/helpers/pycharm_display/datalore/display/display_.py", line 61, in try_empty_proxy
    urllib_request.urlopen(url, buffer)
  File "/opt/Dino_parallel/lib/python3.8/urllib/request.py", line 222, in urlopen
    return opener.open(url, data, timeout)
  File "/opt/Dino_parallel/lib/python3.8/urllib/request.py", line 531, in open
    response = meth(req, response)
  File "/opt/Dino_parallel/lib/python3.8/urllib/request.py", line 640, in http_response
    response = self.parent.error(
  File "/opt/Dino_parallel/lib/python3.8/urllib/request.py", line 569, in error
    return self._call_chain(*args)
  File "/opt/Dino_parallel/lib/python3.8/urllib/request.py", line 502, in _call_chain
    result = func(*args)
  File "/opt/Dino_parallel/lib/python3.8/urllib/request.py", line 649, in http_error_default
    raise HTTPError(req.full_url, code, msg, hdrs, fp)
urllib.error.HTTPError: HTTP Error 429: Too Many Requests

--------------------------------------------------

--- Running: 1D_Euler_Shock_Tube.py ---
Exit Code: 0
Output:

Errors:
/opt/CFD-Benchmark/PDE_Benchmark_5/solver_3/1D_Euler_Shock_Tube.py:38: RuntimeWarning: overflow encountered in square
  F_2 = ρ_u ** 2 / ρ + p
/opt/CFD-Benchmark/PDE_Benchmark_5/solver_3/1D_Euler_Shock_Tube.py:40: RuntimeWarning: invalid value encountered in subtract
  ρ_u[1:] = 0.5 * (ρ_u_old[1:] + ρ_u[1:] - dt / dx * (F_2[1:] - F_2[:-1]))
/opt/CFD-Benchmark/PDE_Benchmark_5/solver_3/1D_Euler_Shock_Tube.py:34: RuntimeWarning: invalid value encountered in subtract
  ρ_u[:-1] -= dt / dx * (F_2[1:] - F_2[:-1])
Error: failed to send plot to http://127.0.0.1:63342
Traceback (most recent call last):
  File "/home/weichao/Downloads/pycharm-2023.2.1/plugins/python/helpers/pycharm_display/datalore/display/display_.py", line 86, in _send_display_message
    urllib_request.urlopen(url, buffer)
  File "/opt/Dino_parallel/lib/python3.8/urllib/request.py", line 222, in urlopen
    return opener.open(url, data, timeout)
  File "/opt/Dino_parallel/lib/python3.8/urllib/request.py", line 531, in open
    response = meth(req, response)
  File "/opt/Dino_parallel/lib/python3.8/urllib/request.py", line 640, in http_response
    response = self.parent.error(
  File "/opt/Dino_parallel/lib/python3.8/urllib/request.py", line 569, in error
    return self._call_chain(*args)
  File "/opt/Dino_parallel/lib/python3.8/urllib/request.py", line 502, in _call_chain
    result = func(*args)
  File "/opt/Dino_parallel/lib/python3.8/urllib/request.py", line 649, in http_error_default
    raise HTTPError(req.full_url, code, msg, hdrs, fp)
urllib.error.HTTPError: HTTP Error 429: Too Many Requests

During handling of the above exception, another exception occurred:

Traceback (most recent call last):
  File "/home/weichao/Downloads/pycharm-2023.2.1/plugins/python/helpers/pycharm_display/datalore/display/display_.py", line 61, in try_empty_proxy
    urllib_request.urlopen(url, buffer)
  File "/opt/Dino_parallel/lib/python3.8/urllib/request.py", line 222, in urlopen
    return opener.open(url, data, timeout)
  File "/opt/Dino_parallel/lib/python3.8/urllib/request.py", line 531, in open
    response = meth(req, response)
  File "/opt/Dino_parallel/lib/python3.8/urllib/request.py", line 640, in http_response
    response = self.parent.error(
  File "/opt/Dino_parallel/lib/python3.8/urllib/request.py", line 569, in error
    return self._call_chain(*args)
  File "/opt/Dino_parallel/lib/python3.8/urllib/request.py", line 502, in _call_chain
    result = func(*args)
  File "/opt/Dino_parallel/lib/python3.8/urllib/request.py", line 649, in http_error_default
    raise HTTPError(req.full_url, code, msg, hdrs, fp)
urllib.error.HTTPError: HTTP Error 429: Too Many Requests

--------------------------------------------------

--- Running: 2D_Linear_Convection.py ---
Exit Code: 0
Output:

Errors:

--------------------------------------------------

--- Running: 2D_Laplace_Equation.py ---
Exit Code: 0
Output:

Errors:

--------------------------------------------------

--- Running: 1D_Burgers_Equation.py ---
Exit Code: 0
Output:

Errors:
Error: failed to send plot to http://127.0.0.1:63342
Traceback (most recent call last):
  File "/home/weichao/Downloads/pycharm-2023.2.1/plugins/python/helpers/pycharm_display/datalore/display/display_.py", line 86, in _send_display_message
    urllib_request.urlopen(url, buffer)
  File "/opt/Dino_parallel/lib/python3.8/urllib/request.py", line 222, in urlopen
    return opener.open(url, data, timeout)
  File "/opt/Dino_parallel/lib/python3.8/urllib/request.py", line 531, in open
    response = meth(req, response)
  File "/opt/Dino_parallel/lib/python3.8/urllib/request.py", line 640, in http_response
    response = self.parent.error(
  File "/opt/Dino_parallel/lib/python3.8/urllib/request.py", line 569, in error
    return self._call_chain(*args)
  File "/opt/Dino_parallel/lib/python3.8/urllib/request.py", line 502, in _call_chain
    result = func(*args)
  File "/opt/Dino_parallel/lib/python3.8/urllib/request.py", line 649, in http_error_default
    raise HTTPError(req.full_url, code, msg, hdrs, fp)
urllib.error.HTTPError: HTTP Error 429: Too Many Requests

During handling of the above exception, another exception occurred:

Traceback (most recent call last):
  File "/home/weichao/Downloads/pycharm-2023.2.1/plugins/python/helpers/pycharm_display/datalore/display/display_.py", line 61, in try_empty_proxy
    urllib_request.urlopen(url, buffer)
  File "/opt/Dino_parallel/lib/python3.8/urllib/request.py", line 222, in urlopen
    return opener.open(url, data, timeout)
  File "/opt/Dino_parallel/lib/python3.8/urllib/request.py", line 531, in open
    response = meth(req, response)
  File "/opt/Dino_parallel/lib/python3.8/urllib/request.py", line 640, in http_response
    response = self.parent.error(
  File "/opt/Dino_parallel/lib/python3.8/urllib/request.py", line 569, in error
    return self._call_chain(*args)
  File "/opt/Dino_parallel/lib/python3.8/urllib/request.py", line 502, in _call_chain
    result = func(*args)
  File "/opt/Dino_parallel/lib/python3.8/urllib/request.py", line 649, in http_error_default
    raise HTTPError(req.full_url, code, msg, hdrs, fp)
urllib.error.HTTPError: HTTP Error 429: Too Many Requests

--------------------------------------------------

