====== Execution Results for Generated Solvers ======

--- Running: 2D_Unsteady_Heat_Equation.py ---
Exit Code: 0
Output:

Errors:

--------------------------------------------------

--- Running: Fully_Developed_Turbulent_Channel_Flow.py ---
Exit Code: 0
Output:

Errors:

--------------------------------------------------

--- Running: 2D_Unsteady_Heat_Equation_2.py ---
Exit Code: 0
Output:

Errors:

--------------------------------------------------

--- Running: 2D_Diffusion.py ---
Exit Code: 0
Output:

Errors:

--------------------------------------------------

--- Running: 2D_Navier_Stokes_Cavity.py ---
Exit Code: 0
Output:

Errors:

--------------------------------------------------

--- Running: 1D_Linear_Convection.py ---
Exit Code: 0
Output:

Errors:
Error: failed to send plot to http://127.0.0.1:63342
Traceback (most recent call last):
  File "/home/weichao/Downloads/pycharm-2023.2.1/plugins/python/helpers/pycharm_display/datalore/display/display_.py", line 86, in _send_display_message
    urllib_request.urlopen(url, buffer)
  File "/opt/Dino_parallel/lib/python3.8/urllib/request.py", line 222, in urlopen
    return opener.open(url, data, timeout)
  File "/opt/Dino_parallel/lib/python3.8/urllib/request.py", line 531, in open
    response = meth(req, response)
  File "/opt/Dino_parallel/lib/python3.8/urllib/request.py", line 640, in http_response
    response = self.parent.error(
  File "/opt/Dino_parallel/lib/python3.8/urllib/request.py", line 569, in error
    return self._call_chain(*args)
  File "/opt/Dino_parallel/lib/python3.8/urllib/request.py", line 502, in _call_chain
    result = func(*args)
  File "/opt/Dino_parallel/lib/python3.8/urllib/request.py", line 649, in http_error_default
    raise HTTPError(req.full_url, code, msg, hdrs, fp)
urllib.error.HTTPError: HTTP Error 429: Too Many Requests

During handling of the above exception, another exception occurred:

Traceback (most recent call last):
  File "/home/weichao/Downloads/pycharm-2023.2.1/plugins/python/helpers/pycharm_display/datalore/display/display_.py", line 61, in try_empty_proxy
    urllib_request.urlopen(url, buffer)
  File "/opt/Dino_parallel/lib/python3.8/urllib/request.py", line 222, in urlopen
    return opener.open(url, data, timeout)
  File "/opt/Dino_parallel/lib/python3.8/urllib/request.py", line 531, in open
    response = meth(req, response)
  File "/opt/Dino_parallel/lib/python3.8/urllib/request.py", line 640, in http_response
    response = self.parent.error(
  File "/opt/Dino_parallel/lib/python3.8/urllib/request.py", line 569, in error
    return self._call_chain(*args)
  File "/opt/Dino_parallel/lib/python3.8/urllib/request.py", line 502, in _call_chain
    result = func(*args)
  File "/opt/Dino_parallel/lib/python3.8/urllib/request.py", line 649, in http_error_default
    raise HTTPError(req.full_url, code, msg, hdrs, fp)
urllib.error.HTTPError: HTTP Error 429: Too Many Requests

--------------------------------------------------

--- Running: 2D_Inviscid_Burgers.py ---
Exit Code: 0
Output:

Errors:
Error: failed to send plot to http://127.0.0.1:63342
Traceback (most recent call last):
  File "/home/weichao/Downloads/pycharm-2023.2.1/plugins/python/helpers/pycharm_display/datalore/display/display_.py", line 86, in _send_display_message
    urllib_request.urlopen(url, buffer)
  File "/opt/Dino_parallel/lib/python3.8/urllib/request.py", line 222, in urlopen
    return opener.open(url, data, timeout)
  File "/opt/Dino_parallel/lib/python3.8/urllib/request.py", line 531, in open
    response = meth(req, response)
  File "/opt/Dino_parallel/lib/python3.8/urllib/request.py", line 640, in http_response
    response = self.parent.error(
  File "/opt/Dino_parallel/lib/python3.8/urllib/request.py", line 569, in error
    return self._call_chain(*args)
  File "/opt/Dino_parallel/lib/python3.8/urllib/request.py", line 502, in _call_chain
    result = func(*args)
  File "/opt/Dino_parallel/lib/python3.8/urllib/request.py", line 649, in http_error_default
    raise HTTPError(req.full_url, code, msg, hdrs, fp)
urllib.error.HTTPError: HTTP Error 429: Too Many Requests

During handling of the above exception, another exception occurred:

Traceback (most recent call last):
  File "/home/weichao/Downloads/pycharm-2023.2.1/plugins/python/helpers/pycharm_display/datalore/display/display_.py", line 61, in try_empty_proxy
    urllib_request.urlopen(url, buffer)
  File "/opt/Dino_parallel/lib/python3.8/urllib/request.py", line 222, in urlopen
    return opener.open(url, data, timeout)
  File "/opt/Dino_parallel/lib/python3.8/urllib/request.py", line 531, in open
    response = meth(req, response)
  File "/opt/Dino_parallel/lib/python3.8/urllib/request.py", line 640, in http_response
    response = self.parent.error(
  File "/opt/Dino_parallel/lib/python3.8/urllib/request.py", line 569, in error
    return self._call_chain(*args)
  File "/opt/Dino_parallel/lib/python3.8/urllib/request.py", line 502, in _call_chain
    result = func(*args)
  File "/opt/Dino_parallel/lib/python3.8/urllib/request.py", line 649, in http_error_default
    raise HTTPError(req.full_url, code, msg, hdrs, fp)
urllib.error.HTTPError: HTTP Error 429: Too Many Requests

--------------------------------------------------

--- Running: 2D_Steady_Heat_Equation.py ---
Exit Code: 0
Output:

Errors:
Error: failed to send plot to http://127.0.0.1:63342
Traceback (most recent call last):
  File "/home/weichao/Downloads/pycharm-2023.2.1/plugins/python/helpers/pycharm_display/datalore/display/display_.py", line 86, in _send_display_message
    urllib_request.urlopen(url, buffer)
  File "/opt/Dino_parallel/lib/python3.8/urllib/request.py", line 222, in urlopen
    return opener.open(url, data, timeout)
  File "/opt/Dino_parallel/lib/python3.8/urllib/request.py", line 531, in open
    response = meth(req, response)
  File "/opt/Dino_parallel/lib/python3.8/urllib/request.py", line 640, in http_response
    response = self.parent.error(
  File "/opt/Dino_parallel/lib/python3.8/urllib/request.py", line 569, in error
    return self._call_chain(*args)
  File "/opt/Dino_parallel/lib/python3.8/urllib/request.py", line 502, in _call_chain
    result = func(*args)
  File "/opt/Dino_parallel/lib/python3.8/urllib/request.py", line 649, in http_error_default
    raise HTTPError(req.full_url, code, msg, hdrs, fp)
urllib.error.HTTPError: HTTP Error 429: Too Many Requests

During handling of the above exception, another exception occurred:

Traceback (most recent call last):
  File "/home/weichao/Downloads/pycharm-2023.2.1/plugins/python/helpers/pycharm_display/datalore/display/display_.py", line 61, in try_empty_proxy
    urllib_request.urlopen(url, buffer)
  File "/opt/Dino_parallel/lib/python3.8/urllib/request.py", line 222, in urlopen
    return opener.open(url, data, timeout)
  File "/opt/Dino_parallel/lib/python3.8/urllib/request.py", line 531, in open
    response = meth(req, response)
  File "/opt/Dino_parallel/lib/python3.8/urllib/request.py", line 640, in http_response
    response = self.parent.error(
  File "/opt/Dino_parallel/lib/python3.8/urllib/request.py", line 569, in error
    return self._call_chain(*args)
  File "/opt/Dino_parallel/lib/python3.8/urllib/request.py", line 502, in _call_chain
    result = func(*args)
  File "/opt/Dino_parallel/lib/python3.8/urllib/request.py", line 649, in http_error_default
    raise HTTPError(req.full_url, code, msg, hdrs, fp)
urllib.error.HTTPError: HTTP Error 429: Too Many Requests

--------------------------------------------------

--- Running: 2D_Unsteady_Heat_Equation_1.py ---
Exit Code: 0
Output:

Errors:
Error: failed to send plot to http://127.0.0.1:63342
Traceback (most recent call last):
  File "/home/weichao/Downloads/pycharm-2023.2.1/plugins/python/helpers/pycharm_display/datalore/display/display_.py", line 86, in _send_display_message
    urllib_request.urlopen(url, buffer)
  File "/opt/Dino_parallel/lib/python3.8/urllib/request.py", line 222, in urlopen
    return opener.open(url, data, timeout)
  File "/opt/Dino_parallel/lib/python3.8/urllib/request.py", line 531, in open
    response = meth(req, response)
  File "/opt/Dino_parallel/lib/python3.8/urllib/request.py", line 640, in http_response
    response = self.parent.error(
  File "/opt/Dino_parallel/lib/python3.8/urllib/request.py", line 569, in error
    return self._call_chain(*args)
  File "/opt/Dino_parallel/lib/python3.8/urllib/request.py", line 502, in _call_chain
    result = func(*args)
  File "/opt/Dino_parallel/lib/python3.8/urllib/request.py", line 649, in http_error_default
    raise HTTPError(req.full_url, code, msg, hdrs, fp)
urllib.error.HTTPError: HTTP Error 429: Too Many Requests

During handling of the above exception, another exception occurred:

Traceback (most recent call last):
  File "/home/weichao/Downloads/pycharm-2023.2.1/plugins/python/helpers/pycharm_display/datalore/display/display_.py", line 61, in try_empty_proxy
    urllib_request.urlopen(url, buffer)
  File "/opt/Dino_parallel/lib/python3.8/urllib/request.py", line 222, in urlopen
    return opener.open(url, data, timeout)
  File "/opt/Dino_parallel/lib/python3.8/urllib/request.py", line 531, in open
    response = meth(req, response)
  File "/opt/Dino_parallel/lib/python3.8/urllib/request.py", line 640, in http_response
    response = self.parent.error(
  File "/opt/Dino_parallel/lib/python3.8/urllib/request.py", line 569, in error
    return self._call_chain(*args)
  File "/opt/Dino_parallel/lib/python3.8/urllib/request.py", line 502, in _call_chain
    result = func(*args)
  File "/opt/Dino_parallel/lib/python3.8/urllib/request.py", line 649, in http_error_default
    raise HTTPError(req.full_url, code, msg, hdrs, fp)
urllib.error.HTTPError: HTTP Error 429: Too Many Requests
Error: failed to send plot to http://127.0.0.1:63342
Traceback (most recent call last):
  File "/home/weichao/Downloads/pycharm-2023.2.1/plugins/python/helpers/pycharm_display/datalore/display/display_.py", line 86, in _send_display_message
    urllib_request.urlopen(url, buffer)
  File "/opt/Dino_parallel/lib/python3.8/urllib/request.py", line 222, in urlopen
    return opener.open(url, data, timeout)
  File "/opt/Dino_parallel/lib/python3.8/urllib/request.py", line 531, in open
    response = meth(req, response)
  File "/opt/Dino_parallel/lib/python3.8/urllib/request.py", line 640, in http_response
    response = self.parent.error(
  File "/opt/Dino_parallel/lib/python3.8/urllib/request.py", line 569, in error
    return self._call_chain(*args)
  File "/opt/Dino_parallel/lib/python3.8/urllib/request.py", line 502, in _call_chain
    result = func(*args)
  File "/opt/Dino_parallel/lib/python3.8/urllib/request.py", line 649, in http_error_default
    raise HTTPError(req.full_url, code, msg, hdrs, fp)
urllib.error.HTTPError: HTTP Error 429: Too Many Requests

During handling of the above exception, another exception occurred:

Traceback (most recent call last):
  File "/home/weichao/Downloads/pycharm-2023.2.1/plugins/python/helpers/pycharm_display/datalore/display/display_.py", line 61, in try_empty_proxy
    urllib_request.urlopen(url, buffer)
  File "/opt/Dino_parallel/lib/python3.8/urllib/request.py", line 222, in urlopen
    return opener.open(url, data, timeout)
  File "/opt/Dino_parallel/lib/python3.8/urllib/request.py", line 531, in open
    response = meth(req, response)
  File "/opt/Dino_parallel/lib/python3.8/urllib/request.py", line 640, in http_response
    response = self.parent.error(
  File "/opt/Dino_parallel/lib/python3.8/urllib/request.py", line 569, in error
    return self._call_chain(*args)
  File "/opt/Dino_parallel/lib/python3.8/urllib/request.py", line 502, in _call_chain
    result = func(*args)
  File "/opt/Dino_parallel/lib/python3.8/urllib/request.py", line 649, in http_error_default
    raise HTTPError(req.full_url, code, msg, hdrs, fp)
urllib.error.HTTPError: HTTP Error 429: Too Many Requests
Error: failed to send plot to http://127.0.0.1:63342
Traceback (most recent call last):
  File "/home/weichao/Downloads/pycharm-2023.2.1/plugins/python/helpers/pycharm_display/datalore/display/display_.py", line 86, in _send_display_message
    urllib_request.urlopen(url, buffer)
  File "/opt/Dino_parallel/lib/python3.8/urllib/request.py", line 222, in urlopen
    return opener.open(url, data, timeout)
  File "/opt/Dino_parallel/lib/python3.8/urllib/request.py", line 531, in open
    response = meth(req, response)
  File "/opt/Dino_parallel/lib/python3.8/urllib/request.py", line 640, in http_response
    response = self.parent.error(
  File "/opt/Dino_parallel/lib/python3.8/urllib/request.py", line 569, in error
    return self._call_chain(*args)
  File "/opt/Dino_parallel/lib/python3.8/urllib/request.py", line 502, in _call_chain
    result = func(*args)
  File "/opt/Dino_parallel/lib/python3.8/urllib/request.py", line 649, in http_error_default
    raise HTTPError(req.full_url, code, msg, hdrs, fp)
urllib.error.HTTPError: HTTP Error 429: Too Many Requests

During handling of the above exception, another exception occurred:

Traceback (most recent call last):
  File "/home/weichao/Downloads/pycharm-2023.2.1/plugins/python/helpers/pycharm_display/datalore/display/display_.py", line 61, in try_empty_proxy
    urllib_request.urlopen(url, buffer)
  File "/opt/Dino_parallel/lib/python3.8/urllib/request.py", line 222, in urlopen
    return opener.open(url, data, timeout)
  File "/opt/Dino_parallel/lib/python3.8/urllib/request.py", line 531, in open
    response = meth(req, response)
  File "/opt/Dino_parallel/lib/python3.8/urllib/request.py", line 640, in http_response
    response = self.parent.error(
  File "/opt/Dino_parallel/lib/python3.8/urllib/request.py", line 569, in error
    return self._call_chain(*args)
  File "/opt/Dino_parallel/lib/python3.8/urllib/request.py", line 502, in _call_chain
    result = func(*args)
  File "/opt/Dino_parallel/lib/python3.8/urllib/request.py", line 649, in http_error_default
    raise HTTPError(req.full_url, code, msg, hdrs, fp)
urllib.error.HTTPError: HTTP Error 429: Too Many Requests
Error: failed to send plot to http://127.0.0.1:63342
Traceback (most recent call last):
  File "/home/weichao/Downloads/pycharm-2023.2.1/plugins/python/helpers/pycharm_display/datalore/display/display_.py", line 86, in _send_display_message
    urllib_request.urlopen(url, buffer)
  File "/opt/Dino_parallel/lib/python3.8/urllib/request.py", line 222, in urlopen
    return opener.open(url, data, timeout)
  File "/opt/Dino_parallel/lib/python3.8/urllib/request.py", line 531, in open
    response = meth(req, response)
  File "/opt/Dino_parallel/lib/python3.8/urllib/request.py", line 640, in http_response
    response = self.parent.error(
  File "/opt/Dino_parallel/lib/python3.8/urllib/request.py", line 569, in error
    return self._call_chain(*args)
  File "/opt/Dino_parallel/lib/python3.8/urllib/request.py", line 502, in _call_chain
    result = func(*args)
  File "/opt/Dino_parallel/lib/python3.8/urllib/request.py", line 649, in http_error_default
    raise HTTPError(req.full_url, code, msg, hdrs, fp)
urllib.error.HTTPError: HTTP Error 429: Too Many Requests

During handling of the above exception, another exception occurred:

Traceback (most recent call last):
  File "/home/weichao/Downloads/pycharm-2023.2.1/plugins/python/helpers/pycharm_display/datalore/display/display_.py", line 61, in try_empty_proxy
    urllib_request.urlopen(url, buffer)
  File "/opt/Dino_parallel/lib/python3.8/urllib/request.py", line 222, in urlopen
    return opener.open(url, data, timeout)
  File "/opt/Dino_parallel/lib/python3.8/urllib/request.py", line 531, in open
    response = meth(req, response)
  File "/opt/Dino_parallel/lib/python3.8/urllib/request.py", line 640, in http_response
    response = self.parent.error(
  File "/opt/Dino_parallel/lib/python3.8/urllib/request.py", line 569, in error
    return self._call_chain(*args)
  File "/opt/Dino_parallel/lib/python3.8/urllib/request.py", line 502, in _call_chain
    result = func(*args)
  File "/opt/Dino_parallel/lib/python3.8/urllib/request.py", line 649, in http_error_default
    raise HTTPError(req.full_url, code, msg, hdrs, fp)
urllib.error.HTTPError: HTTP Error 429: Too Many Requests
Error: failed to send plot to http://127.0.0.1:63342
Traceback (most recent call last):
  File "/home/weichao/Downloads/pycharm-2023.2.1/plugins/python/helpers/pycharm_display/datalore/display/display_.py", line 86, in _send_display_message
    urllib_request.urlopen(url, buffer)
  File "/opt/Dino_parallel/lib/python3.8/urllib/request.py", line 222, in urlopen
    return opener.open(url, data, timeout)
  File "/opt/Dino_parallel/lib/python3.8/urllib/request.py", line 531, in open
    response = meth(req, response)
  File "/opt/Dino_parallel/lib/python3.8/urllib/request.py", line 640, in http_response
    response = self.parent.error(
  File "/opt/Dino_parallel/lib/python3.8/urllib/request.py", line 569, in error
    return self._call_chain(*args)
  File "/opt/Dino_parallel/lib/python3.8/urllib/request.py", line 502, in _call_chain
    result = func(*args)
  File "/opt/Dino_parallel/lib/python3.8/urllib/request.py", line 649, in http_error_default
    raise HTTPError(req.full_url, code, msg, hdrs, fp)
urllib.error.HTTPError: HTTP Error 429: Too Many Requests

During handling of the above exception, another exception occurred:

Traceback (most recent call last):
  File "/home/weichao/Downloads/pycharm-2023.2.1/plugins/python/helpers/pycharm_display/datalore/display/display_.py", line 61, in try_empty_proxy
    urllib_request.urlopen(url, buffer)
  File "/opt/Dino_parallel/lib/python3.8/urllib/request.py", line 222, in urlopen
    return opener.open(url, data, timeout)
  File "/opt/Dino_parallel/lib/python3.8/urllib/request.py", line 531, in open
    response = meth(req, response)
  File "/opt/Dino_parallel/lib/python3.8/urllib/request.py", line 640, in http_response
    response = self.parent.error(
  File "/opt/Dino_parallel/lib/python3.8/urllib/request.py", line 569, in error
    return self._call_chain(*args)
  File "/opt/Dino_parallel/lib/python3.8/urllib/request.py", line 502, in _call_chain
    result = func(*args)
  File "/opt/Dino_parallel/lib/python3.8/urllib/request.py", line 649, in http_error_default
    raise HTTPError(req.full_url, code, msg, hdrs, fp)
urllib.error.HTTPError: HTTP Error 429: Too Many Requests
Error: failed to send plot to http://127.0.0.1:63342
Traceback (most recent call last):
  File "/home/weichao/Downloads/pycharm-2023.2.1/plugins/python/helpers/pycharm_display/datalore/display/display_.py", line 86, in _send_display_message
    urllib_request.urlopen(url, buffer)
  File "/opt/Dino_parallel/lib/python3.8/urllib/request.py", line 222, in urlopen
    return opener.open(url, data, timeout)
  File "/opt/Dino_parallel/lib/python3.8/urllib/request.py", line 531, in open
    response = meth(req, response)
  File "/opt/Dino_parallel/lib/python3.8/urllib/request.py", line 640, in http_response
    response = self.parent.error(
  File "/opt/Dino_parallel/lib/python3.8/urllib/request.py", line 569, in error
    return self._call_chain(*args)
  File "/opt/Dino_parallel/lib/python3.8/urllib/request.py", line 502, in _call_chain
    result = func(*args)
  File "/opt/Dino_parallel/lib/python3.8/urllib/request.py", line 649, in http_error_default
    raise HTTPError(req.full_url, code, msg, hdrs, fp)
urllib.error.HTTPError: HTTP Error 429: Too Many Requests

During handling of the above exception, another exception occurred:

Traceback (most recent call last):
  File "/home/weichao/Downloads/pycharm-2023.2.1/plugins/python/helpers/pycharm_display/datalore/display/display_.py", line 61, in try_empty_proxy
    urllib_request.urlopen(url, buffer)
  File "/opt/Dino_parallel/lib/python3.8/urllib/request.py", line 222, in urlopen
    return opener.open(url, data, timeout)
  File "/opt/Dino_parallel/lib/python3.8/urllib/request.py", line 531, in open
    response = meth(req, response)
  File "/opt/Dino_parallel/lib/python3.8/urllib/request.py", line 640, in http_response
    response = self.parent.error(
  File "/opt/Dino_parallel/lib/python3.8/urllib/request.py", line 569, in error
    return self._call_chain(*args)
  File "/opt/Dino_parallel/lib/python3.8/urllib/request.py", line 502, in _call_chain
    result = func(*args)
  File "/opt/Dino_parallel/lib/python3.8/urllib/request.py", line 649, in http_error_default
    raise HTTPError(req.full_url, code, msg, hdrs, fp)
urllib.error.HTTPError: HTTP Error 429: Too Many Requests
Error: failed to send plot to http://127.0.0.1:63342
Traceback (most recent call last):
  File "/home/weichao/Downloads/pycharm-2023.2.1/plugins/python/helpers/pycharm_display/datalore/display/display_.py", line 86, in _send_display_message
    urllib_request.urlopen(url, buffer)
  File "/opt/Dino_parallel/lib/python3.8/urllib/request.py", line 222, in urlopen
    return opener.open(url, data, timeout)
  File "/opt/Dino_parallel/lib/python3.8/urllib/request.py", line 531, in open
    response = meth(req, response)
  File "/opt/Dino_parallel/lib/python3.8/urllib/request.py", line 640, in http_response
    response = self.parent.error(
  File "/opt/Dino_parallel/lib/python3.8/urllib/request.py", line 569, in error
    return self._call_chain(*args)
  File "/opt/Dino_parallel/lib/python3.8/urllib/request.py", line 502, in _call_chain
    result = func(*args)
  File "/opt/Dino_parallel/lib/python3.8/urllib/request.py", line 649, in http_error_default
    raise HTTPError(req.full_url, code, msg, hdrs, fp)
urllib.error.HTTPError: HTTP Error 429: Too Many Requests

During handling of the above exception, another exception occurred:

Traceback (most recent call last):
  File "/home/weichao/Downloads/pycharm-2023.2.1/plugins/python/helpers/pycharm_display/datalore/display/display_.py", line 61, in try_empty_proxy
    urllib_request.urlopen(url, buffer)
  File "/opt/Dino_parallel/lib/python3.8/urllib/request.py", line 222, in urlopen
    return opener.open(url, data, timeout)
  File "/opt/Dino_parallel/lib/python3.8/urllib/request.py", line 531, in open
    response = meth(req, response)
  File "/opt/Dino_parallel/lib/python3.8/urllib/request.py", line 640, in http_response
    response = self.parent.error(
  File "/opt/Dino_parallel/lib/python3.8/urllib/request.py", line 569, in error
    return self._call_chain(*args)
  File "/opt/Dino_parallel/lib/python3.8/urllib/request.py", line 502, in _call_chain
    result = func(*args)
  File "/opt/Dino_parallel/lib/python3.8/urllib/request.py", line 649, in http_error_default
    raise HTTPError(req.full_url, code, msg, hdrs, fp)
urllib.error.HTTPError: HTTP Error 429: Too Many Requests
Error: failed to send plot to http://127.0.0.1:63342
Traceback (most recent call last):
  File "/home/weichao/Downloads/pycharm-2023.2.1/plugins/python/helpers/pycharm_display/datalore/display/display_.py", line 86, in _send_display_message
    urllib_request.urlopen(url, buffer)
  File "/opt/Dino_parallel/lib/python3.8/urllib/request.py", line 222, in urlopen
    return opener.open(url, data, timeout)
  File "/opt/Dino_parallel/lib/python3.8/urllib/request.py", line 531, in open
    response = meth(req, response)
  File "/opt/Dino_parallel/lib/python3.8/urllib/request.py", line 640, in http_response
    response = self.parent.error(
  File "/opt/Dino_parallel/lib/python3.8/urllib/request.py", line 569, in error
    return self._call_chain(*args)
  File "/opt/Dino_parallel/lib/python3.8/urllib/request.py", line 502, in _call_chain
    result = func(*args)
  File "/opt/Dino_parallel/lib/python3.8/urllib/request.py", line 649, in http_error_default
    raise HTTPError(req.full_url, code, msg, hdrs, fp)
urllib.error.HTTPError: HTTP Error 429: Too Many Requests

During handling of the above exception, another exception occurred:

Traceback (most recent call last):
  File "/home/weichao/Downloads/pycharm-2023.2.1/plugins/python/helpers/pycharm_display/datalore/display/display_.py", line 61, in try_empty_proxy
    urllib_request.urlopen(url, buffer)
  File "/opt/Dino_parallel/lib/python3.8/urllib/request.py", line 222, in urlopen
    return opener.open(url, data, timeout)
  File "/opt/Dino_parallel/lib/python3.8/urllib/request.py", line 531, in open
    response = meth(req, response)
  File "/opt/Dino_parallel/lib/python3.8/urllib/request.py", line 640, in http_response
    response = self.parent.error(
  File "/opt/Dino_parallel/lib/python3.8/urllib/request.py", line 569, in error
    return self._call_chain(*args)
  File "/opt/Dino_parallel/lib/python3.8/urllib/request.py", line 502, in _call_chain
    result = func(*args)
  File "/opt/Dino_parallel/lib/python3.8/urllib/request.py", line 649, in http_error_default
    raise HTTPError(req.full_url, code, msg, hdrs, fp)
urllib.error.HTTPError: HTTP Error 429: Too Many Requests
Error: failed to send plot to http://127.0.0.1:63342
Traceback (most recent call last):
  File "/home/weichao/Downloads/pycharm-2023.2.1/plugins/python/helpers/pycharm_display/datalore/display/display_.py", line 86, in _send_display_message
    urllib_request.urlopen(url, buffer)
  File "/opt/Dino_parallel/lib/python3.8/urllib/request.py", line 222, in urlopen
    return opener.open(url, data, timeout)
  File "/opt/Dino_parallel/lib/python3.8/urllib/request.py", line 531, in open
    response = meth(req, response)
  File "/opt/Dino_parallel/lib/python3.8/urllib/request.py", line 640, in http_response
    response = self.parent.error(
  File "/opt/Dino_parallel/lib/python3.8/urllib/request.py", line 569, in error
    return self._call_chain(*args)
  File "/opt/Dino_parallel/lib/python3.8/urllib/request.py", line 502, in _call_chain
    result = func(*args)
  File "/opt/Dino_parallel/lib/python3.8/urllib/request.py", line 649, in http_error_default
    raise HTTPError(req.full_url, code, msg, hdrs, fp)
urllib.error.HTTPError: HTTP Error 429: Too Many Requests

During handling of the above exception, another exception occurred:

Traceback (most recent call last):
  File "/home/weichao/Downloads/pycharm-2023.2.1/plugins/python/helpers/pycharm_display/datalore/display/display_.py", line 61, in try_empty_proxy
    urllib_request.urlopen(url, buffer)
  File "/opt/Dino_parallel/lib/python3.8/urllib/request.py", line 222, in urlopen
    return opener.open(url, data, timeout)
  File "/opt/Dino_parallel/lib/python3.8/urllib/request.py", line 531, in open
    response = meth(req, response)
  File "/opt/Dino_parallel/lib/python3.8/urllib/request.py", line 640, in http_response
    response = self.parent.error(
  File "/opt/Dino_parallel/lib/python3.8/urllib/request.py", line 569, in error
    return self._call_chain(*args)
  File "/opt/Dino_parallel/lib/python3.8/urllib/request.py", line 502, in _call_chain
    result = func(*args)
  File "/opt/Dino_parallel/lib/python3.8/urllib/request.py", line 649, in http_error_default
    raise HTTPError(req.full_url, code, msg, hdrs, fp)
urllib.error.HTTPError: HTTP Error 429: Too Many Requests
Error: failed to send plot to http://127.0.0.1:63342
Traceback (most recent call last):
  File "/home/weichao/Downloads/pycharm-2023.2.1/plugins/python/helpers/pycharm_display/datalore/display/display_.py", line 86, in _send_display_message
    urllib_request.urlopen(url, buffer)
  File "/opt/Dino_parallel/lib/python3.8/urllib/request.py", line 222, in urlopen
    return opener.open(url, data, timeout)
  File "/opt/Dino_parallel/lib/python3.8/urllib/request.py", line 531, in open
    response = meth(req, response)
  File "/opt/Dino_parallel/lib/python3.8/urllib/request.py", line 640, in http_response
    response = self.parent.error(
  File "/opt/Dino_parallel/lib/python3.8/urllib/request.py", line 569, in error
    return self._call_chain(*args)
  File "/opt/Dino_parallel/lib/python3.8/urllib/request.py", line 502, in _call_chain
    result = func(*args)
  File "/opt/Dino_parallel/lib/python3.8/urllib/request.py", line 649, in http_error_default
    raise HTTPError(req.full_url, code, msg, hdrs, fp)
urllib.error.HTTPError: HTTP Error 429: Too Many Requests

During handling of the above exception, another exception occurred:

Traceback (most recent call last):
  File "/home/weichao/Downloads/pycharm-2023.2.1/plugins/python/helpers/pycharm_display/datalore/display/display_.py", line 61, in try_empty_proxy
    urllib_request.urlopen(url, buffer)
  File "/opt/Dino_parallel/lib/python3.8/urllib/request.py", line 222, in urlopen
    return opener.open(url, data, timeout)
  File "/opt/Dino_parallel/lib/python3.8/urllib/request.py", line 531, in open
    response = meth(req, response)
  File "/opt/Dino_parallel/lib/python3.8/urllib/request.py", line 640, in http_response
    response = self.parent.error(
  File "/opt/Dino_parallel/lib/python3.8/urllib/request.py", line 569, in error
    return self._call_chain(*args)
  File "/opt/Dino_parallel/lib/python3.8/urllib/request.py", line 502, in _call_chain
    result = func(*args)
  File "/opt/Dino_parallel/lib/python3.8/urllib/request.py", line 649, in http_error_default
    raise HTTPError(req.full_url, code, msg, hdrs, fp)
urllib.error.HTTPError: HTTP Error 429: Too Many Requests
Error: failed to send plot to http://127.0.0.1:63342
Traceback (most recent call last):
  File "/home/weichao/Downloads/pycharm-2023.2.1/plugins/python/helpers/pycharm_display/datalore/display/display_.py", line 86, in _send_display_message
    urllib_request.urlopen(url, buffer)
  File "/opt/Dino_parallel/lib/python3.8/urllib/request.py", line 222, in urlopen
    return opener.open(url, data, timeout)
  File "/opt/Dino_parallel/lib/python3.8/urllib/request.py", line 531, in open
    response = meth(req, response)
  File "/opt/Dino_parallel/lib/python3.8/urllib/request.py", line 640, in http_response
    response = self.parent.error(
  File "/opt/Dino_parallel/lib/python3.8/urllib/request.py", line 569, in error
    return self._call_chain(*args)
  File "/opt/Dino_parallel/lib/python3.8/urllib/request.py", line 502, in _call_chain
    result = func(*args)
  File "/opt/Dino_parallel/lib/python3.8/urllib/request.py", line 649, in http_error_default
    raise HTTPError(req.full_url, code, msg, hdrs, fp)
urllib.error.HTTPError: HTTP Error 429: Too Many Requests

During handling of the above exception, another exception occurred:

Traceback (most recent call last):
  File "/home/weichao/Downloads/pycharm-2023.2.1/plugins/python/helpers/pycharm_display/datalore/display/display_.py", line 61, in try_empty_proxy
    urllib_request.urlopen(url, buffer)
  File "/opt/Dino_parallel/lib/python3.8/urllib/request.py", line 222, in urlopen
    return opener.open(url, data, timeout)
  File "/opt/Dino_parallel/lib/python3.8/urllib/request.py", line 531, in open
    response = meth(req, response)
  File "/opt/Dino_parallel/lib/python3.8/urllib/request.py", line 640, in http_response
    response = self.parent.error(
  File "/opt/Dino_parallel/lib/python3.8/urllib/request.py", line 569, in error
    return self._call_chain(*args)
  File "/opt/Dino_parallel/lib/python3.8/urllib/request.py", line 502, in _call_chain
    result = func(*args)
  File "/opt/Dino_parallel/lib/python3.8/urllib/request.py", line 649, in http_error_default
    raise HTTPError(req.full_url, code, msg, hdrs, fp)
urllib.error.HTTPError: HTTP Error 429: Too Many Requests
Error: failed to send plot to http://127.0.0.1:63342
Traceback (most recent call last):
  File "/home/weichao/Downloads/pycharm-2023.2.1/plugins/python/helpers/pycharm_display/datalore/display/display_.py", line 86, in _send_display_message
    urllib_request.urlopen(url, buffer)
  File "/opt/Dino_parallel/lib/python3.8/urllib/request.py", line 222, in urlopen
    return opener.open(url, data, timeout)
  File "/opt/Dino_parallel/lib/python3.8/urllib/request.py", line 531, in open
    response = meth(req, response)
  File "/opt/Dino_parallel/lib/python3.8/urllib/request.py", line 640, in http_response
    response = self.parent.error(
  File "/opt/Dino_parallel/lib/python3.8/urllib/request.py", line 569, in error
    return self._call_chain(*args)
  File "/opt/Dino_parallel/lib/python3.8/urllib/request.py", line 502, in _call_chain
    result = func(*args)
  File "/opt/Dino_parallel/lib/python3.8/urllib/request.py", line 649, in http_error_default
    raise HTTPError(req.full_url, code, msg, hdrs, fp)
urllib.error.HTTPError: HTTP Error 429: Too Many Requests

During handling of the above exception, another exception occurred:

Traceback (most recent call last):
  File "/home/weichao/Downloads/pycharm-2023.2.1/plugins/python/helpers/pycharm_display/datalore/display/display_.py", line 61, in try_empty_proxy
    urllib_request.urlopen(url, buffer)
  File "/opt/Dino_parallel/lib/python3.8/urllib/request.py", line 222, in urlopen
    return opener.open(url, data, timeout)
  File "/opt/Dino_parallel/lib/python3.8/urllib/request.py", line 531, in open
    response = meth(req, response)
  File "/opt/Dino_parallel/lib/python3.8/urllib/request.py", line 640, in http_response
    response = self.parent.error(
  File "/opt/Dino_parallel/lib/python3.8/urllib/request.py", line 569, in error
    return self._call_chain(*args)
  File "/opt/Dino_parallel/lib/python3.8/urllib/request.py", line 502, in _call_chain
    result = func(*args)
  File "/opt/Dino_parallel/lib/python3.8/urllib/request.py", line 649, in http_error_default
    raise HTTPError(req.full_url, code, msg, hdrs, fp)
urllib.error.HTTPError: HTTP Error 429: Too Many Requests
Error: failed to send plot to http://127.0.0.1:63342
Traceback (most recent call last):
  File "/home/weichao/Downloads/pycharm-2023.2.1/plugins/python/helpers/pycharm_display/datalore/display/display_.py", line 86, in _send_display_message
    urllib_request.urlopen(url, buffer)
  File "/opt/Dino_parallel/lib/python3.8/urllib/request.py", line 222, in urlopen
    return opener.open(url, data, timeout)
  File "/opt/Dino_parallel/lib/python3.8/urllib/request.py", line 531, in open
    response = meth(req, response)
  File "/opt/Dino_parallel/lib/python3.8/urllib/request.py", line 640, in http_response
    response = self.parent.error(
  File "/opt/Dino_parallel/lib/python3.8/urllib/request.py", line 569, in error
    return self._call_chain(*args)
  File "/opt/Dino_parallel/lib/python3.8/urllib/request.py", line 502, in _call_chain
    result = func(*args)
  File "/opt/Dino_parallel/lib/python3.8/urllib/request.py", line 649, in http_error_default
    raise HTTPError(req.full_url, code, msg, hdrs, fp)
urllib.error.HTTPError: HTTP Error 429: Too Many Requests

During handling of the above exception, another exception occurred:

Traceback (most recent call last):
  File "/home/weichao/Downloads/pycharm-2023.2.1/plugins/python/helpers/pycharm_display/datalore/display/display_.py", line 61, in try_empty_proxy
    urllib_request.urlopen(url, buffer)
  File "/opt/Dino_parallel/lib/python3.8/urllib/request.py", line 222, in urlopen
    return opener.open(url, data, timeout)
  File "/opt/Dino_parallel/lib/python3.8/urllib/request.py", line 531, in open
    response = meth(req, response)
  File "/opt/Dino_parallel/lib/python3.8/urllib/request.py", line 640, in http_response
    response = self.parent.error(
  File "/opt/Dino_parallel/lib/python3.8/urllib/request.py", line 569, in error
    return self._call_chain(*args)
  File "/opt/Dino_parallel/lib/python3.8/urllib/request.py", line 502, in _call_chain
    result = func(*args)
  File "/opt/Dino_parallel/lib/python3.8/urllib/request.py", line 649, in http_error_default
    raise HTTPError(req.full_url, code, msg, hdrs, fp)
urllib.error.HTTPError: HTTP Error 429: Too Many Requests
Error: failed to send plot to http://127.0.0.1:63342
Traceback (most recent call last):
  File "/home/weichao/Downloads/pycharm-2023.2.1/plugins/python/helpers/pycharm_display/datalore/display/display_.py", line 86, in _send_display_message
    urllib_request.urlopen(url, buffer)
  File "/opt/Dino_parallel/lib/python3.8/urllib/request.py", line 222, in urlopen
    return opener.open(url, data, timeout)
  File "/opt/Dino_parallel/lib/python3.8/urllib/request.py", line 531, in open
    response = meth(req, response)
  File "/opt/Dino_parallel/lib/python3.8/urllib/request.py", line 640, in http_response
    response = self.parent.error(
  File "/opt/Dino_parallel/lib/python3.8/urllib/request.py", line 569, in error
    return self._call_chain(*args)
  File "/opt/Dino_parallel/lib/python3.8/urllib/request.py", line 502, in _call_chain
    result = func(*args)
  File "/opt/Dino_parallel/lib/python3.8/urllib/request.py", line 649, in http_error_default
    raise HTTPError(req.full_url, code, msg, hdrs, fp)
urllib.error.HTTPError: HTTP Error 429: Too Many Requests

During handling of the above exception, another exception occurred:

Traceback (most recent call last):
  File "/home/weichao/Downloads/pycharm-2023.2.1/plugins/python/helpers/pycharm_display/datalore/display/display_.py", line 61, in try_empty_proxy
    urllib_request.urlopen(url, buffer)
  File "/opt/Dino_parallel/lib/python3.8/urllib/request.py", line 222, in urlopen
    return opener.open(url, data, timeout)
  File "/opt/Dino_parallel/lib/python3.8/urllib/request.py", line 531, in open
    response = meth(req, response)
  File "/opt/Dino_parallel/lib/python3.8/urllib/request.py", line 640, in http_response
    response = self.parent.error(
  File "/opt/Dino_parallel/lib/python3.8/urllib/request.py", line 569, in error
    return self._call_chain(*args)
  File "/opt/Dino_parallel/lib/python3.8/urllib/request.py", line 502, in _call_chain
    result = func(*args)
  File "/opt/Dino_parallel/lib/python3.8/urllib/request.py", line 649, in http_error_default
    raise HTTPError(req.full_url, code, msg, hdrs, fp)
urllib.error.HTTPError: HTTP Error 429: Too Many Requests
Error: failed to send plot to http://127.0.0.1:63342
Traceback (most recent call last):
  File "/home/weichao/Downloads/pycharm-2023.2.1/plugins/python/helpers/pycharm_display/datalore/display/display_.py", line 86, in _send_display_message
    urllib_request.urlopen(url, buffer)
  File "/opt/Dino_parallel/lib/python3.8/urllib/request.py", line 222, in urlopen
    return opener.open(url, data, timeout)
  File "/opt/Dino_parallel/lib/python3.8/urllib/request.py", line 531, in open
    response = meth(req, response)
  File "/opt/Dino_parallel/lib/python3.8/urllib/request.py", line 640, in http_response
    response = self.parent.error(
  File "/opt/Dino_parallel/lib/python3.8/urllib/request.py", line 569, in error
    return self._call_chain(*args)
  File "/opt/Dino_parallel/lib/python3.8/urllib/request.py", line 502, in _call_chain
    result = func(*args)
  File "/opt/Dino_parallel/lib/python3.8/urllib/request.py", line 649, in http_error_default
    raise HTTPError(req.full_url, code, msg, hdrs, fp)
urllib.error.HTTPError: HTTP Error 429: Too Many Requests

During handling of the above exception, another exception occurred:

Traceback (most recent call last):
  File "/home/weichao/Downloads/pycharm-2023.2.1/plugins/python/helpers/pycharm_display/datalore/display/display_.py", line 61, in try_empty_proxy
    urllib_request.urlopen(url, buffer)
  File "/opt/Dino_parallel/lib/python3.8/urllib/request.py", line 222, in urlopen
    return opener.open(url, data, timeout)
  File "/opt/Dino_parallel/lib/python3.8/urllib/request.py", line 531, in open
    response = meth(req, response)
  File "/opt/Dino_parallel/lib/python3.8/urllib/request.py", line 640, in http_response
    response = self.parent.error(
  File "/opt/Dino_parallel/lib/python3.8/urllib/request.py", line 569, in error
    return self._call_chain(*args)
  File "/opt/Dino_parallel/lib/python3.8/urllib/request.py", line 502, in _call_chain
    result = func(*args)
  File "/opt/Dino_parallel/lib/python3.8/urllib/request.py", line 649, in http_error_default
    raise HTTPError(req.full_url, code, msg, hdrs, fp)
urllib.error.HTTPError: HTTP Error 429: Too Many Requests
Error: failed to send plot to http://127.0.0.1:63342
Traceback (most recent call last):
  File "/home/weichao/Downloads/pycharm-2023.2.1/plugins/python/helpers/pycharm_display/datalore/display/display_.py", line 86, in _send_display_message
    urllib_request.urlopen(url, buffer)
  File "/opt/Dino_parallel/lib/python3.8/urllib/request.py", line 222, in urlopen
    return opener.open(url, data, timeout)
  File "/opt/Dino_parallel/lib/python3.8/urllib/request.py", line 531, in open
    response = meth(req, response)
  File "/opt/Dino_parallel/lib/python3.8/urllib/request.py", line 640, in http_response
    response = self.parent.error(
  File "/opt/Dino_parallel/lib/python3.8/urllib/request.py", line 569, in error
    return self._call_chain(*args)
  File "/opt/Dino_parallel/lib/python3.8/urllib/request.py", line 502, in _call_chain
    result = func(*args)
  File "/opt/Dino_parallel/lib/python3.8/urllib/request.py", line 649, in http_error_default
    raise HTTPError(req.full_url, code, msg, hdrs, fp)
urllib.error.HTTPError: HTTP Error 429: Too Many Requests

During handling of the above exception, another exception occurred:

Traceback (most recent call last):
  File "/home/weichao/Downloads/pycharm-2023.2.1/plugins/python/helpers/pycharm_display/datalore/display/display_.py", line 61, in try_empty_proxy
    urllib_request.urlopen(url, buffer)
  File "/opt/Dino_parallel/lib/python3.8/urllib/request.py", line 222, in urlopen
    return opener.open(url, data, timeout)
  File "/opt/Dino_parallel/lib/python3.8/urllib/request.py", line 531, in open
    response = meth(req, response)
  File "/opt/Dino_parallel/lib/python3.8/urllib/request.py", line 640, in http_response
    response = self.parent.error(
  File "/opt/Dino_parallel/lib/python3.8/urllib/request.py", line 569, in error
    return self._call_chain(*args)
  File "/opt/Dino_parallel/lib/python3.8/urllib/request.py", line 502, in _call_chain
    result = func(*args)
  File "/opt/Dino_parallel/lib/python3.8/urllib/request.py", line 649, in http_error_default
    raise HTTPError(req.full_url, code, msg, hdrs, fp)
urllib.error.HTTPError: HTTP Error 429: Too Many Requests
Error: failed to send plot to http://127.0.0.1:63342
Traceback (most recent call last):
  File "/home/weichao/Downloads/pycharm-2023.2.1/plugins/python/helpers/pycharm_display/datalore/display/display_.py", line 86, in _send_display_message
    urllib_request.urlopen(url, buffer)
  File "/opt/Dino_parallel/lib/python3.8/urllib/request.py", line 222, in urlopen
    return opener.open(url, data, timeout)
  File "/opt/Dino_parallel/lib/python3.8/urllib/request.py", line 531, in open
    response = meth(req, response)
  File "/opt/Dino_parallel/lib/python3.8/urllib/request.py", line 640, in http_response
    response = self.parent.error(
  File "/opt/Dino_parallel/lib/python3.8/urllib/request.py", line 569, in error
    return self._call_chain(*args)
  File "/opt/Dino_parallel/lib/python3.8/urllib/request.py", line 502, in _call_chain
    result = func(*args)
  File "/opt/Dino_parallel/lib/python3.8/urllib/request.py", line 649, in http_error_default
    raise HTTPError(req.full_url, code, msg, hdrs, fp)
urllib.error.HTTPError: HTTP Error 429: Too Many Requests

During handling of the above exception, another exception occurred:

Traceback (most recent call last):
  File "/home/weichao/Downloads/pycharm-2023.2.1/plugins/python/helpers/pycharm_display/datalore/display/display_.py", line 61, in try_empty_proxy
    urllib_request.urlopen(url, buffer)
  File "/opt/Dino_parallel/lib/python3.8/urllib/request.py", line 222, in urlopen
    return opener.open(url, data, timeout)
  File "/opt/Dino_parallel/lib/python3.8/urllib/request.py", line 531, in open
    response = meth(req, response)
  File "/opt/Dino_parallel/lib/python3.8/urllib/request.py", line 640, in http_response
    response = self.parent.error(
  File "/opt/Dino_parallel/lib/python3.8/urllib/request.py", line 569, in error
    return self._call_chain(*args)
  File "/opt/Dino_parallel/lib/python3.8/urllib/request.py", line 502, in _call_chain
    result = func(*args)
  File "/opt/Dino_parallel/lib/python3.8/urllib/request.py", line 649, in http_error_default
    raise HTTPError(req.full_url, code, msg, hdrs, fp)
urllib.error.HTTPError: HTTP Error 429: Too Many Requests
Error: failed to send plot to http://127.0.0.1:63342
Traceback (most recent call last):
  File "/home/weichao/Downloads/pycharm-2023.2.1/plugins/python/helpers/pycharm_display/datalore/display/display_.py", line 86, in _send_display_message
    urllib_request.urlopen(url, buffer)
  File "/opt/Dino_parallel/lib/python3.8/urllib/request.py", line 222, in urlopen
    return opener.open(url, data, timeout)
  File "/opt/Dino_parallel/lib/python3.8/urllib/request.py", line 531, in open
    response = meth(req, response)
  File "/opt/Dino_parallel/lib/python3.8/urllib/request.py", line 640, in http_response
    response = self.parent.error(
  File "/opt/Dino_parallel/lib/python3.8/urllib/request.py", line 569, in error
    return self._call_chain(*args)
  File "/opt/Dino_parallel/lib/python3.8/urllib/request.py", line 502, in _call_chain
    result = func(*args)
  File "/opt/Dino_parallel/lib/python3.8/urllib/request.py", line 649, in http_error_default
    raise HTTPError(req.full_url, code, msg, hdrs, fp)
urllib.error.HTTPError: HTTP Error 429: Too Many Requests

During handling of the above exception, another exception occurred:

Traceback (most recent call last):
  File "/home/weichao/Downloads/pycharm-2023.2.1/plugins/python/helpers/pycharm_display/datalore/display/display_.py", line 61, in try_empty_proxy
    urllib_request.urlopen(url, buffer)
  File "/opt/Dino_parallel/lib/python3.8/urllib/request.py", line 222, in urlopen
    return opener.open(url, data, timeout)
  File "/opt/Dino_parallel/lib/python3.8/urllib/request.py", line 531, in open
    response = meth(req, response)
  File "/opt/Dino_parallel/lib/python3.8/urllib/request.py", line 640, in http_response
    response = self.parent.error(
  File "/opt/Dino_parallel/lib/python3.8/urllib/request.py", line 569, in error
    return self._call_chain(*args)
  File "/opt/Dino_parallel/lib/python3.8/urllib/request.py", line 502, in _call_chain
    result = func(*args)
  File "/opt/Dino_parallel/lib/python3.8/urllib/request.py", line 649, in http_error_default
    raise HTTPError(req.full_url, code, msg, hdrs, fp)
urllib.error.HTTPError: HTTP Error 429: Too Many Requests
Error: failed to send plot to http://127.0.0.1:63342
Traceback (most recent call last):
  File "/home/weichao/Downloads/pycharm-2023.2.1/plugins/python/helpers/pycharm_display/datalore/display/display_.py", line 86, in _send_display_message
    urllib_request.urlopen(url, buffer)
  File "/opt/Dino_parallel/lib/python3.8/urllib/request.py", line 222, in urlopen
    return opener.open(url, data, timeout)
  File "/opt/Dino_parallel/lib/python3.8/urllib/request.py", line 531, in open
    response = meth(req, response)
  File "/opt/Dino_parallel/lib/python3.8/urllib/request.py", line 640, in http_response
    response = self.parent.error(
  File "/opt/Dino_parallel/lib/python3.8/urllib/request.py", line 569, in error
    return self._call_chain(*args)
  File "/opt/Dino_parallel/lib/python3.8/urllib/request.py", line 502, in _call_chain
    result = func(*args)
  File "/opt/Dino_parallel/lib/python3.8/urllib/request.py", line 649, in http_error_default
    raise HTTPError(req.full_url, code, msg, hdrs, fp)
urllib.error.HTTPError: HTTP Error 429: Too Many Requests

During handling of the above exception, another exception occurred:

Traceback (most recent call last):
  File "/home/weichao/Downloads/pycharm-2023.2.1/plugins/python/helpers/pycharm_display/datalore/display/display_.py", line 61, in try_empty_proxy
    urllib_request.urlopen(url, buffer)
  File "/opt/Dino_parallel/lib/python3.8/urllib/request.py", line 222, in urlopen
    return opener.open(url, data, timeout)
  File "/opt/Dino_parallel/lib/python3.8/urllib/request.py", line 531, in open
    response = meth(req, response)
  File "/opt/Dino_parallel/lib/python3.8/urllib/request.py", line 640, in http_response
    response = self.parent.error(
  File "/opt/Dino_parallel/lib/python3.8/urllib/request.py", line 569, in error
    return self._call_chain(*args)
  File "/opt/Dino_parallel/lib/python3.8/urllib/request.py", line 502, in _call_chain
    result = func(*args)
  File "/opt/Dino_parallel/lib/python3.8/urllib/request.py", line 649, in http_error_default
    raise HTTPError(req.full_url, code, msg, hdrs, fp)
urllib.error.HTTPError: HTTP Error 429: Too Many Requests
Error: failed to send plot to http://127.0.0.1:63342
Traceback (most recent call last):
  File "/home/weichao/Downloads/pycharm-2023.2.1/plugins/python/helpers/pycharm_display/datalore/display/display_.py", line 86, in _send_display_message
    urllib_request.urlopen(url, buffer)
  File "/opt/Dino_parallel/lib/python3.8/urllib/request.py", line 222, in urlopen
    return opener.open(url, data, timeout)
  File "/opt/Dino_parallel/lib/python3.8/urllib/request.py", line 531, in open
    response = meth(req, response)
  File "/opt/Dino_parallel/lib/python3.8/urllib/request.py", line 640, in http_response
    response = self.parent.error(
  File "/opt/Dino_parallel/lib/python3.8/urllib/request.py", line 569, in error
    return self._call_chain(*args)
  File "/opt/Dino_parallel/lib/python3.8/urllib/request.py", line 502, in _call_chain
    result = func(*args)
  File "/opt/Dino_parallel/lib/python3.8/urllib/request.py", line 649, in http_error_default
    raise HTTPError(req.full_url, code, msg, hdrs, fp)
urllib.error.HTTPError: HTTP Error 429: Too Many Requests

During handling of the above exception, another exception occurred:

Traceback (most recent call last):
  File "/home/weichao/Downloads/pycharm-2023.2.1/plugins/python/helpers/pycharm_display/datalore/display/display_.py", line 61, in try_empty_proxy
    urllib_request.urlopen(url, buffer)
  File "/opt/Dino_parallel/lib/python3.8/urllib/request.py", line 222, in urlopen
    return opener.open(url, data, timeout)
  File "/opt/Dino_parallel/lib/python3.8/urllib/request.py", line 531, in open
    response = meth(req, response)
  File "/opt/Dino_parallel/lib/python3.8/urllib/request.py", line 640, in http_response
    response = self.parent.error(
  File "/opt/Dino_parallel/lib/python3.8/urllib/request.py", line 569, in error
    return self._call_chain(*args)
  File "/opt/Dino_parallel/lib/python3.8/urllib/request.py", line 502, in _call_chain
    result = func(*args)
  File "/opt/Dino_parallel/lib/python3.8/urllib/request.py", line 649, in http_error_default
    raise HTTPError(req.full_url, code, msg, hdrs, fp)
urllib.error.HTTPError: HTTP Error 429: Too Many Requests

--------------------------------------------------

--- Running: 2D_Diffusion_FVM.py ---
Exit Code: 0
Output:

Errors:
Error: failed to send plot to http://127.0.0.1:63342
Traceback (most recent call last):
  File "/home/weichao/Downloads/pycharm-2023.2.1/plugins/python/helpers/pycharm_display/datalore/display/display_.py", line 86, in _send_display_message
    urllib_request.urlopen(url, buffer)
  File "/opt/Dino_parallel/lib/python3.8/urllib/request.py", line 222, in urlopen
    return opener.open(url, data, timeout)
  File "/opt/Dino_parallel/lib/python3.8/urllib/request.py", line 531, in open
    response = meth(req, response)
  File "/opt/Dino_parallel/lib/python3.8/urllib/request.py", line 640, in http_response
    response = self.parent.error(
  File "/opt/Dino_parallel/lib/python3.8/urllib/request.py", line 569, in error
    return self._call_chain(*args)
  File "/opt/Dino_parallel/lib/python3.8/urllib/request.py", line 502, in _call_chain
    result = func(*args)
  File "/opt/Dino_parallel/lib/python3.8/urllib/request.py", line 649, in http_error_default
    raise HTTPError(req.full_url, code, msg, hdrs, fp)
urllib.error.HTTPError: HTTP Error 429: Too Many Requests

During handling of the above exception, another exception occurred:

Traceback (most recent call last):
  File "/home/weichao/Downloads/pycharm-2023.2.1/plugins/python/helpers/pycharm_display/datalore/display/display_.py", line 61, in try_empty_proxy
    urllib_request.urlopen(url, buffer)
  File "/opt/Dino_parallel/lib/python3.8/urllib/request.py", line 222, in urlopen
    return opener.open(url, data, timeout)
  File "/opt/Dino_parallel/lib/python3.8/urllib/request.py", line 531, in open
    response = meth(req, response)
  File "/opt/Dino_parallel/lib/python3.8/urllib/request.py", line 640, in http_response
    response = self.parent.error(
  File "/opt/Dino_parallel/lib/python3.8/urllib/request.py", line 569, in error
    return self._call_chain(*args)
  File "/opt/Dino_parallel/lib/python3.8/urllib/request.py", line 502, in _call_chain
    result = func(*args)
  File "/opt/Dino_parallel/lib/python3.8/urllib/request.py", line 649, in http_error_default
    raise HTTPError(req.full_url, code, msg, hdrs, fp)
urllib.error.HTTPError: HTTP Error 429: Too Many Requests

--------------------------------------------------

--- Running: 2D_Convection.py ---
Exit Code: 0
Output:

Errors:
/opt/CFD-Benchmark/PDE_Benchmark_5/solver_6/2D_Convection.py:31: RuntimeWarning: overflow encountered in multiply
  u[1:, 1:] = un[1:, 1:] - un[1:, 1:]*dt/dx*(un[1:, 1:] - un[1:, :-1]) - vn[1:, 1:]*dt/dy*(un[1:, 1:] - un[:-1, 1:])
/opt/CFD-Benchmark/PDE_Benchmark_5/solver_6/2D_Convection.py:31: RuntimeWarning: invalid value encountered in subtract
  u[1:, 1:] = un[1:, 1:] - un[1:, 1:]*dt/dx*(un[1:, 1:] - un[1:, :-1]) - vn[1:, 1:]*dt/dy*(un[1:, 1:] - un[:-1, 1:])
/opt/CFD-Benchmark/PDE_Benchmark_5/solver_6/2D_Convection.py:32: RuntimeWarning: overflow encountered in multiply
  v[1:, 1:] = vn[1:, 1:] - un[1:, 1:]*dt/dx*(vn[1:, 1:] - vn[1:, :-1]) - vn[1:, 1:]*dt/dy*(vn[1:, 1:] - vn[:-1, 1:])
/opt/CFD-Benchmark/PDE_Benchmark_5/solver_6/2D_Convection.py:32: RuntimeWarning: invalid value encountered in subtract
  v[1:, 1:] = vn[1:, 1:] - un[1:, 1:]*dt/dx*(vn[1:, 1:] - vn[1:, :-1]) - vn[1:, 1:]*dt/dy*(vn[1:, 1:] - vn[:-1, 1:])
/opt/CFD-Benchmark/PDE_Benchmark_5/solver_6/2D_Convection.py:31: RuntimeWarning: invalid value encountered in multiply
  u[1:, 1:] = un[1:, 1:] - un[1:, 1:]*dt/dx*(un[1:, 1:] - un[1:, :-1]) - vn[1:, 1:]*dt/dy*(un[1:, 1:] - un[:-1, 1:])
/opt/CFD-Benchmark/PDE_Benchmark_5/solver_6/2D_Convection.py:32: RuntimeWarning: invalid value encountered in multiply
  v[1:, 1:] = vn[1:, 1:] - un[1:, 1:]*dt/dx*(vn[1:, 1:] - vn[1:, :-1]) - vn[1:, 1:]*dt/dy*(vn[1:, 1:] - vn[:-1, 1:])
Error: failed to send plot to http://127.0.0.1:63342
Traceback (most recent call last):
  File "/home/weichao/Downloads/pycharm-2023.2.1/plugins/python/helpers/pycharm_display/datalore/display/display_.py", line 86, in _send_display_message
    urllib_request.urlopen(url, buffer)
  File "/opt/Dino_parallel/lib/python3.8/urllib/request.py", line 222, in urlopen
    return opener.open(url, data, timeout)
  File "/opt/Dino_parallel/lib/python3.8/urllib/request.py", line 531, in open
    response = meth(req, response)
  File "/opt/Dino_parallel/lib/python3.8/urllib/request.py", line 640, in http_response
    response = self.parent.error(
  File "/opt/Dino_parallel/lib/python3.8/urllib/request.py", line 569, in error
    return self._call_chain(*args)
  File "/opt/Dino_parallel/lib/python3.8/urllib/request.py", line 502, in _call_chain
    result = func(*args)
  File "/opt/Dino_parallel/lib/python3.8/urllib/request.py", line 649, in http_error_default
    raise HTTPError(req.full_url, code, msg, hdrs, fp)
urllib.error.HTTPError: HTTP Error 429: Too Many Requests

During handling of the above exception, another exception occurred:

Traceback (most recent call last):
  File "/home/weichao/Downloads/pycharm-2023.2.1/plugins/python/helpers/pycharm_display/datalore/display/display_.py", line 61, in try_empty_proxy
    urllib_request.urlopen(url, buffer)
  File "/opt/Dino_parallel/lib/python3.8/urllib/request.py", line 222, in urlopen
    return opener.open(url, data, timeout)
  File "/opt/Dino_parallel/lib/python3.8/urllib/request.py", line 531, in open
    response = meth(req, response)
  File "/opt/Dino_parallel/lib/python3.8/urllib/request.py", line 640, in http_response
    response = self.parent.error(
  File "/opt/Dino_parallel/lib/python3.8/urllib/request.py", line 569, in error
    return self._call_chain(*args)
  File "/opt/Dino_parallel/lib/python3.8/urllib/request.py", line 502, in _call_chain
    result = func(*args)
  File "/opt/Dino_parallel/lib/python3.8/urllib/request.py", line 649, in http_error_default
    raise HTTPError(req.full_url, code, msg, hdrs, fp)
urllib.error.HTTPError: HTTP Error 429: Too Many Requests

--------------------------------------------------

--- Running: 1D_Nonlinear_Convection.py ---
Exit Code: 0
Output:

Errors:
Error: failed to send plot to http://127.0.0.1:63342
Traceback (most recent call last):
  File "/home/weichao/Downloads/pycharm-2023.2.1/plugins/python/helpers/pycharm_display/datalore/display/display_.py", line 86, in _send_display_message
    urllib_request.urlopen(url, buffer)
  File "/opt/Dino_parallel/lib/python3.8/urllib/request.py", line 222, in urlopen
    return opener.open(url, data, timeout)
  File "/opt/Dino_parallel/lib/python3.8/urllib/request.py", line 531, in open
    response = meth(req, response)
  File "/opt/Dino_parallel/lib/python3.8/urllib/request.py", line 640, in http_response
    response = self.parent.error(
  File "/opt/Dino_parallel/lib/python3.8/urllib/request.py", line 569, in error
    return self._call_chain(*args)
  File "/opt/Dino_parallel/lib/python3.8/urllib/request.py", line 502, in _call_chain
    result = func(*args)
  File "/opt/Dino_parallel/lib/python3.8/urllib/request.py", line 649, in http_error_default
    raise HTTPError(req.full_url, code, msg, hdrs, fp)
urllib.error.HTTPError: HTTP Error 429: Too Many Requests

During handling of the above exception, another exception occurred:

Traceback (most recent call last):
  File "/home/weichao/Downloads/pycharm-2023.2.1/plugins/python/helpers/pycharm_display/datalore/display/display_.py", line 61, in try_empty_proxy
    urllib_request.urlopen(url, buffer)
  File "/opt/Dino_parallel/lib/python3.8/urllib/request.py", line 222, in urlopen
    return opener.open(url, data, timeout)
  File "/opt/Dino_parallel/lib/python3.8/urllib/request.py", line 531, in open
    response = meth(req, response)
  File "/opt/Dino_parallel/lib/python3.8/urllib/request.py", line 640, in http_response
    response = self.parent.error(
  File "/opt/Dino_parallel/lib/python3.8/urllib/request.py", line 569, in error
    return self._call_chain(*args)
  File "/opt/Dino_parallel/lib/python3.8/urllib/request.py", line 502, in _call_chain
    result = func(*args)
  File "/opt/Dino_parallel/lib/python3.8/urllib/request.py", line 649, in http_error_default
    raise HTTPError(req.full_url, code, msg, hdrs, fp)
urllib.error.HTTPError: HTTP Error 429: Too Many Requests

--------------------------------------------------

--- Running: 1D_Euler_Shock_Tube.py ---
Exit Code: 0
Output:

Errors:
/opt/CFD-Benchmark/PDE_Benchmark_5/solver_6/1D_Euler_Shock_Tube.py:28: RuntimeWarning: invalid value encountered in divide
  f[:, 1] = ((u[:, 1] ** 2) / u[:, 0]) + (gamma - 1) * (u[:, 2] - 0.5 * (u[:, 1] ** 2 / u[:, 0]))
/opt/CFD-Benchmark/PDE_Benchmark_5/solver_6/1D_Euler_Shock_Tube.py:29: RuntimeWarning: invalid value encountered in divide
  f[:, 2] = (u[:, 2] + (gamma - 1) * (u[:, 2] - 0.5 * (u[:, 1] ** 2 / u[:, 0]))) * (u[:, 1] / u[:, 0])
/opt/CFD-Benchmark/PDE_Benchmark_5/solver_6/1D_Euler_Shock_Tube.py:28: RuntimeWarning: overflow encountered in square
  f[:, 1] = ((u[:, 1] ** 2) / u[:, 0]) + (gamma - 1) * (u[:, 2] - 0.5 * (u[:, 1] ** 2 / u[:, 0]))
/opt/CFD-Benchmark/PDE_Benchmark_5/solver_6/1D_Euler_Shock_Tube.py:28: RuntimeWarning: invalid value encountered in add
  f[:, 1] = ((u[:, 1] ** 2) / u[:, 0]) + (gamma - 1) * (u[:, 2] - 0.5 * (u[:, 1] ** 2 / u[:, 0]))
/opt/CFD-Benchmark/PDE_Benchmark_5/solver_6/1D_Euler_Shock_Tube.py:29: RuntimeWarning: overflow encountered in square
  f[:, 2] = (u[:, 2] + (gamma - 1) * (u[:, 2] - 0.5 * (u[:, 1] ** 2 / u[:, 0]))) * (u[:, 1] / u[:, 0])
/opt/CFD-Benchmark/PDE_Benchmark_5/solver_6/1D_Euler_Shock_Tube.py:43: RuntimeWarning: invalid value encountered in subtract
  u[t+1, 1:] = 0.5 * (u[t, 1:] + u_bar[1:] - dt / dx * (f_bar[1:] - f_bar[:-1]))
/opt/CFD-Benchmark/PDE_Benchmark_5/solver_6/1D_Euler_Shock_Tube.py:39: RuntimeWarning: invalid value encountered in subtract
  u_bar[:-1] = u[t, :-1] - dt / dx * (f[1:] - f[:-1])
/opt/CFD-Benchmark/PDE_Benchmark_5/solver_6/1D_Euler_Shock_Tube.py:47: RuntimeWarning: invalid value encountered in divide
  v = u[:, :, 1] / rho
Error: failed to send plot to http://127.0.0.1:63342
Traceback (most recent call last):
  File "/home/weichao/Downloads/pycharm-2023.2.1/plugins/python/helpers/pycharm_display/datalore/display/display_.py", line 86, in _send_display_message
    urllib_request.urlopen(url, buffer)
  File "/opt/Dino_parallel/lib/python3.8/urllib/request.py", line 222, in urlopen
    return opener.open(url, data, timeout)
  File "/opt/Dino_parallel/lib/python3.8/urllib/request.py", line 531, in open
    response = meth(req, response)
  File "/opt/Dino_parallel/lib/python3.8/urllib/request.py", line 640, in http_response
    response = self.parent.error(
  File "/opt/Dino_parallel/lib/python3.8/urllib/request.py", line 569, in error
    return self._call_chain(*args)
  File "/opt/Dino_parallel/lib/python3.8/urllib/request.py", line 502, in _call_chain
    result = func(*args)
  File "/opt/Dino_parallel/lib/python3.8/urllib/request.py", line 649, in http_error_default
    raise HTTPError(req.full_url, code, msg, hdrs, fp)
urllib.error.HTTPError: HTTP Error 429: Too Many Requests

During handling of the above exception, another exception occurred:

Traceback (most recent call last):
  File "/home/weichao/Downloads/pycharm-2023.2.1/plugins/python/helpers/pycharm_display/datalore/display/display_.py", line 61, in try_empty_proxy
    urllib_request.urlopen(url, buffer)
  File "/opt/Dino_parallel/lib/python3.8/urllib/request.py", line 222, in urlopen
    return opener.open(url, data, timeout)
  File "/opt/Dino_parallel/lib/python3.8/urllib/request.py", line 531, in open
    response = meth(req, response)
  File "/opt/Dino_parallel/lib/python3.8/urllib/request.py", line 640, in http_response
    response = self.parent.error(
  File "/opt/Dino_parallel/lib/python3.8/urllib/request.py", line 569, in error
    return self._call_chain(*args)
  File "/opt/Dino_parallel/lib/python3.8/urllib/request.py", line 502, in _call_chain
    result = func(*args)
  File "/opt/Dino_parallel/lib/python3.8/urllib/request.py", line 649, in http_error_default
    raise HTTPError(req.full_url, code, msg, hdrs, fp)
urllib.error.HTTPError: HTTP Error 429: Too Many Requests
Error: failed to send plot to http://127.0.0.1:63342
Traceback (most recent call last):
  File "/home/weichao/Downloads/pycharm-2023.2.1/plugins/python/helpers/pycharm_display/datalore/display/display_.py", line 86, in _send_display_message
    urllib_request.urlopen(url, buffer)
  File "/opt/Dino_parallel/lib/python3.8/urllib/request.py", line 222, in urlopen
    return opener.open(url, data, timeout)
  File "/opt/Dino_parallel/lib/python3.8/urllib/request.py", line 531, in open
    response = meth(req, response)
  File "/opt/Dino_parallel/lib/python3.8/urllib/request.py", line 640, in http_response
    response = self.parent.error(
  File "/opt/Dino_parallel/lib/python3.8/urllib/request.py", line 569, in error
    return self._call_chain(*args)
  File "/opt/Dino_parallel/lib/python3.8/urllib/request.py", line 502, in _call_chain
    result = func(*args)
  File "/opt/Dino_parallel/lib/python3.8/urllib/request.py", line 649, in http_error_default
    raise HTTPError(req.full_url, code, msg, hdrs, fp)
urllib.error.HTTPError: HTTP Error 429: Too Many Requests

During handling of the above exception, another exception occurred:

Traceback (most recent call last):
  File "/home/weichao/Downloads/pycharm-2023.2.1/plugins/python/helpers/pycharm_display/datalore/display/display_.py", line 61, in try_empty_proxy
    urllib_request.urlopen(url, buffer)
  File "/opt/Dino_parallel/lib/python3.8/urllib/request.py", line 222, in urlopen
    return opener.open(url, data, timeout)
  File "/opt/Dino_parallel/lib/python3.8/urllib/request.py", line 531, in open
    response = meth(req, response)
  File "/opt/Dino_parallel/lib/python3.8/urllib/request.py", line 640, in http_response
    response = self.parent.error(
  File "/opt/Dino_parallel/lib/python3.8/urllib/request.py", line 569, in error
    return self._call_chain(*args)
  File "/opt/Dino_parallel/lib/python3.8/urllib/request.py", line 502, in _call_chain
    result = func(*args)
  File "/opt/Dino_parallel/lib/python3.8/urllib/request.py", line 649, in http_error_default
    raise HTTPError(req.full_url, code, msg, hdrs, fp)
urllib.error.HTTPError: HTTP Error 429: Too Many Requests
Error: failed to send plot to http://127.0.0.1:63342
Traceback (most recent call last):
  File "/home/weichao/Downloads/pycharm-2023.2.1/plugins/python/helpers/pycharm_display/datalore/display/display_.py", line 86, in _send_display_message
    urllib_request.urlopen(url, buffer)
  File "/opt/Dino_parallel/lib/python3.8/urllib/request.py", line 222, in urlopen
    return opener.open(url, data, timeout)
  File "/opt/Dino_parallel/lib/python3.8/urllib/request.py", line 531, in open
    response = meth(req, response)
  File "/opt/Dino_parallel/lib/python3.8/urllib/request.py", line 640, in http_response
    response = self.parent.error(
  File "/opt/Dino_parallel/lib/python3.8/urllib/request.py", line 569, in error
    return self._call_chain(*args)
  File "/opt/Dino_parallel/lib/python3.8/urllib/request.py", line 502, in _call_chain
    result = func(*args)
  File "/opt/Dino_parallel/lib/python3.8/urllib/request.py", line 649, in http_error_default
    raise HTTPError(req.full_url, code, msg, hdrs, fp)
urllib.error.HTTPError: HTTP Error 429: Too Many Requests

During handling of the above exception, another exception occurred:

Traceback (most recent call last):
  File "/home/weichao/Downloads/pycharm-2023.2.1/plugins/python/helpers/pycharm_display/datalore/display/display_.py", line 61, in try_empty_proxy
    urllib_request.urlopen(url, buffer)
  File "/opt/Dino_parallel/lib/python3.8/urllib/request.py", line 222, in urlopen
    return opener.open(url, data, timeout)
  File "/opt/Dino_parallel/lib/python3.8/urllib/request.py", line 531, in open
    response = meth(req, response)
  File "/opt/Dino_parallel/lib/python3.8/urllib/request.py", line 640, in http_response
    response = self.parent.error(
  File "/opt/Dino_parallel/lib/python3.8/urllib/request.py", line 569, in error
    return self._call_chain(*args)
  File "/opt/Dino_parallel/lib/python3.8/urllib/request.py", line 502, in _call_chain
    result = func(*args)
  File "/opt/Dino_parallel/lib/python3.8/urllib/request.py", line 649, in http_error_default
    raise HTTPError(req.full_url, code, msg, hdrs, fp)
urllib.error.HTTPError: HTTP Error 429: Too Many Requests

--------------------------------------------------

--- Running: 2D_Linear_Convection.py ---
Exit Code: 0
Output:

Errors:
Error: failed to send plot to http://127.0.0.1:63342
Traceback (most recent call last):
  File "/home/weichao/Downloads/pycharm-2023.2.1/plugins/python/helpers/pycharm_display/datalore/display/display_.py", line 86, in _send_display_message
    urllib_request.urlopen(url, buffer)
  File "/opt/Dino_parallel/lib/python3.8/urllib/request.py", line 222, in urlopen
    return opener.open(url, data, timeout)
  File "/opt/Dino_parallel/lib/python3.8/urllib/request.py", line 531, in open
    response = meth(req, response)
  File "/opt/Dino_parallel/lib/python3.8/urllib/request.py", line 640, in http_response
    response = self.parent.error(
  File "/opt/Dino_parallel/lib/python3.8/urllib/request.py", line 569, in error
    return self._call_chain(*args)
  File "/opt/Dino_parallel/lib/python3.8/urllib/request.py", line 502, in _call_chain
    result = func(*args)
  File "/opt/Dino_parallel/lib/python3.8/urllib/request.py", line 649, in http_error_default
    raise HTTPError(req.full_url, code, msg, hdrs, fp)
urllib.error.HTTPError: HTTP Error 429: Too Many Requests

During handling of the above exception, another exception occurred:

Traceback (most recent call last):
  File "/home/weichao/Downloads/pycharm-2023.2.1/plugins/python/helpers/pycharm_display/datalore/display/display_.py", line 61, in try_empty_proxy
    urllib_request.urlopen(url, buffer)
  File "/opt/Dino_parallel/lib/python3.8/urllib/request.py", line 222, in urlopen
    return opener.open(url, data, timeout)
  File "/opt/Dino_parallel/lib/python3.8/urllib/request.py", line 531, in open
    response = meth(req, response)
  File "/opt/Dino_parallel/lib/python3.8/urllib/request.py", line 640, in http_response
    response = self.parent.error(
  File "/opt/Dino_parallel/lib/python3.8/urllib/request.py", line 569, in error
    return self._call_chain(*args)
  File "/opt/Dino_parallel/lib/python3.8/urllib/request.py", line 502, in _call_chain
    result = func(*args)
  File "/opt/Dino_parallel/lib/python3.8/urllib/request.py", line 649, in http_error_default
    raise HTTPError(req.full_url, code, msg, hdrs, fp)
urllib.error.HTTPError: HTTP Error 429: Too Many Requests

--------------------------------------------------

--- Running: 2D_Laplace_Equation.py ---
Exit Code: 0
Output:

Errors:
Error: failed to send plot to http://127.0.0.1:63342
Traceback (most recent call last):
  File "/home/weichao/Downloads/pycharm-2023.2.1/plugins/python/helpers/pycharm_display/datalore/display/display_.py", line 86, in _send_display_message
    urllib_request.urlopen(url, buffer)
  File "/opt/Dino_parallel/lib/python3.8/urllib/request.py", line 222, in urlopen
    return opener.open(url, data, timeout)
  File "/opt/Dino_parallel/lib/python3.8/urllib/request.py", line 531, in open
    response = meth(req, response)
  File "/opt/Dino_parallel/lib/python3.8/urllib/request.py", line 640, in http_response
    response = self.parent.error(
  File "/opt/Dino_parallel/lib/python3.8/urllib/request.py", line 569, in error
    return self._call_chain(*args)
  File "/opt/Dino_parallel/lib/python3.8/urllib/request.py", line 502, in _call_chain
    result = func(*args)
  File "/opt/Dino_parallel/lib/python3.8/urllib/request.py", line 649, in http_error_default
    raise HTTPError(req.full_url, code, msg, hdrs, fp)
urllib.error.HTTPError: HTTP Error 429: Too Many Requests

During handling of the above exception, another exception occurred:

Traceback (most recent call last):
  File "/home/weichao/Downloads/pycharm-2023.2.1/plugins/python/helpers/pycharm_display/datalore/display/display_.py", line 61, in try_empty_proxy
    urllib_request.urlopen(url, buffer)
  File "/opt/Dino_parallel/lib/python3.8/urllib/request.py", line 222, in urlopen
    return opener.open(url, data, timeout)
  File "/opt/Dino_parallel/lib/python3.8/urllib/request.py", line 531, in open
    response = meth(req, response)
  File "/opt/Dino_parallel/lib/python3.8/urllib/request.py", line 640, in http_response
    response = self.parent.error(
  File "/opt/Dino_parallel/lib/python3.8/urllib/request.py", line 569, in error
    return self._call_chain(*args)
  File "/opt/Dino_parallel/lib/python3.8/urllib/request.py", line 502, in _call_chain
    result = func(*args)
  File "/opt/Dino_parallel/lib/python3.8/urllib/request.py", line 649, in http_error_default
    raise HTTPError(req.full_url, code, msg, hdrs, fp)
urllib.error.HTTPError: HTTP Error 429: Too Many Requests

--------------------------------------------------

--- Running: 1D_Burgers_Equation.py ---
Exit Code: 0
Output:

Errors:
Error: failed to send plot to http://127.0.0.1:63342
Traceback (most recent call last):
  File "/home/weichao/Downloads/pycharm-2023.2.1/plugins/python/helpers/pycharm_display/datalore/display/display_.py", line 86, in _send_display_message
    urllib_request.urlopen(url, buffer)
  File "/opt/Dino_parallel/lib/python3.8/urllib/request.py", line 222, in urlopen
    return opener.open(url, data, timeout)
  File "/opt/Dino_parallel/lib/python3.8/urllib/request.py", line 531, in open
    response = meth(req, response)
  File "/opt/Dino_parallel/lib/python3.8/urllib/request.py", line 640, in http_response
    response = self.parent.error(
  File "/opt/Dino_parallel/lib/python3.8/urllib/request.py", line 569, in error
    return self._call_chain(*args)
  File "/opt/Dino_parallel/lib/python3.8/urllib/request.py", line 502, in _call_chain
    result = func(*args)
  File "/opt/Dino_parallel/lib/python3.8/urllib/request.py", line 649, in http_error_default
    raise HTTPError(req.full_url, code, msg, hdrs, fp)
urllib.error.HTTPError: HTTP Error 429: Too Many Requests

During handling of the above exception, another exception occurred:

Traceback (most recent call last):
  File "/home/weichao/Downloads/pycharm-2023.2.1/plugins/python/helpers/pycharm_display/datalore/display/display_.py", line 61, in try_empty_proxy
    urllib_request.urlopen(url, buffer)
  File "/opt/Dino_parallel/lib/python3.8/urllib/request.py", line 222, in urlopen
    return opener.open(url, data, timeout)
  File "/opt/Dino_parallel/lib/python3.8/urllib/request.py", line 531, in open
    response = meth(req, response)
  File "/opt/Dino_parallel/lib/python3.8/urllib/request.py", line 640, in http_response
    response = self.parent.error(
  File "/opt/Dino_parallel/lib/python3.8/urllib/request.py", line 569, in error
    return self._call_chain(*args)
  File "/opt/Dino_parallel/lib/python3.8/urllib/request.py", line 502, in _call_chain
    result = func(*args)
  File "/opt/Dino_parallel/lib/python3.8/urllib/request.py", line 649, in http_error_default
    raise HTTPError(req.full_url, code, msg, hdrs, fp)
urllib.error.HTTPError: HTTP Error 429: Too Many Requests

--------------------------------------------------

